Workbook

Sheet Cover
A16: TIMES-Ireland Model
A19: Document type: | B19: System Settings
A20: Sector(s): | B20: All sectors
A21: Purpose: | B21: Specifies various settings, including regions, timeslices and periods
A23: Original developer(s): | B23: James Glynn (UCC, james.glynn@ucc.ie)
B24: Olexandr Balyk (UCC, olexandr.balyk@ucc.ie)
A26: Current maintainer(s): | B26: Bakytzhan Suleimenov (UCC, bsuleimenov@ucc.ie)
A29: Part of TIM version: | B29: 1
A30: Model repository: | B30: https://github.com/MaREI-EPMG/TIMES-Ireland-model
A31: Licence: | B31: CC BY-NC-SA 4.0 (unless specified otherwise)
B32: https://creativecommons.org/licenses/by-nc-sa/4.0/

Sheet Regions
C3: {=IF(INDEX(C5:C7,$A$4)<>0,INDEX(C5:C7,$A$4),"")} -> IE | D3: {=IF(INDEX(D5:D7,$A$4)<>0,INDEX(D5:D7,$A$4),"")} -> National | E3: {=IF(INDEX(E5:E7,$A$4)<>0,INDEX(E5:E7,$A$4),"")} -> IE-CW | F3: {=IF(INDEX(F5:F7,$A$4)<>0,INDEX(F5:F7,$A$4),"")} -> IE-D | G3: {=IF(INDEX(G5:G7,$A$4)<>0,INDEX(G5:G7,$A$4),"")} -> IE-KE | H3: {=IF(INDEX(H5:H7,$A$4)<>0,INDEX(H5:H7,$A$4),"")} -> IE-KK | I3: {=IF(INDEX(I5:I7,$A$4)<>0,INDEX(I5:I7,$A$4),"")} -> IE-LS | J3: {=IF(INDEX(J5:J7,$A$4)<>0,INDEX(J5:J7,$A$4),"")} -> IE-LD | ... AD3: {=IF(INDEX(AD5:AD7,$A$4)<>0,INDEX(AD5:AD7,$A$4),"")} -> IE-MN
A4: 1
A5: Development | C5: IE | D5: National | E5: =A11 -> IE-CW | F5: =A16 -> IE-D | G5: =A19 -> IE-KE | H5: =A20 -> IE-KK | I5: =A21 -> IE-LS | J5: =A24 -> IE-LD | K5: =A25 -> IE-LH | L5: =A27 -> IE-MH | M5: =A29 -> IE-OY | N5: =A34 -> IE-WH | O5: =A35 -> IE-WX | P5: =A36 -> IE-WW | Q5: =A13 -> IE-CE | R5: =A14 -> IE-CO | S5: =A18 -> IE-KY | T5: =A23 -> IE-LK | U5: =A32 -> IE-TA | V5: =A33 -> IE-WD | W5: =A17 -> IE-G | X5: =A22 -> IE-LM | Y5: =A26 -> IE-MO | Z5: =A30 -> IE-RN | AA5: =A31 -> IE-SO | AB5: =A12 -> IE-CN | AC5: =A15 -> IE-DL | AD5: =A28 -> IE-MN
A6: Single-region | C6: =C5 -> IE
A7: Multi-region | C7: =D5 -> National | D7: =E5 -> IE-CW | E7: =F5 -> IE-D | F7: =G5 -> IE-KE | G7: =H5 -> IE-KK | H7: =I5 -> IE-LS | I7: =J5 -> IE-LD | J7: =K5 -> IE-LH | ... AC7: =AD5 -> IE-MN
A10: Code | B10: County name
A11: IE-CW | B11: Carlow
A12: IE-CN | B12: Cavan
A13: IE-CE | B13: Clare
A14: IE-CO | B14: Cork
A15: IE-DL | B15: Donegal
A16: IE-D | B16: Dublin
A17: IE-G | B17: Galway
A18: IE-KY | B18: Kerry
A19: IE-KE | B19: Kildare
A20: IE-KK | B20: Kilkenny
A21: IE-LS | B21: Laois
... A36: IE-WW | B36: Wicklow
A37: Source: https://en.wikipedia.org/wiki/ISO_3166-2:IE

Sheet Region Definition
B3: ~BookRegions_Map
B4: BookName | C4: Region
B5: IE | C5: =Regions!C3 -> IE
C6: =Regions!D3 -> National
C7: =Regions!E3 -> IE-CW
C8: =Regions!F3 -> IE-D
C9: =Regions!G3 -> IE-KE
C10: =Regions!H3 -> IE-KK
C11: =Regions!I3 -> IE-LS
C12: =Regions!J3 -> IE-LD
C13: =Regions!K3 -> IE-LH
C14: =Regions!L3 -> IE-MH
C15: =Regions!M3 -> IE-OY
C16: =Regions!N3 -> IE-WH
C17: =Regions!O3 -> IE-WX
C18: =Regions!P3 -> IE-WW
C19: =Regions!Q3 -> IE-CE
C20: =Regions!R3 -> IE-CO
C21: =Regions!S3 -> IE-KY
C22: =Regions!T3 -> IE-LK
C23: =Regions!U3 -> IE-TA
C24: =Regions!V3 -> IE-WD
C25: =Regions!W3 -> IE-G
C26: =Regions!X3 -> IE-LM
C27: =Regions!Y3 -> IE-MO
C28: =Regions!Z3 -> IE-RN
C29: =Regions!AA3 -> IE-SO
C30: =Regions!AB3 -> IE-CN
C31: =Regions!AC3 -> IE-DL
C32: =Regions!AD3 -> IE-MN

Sheet TimePeriods
B3: ~StartYear
B4: 2018
B7: ~ActivePDef
B8: P15
B11: ~TimePeriods
B12: P5 | C12: P9 | D12: P12 | E12: P13 | F12: P15 | G12: P23 | H12: P33 | I12: P39 | J12: P16 | K12: P24 | L12: P53 | M12: P54 | P12: P5 | Q12: P9 | R12: P12 | S12: P13 | T12: P15 | U12: P23 | V12: P33 | W12: P39 | X12: P16 | Y12: P24
B13: 1 | C13: 1 | D13: 1 | E13: 1 | F13: 1 | G13: 1 | H13: 1 | I13: 1 | J13: 1 | K13: 1 | L13: 1 | M13: 1 | P13: =+B4 -> 2018 | Q13: =+P13 -> 2018 | R13: =+Q13 -> 2018 | S13: =+R13 -> 2018 | T13: =+S13 -> 2018 | U13: =+T13 -> 2018 | V13: =+U13 -> 2018 | W13: =+V13 -> 2018 | X13: =+W13 -> 2018 | Y13: =+X13 -> 2018
B14: 1 | C14: 1 | D14: 4 | E14: 3 | F14: 1 | G14: 1 | H14: 1 | I14: 1 | J14: 1 | K14: 1 | L14: 1 | M14: 1 | P14: =+P13+B14 -> 2019 | Q14: =+Q13+C14 -> 2019 | R14: =+R13+D14 -> 2022 | S14: =+S13+E14 -> 2021 | T14: =+T13+F14 -> 2019 | U14: =+U13+G14 -> 2019 | V14: =+V13+H14 -> 2019 | W14: =+W13+I14 -> 2019 | ... Y14: =+Y13+K14 -> 2019
B15: 1 | C15: 1 | D15: 5 | E15: 1 | F15: 1 | G15: 1 | H15: 1 | I15: 1 | J15: 1 | K15: 1 | L15: 1 | M15: 1 | P15: =+P14+B15 -> 2020 | Q15: =+Q14+C15 -> 2020 | R15: =+R14+D15 -> 2027 | S15: =+S14+E15 -> 2022 | T15: =+T14+F15 -> 2020 | U15: =+U14+G15 -> 2020 | V15: =+V14+H15 -> 2020 | W15: =+W14+I15 -> 2020 | ... Y15: =+Y14+K15 -> 2020
B16: 20 | C16: 1 | D16: 5 | E16: 5 | F16: 1 | G16: 1 | H16: 1 | I16: 1 | J16: 1 | K16: 1 | L16: 1 | M16: 1 | P16: =+P15+B16 -> 2040 | Q16: =+Q15+C16 -> 2021 | R16: =+R15+D16 -> 2032 | S16: =+S15+E16 -> 2027 | T16: =+T15+F16 -> 2021 | U16: =+U15+G16 -> 2021 | V16: =+V15+H16 -> 2021 | W16: =+W15+I16 -> 2021 | ... Y16: =+Y15+K16 -> 2021
B17: 20 | C17: 1 | D17: 5 | E17: 5 | F17: 1 | G17: 1 | H17: 1 | I17: 1 | J17: 1 | K17: 1 | L17: 1 | M17: 1 | P17: =+P16+B17 -> 2060 | Q17: =+Q16+C17 -> 2022 | R17: =+R16+D17 -> 2037 | S17: =+S16+E17 -> 2032 | T17: =+T16+F17 -> 2022 | U17: =+U16+G17 -> 2022 | V17: =+V16+H17 -> 2022 | W17: =+W16+I17 -> 2022 | ... Y17: =+Y16+K17 -> 2022
C18: 5 | D18: 5 | E18: 5 | F18: 5 | G18: 1 | H18: 1 | I18: 1 | J18: 1 | K18: 1 | L18: 1 | M18: 1 | Q18: =+Q17+C18 -> 2027 | R18: =+R17+D18 -> 2042 | S18: =+S17+E18 -> 2037 | T18: =+T17+F18 -> 2027 | U18: =+U17+G18 -> 2023 | V18: =+V17+H18 -> 2023 | W18: =+W17+I18 -> 2023 | X18: =+X17+J18 -> 2023 | Y18: =+Y17+K18 -> 2023
C19: 45 | D19: 5 | E19: 5 | F19: 5 | G19: 1 | H19: 1 | I19: 1 | J19: 1 | K19: 1 | L19: 1 | M19: 1 | Q19: =+Q18+C19 -> 2072 | R19: =+R18+D19 -> 2047 | S19: =+S18+E19 -> 2042 | T19: =+T18+F19 -> 2032 | U19: =+U18+G19 -> 2024 | V19: =+V18+H19 -> 2024 | W19: =+W18+I19 -> 2024 | X19: =+X18+J19 -> 2024 | Y19: =+Y18+K19 -> 2024
C20: 25 | D20: 5 | E20: 5 | F20: 5 | G20: 1 | H20: 1 | I20: 1 | J20: 1 | K20: 1 | L20: 1 | M20: 1 | Q20: =+Q19+C20 -> 2097 | R20: =+R19+D20 -> 2052 | S20: =+S19+E20 -> 2047 | T20: =+T19+F20 -> 2037 | U20: =+U19+G20 -> 2025 | V20: =+V19+H20 -> 2025 | W20: =+W19+I20 -> 2025 | X20: =+X19+J20 -> 2025 | Y20: =+Y19+K20 -> 2025
C21: 5 | D21: 5 | E21: 5 | F21: 5 | G21: 1 | H21: 1 | I21: 1 | J21: 10 | K21: 3 | L21: 1 | M21: 1 | Q21: =+Q20+C21 -> 2102 | R21: =+R20+D21 -> 2057 | S21: =+S20+E21 -> 2052 | T21: =+T20+F21 -> 2042 | U21: =+U20+G21 -> 2026 | V21: =+V20+H21 -> 2026 | W21: =+W20+I21 -> 2026 | X21: =+X20+J21-5 -> 2030 | Y21: =+Y20+K21-1 -> 2027
D22: 5 | E22: 5 | F22: 5 | G22: 1 | H22: 1 | I22: 1 | J22: 10 | K22: 4 | L22: 1 | M22: 1 | R22: =+R21+D22 -> 2062 | S22: =+S21+E22 -> 2057 | T22: =+T21+F22 -> 2047 | U22: =+U21+G22 -> 2027 | V22: =+V21+H22 -> 2027 | W22: =+W21+I22 -> 2027 | X22: =+X21+J22 -> 2040 | Y22: =+Y21+K22-2 -> 2029
D23: 5 | E23: 5 | F23: 5 | G23: 1 | H23: 1 | I23: 1 | J23: 10 | K23: 5 | L23: 1 | M23: 1 | R23: =+R22+D23 -> 2067 | S23: =+S22+E23 -> 2062 | T23: =+T22+F23 -> 2052 | U23: =+U22+G23 -> 2028 | V23: =+V22+H23 -> 2028 | W23: =+W22+I23 -> 2028 | X23: =+X22+J23 -> 2050 | Y23: =+Y22+K23 -> 2034
D24: 5 | E24: 5 | F24: 5 | G24: 1 | H24: 1 | I24: 1 | J24: 10 | K24: 5 | L24: 1 | M24: 1 | R24: =+R23+D24 -> 2072 | S24: =+S23+E24 -> 2067 | T24: =+T23+F24 -> 2057 | U24: =+U23+G24 -> 2029 | V24: =+V23+H24 -> 2029 | W24: =+W23+I24 -> 2029 | X24: =+X23+J24 -> 2060 | Y24: =+Y23+K24 -> 2039
E25: 5 | F25: 5 | G25: 1 | H25: 1 | I25: 1 | J25: 10 | K25: 5 | L25: 1 | M25: 1 | S25: =+S24+E25 -> 2072 | T25: =+T24+F25 -> 2062 | U25: =+U24+G25 -> 2030 | V25: =+V24+H25 -> 2030 | W25: =+W24+I25 -> 2030 | X25: =+X24+J25 -> 2070 | Y25: =+Y24+K25 -> 2044
F26: 5 | G26: 1 | H26: 1 | I26: 1 | J26: 10 | K26: 5 | L26: 1 | M26: 1 | T26: =+T25+F26 -> 2067 | U26: =+U25+G26 -> 2031 | V26: =+V25+H26 -> 2031 | W26: =+W25+I26 -> 2031 | X26: =+X25+J26 -> 2080 | Y26: =+Y25+K26 -> 2049
F27: 5 | G27: 1 | H27: 1 | I27: 1 | J27: 10 | K27: 5 | L27: 1 | M27: 1 | T27: =+T26+F27 -> 2072 | U27: =+U26+G27 -> 2032 | V27: =+V26+H27 -> 2032 | W27: =+W26+I27 -> 2032 | X27: =+X26+J27 -> 2090 | Y27: =+Y26+K27 -> 2054
G28: 5 | H28: 1 | I28: 1 | J28: 10 | K28: 5 | L28: 1 | M28: 1 | U28: =+U27+G28 -> 2037 | V28: =+V27+H28 -> 2033 | W28: =+W27+I28 -> 2033 | X28: =+X27+J28 -> 2100 | Y28: =+Y27+K28 -> 2059
G29: 5 | H29: 1 | I29: 1 | K29: 5 | L29: 1 | M29: 1 | U29: =+U28+G29 -> 2042 | V29: =+V28+H29 -> 2034 | W29: =+W28+I29 -> 2034 | Y29: =+Y28+K29 -> 2064
G30: 5 | H30: 1 | I30: 1 | K30: 5 | L30: 1 | M30: 1 | U30: =+U29+G30 -> 2047 | V30: =+V29+H30 -> 2035 | W30: =+W29+I30 -> 2035 | Y30: =+Y29+K30 -> 2069
G31: 5 | H31: 1 | I31: 1 | K31: 5 | L31: 1 | M31: 1 | U31: =+U30+G31 -> 2052 | V31: =+V30+H31 -> 2036 | W31: =+W30+I31 -> 2036 | Y31: =+Y30+K31 -> 2074
G32: 5 | H32: 1 | I32: 1 | K32: 5 | L32: 1 | M32: 1 | U32: =+U31+G32 -> 2057 | V32: =+V31+H32 -> 2037 | W32: =+W31+I32 -> 2037 | Y32: =+Y31+K32 -> 2079
G33: 5 | H33: 1 | I33: 1 | K33: 5 | L33: 1 | M33: 1 | U33: =+U32+G33 -> 2062 | V33: =+V32+H33 -> 2038 | W33: =+W32+I33 -> 2038 | Y33: =+Y32+K33 -> 2084
G34: 5 | H34: 1 | I34: 1 | K34: 5 | L34: 1 | M34: 1 | U34: =+U33+G34 -> 2067 | V34: =+V33+H34 -> 2039 | W34: =+W33+I34 -> 2039 | Y34: =+Y33+K34 -> 2089
G35: 5 | H35: 1 | I35: 1 | K35: 5 | L35: 1 | M35: 1 | U35: =+U34+G35 -> 2072 | V35: =+V34+H35 -> 2040 | W35: =+W34+I35 -> 2040 | Y35: =+Y34+K35 -> 2094
H36: 1 | I36: 1 | K36: 5 | L36: 1 | M36: 1 | V36: =+V35+H36 -> 2041 | W36: =+W35+I36 -> 2041 | Y36: =+Y35+K36 -> 2099
H37: 1 | I37: 1 | L37: 1 | M37: 1 | V37: =+V36+H37 -> 2042 | W37: =+W36+I37 -> 2042
H38: 1 | I38: 1 | L38: 1 | M38: 1 | V38: =+V37+H38 -> 2043 | W38: =+W37+I38 -> 2043
H39: 1 | I39: 1 | L39: 1 | M39: 1 | V39: =+V38+H39 -> 2044 | W39: =+W38+I39 -> 2044
H40: 1 | I40: 1 | L40: 1 | M40: 1 | V40: =+V39+H40 -> 2045 | W40: =+W39+I40 -> 2045
H41: 1 | I41: 1 | L41: 1 | M41: 1 | V41: =+V40+H41 -> 2046 | W41: =+W40+I41 -> 2046
H42: 1 | I42: 1 | L42: 1 | M42: 1 | V42: =+V41+H42 -> 2047 | W42: =+W41+I42 -> 2047
H43: 1 | I43: 1 | L43: 1 | M43: 1 | V43: =+V42+H43 -> 2048 | W43: =+W42+I43 -> 2048
H44: 1 | I44: 1 | L44: 1 | M44: 1 | V44: =+V43+H44 -> 2049 | W44: =+W43+I44 -> 2049
H45: 1 | I45: 1 | L45: 1 | M45: 1 | V45: =+V44+H45 -> 2050 | W45: =+W44+I45 -> 2050
I46: 1 | L46: 1 | M46: 1 | W46: =+W45+I46 -> 2051
...

Sheet Import Settings
B3: ~ImpSettings
B4: Option | C4: Value
B5: Check #DIV/0 and #REF errors in Templates | C5: 1
B6: Create Dummy Imports for Energy and Material Commodities | C6: 1
B7: Create Dummy Imports for Demands | C7: 1
B8: Generate Vintage Bounds | C8: 0
B9: DumVarforUC | C9: 0

Sheet Interpol_Extrapol_Defaults
A13: Dummy Imp Prices
A14: ~TFM_UPD
A15: TimeSlice | B15: LimType | C15: Attribute | D15: Year | E15: Other_Indexes | F15: AllRegions | G15: REG1 | H15: REG2 | I15: Pset_Set | J15: Pset_PN | K15: Pset_PD | L15: Pset_CI | M15: Pset_CO | N15: Cset_Set | O15: Cset_CN | P15: Cset_CD
C16: ACTCOST | F16: 2500 | I16: IRE | J16: IMP*Z
C17: ACTCOST | F17: 5000 | I17: IRE | J17: IMPDEMZ
A19: ~TFM_INS
A20: TimeSlice | B20: LimType | C20: Attribute | D20: Year | E20: Other_Indexes | F20: AllRegions | G20: REG1 | H20: REG2 | I20: Pset_Set | J20: Pset_PN | K20: Pset_PD | L20: Pset_CI | M20: Pset_CO | N20: Cset_Set | O20: Cset_CN | P20: Cset_CD
A21: * | B21: * | C21: *FLO_BND | F21: * | I21: IRE | J21: IMP*Z | M21: IND* | O21: *HTH,*LTH,*MTH,*HET
C22: ACT_BND | F22: 0 | J22: IMPDEMZ
C23: ACT_BND | D23: 0 | F23: 5 | J23: IMP*Z,-IMPDUCZ
C24: ACT_BND | F24: 0 | J24: IMP*Z,-IMPDUCZ

Sheet Constants
B1: * Discount rates, Timeslices, Exchange rates
B3: ~TFM_INS
B4: TimeSlice | C4: CURR | D4: Attribute | E4: Year | F4: Other_Indexes | G4: AllRegions
D5: G_DYEAR | G5: 2018
D6: G_DRATE | G6: 0.04
C7: =_xlfn.CONCAT("MEUR",RIGHT(CPI!B3,4)) -> MEUR2000 | D7: G_CUREX | F7: MEUR2018 | G7: =CPI!$D$21/CPI!D3 -> 1.3926669
C8: =_xlfn.CONCAT("MEUR",RIGHT(CPI!B4,4)) -> MEUR2001 | D8: G_CUREX | F8: MEUR2018 | G8: =CPI!$D$21/CPI!D4 -> 1.3626878
C9: =_xlfn.CONCAT("MEUR",RIGHT(CPI!B5,4)) -> MEUR2002 | D9: G_CUREX | F9: MEUR2018 | G9: =CPI!$D$21/CPI!D5 -> 1.3346599
C10: =_xlfn.CONCAT("MEUR",RIGHT(CPI!B6,4)) -> MEUR2003 | D10: G_CUREX | F10: MEUR2018 | G10: =CPI!$D$21/CPI!D6 -> 1.3084901
C11: =_xlfn.CONCAT("MEUR",RIGHT(CPI!B7,4)) -> MEUR2004 | D11: G_CUREX | F11: MEUR2018 | G11: =CPI!$D$21/CPI!D7 -> 1.2828335
C12: =_xlfn.CONCAT("MEUR",RIGHT(CPI!B8,4)) -> MEUR2005 | D12: G_CUREX | F12: MEUR2018 | G12: =CPI!$D$21/CPI!D8 -> 1.2552187
C13: =_xlfn.CONCAT("MEUR",RIGHT(CPI!B9,4)) -> MEUR2006 | D13: G_CUREX | F13: MEUR2018 | G13: =CPI!$D$21/CPI!D9 -> 1.2281983
C14: =_xlfn.CONCAT("MEUR",RIGHT(CPI!B10,4)) -> MEUR2007 | D14: G_CUREX | F14: MEUR2018 | G14: =CPI!$D$21/CPI!D10 -> 1.2005848
C15: =_xlfn.CONCAT("MEUR",RIGHT(CPI!B11,4)) -> MEUR2008 | D15: G_CUREX | F15: MEUR2018 | G15: =CPI!$D$21/CPI!D11 -> 1.1577482
C16: =_xlfn.CONCAT("MEUR",RIGHT(CPI!B12,4)) -> MEUR2009 | D16: G_CUREX | F16: MEUR2018 | G16: =CPI!$D$21/CPI!D12 -> 1.1462853
C17: =_xlfn.CONCAT("MEUR",RIGHT(CPI!B13,4)) -> MEUR2010 | D17: G_CUREX | F17: MEUR2018 | G17: =CPI!$D$21/CPI!D13 -> 1.1227084
C18: =_xlfn.CONCAT("MEUR",RIGHT(CPI!B14,4)) -> MEUR2011 | D18: G_CUREX | F18: MEUR2018 | G18: =CPI!$D$21/CPI!D14 -> 1.088951
... C24: =_xlfn.CONCAT("MEUR",RIGHT(CPI!B20,4)) -> MEUR2017 | D24: G_CUREX | F24: MEUR2018 | G24: =CPI!$D$21/CPI!D20 -> 1.019
C25: =_xlfn.CONCAT("MEUR",RIGHT(CPI!B22,4)) -> MEUR2019 | D25: G_CUREX | F25: MEUR2018 | G25: =CPI!$D$21/CPI!D22 -> 0.98522167
C26: =_xlfn.CONCAT("MEUR",RIGHT(CPI!B23,4)) -> MEUR2020 | D26: G_CUREX | F26: MEUR2018 | G26: =CPI!$D$21/CPI!D23 -> 0.97837306
C27: =_xlfn.CONCAT("MEUR",RIGHT(CPI!B24,4)) -> MEUR2021 | D27: G_CUREX | F27: MEUR2018 | G27: =CPI!$D$21/CPI!D24 -> 0.95079987

Sheet Defaults
B2: ~Currencies | D2: DefUnits | M2: ~UnitConversion
B3: Currency | D3: Option | E3: SUP | F3: AGR | G3: IND | H3: PWR | I3: TRA | J3: SRV | K3: RSD | M3: from_unit | N3: to_unit | O3: multiplier
B4: MEUR2018 | D4: Process_ActUnit | E4: PJ | F4: PJ | H4: PJ | J4: PJ | M4: Billion Kwh | N4: PJ | O4: 3.6
B5: =Constants!C7 -> MEUR2000 | D5: Process_CapUnit | E5: PJa | F5: PJa | H5: GW | J5: GW | M5: Mt | N5: Kt | O5: 1000
B6: =Constants!C8 -> MEUR2001 | D6: Commodity_Unit | E6: PJ | F6: PJ | H6: PJ | J6: PJ | M6: BEuro | N6: MEuro | O6: 1000
B7: =Constants!C9 -> MEUR2002 | M7: ktoe | N7: PJ | O7: 0.04
B8: =Constants!C10 -> MEUR2003 | M8: mtoe | N8: PJ | O8: 41.87
B9: =Constants!C11 -> MEUR2004 | M9: Gwh | N9: PJ | O9: 0.0036
B10: =Constants!C12 -> MEUR2005 | M10: Gt | N10: Kt | O10: 1000000
B11: =Constants!C13 -> MEUR2006 | M11: EJ | N11: PJ | O11: 1000
B12: =Constants!C14 -> MEUR2007 | M12: Twh | N12: PJ | O12: 3.6
B13: =Constants!C15 -> MEUR2008 | M13: PJ | N13: PJ | O13: 1
B14: =Constants!C16 -> MEUR2009 | M14: Kt | N14: Kt | O14: 1
B15: =Constants!C17 -> MEUR2010 | M15: MEuro | N15: MEuro | O15: 1
B16: =Constants!C18 -> MEUR2011
B17: =Constants!C19 -> MEUR2012
B18: =Constants!C20 -> MEUR2013
B19: =Constants!C21 -> MEUR2014
B20: =Constants!C22 -> MEUR2015
B21: =Constants!C23 -> MEUR2016
B22: =Constants!C24 -> MEUR2017
B23: =Constants!C25 -> MEUR2019
B24: =Constants!C26 -> MEUR2020
B25: =Constants!C27 -> MEUR2021

Sheet CPI
C2: Euro inflation rate | D2: € CPI
B3: 2000 | D3: 100
B4: 2001 | C4: 0.022 | D4: =D3+D3*C4 -> 102.2
B5: 2002 | C5: 0.021 | D5: =D4+D4*C5 -> 104.3462
B6: 2003 | C6: 0.02 | D6: =D5+D5*C6 -> 106.43312
B7: 2004 | C7: 0.02 | D7: =D6+D6*C7 -> 108.56179
B8: 2005 | C8: 0.022 | D8: =D7+D7*C8 -> 110.95015
B9: 2006 | C9: 0.022 | D9: =D8+D8*C9 -> 113.39105
B10: 2007 | C10: 0.023 | D10: =D9+D9*C10 -> 115.99904
B11: 2008 | C11: 0.037 | D11: =D10+D10*C11 -> 120.29101
B12: 2009 | C12: 0.01 | D12: =D11+D11*C12 -> 121.49392
B13: 2010 | C13: 0.021 | D13: =D12+D12*C13 -> 124.04529
B14: 2011 | C14: 0.031 | D14: =D13+D13*C14 -> 127.89069
B15: 2012 | C15: 0.026 | D15: =D14+D14*C15 -> 131.21585
... B24: 2021 | C24: 0.029 | D24: =D23+D23*C24 -> 146.47319
B26: Source: Eurostat
