Workbook
Name FID_1: [1]AGR_Fuels!$A$2

Sheet Cover

Sheet FRS_Processes
B1: Fixed layout table
B3: * Define the Processes used in this workbook
B5: Processes
B6: ~FI_Process
B7: Sets | C7: Region | D7: TechName | E7: TechDesc | F7: Tact | G7: Tcap | H7: Tslvl | I7: PrimaryCG | J7: Vintage
B8: *Process Set Membership | C8: Region Name | D8: Technology Name | E8: Technology Description | F8: Activity Unit | G8: Capacity Unit | H8: TimeSlice level of Process Activity | I8: Primary Commodity Group | J8: Vintage Tracking
B9: MIN | C9: IE,National | D9: FORLANDPOT | E9: Forest land potential | F9: Mha | G9: Mha | J9: NO
B10: PRE | C10: IE,National | D10: WOODPRO_PROC | E10: Wood products processing | F10: Mm3 | G10: Mm3 | I10: ROUNDWOOD | J10: NO
B11: PRE | C11: IE,National | D11: PCRW_TECH | E11: Post consumer recycled wood | F11: Mm3 | G11: Mm3 | J11: NO
B12: IMP | C12: IE,National | D12: IMPSAWResidues | E12: Sawmill residues import | F12: Mm3 | G12: Mm3 | J12: NO
B13: PRE | C13: IE,National | D13: BIOWPE_Domestic | E13: Domestic production of WPE | F13: PJ | G13: Mm3 | J13: NO
B14: PRE | C14: IE,National | D14: ABIOFRSR1 | E14: Forestry residues harvest | F14: PJ | G14: Mm3 | J14: NO
B15: PRE | C15: IE,National | D15: MINBIOWOO1_S1 | E15: Sawmill residues biomass | F15: PJ | G15: Mm3 | J15: NO
B16: PRE | C16: IE,National | D16: MINBIOWOO2_S1 | E16: PCRW biomass | F16: PJ | G16: Mm3 | J16: NO
B17: PRE | C17: IE,National | D17: ABIOFRSR2 | E17: Forestry residues harvest step 2 | F17: PJ | G17: Mm3 | J17: NO
B18: PRE | C18: IE,National | D18: ABIOFRSR3 | E18: Forestry residues harvest step 3 | F18: PJ | G18: Mm3 | J18: NO
B19: PRE | C19: IE,National | D19: MINBIOWOO1_S2 | E19: Sawmill residues biomass step 2 | F19: PJ | G19: Mm3 | J19: NO
B20: PRE | C20: IE,National | D20: MINBIOWOO1_S3 | E20: Sawmill residues biomass step 3 | F20: PJ | G20: Mm3 | J20: NO
B21: PRE | C21: IE,National | D21: MINBIOWOO2_S2 | E21: PCRW biomass step 2 | F21: PJ | G21: Mm3 | J21: NO
B22: PRE | C22: IE,National | D22: MINBIOWOO2_S3 | E22: PCRW biomass step 3 | F22: PJ | G22: Mm3 | J22: NO
B26: ~FI_Process
B27: Sets | C27: Region | D27: TechName | E27: TechDesc | F27: Tact | G27: Tcap | H27: Tslvl | I27: PrimaryCG | J27: Vintage
B28: *Process Set Membership | C28: Region Name | D28: Technology Name | E28: Technology Description | F28: Activity Unit | G28: Capacity Unit | H28: TimeSlice level of Process Activity | I28: Primary Commodity Group | J28: Vintage Tracking
B29: * | C29: IE,National | D29: Forest_Stock_Nat | E29: Natural forest stock | F29: Mha | G29: Mha | J29: NO
B30: * | C30: IE,National | D30: Forest_Stock_Plan | E30: Regenerated forest stock | F30: Mha | G30: Mha | J30: NO
B31: PRE | C31: IE,National | D31: FOR_Thin | E31: Thinning of forest | F31: Mm3 | G31: Mha | J31: NO
B32: PRE | C32: IE,National | D32: FOR_Felled | E32: Clearfelling of forest | F32: Mm3 | G32: Mha | J32: NO
B33: PRE | C33: IE,National | D33: AFORRWOOD_PROC | E33: Round wood processed | F33: Mm3 | G33: Mm3 | I33: FORRWOOD_RAW | J33: NO
B34: PRE | C34: IE,National | D34: AFORSEXP | E34: Forest remaining stock | F34: Mha | G34: Mha | J34: NO
B35: EXP | C35: IE,National | D35: FORStock | E35: Total NIR Forest Stock | F35: Mha | G35: Mha | J35: NO
B36: PRE | C36: IE,National | D36: OA_stock | E36: Open area stock | F36: Mha | G36: Mha | J36: NO
B37: MIN | C37: IE,National | D37: OpenArea | E37: Open area forest - intent to use | F37: Mha | G37: Mha | J37: NO
B38: PRE | C38: IE,National | D38: ManagedForest_00 | E38: Existing Managed forest | F38: Mha | G38: Mha | J38: YES
B39: PRE | C39: IE,National | D39: FORLAND_00 | E39: Forest remaining as forest | F39: Mha | G39: Mha | J39: NO
N40: s

Sheet FRS_Comm
B1: Fixed layout table
B4: * Define the commodities used in this workbook
B6: Commodities
B7: ~FI_Comm
B8: Csets | C8: Region | D8: CommName | E8: CommDesc | F8: Unit | G8: LimType | H8: CTSLvl | I8: PeakTS | J8: Ctype
B9: *Commodity Set Membership | C9: Region Name | D9: Commodity Name | E9: Commodity Description | F9: Unit | G9: Sense of the Balance EQN. | H9: Timeslice Level | I9: Peak Monitoring | J9: Electricity Indicator
B10: MAT | C10: IE,National | D10: FORLAND | E10: Forestry land | F10: Mha
B11: MAT | C11: IE,National | D11: WOOD_Products | E11: Wood products processed | F11: Mm3
B12: MAT | C12: IE,National | D12: WOOD_Otheruses | E12: Wood for other uses | F12: Mm3
B13: MAT | C13: IE,National | D13: WOOD_RES | E13: wood based energy - residues | F13: Mm3
B14: NRG | C14: IE,National | D14: BIOWPE | E14: Wood pellets from wood residues | F14: PJ
B15: NRG | C15: IE,National | D15: BIOWOO1 | E15: Biomass feedstock / sawmill residues | F15: PJ
B16: NRG | C16: IE,National | D16: BIOWOO2 | E16: Biomass feedstock / PCRW residues | F16: PJ
B19: ~FI_Comm
B20: Csets | C20: Region | D20: CommName | E20: CommDesc | F20: Unit | G20: LimType | H20: CTSLvl | I20: PeakTS | J20: Ctype
B21: *Commodity Set Membership | C21: Region Name | D21: Commodity Name | E21: Commodity Description | F21: Unit | G21: Sense of the Balance EQN. | H21: Timeslice Level | I21: Peak Monitoring | J21: Electricity Indicator
B22: MAT | C22: IE,National | D22: FOR_OpenArea | E22: Open forest area | F22: Mha
B23: MAT | C23: IE,National | D23: FOR_Managed | E23: Forest stock | F23: Mha
B24: MAT | C24: IE,National | D24: FORRWOOD_RAW | E24: Forest roundwood harvested | F24: Mm3
B25: MAT | C25: IE,National | D25: ROUNDWOOD | E25: Forest roundwood processed | F25: Mm3
B26: MAT | C26: IE,National | D26: HARVEST_RES | E26: Forest harvest residues | F26: Mm3
B27: MAT | C27: IE,National | D27: RES_LOSS_EXP | E27: Harvested residues losses or exports | F27: Mm3
B28: MAT | C28: IE,National | D28: FORLANDSEQ | E28: Forest land available for sequestration | F28: Mha
B29: MAT | C29: IE,National | D29: FOREST_00 | E29: Forest remaining forest | F29: Mha

Sheet Forest_flows
I4: ~FI_T
B5: TechName | C5: *TechDesc | D5: Comm_IN | E5: Comm_OUT | F5: ACT_BND~FX | G5: ACT_BND~FX~0 | H5: Input | I5: Output | J5: CAP2ACT | K5: EFF | L5: AF | M5: AFA~fx | N5: LIFE
B6: *Description and units | K6: Harvest yield (Mm3 / Mha)
B7: *Forest land resources
B8: *FORLANDPOT | E8: *FOREST_00 | N8: 100
B9: FORLAND_00 | C9: Forest remaining forest | D9: IRL_Land | E9: FORLAND | F9: 0.4428 | G9: 5 | H9: 1 | I9: 1 | J9: 1 | N9: 100
B10: ManagedForest_00 | C10: Managed forest | D10: FORLAND | E10: FOR_Managed | H10: 1 | I10: 1 | J10: 1 | M10: 1 | N10: 100
B11: *harvesting
B12: =FRS_Processes!D31 -> FOR_Thin | D12: FOR_Managed | E12: =FRS_Comm!D24 -> FORRWOOD_RAW | K12: 104 | M12: 1 | N12: 1
B13: =FRS_Processes!D32 -> FOR_Felled | D13: FOR_Managed | E13: FORRWOOD_RAW | K13: 490 | M13: 1 | N13: 1
B14: =FRS_Processes!D33 -> AFORRWOOD_PROC | D14: FORRWOOD_RAW | H14: 1 | N14: 1
E15: =FRS_Comm!D25 -> ROUNDWOOD | I15: 0.88
E16: =FRS_Comm!D26 -> HARVEST_RES | I16: 0.024
E17: =FRS_Comm!D27 -> RES_LOSS_EXP | I17: 0.096
B18: WOODPRO_PROC | C18: Wood products processing | D18: ROUNDWOOD | H18: 1 | N18: 1
E19: WOOD_Products | I19: 0.54
E20: WOOD_Otheruses | I20: 0.1
E21: WOOD_RES | I21: 0.36
G26: ~FI_T
B27: TechName | C27: *TechDesc | D27: Comm_IN | E27: Comm_OUT | F27: Input | G27: Output | H27: CAP2ACT | I27: EFF | J27: AFA~FX | K27: LIFE
B28: *Vintage process for age based emissions shaping
B29: FORStock | C29: Standing forest area | D29: FOR_Managed | H29: 1

Sheet Forest Area change
B3: Change in managed forest land as per NID
C5: ~FI_T: NCAP_Pasti
B6: TechName | C6: 1990 | D6: 1991 | E6: 1992 | F6: 1993 | G6: 1994 | H6: 1995 | I6: 1996 | J6: 1997 | K6: 1998 | L6: 1999 | M6: 2000 | N6: 2001 | O6: 2002 | P6: 2003 | Q6: 2004 | R6: 2005 | S6: 2006 | T6: 2007 | U6: 2008 | V6: 2009 | W6: 2010 | X6: 2011 | Y6: 2012 | Z6: 2013 | AA6: 2014 | AB6: 2015 | AC6: 2016 | AD6: 2017
B7: ManagedForest_00 | C7: 0.48107 | D7: 0.01798683 | E7: 0.01568196 | F7: 0.0150252 | G7: 0.01826906 | H7: 0.02196424 | I7: 0.019435 | J7: 0.01043678 | K7: 0.01184715 | L7: 0.01159328 | M7: 0.01394391 | N7: 0.01373705 | O7: 0.01335155 | P7: 0.00775706 | Q7: 0.00834942 | R7: 0.00868791 | S7: 0.00566971 | T7: 0.00523719 | U7: 0.00399606 | V7: 7.064e-05 | W7: 0.00209 | X7: 0.0305 | Y7: 0.00586 | Z7: 0.00464 | AA7: 0.00577 | AB7: 0.00548 | AC7: 0.0053 | AD7: 0.00514

Sheet Forest_Biomass
H4: ~FI_T
C5: TechName | D5: *TechDesc | E5: Comm_IN | F5: Comm_OUT | G5: Input | H5: Output | I5: CAP2ACT | J5: EFF
C6: *Forest biomass feedstock
C7: ABIOFRSR1 | D7: Forest residues harvest step 1 | E7: HARVEST_RES | F7: BIOWOO | G7: 0.106 | H7: 1 | I7: 9.4
C8: MINBIOWOO1_S1 | D8: Sawmill residues biomass step 1 | E8: WOOD_RES | F8: BIOWOO1 | G8: 0.076 | H8: 1 | I8: 13.1
C9: MINBIOWOO2_S1 | D9: PCRW biomass step 1 | E9: WOOD_RES | F9: BIOWOO2 | G9: 0.076 | H9: 1 | I9: 13.1
C10: BIOWPE_Domestic | D10: Domestic WPE production | E10: WOOD_RES | F10: BIOWPE | G10: 0.076 | H10: 1 | I10: 17.28
I23: FI_T
C24: TechName | D24: *TechDesc | E24: Comm_IN | F24: Comm_OUT | G24: Input | H24: Output | I24: CAP2ACT | J24: EFF
C25: *Forest biomass feedstock
C26: ABIOFRSR1 | D26: Forest residues harvest step 1 | E26: HARVEST_RES | F26: BIOWOO | G26: 0.106 | H26: 1 | I26: 9.4
C27: ABIOFRSR2 | D27: Forest residues harvest step 2 | E27: HARVEST_RES | F27: BIOWOO | G27: 0.106 | H27: 1 | I27: 9.4
C28: ABIOFRSR3 | D28: Forest residues harvest step 3 | E28: HARVEST_RES | F28: BIOWOO | G28: 0.106 | H28: 1 | I28: 9.4
C29: MINBIOWOO1_S1 | D29: Sawmill residues biomass step 1 | E29: WOOD_RES | F29: BIOWOO1 | G29: 0.076 | H29: 1 | I29: 13.1
C30: MINBIOWOO1_S2 | D30: Sawmill residues biomass step 2 | E30: WOOD_RES | F30: BIOWOO1 | G30: 0.076 | H30: 1 | I30: 13.1
C31: MINBIOWOO1_S3 | D31: Sawmill residues biomass step 3 | E31: WOOD_RES | F31: BIOWOO1 | G31: 0.076 | H31: 1 | I31: 13.1
C32: MINBIOWOO2_S1 | D32: PCRW biomass step 1 | E32: WOOD_RES | F32: BIOWOO2 | G32: 0.076 | H32: 1 | I32: 13.1
C33: MINBIOWOO2_S2 | D33: PCRW biomass step 2 | E33: WOOD_RES | F33: BIOWOO2 | G33: 0.076 | H33: 1 | I33: 13.1
C34: MINBIOWOO2_S3 | D34: PCRW biomass step 3 | E34: WOOD_RES | F34: BIOWOO2 | G34: 0.076 | H34: 1 | I34: 13.1
C35: BIOWPE_Domestic | D35: Domestic WPE production | E35: WOOD_RES | F35: BIOWPE | G35: 0.076 | H35: 1 | I35: 17.28

Sheet HWP_storage
B4: ~FI_Comm
B5: Csets | C5: CommName | D5: CommDesc | E5: Unit | F5: LimType | G5: CTSLvl | H5: PeakTS | I5: Ctype
B6: \I: Commodity Set Membership | C6: Commodity Name | D6: Commodity Description | E6: Unit | F6: Balance Equ Type Override | G6: Timeslice Tracking Level | H6: Peak Monitoring | I6: Electricity Indicator
B7: MAT | C7: HWP_Cstored | D7: Carbon stored in HWP | E7: tC
B8: MAT | C8: HWP_Cinflow | D8: C inflow from wood products | E8: tC
B9: ENV | C9: EMI_HWP_C | D9: HWP harvesting emissions | E9: tC
B10: ENV | C10: EMI_HWP_Sink | D10: HWP sink (annual) | E10: tC
B13: ~FI_Process
B14: Sets | C14: TechName | D14: TechDesc | E14: Tact | F14: Tcap | G14: Tslvl | H14: PrimaryCG | I14: Vintage
B15: \I: Process Set Membership | C15: Technology Name | D15: Technology Description | E15: Activity Unit | F15: Capacity Unit | G15: Timeslice Operational Level | H15: Operational Commodity Group | I15: Vintage Tracking
B16: PRE | C16: HWP_Carbon | D16: HWP C from wood products | E16: Mm3 | F16: Mm3 | H16: WOOD_Products | I16: NO
B17: PRE | C17: HWP_CO2_inflow | D17: HWP carbon inflow | E17: tC | F17: tC | H17: HWP_Cinflow | I17: NO
B18: STK | C18: HWP_CO2storage | D18: HWP carbon storage | E18: tC | F18: tC | G18: ANNUAL | I18: NO
H23: ~FI_T
B24: TechName | C24: TechDesc | D24: Comm-IN | E24: Comm-OUT | F24: Comm-IN-A | G24: Comm-OUT-A | H24: Input | I24: Output | J24: PRC_ACTFLO | K24: S_EFF | L24: CAP2ACT | M24: STG_CHRG~2017 | N24: STG_LOSS
B25: \I:Technology Name | C25: Technology Description | D25: Input Commodity | E25: Output Commodity | F25: Auxiliary Input Commodity | G25: Auxiliary Output Commodity | M25: tCarbon in 2017 | N25: Losses (1-e(-k))
B26: HWP_Carbon | C26: HWP C from wood products | D26: WOOD_Products | H26: 1
E27: HWP_Cinflow | I27: 250000
E28: ROUNDWOOD | I28: 0.157
B29: HWP_CO2_inflow | C29: CO2 inflow from wood products, 1st emission phase | D29: HWP_Cinflow | E29: HWP_Cstored | H29: 1 | I29: 0.98893166 | L29: 1
E30: EMI_HWP_C | I30: 0.011068337
B31: HWP_CO2storage | C31: HWP carbon storage | D31: HWP_Cstored | E31: HWP_Cstored | M31: 11675412 | N31: -0.02230154
G39: EMI_HWP_Sink | J39: 0.0221

Sheet Efficiency
A1: Determining the yield for felling processes for Irish woodflow
B3: Refer to chapter 8 of the NFI results report - Chapter 8: Felling
B4: Using the statistics published for year 2022
B5: Harvest area for thinning and clearfell activities
B6: Roundwood harvested per each activity for that
B7: Mean yield would be obtained for those activities - in sensitivity analysis we can change those values by +/- 10% to show that it is difficult to wholly portray the diversity in forest species and we try to find a middle ground within an ESOM
A11: Page 126 | B11: Mean annual fell volume classified by harvest type
A13: Harvest type | B13: 1000 m3 | C13: confidence interval | D13: %
A14: Clearfell | B14: 2680.3 | C14: 2357.3 - 3003.2 | D14: 64.9
A15: 1st thin | B15: 848.9 | C15: 743.4 - 954.4 | D15: 20.6
A16: 2nd thin | B16: 341.1 | C16: 277.1 - 405.2 | D16: 8.3
A17: subsequent thin | B17: 256.8 | C17: 209.1 - 304.6 | D17: 6.2
A19: Page 122 | B19: 8.2.1 stocked forest area by ownwership and felling intervention
A21: stocked forest area by ownership and felling intervention that occurred between third and fourth inventory cycles ( i.e 2017 - 2022)
A23: Felling intervention | B23: 1000 ha | C23: confidence interval | D23: %
A24: No Intervention | B24: 624.25 | C24: 613.04 - 635.45 | D24: 86.5
A25: 1st thin | B25: 40.04 | C25: 32.46 - 47.62 | D25: 5.6
A26: 2nd thin | B26: 18.01 | C26: 12.84- 23.18 | D26: 2.5
A27: subsequent thin | B27: 11.23 | C27: 7.14 - 15.33 | D27: 1.6
A28: Clearfell | B28: 27.21 | C28: 20.87 - 33.55 | D28: 3.8
A31: Annualising the forest area for calculation
B32: Per year (1000 ha)
A33: 1st thin | B33: 8.008
A34: 2nd thin | B34: 3.602
A35: subsequent thin | B35: 2.246 | C35: Total Thinning area | D35: 13.856
A36: Clearfell | B36: 5.442
A38: Harvest | B38: 1000 m3
A39: Thinning (Total) | B39: 1446.8 | C39: 104.41686
A40: Clearfell | B40: 2680.3 | C40: 492.52113
A43: Accounting for confidence interval - run sensitivity analysis based on the range
A45: Low confidence | B45: 1000 ha | C45: 1000 m3 (annual) | D45: annual 1000 ha | F45: yield m3/ha | H45: Combining thinning | J45: Average Yield
A46: 1st thin | B46: 32.46 | C46: 743.4 | D46: 6.492 | H46: 1229.6 | I46: 10.488 | J46: 117.23875
A47: 2nd thin | B47: 12.84 | C47: 277.1 | D47: 2.568
A48: subsequent thin | B48: 7.14 | C48: 209.1 | D48: 1.428
A49: Clearfell | B49: 20.87 | C49: 2357.3 | D49: 4.174 | F49: 564.75803
A52: High confidence | B52: 1000 ha | C52: 1000 m3 (annual) | D52: annual 1000 ha | F52: yield m3/ha | H52: Combining thinning | J52: Average Yield
A53: 1st thin | B53: 47.62 | C53: 954.4 | D53: 9.524 | H53: 1664.2 | I53: 17.226 | J53: 96.609776
A54: 2nd thin | B54: 23.18 | C54: 405.2 | D54: 4.636
A55: subsequent thin | B55: 15.33 | C55: 304.6 | D55: 3.066
A56: Clearfell | B56: 33.55 | C56: 3003.2 | D56: 6.71 | F56: 447.57079
...

Sheet Raw data
B3: Forest Statistics 2025 | S3: Forest Stock | U3: 778900 | V3: Hectares
A5: Forecast of net realisable volume (000 m3 overbark) | G5: Forecast Harvest Area | S5: Based on harvested area, assumption on how forest area will change, given no afforestation undertaken
E6: Gross Volume | H6: Private sector | J6: Coillte | L6: DAERA FS | N6: Tota; | P6: Total harvest area | S6: Remaining stock
B7: Year | C7: Total ROI | G7: Year | H7: Thin | I7: Clearfell | J7: Thin | K7: Clearfell | L7: Thin | M7: Clearfell | N7: Thin | O7: Clearfell | U7: in Mha
B8: 2021 | C8: 4224 | E8: 4589 | G8: 2021 | H8: 9079 | I8: 3245 | J8: 16448 | K8: 5863 | L8: 1322 | M8: 901 | N8: 26849 | O8: 10009 | P8: 36858 | S8: 742042 | U8: 0.742 | V8: =N8/S8 -> 0.036182588 | W8: =O8/S8 -> 0.013488455
B9: 2022 | C9: 4499 | E9: 4906 | G9: 2022 | H9: 11124 | I9: 3539 | J9: 16448 | K9: 5863 | L9: 1322 | M9: 901 | N9: 28894 | O9: 10303 | P9: 39197 | S9: 739703 | U9: 0.74 | V9: =N9/S9 -> 0.039061623 | W9: =O9/S9 -> 0.013928563
B10: 2023 | C10: 5142 | E10: 5602 | G10: 2023 | H10: 12577 | I10: 4914 | J10: 16448 | K10: 5863 | L10: 1322 | M10: 901 | N10: 30347 | O10: 11678 | P10: 42025 | S10: 736875 | U10: 0.737 | V10: =N10/S10 -> 0.041183376 | W10: =O10/S10 -> 0.015848007
B11: 2024 | C11: 4165 | E11: 5623 | G11: 2024 | H11: 12043 | I11: 4652 | J11: 16448 | K11: 5863 | L11: 1322 | M11: 901 | N11: 29813 | O11: 11416 | P11: 41229 | S11: 737671 | U11: 0.738 | V11: =N11/S11 -> 0.040415036 | W11: =O11/S11 -> 0.015475734
B12: 2025 | C12: 5229 | E12: 5699 | G12: 2025 | H12: 13100 | I12: 5105 | J12: 16448 | K12: 5863 | L12: 1322 | M12: 901 | N12: 30870 | O12: 11869 | P12: 42739 | S12: 736161 | U12: 0.736 | V12: =N12/S12 -> 0.041933762 | W12: =O12/S12 -> 0.016122832
B13: 2026 | C13: 5309 | E13: 5768 | G13: 2026 | H13: 19022 | I13: 5476 | J13: 15125 | K13: 5863 | L13: 1333 | M13: 1003 | N13: 35480 | O13: 12342 | P13: 47822 | S13: 731078 | U13: 0.731 | V13: =N13/S13 -> 0.048531073 | W13: =O13/S13 -> 0.01688192
B14: 2027 | C14: 5482 | E14: 5976 | G14: 2027 | H14: 16030 | I14: 6081 | J14: 15125 | K14: 5863 | L14: 1333 | M14: 1003 | N14: 32488 | O14: 12947 | P14: 45435 | S14: 733465 | U14: 0.733 | V14: =N14/S14 -> 0.044293865 | W14: =O14/S14 -> 0.017651831
B15: 2028 | C15: 5484 | E15: 5987 | G15: 2028 | H15: 15739 | I15: 6308 | J15: 15125 | K15: 5863 | L15: 1333 | M15: 1003 | N15: 32197 | O15: 13174 | P15: 45371 | S15: 733529 | U15: 0.734 | V15: =N15/S15 -> 0.043893288 | W15: =O15/S15 -> 0.017959753
B16: 2029 | C16: 5716 | E16: 6237 | G16: 2029 | H16: 15955 | I16: 7006 | J16: 15125 | K16: 5863 | L16: 1333 | M16: 1003 | N16: 32413 | O16: 13872 | P16: 46285 | S16: 732615 | U16: 0.733 | V16: =N16/S16 -> 0.044242883 | W16: =O16/S16 -> 0.018934911
B17: 2030 | C17: 6059 | E17: 6605 | G17: 2030 | H17: 17858 | I17: 7787 | J17: 15125 | K17: 5863 | L17: 1333 | M17: 1003 | N17: 34316 | O17: 14653 | P17: 48969 | S17: 729931 | U17: 0.73 | V17: =N17/S17 -> 0.047012663 | W17: =O17/S17 -> 0.0200745
B18: 2031 | C18: 6456 | E18: 7006 | G18: 2031 | H18: 17438 | I18: 8995 | J18: 14634 | K18: 5863 | L18: 1189 | M18: 1429 | N18: 33261 | O18: 16287 | P18: 49548 | S18: 729352 | U18: 0.729 | V18: =N18/S18 -> 0.045603495 | W18: =O18/S18 -> 0.022330781
B19: 2032 | C19: 6759 | E19: 7356 | G19: 2032 | H19: 15424 | I19: 10494 | J19: 14634 | K19: 5863 | L19: 1189 | M19: 1429 | N19: 31247 | O19: 17786 | P19: 49033 | S19: 729867 | U19: 0.73 | V19: =N19/S19 -> 0.04281191 | W19: =O19/S19 -> 0.024368823
... B27: 2040 | C27: 6880 | E27: 7419 | G27: 2040 | H27: 14341 | I27: 6497 | J27: 10325 | K27: 5942 | L27: 1120 | M27: 1276 | N27: 25786 | O27: 13715 | P27: 39501 | S27: 739399 | U27: 0.739 | V27: =N27/S27 -> 0.03487427 | W27: =O27/S27 -> 0.018548848
A31: Forecast of wood fibre and potential for wood energy in ROI 000 m3
B32: Year | C32: Roundwood | D32: Downgrade + wood residues | E32: Harvesting residues | F32: Total | G32: Energy Content Millions (GJ)
B33: 2021 | C33: 184 | D33: 589 | E33: 113 | F33: 886 | G33: 6.1
B34: 2022 | C34: 258 | D34: 708 | E34: 93 | F34: 1059 | G34: 7.3
B35: 2023 | C35: 348 | D35: 1005 | E35: 112 | F35: 1465 | G35: 101.1
B36: 2024 | C36: 325 | D36: 1002 | E36: 86 | F36: 1413 | G36: 9.8
B37: 2025 | C37: 357 | D37: 1013 | E37: 95 | F37: 1465 | G37: 10.1
B38: 2026 | C38: 394 | D38: 982 | E38: 145 | F38: 1521 | G38: 10.5
B39: 2027 | C39: 396 | D39: 1052 | E39: 164 | F39: 1612 | G39: 11.1
B40: 2028 | C40: 363 | D40: 1037 | E40: 153 | F40: 1553 | G40: 10.7
B41: 2029 | C41: 405 | D41: 1129 | E41: 145 | F41: 1679 | G41: 11.6
B42: 2030 | C42: 467 | D42: 1280 | E42: 146 | F42: 1893 | G42: 13.1
B43: 2031 | C43: 505 | D43: 1416 | E43: 91 | F43: 2012 | G43: 13.9
B44: 2032 | C44: 591 | D44: 1538 | E44: 98 | F44: 2227 | G44: 15.4
... B52: 2040 | C52: 301 | D52: 1472 | E52: 45 | F52: 1818 | G52: 12.5
