Workbook

Sheet Cover
A16: TIMES-Ireland Model
A19: Document type: | B19: Base Year Template
A20: Sector(s): | B20: Supply sector (SUP)
A21: Purpose: | B21: Specify base year data and define sector structure
A23: Original developer(s): | B23: James Glynn (UCC, james.glynn@ucc.ie)
B24: Xiufeng Yue (UCC, xiufeng.yue@ucc.ie)
B25: Olexandr Balyk (UCC, olexandr.balyk@ucc.ie)
A26: Current maintainer(s): | B26: Vahid Aryanpur (UCC,vahid.aryanpur@ucc.ie)
B27: Bakytzhan Suleimenov (UCC, bsuleimenov@ucc.ie)
A29: Part of TIM version: | B29: 1
A30: Model repository: | B30: https://github.com/MaREI-EPMG/TIMES-Ireland-model
A31: Licence: | B31: CC BY-NC-SA 4.0 (unless specified otherwise)
B32: https://creativecommons.org/licenses/by-nc-sa/4.0/

Sheet Regions
C3: {=INDEX(C5:C7,$A$4)} -> IE | D3: {=INDEX(D5:D7,$A$4)} -> National | E3: {=INDEX(E5:E7,$A$4)} -> IE-CW | F3: {=INDEX(F5:F7,$A$4)} -> IE-D | G3: {=INDEX(G5:G7,$A$4)} -> IE-KE | H3: {=INDEX(H5:H7,$A$4)} -> IE-KK | I3: {=INDEX(I5:I7,$A$4)} -> IE-LS | J3: {=INDEX(J5:J7,$A$4)} -> IE-LD | ... AD3: {=INDEX(AD5:AD7,$A$4)} -> IE-MN
A4: 1
A5: Development | C5: IE | D5: National | E5: =A11 -> IE-CW | F5: =A16 -> IE-D | G5: =A19 -> IE-KE | H5: =A20 -> IE-KK | I5: =A21 -> IE-LS | J5: =A24 -> IE-LD | K5: =A25 -> IE-LH | L5: =A27 -> IE-MH | M5: =A29 -> IE-OY | N5: =A34 -> IE-WH | O5: =A35 -> IE-WX | P5: =A36 -> IE-WW | Q5: =A13 -> IE-CE | R5: =A14 -> IE-CO | S5: =A18 -> IE-KY | T5: =A23 -> IE-LK | U5: =A32 -> IE-TA | V5: =A33 -> IE-WD | W5: =A17 -> IE-G | X5: =A22 -> IE-LM | Y5: =A26 -> IE-MO | Z5: =A30 -> IE-RN | AA5: =A31 -> IE-SO | AB5: =A12 -> IE-CN | AC5: =A15 -> IE-DL | AD5: =A28 -> IE-MN
A6: Single-region | C6: =C5 -> IE | D6: ="*"&D5 -> *National | E6: ="*"&E5 -> *IE-CW | F6: ="*"&F5 -> *IE-D | G6: ="*"&G5 -> *IE-KE | H6: ="*"&H5 -> *IE-KK | I6: ="*"&I5 -> *IE-LS | J6: ="*"&J5 -> *IE-LD | K6: ="*"&K5 -> *IE-LH | ... AD6: ="*"&AD5 -> *IE-MN
A7: Multi-region | C7: ="*"&C5 -> *IE | D7: =D5 -> National | E7: =E5 -> IE-CW | F7: =F5 -> IE-D | G7: =G5 -> IE-KE | H7: =H5 -> IE-KK | I7: =I5 -> IE-LS | J7: =J5 -> IE-LD | K7: =K5 -> IE-LH | ... AD7: =AD5 -> IE-MN
A10: Code | B10: County name
A11: IE-CW | B11: Carlow
A12: IE-CN | B12: Cavan
A13: IE-CE | B13: Clare
A14: IE-CO | B14: Cork
A15: IE-DL | B15: Donegal
A16: IE-D | B16: Dublin
A17: IE-G | B17: Galway
A18: IE-KY | B18: Kerry
A19: IE-KE | B19: Kildare
A20: IE-KK | B20: Kilkenny
A21: IE-LS | B21: Laois
... A36: IE-WW | B36: Wicklow
A37: Source: https://en.wikipedia.org/wiki/ISO_3166-2:IE

Sheet EB2018
A1: 2018 Units = ktoe | B1: NACE (Rev 2) | C1: Coal | D1: Bituminous Coal | E1: Anthracite + Manufactured Ovoids | F1: Coke | G1: Lignite \ Brown Coal Briquettes | H1: Peat | I1: Milled Peat | J1: Sod Peat | K1: Briquettes | L1: Oil | M1: Crude | N1: Refinery Feedstocks | O1: Refinery Gas | P1: Gasoline | Q1: Kerosene | R1: Jet Kerosene | S1: Fueloil | T1: LPG | U1: Gasoil / Diesel /DERV | V1: Petroleum Coke | W1: Naphta | X1: Bitumen | Y1: White Spirit | Z1: Lubricants | AA1: Natural Gas | AB1: Renewables | AC1: Hydro | AD1: Wind | AE1: Biomass | AF1: Renewable Waste | AG1: Landfill Gas | AH1: Biogas | AI1: Biodiesel | AJ1: Bioethanol | AK1: Solar Photovoltaic | AL1: Solar Thermal | AM1: Ambient Heat | AN1: Non-Renewable Waste | AO1: Electricity | AP1: Heat | AQ1: TOTAL
A2: Indigenous Production | C2: =SUM(D2:G2) -> 0 | D2: 0 | H2: =SUM(I2:K2) -> 815.92435 | I2: 688.22035 | J2: 127.704 | L2: =SUM(M2:Z2) -> 0 | AA2: 2751.9192 | AB2: =SUM(AC2:AM2) -> 1334.6583 | AC2: 59.691709 | AD2: 743.01992 | AE2: 248.9086 | AF2: 139.99993 | AG2: 33.531819 | AH2: 16.813133 | AI2: 31.064468 | AJ2: 2.6691993 | AK2: 1.8899881 | AL2: 13.546086 | AM2: 43.523448 | AN2: 145.4371 | AQ2: =C2+H2+L2+AA2+AB2+AN2+AO2+AP2 -> 5047.9389
A3: Imports | C3: =SUM(D3:G3) -> 903.49466 | D3: 829.5746 | E3: 61.722868 | G3: 12.197194 | H3: =SUM(I3:K3) -> 0 | L3: =SUM(M3:Z3) -> 9138.5578 | M3: 3053.4743 | N3: 16.633377 | O3: 0 | P3: 564.23641 | Q3: 369.14639 | R3: 1542.2444 | S3: 82.827949 | T3: 157.54636 | U3: 2932.6956 | V3: 166.37648 | W3: 7.5616539 | X3: 200.83222 | Y3: 1.228147 | Z3: 43.754533 | AA3: 1728.3381 | AB3: =SUM(AC3:AM3) -> 151.93356 | AE3: 24.282116 | AI3: 104.81441 | AJ3: 22.83703 | AO3: 139.45062 | AQ3: =C3+H3+L3+AA3+AB3+AN3+AO3+AP3 -> 12061.775
A4: Exports | C4: =SUM(D4:G4) -> 15.186581 | D4: 0 | E4: 14.097722 | G4: 1.0888587 | H4: =SUM(I4:K4) -> 7.033068 | K4: 7.033068 | L4: =SUM(M4:Z4) -> 1717.0625 | M4: 0 | N4: 0 | P4: 364.52222 | Q4: 21.672508 | R4: 156.2938 | S4: 986.60612 | T4: 35.289733 | U4: 102.14625 | V4: 0.0029088438 | W4: 36.297317 | X4: 5.469469 | Y4: 0.018500298 | Z4: 8.7436483 | AA4: 0 | AB4: =SUM(AC4:AM4) -> 9.4476585 | AE4: 0.4126464 | AI4: 9.0350121 | AJ4: 0 | AO4: 141.83539 | AQ4: =C4+H4+L4+AA4+AB4+AN4+AO4+AP4 -> 1890.5652
A5: Mar. Bunkers | C5: =SUM(D5:G5) -> 0 | H5: =SUM(I5:K5) -> 0 | L5: =SUM(M5:Z5) -> 172.71259 | S5: 15.730078 | U5: 156.98251 | AB5: =SUM(AC5:AM5) -> 0 | AQ5: =C5+H5+L5+AA5+AB5+AN5+AO5+AP5 -> 172.71259
A6: Stock Change | C6: =SUM(D6:G6) -> -101.25635 | D6: -101.86989 | E6: -0.80797667 | G6: 1.421516 | H6: =SUM(I6:K6) -> -122.93905 | I6: -136.53827 | J6: 0 | K6: 13.599214 | L6: =SUM(M6:Z6) -> 151.33981 | M6: 38.730965 | N6: -8.875152 | P6: -9.6980083 | Q6: 12.883202 | R6: 82.120249 | S6: 23.6376 | T6: 1.4659197 | U6: 8.3874136 | V6: 3.2040911 | W6: -0.51646779 | X6: 0 | Y6: 0 | Z6: 0 | AA6: 0 | AB6: =SUM(AC6:AM6) -> 4.4601014 | AE6: 0.26707428 | AI6: 1.7828522 | AJ6: 2.410175 | AQ6: =C6+H6+L6+AA6+AB6+AN6+AO6+AP6 -> -68.395488
A7: Primary Energy Supply (incl non-energy) | C7: =C2+C3-C4-C5+C6 -> 787.05173 | D7: =D2+D3-D4-D5+D6 -> 727.70471 | E7: =E2+E3-E4-E5+E6 -> 46.817169 | F7: =F2+F3-F4-F5+F6 -> 0 | G7: =G2+G3-G4-G5+G6 -> 12.529851 | H7: =H2+H3-H4-H5+H6 -> 685.95223 | I7: =I2+I3-I4-I5+I6 -> 551.68208 | J7: =J2+J3-J4-J5+J6 -> 127.704 | ... AP7: =AP2+AP3-AP4-AP5+AP6 -> 0 | AQ7: =C7+H7+L7+AA7+AB7+AN7+AO7+AP7 -> 14978.04
A8: Primary Energy Requirement (excl. non-energy) | C8: =C7-C27 -> 787.05173 | D8: =D7-D27 -> 727.70471 | E8: =E7-E27 -> 46.817169 | F8: =F7-F27 -> 0 | G8: =G7-G27 -> 12.529851 | H8: =H7-H27 -> 685.95223 | I8: =I7-I27 -> 551.68208 | J8: =J7-J27 -> 127.704 | ... AP8: =AP7-AP27 -> 0 | AQ8: =C8+H8+L8+AA8+AB8+AN8+AO8+AP8 -> 14978.04
A9: Transformation Input | C9: =SUM(C10:C14) -> 489.1342 | D9: =SUM(D10:D14) -> 489.1342 | E9: =SUM(E10:E14) -> 0 | F9: =SUM(F10:F14) -> 0 | G9: =SUM(G10:G14) -> 0 | H9: =SUM(H10:H14) -> 541.02658 | I9: =SUM(I10:I14) -> 541.02658 | J9: =SUM(J10:J14) -> 0 | ... AP9: =SUM(AP10:AP14) -> 0 | AQ9: =C9+H9+L9+AA9+AB9+AN9+AO9+AP9 -> 7058.1841
A10: Public Thermal Power Plants (Input) | C10: =SUM(D10:G10) -> 489.1342 | D10: 489.1342 | H10: =SUM(I10:K10) -> 467.10846 | I10: 467.10846 | J10: 0 | L10: =SUM(M10:Z10) -> 34.094789 | S10: 25.868327 | U10: 8.2264622 | AA10: 2187.6034 | AB10: =SUM(AC10:AM10) -> 205.3059 | AE10: 72.46706 | AF10: 99.307023 | AG10: 33.531819 | AN10: 90.714163 | AQ10: =C10+H10+L10+AA10+AB10+AN10+AO10+AP10 -> 3473.9609
A11: Combined Heat and Power Plants (Input) | C11: =SUM(D11:G11) -> 0 | D11: 0 | H11: =SUM(I11:K11) -> 5.8425469 | I11: 5.8425469 | L11: =SUM(M11:Z11) -> 0.63499472 | O11: 0 | S11: 0 | T11: 0.63499472 | U11: 0 | AA11: 272.96145 | AB11: =SUM(AC11:AM11) -> 10.597627 | AE11: 3.561556 | AH11: 7.0360715 | AQ11: =C11+H11+L11+AA11+AB11+AN11+AO11+AP11 -> 290.03662
A12: Pumped Storage Consumption (Input) | AO12: 42.94206 | AQ12: =C12+H12+L12+AA12+AB12+AN12+AO12+AP12 -> 42.94206
A13: Briquetting Plants (Input) | C13: =SUM(D13:G13) -> 0 | H13: =SUM(I13:K13) -> 68.075577 | I13: 68.075577 | L13: =SUM(M13:Z13) -> 0 | AB13: =SUM(AC13:AM13) -> 0 | AQ13: =C13+H13+L13+AA13+AB13+AN13+AO13+AP13 -> 68.075577
A14: Oil Refineries & other energy sector (Input) | C14: =SUM(D14:G14) -> 0 | H14: =SUM(I14:K14) -> 0 | L14: =SUM(M14:Z14) -> 3130.9919 | M14: 3092.2053 | N14: 38.786602 | AA14: 40.734585 | AB14: =SUM(AC14:AM14) -> 0 | AO14: 11.442472 | AQ14: =C14+H14+L14+AA14+AB14+AN14+AO14+AP14 -> 3183.1689
A15: Transformation Output | C15: =SUM(C16:C20) -> 0 | D15: =SUM(D16:D20) -> 0 | E15: =SUM(E16:E20) -> 0 | F15: =SUM(F16:F20) -> 0 | G15: =SUM(G16:G20) -> 0 | H15: =SUM(H16:H20) -> 64.671798 | I15: =SUM(I16:I20) -> 0 | J15: =SUM(J16:J20) -> 0 | ... AP15: =SUM(AP16:AP20) -> 0 | AQ15: =C15+H15+L15+AA15+AB15+AN15+AO15+AP15 -> 5104.8192
A16: Public Thermal Power Plants (Output) | C16: =SUM(D16:G16) -> 0 | H16: =SUM(I16:K16) -> 0 | L16: =SUM(M16:Z16) -> 0 | AB16: =SUM(AC16:AL16) -> 0 | AO16: 1667.7866 | AQ16: =C16+H16+L16+AA16+AO16+AP16 -> 1667.7866
A17: Combined Heat and Power Plants (Output) | C17: =SUM(D17:G17) -> 0 | H17: =SUM(I17:K17) -> 0 | L17: =SUM(M17:Z17) -> 0 | AB17: =SUM(AC17:AL17) -> 0 | AO17: 185.14396 | AQ17: =C17+H17+L17+AA17+AO17+AP17 -> 185.14396
A18: Pumped Storage Generation (Output) | AO18: 20.430939 | AQ18: =C18+H18+L18+AA18+AB18+AN18+AO18+AP18 -> 20.430939
A19: Briquetting Plants (Output) | H19: =SUM(I19:K19) -> 64.671798 | K19: 64.671798 | L19: =SUM(M19:Z19) -> 0 | AB19: =SUM(AC19:AL19) -> 0 | AQ19: =C19+H19+L19+AA19+AB19+AN19+AO19+AP19 -> 64.671798
A20: Oil Refineries & other energy sector (Output) | H20: =SUM(I20:K20) -> 0 | L20: =SUM(M20:Z20) -> 3166.7859 | O20: 90.017984 | P20: 640.5368 | Q20: 226.77459 | R20: 0 | S20: 960.95018 | T20: 64.797463 | U20: 1146.9502 | W20: 36.758644 | AB20: =SUM(AC20:AL20) -> 0 | AQ20: =C20+H20+L20+AA20+AB20+AN20+AO20+AP20 -> 3166.7859
A21: Exchanges and transfers | C21: =SUM(C22:C24) -> 22.240062 | D21: =SUM(D22:D24) -> -17.141361 | E21: =SUM(E22:E24) -> 39.381423 | F21: =SUM(F22:F24) -> 0 | G21: =SUM(G22:G24) -> 0 | H21: =SUM(I21:K21) -> 0 | I21: =SUM(I22:I24) -> 0 | J21: =SUM(J22:J24) -> 0 | K21: =SUM(K22:K24) -> 0 | L21: =SUM(M21:Z21) -> -24.684016 | M21: =SUM(M22:M24) -> 0 | N21: =SUM(N22:N24) -> 30.880435 | O21: =SUM(O22:O24) -> 0 | P21: =SUM(P22:P24) -> -31.331711 | Q21: =SUM(Q22:Q24) -> 361.9108 | R21: =SUM(R22:R24) -> -361.12225 | S21: =SUM(S22:S24) -> -0.17168421 | T21: =SUM(T22:T24) -> 0 | ... AQ21: =SUM(AQ22:AQ24) -> -2.4439548
A22: Electricity Exchange & Transfers | AB22: =SUM(AC22:AM22) -> -804.60162 | AC22: =-AC2 -> -59.691709 | AD22: =-AD2 -> -743.01992 | AK22: -1.8899881 | AO22: =-(C22+H22+L22+AA22+AB22) -> 804.60162 | AQ22: =C22+H22+L22+AA22+AB22+AN22+AO22+AP22 -> 0
A23: Heat Exchange & Transfers | AQ23: =C23+H23+L23+AA23+AB23+AN23+AO23+AP23 -> 0
A24: Other Exchange & Transfers | C24: =SUM(D24:G24) -> 22.240062 | D24: -17.141361 | E24: =-D24-V24 -> 39.381423 | L24: =SUM(N24:Z24) -> -24.684016 | N24: 30.880435 | P24: -31.331711 | Q24: 361.9108 | R24: -361.12225 | S24: -0.17168421 | U24: -2.6095464 | V24: -22.240062 | W24: 0 | AB24: =SUM(AC24:AM24) -> 0 | AQ24: =C24+H24+L24+AA24+AB24+AN24+AO24+AP24 -> -2.4439548
A25: Own Use and Distribution Losses | C25: =SUM(D25:G25) -> 0 | H25: =SUM(I25:K25) -> 10.283248 | I25: 10.283248 | L25: =SUM(O25:Z25) -> 98.284658 | O25: 95.274692 | S25: 0 | T25: 0.0041693256 | U25: 3.0057963 | AA25: 57.5286 | AB25: =SUM(AC25:AI25) -> 0 | AO25: 259.46681 | AQ25: =C25+H25+L25+AA25+AB25+AN25+AO25+AP25 -> 425.56332
A26: Available Final Energy Consumption | C26: =C7-C9+C15+C21-C25 -> 320.1576 | D26: =D7-D9+D15+D21-D25 -> 221.42916 | E26: =E7-E9+E15+E21-E25 -> 86.198592 | F26: =F7-F9+F15+F21-F25 -> 0 | G26: =G7-G9+G15+G21-G25 -> 12.529851 | H26: =H7-H9+H15+H21-H25 -> 199.3142 | I26: =I7-I9+I15+I21-I25 -> 0.37225107 | J26: =J7-J9+J15+J21-J25 -> 127.704 | ... AP26: =AP7-AP9+AP15+AP21-AP25 -> 0 | AQ26: =C26+H26+L26+AA26+AB26+AN26+AO26+AP26 -> 12596.668

Sheet CONVENTIONS
B3: Energy Commodities | E3: Technologies - Convention for Naming | L3: . | M3: Emission Commodities | P3: Sectors | S3: Transformations | V3: Suffixes | Y3: Commodity State | AB3: Commodity Type
B4: Code | C4: Description | E4: Code | F4: Description | G4: Technology type | H4: Fuel | I4: Technology Type | J4: Suffix (Technology Generation or regions) | K4: TIMES Set | M4: Code | N4: Description | P4: Code | Q4: Description | S4: Code | T4: Description | V4: Code | W4: Description | Y4: Code | Z4: Description | AB4: Code | AC4: Description
B5: COA | C5: Coal | E5: =I5&H5&J5 -> IMPCOABIT | F5: =G5 & " of " & VLOOKUP(H5,$B$5:$C$84,2,FALSE) & IF(J5<>0,IF(VLOOKUP(J5,$V$5:$W$12,2,FALSE)<>""," - " & VLOOKUP(J5,$V$5:$W$12,2,FALSE),""),"") -> Import of Bituminous Coal | G5: =VLOOKUP(I5,$S$5:$T$10,2,FALSE) -> Import | H5: =B38 -> COABIT | I5: =$S$6 -> IMP | K5: IMP | M5: CH4N | N5: Methane - eNergy Emissions | P5: SUP | Q5: Supply and Upstream | S5: MIN | T5: Domestic Potential | V5: _UK | W5: UK | Y5: G | Z5: gaseous | AB5: C | AC5: centralised
B6: DST | C6: Diesel | E6: =I6&H6&J6 -> IMPCOAHAR | F6: =G6 & " of " & VLOOKUP(H6,$B$5:$C$84,2,FALSE) & IF(J6<>0,IF(VLOOKUP(J6,$V$5:$W$12,2,FALSE)<>""," - " & VLOOKUP(J6,$V$5:$W$12,2,FALSE),""),"") -> Import of Hard Coal / Antracite | G6: =VLOOKUP(I6,$S$5:$T$10,2,FALSE) -> Import | H6: =B39 -> COAHAR | I6: =$S$6 -> IMP | K6: IMP | M6: CH4P | N6: Methane Emissions - Process Emissions | P6: ELC | Q6: Electricity | S6: IMP | T6: Import | V6: _UK-EWIC | W6: UK East-West Interconnector | Y6: L | Z6: liquid | AB6: D | AC6: decentralised
B7: GSL | C7: Gasoline | E7: =I7&H7&J7 -> IMPCOACOK | F7: =G7 & " of " & VLOOKUP(H7,$B$5:$C$84,2,FALSE) & IF(J7<>0,IF(VLOOKUP(J7,$V$5:$W$12,2,FALSE)<>""," - " & VLOOKUP(J7,$V$5:$W$12,2,FALSE),""),"") -> Import of Coke Coal | G7: =VLOOKUP(I7,$S$5:$T$10,2,FALSE) -> Import | H7: =B40 -> COACOK | I7: =$S$6 -> IMP | K7: IMP | M7: N2ON | N7: N2O Emissions - eNergy Emissions | S7: EXP | T7: Export | V7: _GLOBAL
B8: HFO | C8: Heavy Fuel Oil | E8: =I8&H8&J8 -> IMPCOALIG | F8: =G8 & " of " & VLOOKUP(H8,$B$5:$C$84,2,FALSE) & IF(J8<>0,IF(VLOOKUP(J8,$V$5:$W$12,2,FALSE)<>""," - " & VLOOKUP(J8,$V$5:$W$12,2,FALSE),""),"") -> Import of Lignite / Brown Coal | G8: =VLOOKUP(I8,$S$5:$T$10,2,FALSE) -> Import | H8: =B41 -> COALIG | I8: =$S$6 -> IMP | K8: IMP | M8: SO2N | N8: Sulfur dioxide - eNergy Emissions | S8: REF | T8: Refinery | V8: _Whitegate | W8: Whitegate
B9: KER | C9: Kerosene | E9: =I9&H9&J9 -> IMPOILCRD | F9: =G9 & " of " & VLOOKUP(H9,$B$5:$C$84,2,FALSE) & IF(J9<>0,IF(VLOOKUP(J9,$V$5:$W$12,2,FALSE)<>""," - " & VLOOKUP(J9,$V$5:$W$12,2,FALSE),""),"") -> Import of Crude Oil | G9: =VLOOKUP(I9,$S$5:$T$10,2,FALSE) -> Import | H9: =B43 -> OILCRD | I9: =$S$6 -> IMP | K9: IMP | M9: CO2N | N9: Carbon Dioxide - eNergy Emissions | S9: FT- | T9: Fuel Tech | V9: _S1 | W9: Step 1
B10: LPG | C10: Liquified Petroleum Gases | E10: =I10&H10&J10 -> IMPOILKER | F10: =G10 & " of " & VLOOKUP(H10,$B$5:$C$84,2,FALSE) & IF(J10<>0,IF(VLOOKUP(J10,$V$5:$W$12,2,FALSE)<>""," - " & VLOOKUP(J10,$V$5:$W$12,2,FALSE),""),"") -> Import of Kerosene | G10: =VLOOKUP(I10,$S$5:$T$10,2,FALSE) -> Import | H10: =B45 -> OILKER | I10: =$S$6 -> IMP | K10: IMP | M10: CO2P | N10: Carbon Dioxide - Process Emissions | V10: _S2 | W10: Step 2
B11: OIL | C11: Oil | E11: =I11&H11&J11 -> IMPOILHFO | F11: =G11 & " of " & VLOOKUP(H11,$B$5:$C$84,2,FALSE) & IF(J11<>0,IF(VLOOKUP(J11,$V$5:$W$12,2,FALSE)<>""," - " & VLOOKUP(J11,$V$5:$W$12,2,FALSE),""),"") -> Import of Heavy Fuel Oil | G11: =VLOOKUP(I11,$S$5:$T$10,2,FALSE) -> Import | H11: =B46 -> OILHFO | I11: =$S$6 -> IMP | K11: IMP | M11: CO2S | N11: Carbon Dioxide - Sequestered | V11: _S3 | W11: Step 3
B12: NGA | C12: Natural Gas | E12: =I12&H12&J12 -> IMPOILDST | F12: =G12 & " of " & VLOOKUP(H12,$B$5:$C$84,2,FALSE) & IF(J12<>0,IF(VLOOKUP(J12,$V$5:$W$12,2,FALSE)<>""," - " & VLOOKUP(J12,$V$5:$W$12,2,FALSE),""),"") -> Import of Diesel Oil | G12: =VLOOKUP(I12,$S$5:$T$10,2,FALSE) -> Import | H12: =B47 -> OILDST | I12: =$S$6 -> IMP | K12: IMP | M12: NOXN | N12: Nitrogen Oxide - eNergy Emissions | V12: _S4 | W12: Step 4
B13: BIO | C13: Biomass | E13: =I13&H13&J13 -> IMPOILLPG | F13: =G13 & " of " & VLOOKUP(H13,$B$5:$C$84,2,FALSE) & IF(J13<>0,IF(VLOOKUP(J13,$V$5:$W$12,2,FALSE)<>""," - " & VLOOKUP(J13,$V$5:$W$12,2,FALSE),""),"") -> Import of Liquified Petroleum Gas | G13: =VLOOKUP(I13,$S$5:$T$10,2,FALSE) -> Import | H13: =B48 -> OILLPG | I13: =$S$6 -> IMP | K13: IMP | M13: PM10 | N13: Particulate Matter <10 µm
B14: BLQ | C14: Bioliquid | E14: =I14&H14&J14 -> IMPOILGSL | F14: =G14 & " of " & VLOOKUP(H14,$B$5:$C$84,2,FALSE) & IF(J14<>0,IF(VLOOKUP(J14,$V$5:$W$12,2,FALSE)<>""," - " & VLOOKUP(J14,$V$5:$W$12,2,FALSE),""),"") -> Import of Gasoline | G14: =VLOOKUP(I14,$S$5:$T$10,2,FALSE) -> Import | H14: =B49 -> OILGSL | I14: =$S$6 -> IMP | K14: IMP | M14: PM25 | N14: Particulate Matter <2.5 µm
B15: BSL | C15: Biomass solid | E15: =I15&H15&J15 -> IMPOILCOK | F15: =G15 & " of " & VLOOKUP(H15,$B$5:$C$84,2,FALSE) & IF(J15<>0,IF(VLOOKUP(J15,$V$5:$W$12,2,FALSE)<>""," - " & VLOOKUP(J15,$V$5:$W$12,2,FALSE),""),"") -> Import of Petroleum Coke | G15: =VLOOKUP(I15,$S$5:$T$10,2,FALSE) -> Import | H15: =B50 -> OILCOK | I15: =$S$6 -> IMP | K15: IMP
B16: BGA | C16: Biogas | E16: =I16&H16&J16 -> IMPOILNEU | F16: =G16 & " of " & VLOOKUP(H16,$B$5:$C$84,2,FALSE) & IF(J16<>0,IF(VLOOKUP(J16,$V$5:$W$12,2,FALSE)<>""," - " & VLOOKUP(J16,$V$5:$W$12,2,FALSE),""),"") -> Import of Oil for Non-Energy uses | G16: =VLOOKUP(I16,$S$5:$T$10,2,FALSE) -> Import | H16: =B52 -> OILNEU | I16: =$S$6 -> IMP | K16: IMP
B17: BWA | C17: Bio Wastes | E17: =I17&H17&J17 -> IMPGASNAT_UK | F17: =G17 & " of " & VLOOKUP(H17,$B$5:$C$84,2,FALSE) & IF(J17<>0,IF(VLOOKUP(J17,$V$5:$W$12,2,FALSE)<>""," - " & VLOOKUP(J17,$V$5:$W$12,2,FALSE),""),"") -> Import of Natural Gas - UK | G17: =VLOOKUP(I17,$S$5:$T$10,2,FALSE) -> Import | H17: =B53 -> GASNAT | I17: =$S$6 -> IMP | J17: =V5 -> _UK | K17: IMP
B18: AVG | C18: Aviation Gasoline | E18: =I18&H18&J18 -> IMPGASLNG_GLOBAL | F18: =G18 & " of " & VLOOKUP(H18,$B$5:$C$84,2,FALSE) & IF(J18<>0,IF(VLOOKUP(J18,$V$5:$W$12,2,FALSE)<>""," - " & VLOOKUP(J18,$V$5:$W$12,2,FALSE),""),"") -> Import of Liquified Natural Gas | G18: =VLOOKUP(I18,$S$5:$T$10,2,FALSE) -> Import | H18: =B54 -> GASLNG | I18: =$S$6 -> IMP | J18: =V7 -> _GLOBAL | K18: IMP
B19: JTK | C19: Jet Kerosene | E19: =I19&H19&J19 -> IMPNUCURM | F19: =G19 & " of " & VLOOKUP(H19,$B$5:$C$84,2,FALSE) & IF(J19<>0,IF(VLOOKUP(J19,$V$5:$W$12,2,FALSE)<>""," - " & VLOOKUP(J19,$V$5:$W$12,2,FALSE),""),"") -> Import of Uranium | G19: =VLOOKUP(I19,$S$5:$T$10,2,FALSE) -> Import | H19: =B55 -> NUCURM | I19: =$S$6 -> IMP | K19: IMP
B20: BDL | C20: Bio Diesel | E20: =I20&H20&J20 -> IMPBIOETH1G_S1 | F20: =G20 & " of " & VLOOKUP(H20,$B$5:$C$84,2,FALSE) & IF(J20<>0,IF(VLOOKUP(J20,$V$5:$W$12,2,FALSE)<>""," - " & VLOOKUP(J20,$V$5:$W$12,2,FALSE),""),"") -> Import of Ethanol 1st generation - Step 1 | G20: =VLOOKUP(I20,$S$5:$T$10,2,FALSE) -> Import | H20: =B62 -> BIOETH1G | I20: =$S$6 -> IMP | J20: =$V$9 -> _S1 | K20: IMP
B21: BGL | C21: Bio Gasoline | E21: =I21&H21&J21 -> IMPBIOETH1G_S2 | F21: =G21 & " of " & VLOOKUP(H21,$B$5:$C$84,2,FALSE) & IF(J21<>0,IF(VLOOKUP(J21,$V$5:$W$12,2,FALSE)<>""," - " & VLOOKUP(J21,$V$5:$W$12,2,FALSE),""),"") -> Import of Ethanol 1st generation - Step 2 | G21: =VLOOKUP(I21,$S$5:$T$10,2,FALSE) -> Import | H21: =B62 -> BIOETH1G | I21: =$S$6 -> IMP | J21: =$V$10 -> _S2 | K21: IMP
B22: BGA | C22: Bio Gas | E22: =I22&H22&J22 -> IMPBIOETH1G_S3 | F22: =G22 & " of " & VLOOKUP(H22,$B$5:$C$84,2,FALSE) & IF(J22<>0,IF(VLOOKUP(J22,$V$5:$W$12,2,FALSE)<>""," - " & VLOOKUP(J22,$V$5:$W$12,2,FALSE),""),"") -> Import of Ethanol 1st generation - Step 3 | G22: =VLOOKUP(I22,$S$5:$T$10,2,FALSE) -> Import | H22: =B62 -> BIOETH1G | I22: =$S$6 -> IMP | J22: =$V$11 -> _S3 | K22: IMP
B23: BJK | C23: Jet Bio Kerosene | E23: =I23&H23&J23 -> IMPBIOETH1G_S4 | F23: =G23 & " of " & VLOOKUP(H23,$B$5:$C$84,2,FALSE) & IF(J23<>0,IF(VLOOKUP(J23,$V$5:$W$12,2,FALSE)<>""," - " & VLOOKUP(J23,$V$5:$W$12,2,FALSE),""),"") -> Import of Ethanol 1st generation - Step 4 | G23: =VLOOKUP(I23,$S$5:$T$10,2,FALSE) -> Import | H23: =B62 -> BIOETH1G | I23: =$S$6 -> IMP | J23: =$V$12 -> _S4 | K23: IMP
B24: SOL | C24: Solar | E24: =I24&H24&J24 -> IMPBIODST1G_S1 | F24: =G24 & " of " & VLOOKUP(H24,$B$5:$C$84,2,FALSE) & IF(J24<>0,IF(VLOOKUP(J24,$V$5:$W$12,2,FALSE)<>""," - " & VLOOKUP(J24,$V$5:$W$12,2,FALSE),""),"") -> Import of Biodiesel 1st generation - Step 1 | G24: =VLOOKUP(I24,$S$5:$T$10,2,FALSE) -> Import | H24: =B64 -> BIODST1G | I24: =$S$6 -> IMP | J24: =$V$9 -> _S1 | K24: IMP
B25: SPV | C25: Solar Photovoltaic | E25: =I25&H25&J25 -> IMPBIODST1G_S2 | F25: =G25 & " of " & VLOOKUP(H25,$B$5:$C$84,2,FALSE) & IF(J25<>0,IF(VLOOKUP(J25,$V$5:$W$12,2,FALSE)<>""," - " & VLOOKUP(J25,$V$5:$W$12,2,FALSE),""),"") -> Import of Biodiesel 1st generation - Step 2 | G25: =VLOOKUP(I25,$S$5:$T$10,2,FALSE) -> Import | H25: =B64 -> BIODST1G | I25: =$S$6 -> IMP | J25: =$V$10 -> _S2 | K25: IMP
B26: STH | C26: Solar Thermal | E26: =I26&H26&J26 -> IMPBIODST1G_S3 | F26: =G26 & " of " & VLOOKUP(H26,$B$5:$C$84,2,FALSE) & IF(J26<>0,IF(VLOOKUP(J26,$V$5:$W$12,2,FALSE)<>""," - " & VLOOKUP(J26,$V$5:$W$12,2,FALSE),""),"") -> Import of Biodiesel 1st generation - Step 3 | G26: =VLOOKUP(I26,$S$5:$T$10,2,FALSE) -> Import | H26: =B64 -> BIODST1G | I26: =$S$6 -> IMP | J26: =$V$11 -> _S3 | K26: IMP
B27: GEO | C27: Geothermal | E27: =I27&H27&J27 -> IMPBIODST1G_S4 | F27: =G27 & " of " & VLOOKUP(H27,$B$5:$C$84,2,FALSE) & IF(J27<>0,IF(VLOOKUP(J27,$V$5:$W$12,2,FALSE)<>""," - " & VLOOKUP(J27,$V$5:$W$12,2,FALSE),""),"") -> Import of Biodiesel 1st generation - Step 4 | G27: =VLOOKUP(I27,$S$5:$T$10,2,FALSE) -> Import | H27: =B64 -> BIODST1G | I27: =$S$6 -> IMP | J27: =$V$12 -> _S4 | K27: IMP
B28: WIN | C28: Wind | E28: =I28&H28&J28 -> IMPBIOJKR_S1 | F28: =G28 & " of " & VLOOKUP(H28,$B$5:$C$84,2,FALSE) & IF(J28<>0,IF(VLOOKUP(J28,$V$5:$W$12,2,FALSE)<>""," - " & VLOOKUP(J28,$V$5:$W$12,2,FALSE),""),"") -> Import of Bio Jet Kerosene - Step 1 | G28: =VLOOKUP(I28,$S$5:$T$10,2,FALSE) -> Import | H28: =B68 -> BIOJKR | I28: =$S$6 -> IMP | J28: =$V$9 -> _S1 | K28: IMP
B29: WON | C29: Wind On-Shore | E29: =I29&H29&J29 -> IMPBIOWPE_S1 | F29: =G29 & " of " & VLOOKUP(H29,$B$5:$C$84,2,FALSE) & IF(J29<>0,IF(VLOOKUP(J29,$V$5:$W$12,2,FALSE)<>""," - " & VLOOKUP(J29,$V$5:$W$12,2,FALSE),""),"") -> Import of Wood Pellets - Step 1 | G29: =VLOOKUP(I29,$S$5:$T$10,2,FALSE) -> Import | H29: =B73 -> BIOWPE | I29: =$S$6 -> IMP | J29: =$V$9 -> _S1 | K29: IMP
B30: WOF | C30: Wind Off-Shore | E30: =I30&H30&J30 -> IMPBIOWPE_S2 | F30: =G30 & " of " & VLOOKUP(H30,$B$5:$C$84,2,FALSE) & IF(J30<>0,IF(VLOOKUP(J30,$V$5:$W$12,2,FALSE)<>""," - " & VLOOKUP(J30,$V$5:$W$12,2,FALSE),""),"") -> Import of Wood Pellets - Step 2 | G30: =VLOOKUP(I30,$S$5:$T$10,2,FALSE) -> Import | H30: =B73 -> BIOWPE | I30: =$S$6 -> IMP | J30: =$V$10 -> _S2 | K30: IMP
B31: HYD | C31: Hydro | E31: =I31&H31&J31 -> IMPBIOWPE_S3 | F31: =G31 & " of " & VLOOKUP(H31,$B$5:$C$84,2,FALSE) & IF(J31<>0,IF(VLOOKUP(J31,$V$5:$W$12,2,FALSE)<>""," - " & VLOOKUP(J31,$V$5:$W$12,2,FALSE),""),"") -> Import of Wood Pellets - Step 3 | G31: =VLOOKUP(I31,$S$5:$T$10,2,FALSE) -> Import | H31: =B73 -> BIOWPE | I31: =$S$6 -> IMP | J31: =$V$11 -> _S3 | K31: IMP
B32: TDL | C32: Tide | E32: =I32&H32&J32 -> IMPBIOWPE_S4 | F32: =G32 & " of " & VLOOKUP(H32,$B$5:$C$84,2,FALSE) & IF(J32<>0,IF(VLOOKUP(J32,$V$5:$W$12,2,FALSE)<>""," - " & VLOOKUP(J32,$V$5:$W$12,2,FALSE),""),"") -> Import of Wood Pellets - Step 4 | G32: =VLOOKUP(I32,$S$5:$T$10,2,FALSE) -> Import | H32: =B73 -> BIOWPE | I32: =$S$6 -> IMP | J32: =$V$12 -> _S4 | K32: IMP
B33: WAV | C33: Wave | E33: =I33&H33&J33 -> IMPBIOWCH_S1 | F33: =G33 & " of " & VLOOKUP(H33,$B$5:$C$84,2,FALSE) & IF(J33<>0,IF(VLOOKUP(J33,$V$5:$W$12,2,FALSE)<>""," - " & VLOOKUP(J33,$V$5:$W$12,2,FALSE),""),"") -> Import of Wood Chip - Step 1 | G33: =VLOOKUP(I33,$S$5:$T$10,2,FALSE) -> Import | H33: =B74 -> BIOWCH | I33: =$S$6 -> IMP | J33: =$V$9 -> _S1 | K33: IMP
B34: NUC | C34: Uranium | E34: =I34&H34&J34 -> IMPBIOWCH_S2 | F34: =G34 & " of " & VLOOKUP(H34,$B$5:$C$84,2,FALSE) & IF(J34<>0,IF(VLOOKUP(J34,$V$5:$W$12,2,FALSE)<>""," - " & VLOOKUP(J34,$V$5:$W$12,2,FALSE),""),"") -> Import of Wood Chip - Step 2 | G34: =VLOOKUP(I34,$S$5:$T$10,2,FALSE) -> Import | H34: =B74 -> BIOWCH | I34: =$S$6 -> IMP | J34: =$V$10 -> _S2 | K34: IMP
B35: ELC | C35: Electricity | E35: =I35&H35&J35 -> IMPBIOWCH_S3 | F35: =G35 & " of " & VLOOKUP(H35,$B$5:$C$84,2,FALSE) & IF(J35<>0,IF(VLOOKUP(J35,$V$5:$W$12,2,FALSE)<>""," - " & VLOOKUP(J35,$V$5:$W$12,2,FALSE),""),"") -> Import of Wood Chip - Step 3 | G35: =VLOOKUP(I35,$S$5:$T$10,2,FALSE) -> Import | H35: =B74 -> BIOWCH | I35: =$S$6 -> IMP | J35: =$V$11 -> _S3 | K35: IMP
B36: HET | C36: Heat | E36: =I36&H36&J36 -> IMPBIOWCH_S4 | F36: =G36 & " of " & VLOOKUP(H36,$B$5:$C$84,2,FALSE) & IF(J36<>0,IF(VLOOKUP(J36,$V$5:$W$12,2,FALSE)<>""," - " & VLOOKUP(J36,$V$5:$W$12,2,FALSE),""),"") -> Import of Wood Chip - Step 4 | G36: =VLOOKUP(I36,$S$5:$T$10,2,FALSE) -> Import | H36: =B74 -> BIOWCH | I36: =$S$6 -> IMP | J36: =$V$12 -> _S4 | K36: IMP
B37: WAS | C37: Waste | E37: =I37&H37&J37 -> MINGASNAT_S1 | F37: =G37 & " of " & VLOOKUP(H37,$B$5:$C$84,2,FALSE) & IF(J37<>0,IF(VLOOKUP(J37,$V$5:$W$12,2,FALSE)<>""," - " & VLOOKUP(J37,$V$5:$W$12,2,FALSE),""),"") -> Domestic Potential of Natural Gas - Step 1 | G37: =VLOOKUP(I37,$S$5:$T$10,2,FALSE) -> Domestic Potential | H37: =B53 -> GASNAT | I37: =$S$5 -> MIN | J37: =$V$9 -> _S1 | K37: MIN
B38: COABIT | C38: Bituminous Coal | E38: =I38&H38&J38 -> MINGASNAT_S2 | F38: =G38 & " of " & VLOOKUP(H38,$B$5:$C$84,2,FALSE) & IF(J38<>0,IF(VLOOKUP(J38,$V$5:$W$12,2,FALSE)<>""," - " & VLOOKUP(J38,$V$5:$W$12,2,FALSE),""),"") -> Domestic Potential of Natural Gas - Step 2 | G38: =VLOOKUP(I38,$S$5:$T$10,2,FALSE) -> Domestic Potential | H38: =B53 -> GASNAT | I38: =$S$5 -> MIN | J38: =$V$10 -> _S2 | K38: MIN
B39: COAHAR | C39: Hard Coal / Antracite | E39: =I39&H39&J39 -> MINPEAT_S1 | F39: =G39 & " of " & VLOOKUP(H39,$B$5:$C$84,2,FALSE) & IF(J39<>0,IF(VLOOKUP(J39,$V$5:$W$12,2,FALSE)<>""," - " & VLOOKUP(J39,$V$5:$W$12,2,FALSE),""),"") -> Domestic Potential of Peat - Step 1 | G39: =VLOOKUP(I39,$S$5:$T$10,2,FALSE) -> Domestic Potential | H39: =B42 -> PEAT | I39: =$S$5 -> MIN | J39: =$V$9 -> _S1 | K39: MIN
B40: COACOK | C40: Coke Coal | E40: =I40&H40&J40 -> MINPEAT_S2 | F40: =G40 & " of " & VLOOKUP(H40,$B$5:$C$84,2,FALSE) & IF(J40<>0,IF(VLOOKUP(J40,$V$5:$W$12,2,FALSE)<>""," - " & VLOOKUP(J40,$V$5:$W$12,2,FALSE),""),"") -> Domestic Potential of Peat - Step 2 | G40: =VLOOKUP(I40,$S$5:$T$10,2,FALSE) -> Domestic Potential | H40: =B42 -> PEAT | I40: =$S$5 -> MIN | J40: =$V$10 -> _S2 | K40: MIN
B41: COALIG | C41: Lignite / Brown Coal | E41: =I41&H41&J41 -> MINRENHYD | F41: =G41 & " of " & VLOOKUP(H41,$B$5:$C$84,2,FALSE) & IF(J41<>0,IF(VLOOKUP(J41,$V$5:$W$12,2,FALSE)<>""," - " & VLOOKUP(J41,$V$5:$W$12,2,FALSE),""),"") -> Domestic Potential of Hydro | G41: =VLOOKUP(I41,$S$5:$T$10,2,FALSE) -> Domestic Potential | H41: =B56 -> RENHYD | I41: =$S$5 -> MIN | K41: MIN
B42: PEAT | C42: Peat | E42: =I42&H42&J42 -> MINRENWIN | F42: =G42 & " of " & VLOOKUP(H42,$B$5:$C$84,2,FALSE) & IF(J42<>0,IF(VLOOKUP(J42,$V$5:$W$12,2,FALSE)<>""," - " & VLOOKUP(J42,$V$5:$W$12,2,FALSE),""),"") -> Domestic Potential of Wind | G42: =VLOOKUP(I42,$S$5:$T$10,2,FALSE) -> Domestic Potential | H42: =B57 -> RENWIN | I42: =$S$5 -> MIN | K42: MIN
...

Sheet Commodities
B2: ~FI_Comm
B3: Csets | C3: CommName | D3: CommDesc | E3: Unit | F3: LimType | G3: CTSLvl | H3: PeakTS | I3: Ctype
B4: \I: Commodity set | C4: Commodity name | D4: Description
B5: \I: Energy Commodities
B6: NRG | C6: =CONVENTIONS!B38 -> COABIT | D6: =CONVENTIONS!C38 -> Bituminous Coal | E6: PJ
B7: NRG | C7: =CONVENTIONS!B39 -> COAHAR | D7: =CONVENTIONS!C39 -> Hard Coal / Antracite | E7: PJ
B8: NRG | C8: =CONVENTIONS!B40 -> COACOK | D8: =CONVENTIONS!C40 -> Coke Coal | E8: PJ
B9: NRG | C9: =CONVENTIONS!B41 -> COALIG | D9: =CONVENTIONS!C41 -> Lignite / Brown Coal | E9: PJ
B10: NRG | C10: =CONVENTIONS!B42 -> PEAT | D10: =CONVENTIONS!C42 -> Peat | E10: PJ
B11: NRG | C11: =CONVENTIONS!B43 -> OILCRD | D11: =CONVENTIONS!C43 -> Crude Oil | E11: PJ
B12: NRG | C12: =CONVENTIONS!B44 -> OILRFG | D12: =CONVENTIONS!C44 -> Refinery Gas | E12: PJ
B13: NRG | C13: =CONVENTIONS!B45 -> OILKER | D13: =CONVENTIONS!C45 -> Kerosene | E13: PJ
B14: NRG | C14: =CONVENTIONS!B46 -> OILHFO | D14: =CONVENTIONS!C46 -> Heavy Fuel Oil | E14: PJ
B15: NRG | C15: =CONVENTIONS!B47 -> OILDST | D15: =CONVENTIONS!C47 -> Diesel Oil | E15: PJ
B16: NRG | C16: =CONVENTIONS!B48 -> OILLPG | D16: =CONVENTIONS!C48 -> Liquified Petroleum Gas | E16: PJ
B17: NRG | C17: =CONVENTIONS!B49 -> OILGSL | D17: =CONVENTIONS!C49 -> Gasoline | E17: PJ
... B20: NRG | C20: =CONVENTIONS!B52 -> OILNEU | D20: =CONVENTIONS!C52 -> Oil for Non-Energy uses | E20: PJ
B21: NRG | C21: =CONVENTIONS!B53 -> GASNAT | D21: =CONVENTIONS!C53 -> Natural Gas | E21: PJ | G21: SEASON
B22: NRG | C22: =CONVENTIONS!B54 -> GASLNG | D22: =CONVENTIONS!C54 -> Liquified Natural Gas | E22: PJ | G22: SEASON
B23: NRG | C23: =CONVENTIONS!B55 -> NUCURM | D23: =CONVENTIONS!C55 -> Uranium | E23: PJ
B24: NRG | C24: =CONVENTIONS!B56 -> RENHYD | D24: =CONVENTIONS!C56 -> Hydro | E24: PJ
B25: NRG | C25: =CONVENTIONS!B57 -> RENWIN | D25: =CONVENTIONS!C57 -> Wind | E25: PJ
B26: NRG | C26: =CONVENTIONS!B58 -> RENSOL | D26: =CONVENTIONS!C58 -> Solar | E26: PJ
B27: NRG | C27: =CONVENTIONS!B59 -> MSWAS | D27: =CONVENTIONS!C59 -> Municipal Solid Waste | E27: PJ
B28: NRG | C28: =CONVENTIONS!B60 -> RENOCE | D28: =CONVENTIONS!C60 -> Ocean | E28: PJ
B29: NRG | C29: =CONVENTIONS!B61 -> RENAHT | D29: =CONVENTIONS!C61 -> Ambient Heat | E29: PJ
B30: NRG | C30: =CONVENTIONS!B62 -> BIOETH1G | D30: =CONVENTIONS!C62 -> Ethanol 1st generation | E30: PJ
B31: NRG | C31: =CONVENTIONS!B63 -> BIOETH2G | D31: =CONVENTIONS!C63 -> Ethanol 2nd generation | E31: PJ
B32: NRG | C32: =CONVENTIONS!B64 -> BIODST1G | D32: =CONVENTIONS!C64 -> Biodiesel 1st generation | E32: PJ
B33: NRG | C33: =CONVENTIONS!B65 -> BIODST2G | D33: =CONVENTIONS!C65 -> Biodiesel 2nd generation | E33: PJ
B34: NRG | C34: =CONVENTIONS!B66 -> BIOGAS1G | D34: =CONVENTIONS!C66 -> Biogas 1st generation | E34: PJ
B35: NRG | C35: =CONVENTIONS!B67 -> BIOGAS2G | D35: =CONVENTIONS!C67 -> Biogas 2nd generation | E35: PJ
B36: NRG | C36: =CONVENTIONS!B68 -> BIOJKR | D36: Bio Jet Kerosene | E36: PJ
B37: NRG | C37: =CONVENTIONS!B69 -> BIOWOO | D37: =CONVENTIONS!C69 -> Biomass - generic | E37: PJ
B38: NRG | C38: =CONVENTIONS!B70 -> BIOWOO1 | D38: =CONVENTIONS!C70 -> Sawmill residues | E38: PJ
B39: NRG | C39: =CONVENTIONS!B71 -> BIOWOO2 | D39: =CONVENTIONS!C71 -> Post-Consumer Recycled Wood | E39: PJ
B40: NRG | C40: =CONVENTIONS!B72 -> BIOWOO3 | D40: =CONVENTIONS!C72 -> Straw | E40: PJ
B41: NRG | C41: =CONVENTIONS!B73 -> BIOWPE | D41: =CONVENTIONS!C73 -> Wood Pellets | E41: PJ
B42: NRG | C42: =CONVENTIONS!B74 -> BIOWCH | D42: =CONVENTIONS!C74 -> Wood Chip | E42: PJ
B43: NRG | C43: =CONVENTIONS!B75 -> BIOMSW1 | D43: =CONVENTIONS!C75 -> Biodegradable Municipal Solid Waste potential - Solid | E43: PJ
...

Sheet Processes
B1: Processes definition
B3: ~FI_Process | N3: ~FI_Process
B4: Sets | C4: Region | D4: TechName | E4: TechDesc | F4: Tact | G4: Tcap | H4: Tslvl | I4: PrimaryCG | J4: Vintage | N4: Sets | O4: Region | P4: TechName | Q4: TechDesc | R4: Tact | S4: Tcap | T4: Tslvl | U4: PrimaryCG | V4: Vintage
B5: \I: Process Set Membership | D5: Technology name | E5: Description | F5: Activity unit | G5: Capacity unit | H5: TimeSlice level of Process Activity | I5: Primary Commodity Group | J5: Vintage Tracking | N5: \I: Process Set Membership | P5: Technology name | Q5: Description | R5: Activity unit | S5: Capacity unit | T5: TimeSlice level of Process Activity | U5: Primary Commodity Group | V5: Vintage Tracking
B6: \I: Fossil Import Processes | N6: \I: Fossil Import Processes
B7: =CONVENTIONS!K5 -> IMP | C7: =_xlfn.TEXTJOIN(",",TRUE,IF(LEFT(Regions!$C$3,1)<>"*",Regions!$C$3,""),IF(LEFT(Regions!$D$3,1)<>"*",Regions!$D$3,"")) -> IE,National | D7: =CONVENTIONS!E5 -> IMPCOABIT | E7: =CONVENTIONS!F5 -> Import of Bituminous Coal | F7: PJ | G7: PJa | N7: MIN | O7: IE,National | P7: MINBIOWOO3_S1 | Q7: Domestic Potential of Straw - Step 1 | R7: PJ | S7: PJa
B8: =CONVENTIONS!K6 -> IMP | C8: =_xlfn.TEXTJOIN(",",TRUE,IF(LEFT(Regions!$C$3,1)<>"*",Regions!$C$3,""),IF(LEFT(Regions!$D$3,1)<>"*",Regions!$D$3,"")) -> IE,National | D8: =CONVENTIONS!E6 -> IMPCOAHAR | E8: =CONVENTIONS!F6 -> Import of Hard Coal / Antracite | F8: PJ | G8: PJa | N8: MIN | O8: IE,National | P8: MINBIOWOO3_S2 | Q8: Domestic Potential of Straw - Step 2 | R8: PJ | S8: PJa
B9: =CONVENTIONS!K7 -> IMP | C9: =_xlfn.TEXTJOIN(",",TRUE,IF(LEFT(Regions!$C$3,1)<>"*",Regions!$C$3,""),IF(LEFT(Regions!$D$3,1)<>"*",Regions!$D$3,"")) -> IE,National | D9: =CONVENTIONS!E7 -> IMPCOACOK | E9: =CONVENTIONS!F7 -> Import of Coke Coal | F9: PJ | G9: PJa | N9: MIN | O9: IE,National | P9: MINBIOWOO3_S3 | Q9: Domestic Potential of Straw - Step 3 | R9: PJ | S9: PJa
B10: =CONVENTIONS!K8 -> IMP | C10: =_xlfn.TEXTJOIN(",",TRUE,IF(LEFT(Regions!$C$3,1)<>"*",Regions!$C$3,""),IF(LEFT(Regions!$D$3,1)<>"*",Regions!$D$3,"")) -> IE,National | D10: =CONVENTIONS!E8 -> IMPCOALIG | E10: =CONVENTIONS!F8 -> Import of Lignite / Brown Coal | F10: PJ | G10: PJa | N10: MIN | O10: IE,National | P10: MINBIOMSW1_S1 | Q10: Domestic Potential of Biodegradable Municipal Solid Waste potential - Solid - Step 1 | R10: PJ | S10: PJa
B11: =CONVENTIONS!K9 -> IMP | C11: =_xlfn.TEXTJOIN(",",TRUE,IF(LEFT(Regions!$C$3,1)<>"*",Regions!$C$3,""),IF(LEFT(Regions!$D$3,1)<>"*",Regions!$D$3,"")) -> IE,National | D11: =CONVENTIONS!E9 -> IMPOILCRD | E11: =CONVENTIONS!F9 -> Import of Crude Oil | F11: PJ | G11: PJa | N11: MIN | O11: IE,National | P11: MINBIOMSW1_S2 | Q11: Domestic Potential of Biodegradable Municipal Solid Waste potential - Solid - Step 2 | R11: PJ | S11: PJa
B12: =CONVENTIONS!K10 -> IMP | C12: =_xlfn.TEXTJOIN(",",TRUE,IF(LEFT(Regions!$C$3,1)<>"*",Regions!$C$3,""),IF(LEFT(Regions!$D$3,1)<>"*",Regions!$D$3,"")) -> IE,National | D12: =CONVENTIONS!E10 -> IMPOILKER | E12: =CONVENTIONS!F10 -> Import of Kerosene | F12: PJ | G12: PJa | N12: MIN | O12: IE,National | P12: MINBIOMSW1_S3 | Q12: Domestic Potential of Biodegradable Municipal Solid Waste potential - Solid - Step 3 | R12: PJ | S12: PJa
B13: =CONVENTIONS!K11 -> IMP | C13: =_xlfn.TEXTJOIN(",",TRUE,IF(LEFT(Regions!$C$3,1)<>"*",Regions!$C$3,""),IF(LEFT(Regions!$D$3,1)<>"*",Regions!$D$3,"")) -> IE,National | D13: =CONVENTIONS!E11 -> IMPOILHFO | E13: =CONVENTIONS!F11 -> Import of Heavy Fuel Oil | F13: PJ | G13: PJa | N13: MIN | O13: IE,National | P13: MINBIOMSW2_S1 | Q13: Domestic Potential of Biodegradable Municipal Solid Waste - Step 1 | R13: PJ | S13: PJa
B14: =CONVENTIONS!K12 -> IMP | C14: =_xlfn.TEXTJOIN(",",TRUE,IF(LEFT(Regions!$C$3,1)<>"*",Regions!$C$3,""),IF(LEFT(Regions!$D$3,1)<>"*",Regions!$D$3,"")) -> IE,National | D14: =CONVENTIONS!E12 -> IMPOILDST | E14: =CONVENTIONS!F12 -> Import of Diesel Oil | F14: PJ | G14: PJa | N14: MIN | O14: IE,National | P14: MINBIOMSW2_S2 | Q14: Domestic Potential of Biodegradable Municipal Solid Waste - Step 2 | R14: PJ | S14: PJa
B15: =CONVENTIONS!K13 -> IMP | C15: =_xlfn.TEXTJOIN(",",TRUE,IF(LEFT(Regions!$C$3,1)<>"*",Regions!$C$3,""),IF(LEFT(Regions!$D$3,1)<>"*",Regions!$D$3,"")) -> IE,National | D15: =CONVENTIONS!E13 -> IMPOILLPG | E15: =CONVENTIONS!F13 -> Import of Liquified Petroleum Gas | F15: PJ | G15: PJa | N15: MIN | O15: IE,National | P15: MINBIOMSW2_S3 | Q15: Domestic Potential of Biodegradable Municipal Solid Waste - Step 3 | R15: PJ | S15: PJa
B16: =CONVENTIONS!K14 -> IMP | C16: =_xlfn.TEXTJOIN(",",TRUE,IF(LEFT(Regions!$C$3,1)<>"*",Regions!$C$3,""),IF(LEFT(Regions!$D$3,1)<>"*",Regions!$D$3,"")) -> IE,National | D16: =CONVENTIONS!E14 -> IMPOILGSL | E16: =CONVENTIONS!F14 -> Import of Gasoline | F16: PJ | G16: PJa | N16: MIN | O16: IE,National | P16: MINBIOTLW_S1 | Q16: Domestic Potential of Tallow - Step 1 | R16: PJ | S16: PJa
B17: =CONVENTIONS!K15 -> IMP | C17: =_xlfn.TEXTJOIN(",",TRUE,IF(LEFT(Regions!$C$3,1)<>"*",Regions!$C$3,""),IF(LEFT(Regions!$D$3,1)<>"*",Regions!$D$3,"")) -> IE,National | D17: =CONVENTIONS!E15 -> IMPOILCOK | E17: =CONVENTIONS!F15 -> Import of Petroleum Coke | F17: PJ | G17: PJa | N17: MIN | O17: IE,National | P17: MINBIOTLW_S2 | Q17: Domestic Potential of Tallow - Step 2 | R17: PJ | S17: PJa
B18: =CONVENTIONS!K16 -> IMP | C18: =_xlfn.TEXTJOIN(",",TRUE,IF(LEFT(Regions!$C$3,1)<>"*",Regions!$C$3,""),IF(LEFT(Regions!$D$3,1)<>"*",Regions!$D$3,"")) -> IE,National | D18: =CONVENTIONS!E16 -> IMPOILNEU | E18: =CONVENTIONS!F16 -> Import of Oil for Non-Energy uses | F18: PJ | G18: PJa | N18: MIN | O18: IE,National | P18: MINBIOTLW_S3 | Q18: Domestic Potential of Tallow - Step 3 | R18: PJ | S18: PJa
... B21: =CONVENTIONS!K19 -> IMP | C21: =_xlfn.TEXTJOIN(",",TRUE,IF(LEFT(Regions!$C$3,1)<>"*",Regions!$C$3,""),IF(LEFT(Regions!$D$3,1)<>"*",Regions!$D$3,"")) -> IE,National | D21: =CONVENTIONS!E19 -> IMPNUCURM | E21: =CONVENTIONS!F19 -> Import of Uranium | F21: PJ | G21: PJa | N21: MIN | O21: IE,National | P21: MINBIORVO_S3 | Q21: Domestic Potential of Recovered Vegetable Oil - Step 3 | R21: PJ | S21: PJa
B22: \I:Bio Import Processes | N22: MIN | O22: IE,National | P22: MINBIOCATW_S1 | Q22: Domestic Potential of Cattle Waste - Step 1 | R22: PJ | S22: PJa
B23: =CONVENTIONS!K20 -> IMP | C23: =_xlfn.TEXTJOIN(",",TRUE,IF(LEFT(Regions!$C$3,1)<>"*",Regions!$C$3,""),IF(LEFT(Regions!$D$3,1)<>"*",Regions!$D$3,"")) -> IE,National | D23: =CONVENTIONS!E20 -> IMPBIOETH1G_S1 | E23: =CONVENTIONS!F20 -> Import of Ethanol 1st generation - Step 1 | F23: PJ | G23: PJa | N23: MIN | O23: IE,National | P23: MINBIOCATW_S2 | Q23: Domestic Potential of Cattle Waste - Step 2 | R23: PJ | S23: PJa
B24: =CONVENTIONS!K21 -> IMP | C24: =_xlfn.TEXTJOIN(",",TRUE,IF(LEFT(Regions!$C$3,1)<>"*",Regions!$C$3,""),IF(LEFT(Regions!$D$3,1)<>"*",Regions!$D$3,"")) -> IE,National | D24: =CONVENTIONS!E21 -> IMPBIOETH1G_S2 | E24: =CONVENTIONS!F21 -> Import of Ethanol 1st generation - Step 2 | F24: PJ | G24: PJa | N24: MIN | O24: IE,National | P24: MINBIOCATW_S3 | Q24: Domestic Potential of Cattle Waste - Step 3 | R24: PJ | S24: PJa
B25: =CONVENTIONS!K22 -> IMP | C25: =_xlfn.TEXTJOIN(",",TRUE,IF(LEFT(Regions!$C$3,1)<>"*",Regions!$C$3,""),IF(LEFT(Regions!$D$3,1)<>"*",Regions!$D$3,"")) -> IE,National | D25: =CONVENTIONS!E22 -> IMPBIOETH1G_S3 | E25: =CONVENTIONS!F22 -> Import of Ethanol 1st generation - Step 3 | F25: PJ | G25: PJa | N25: MIN | O25: IE,National | P25: MINBIOPIGW_S1 | Q25: Domestic Potential of Pig Waste - Step 1 | R25: PJ | S25: PJa
B26: =CONVENTIONS!K23 -> IMP | C26: =_xlfn.TEXTJOIN(",",TRUE,IF(LEFT(Regions!$C$3,1)<>"*",Regions!$C$3,""),IF(LEFT(Regions!$D$3,1)<>"*",Regions!$D$3,"")) -> IE,National | D26: =CONVENTIONS!E23 -> IMPBIOETH1G_S4 | E26: =CONVENTIONS!F23 -> Import of Ethanol 1st generation - Step 4 | F26: PJ | G26: PJa | N26: MIN | O26: IE,National | P26: MINBIOPIGW_S2 | Q26: Domestic Potential of Pig Waste - Step 2 | R26: PJ | S26: PJa
B27: =CONVENTIONS!K24 -> IMP | C27: =_xlfn.TEXTJOIN(",",TRUE,IF(LEFT(Regions!$C$3,1)<>"*",Regions!$C$3,""),IF(LEFT(Regions!$D$3,1)<>"*",Regions!$D$3,"")) -> IE,National | D27: =CONVENTIONS!E24 -> IMPBIODST1G_S1 | E27: =CONVENTIONS!F24 -> Import of Biodiesel 1st generation - Step 1 | F27: PJ | G27: PJa | N27: MIN | O27: IE,National | P27: MINBIOPIGW_S3 | Q27: Domestic Potential of Pig Waste - Step 3 | R27: PJ | S27: PJa
B28: =CONVENTIONS!K25 -> IMP | C28: =_xlfn.TEXTJOIN(",",TRUE,IF(LEFT(Regions!$C$3,1)<>"*",Regions!$C$3,""),IF(LEFT(Regions!$D$3,1)<>"*",Regions!$D$3,"")) -> IE,National | D28: =CONVENTIONS!E25 -> IMPBIODST1G_S2 | E28: =CONVENTIONS!F25 -> Import of Biodiesel 1st generation - Step 2 | F28: PJ | G28: PJa | N28: MIN | O28: IE,National | P28: MINBIOINDF_S1 | Q28: Domestic Potential of Industrial Food Waste - Step 1 | R28: PJ | S28: PJa
B29: =CONVENTIONS!K26 -> IMP | C29: =_xlfn.TEXTJOIN(",",TRUE,IF(LEFT(Regions!$C$3,1)<>"*",Regions!$C$3,""),IF(LEFT(Regions!$D$3,1)<>"*",Regions!$D$3,"")) -> IE,National | D29: =CONVENTIONS!E26 -> IMPBIODST1G_S3 | E29: =CONVENTIONS!F26 -> Import of Biodiesel 1st generation - Step 3 | F29: PJ | G29: PJa | N29: MIN | O29: IE,National | P29: MINBIOINDF_S2 | Q29: Domestic Potential of Industrial Food Waste - Step 2 | R29: PJ | S29: PJa
B30: =CONVENTIONS!K27 -> IMP | C30: =_xlfn.TEXTJOIN(",",TRUE,IF(LEFT(Regions!$C$3,1)<>"*",Regions!$C$3,""),IF(LEFT(Regions!$D$3,1)<>"*",Regions!$D$3,"")) -> IE,National | D30: =CONVENTIONS!E27 -> IMPBIODST1G_S4 | E30: =CONVENTIONS!F27 -> Import of Biodiesel 1st generation - Step 4 | F30: PJ | G30: PJa | N30: MIN | O30: IE,National | P30: MINBIOINDF_S3 | Q30: Domestic Potential of Industrial Food Waste - Step 3 | R30: PJ | S30: PJa
B31: =CONVENTIONS!K29 -> IMP | C31: =_xlfn.TEXTJOIN(",",TRUE,IF(LEFT(Regions!$C$3,1)<>"*",Regions!$C$3,""),IF(LEFT(Regions!$D$3,1)<>"*",Regions!$D$3,"")) -> IE,National | D31: =CONVENTIONS!E28 -> IMPBIOJKR_S1 | E31: =CONVENTIONS!F28 -> Import of Bio Jet Kerosene - Step 1 | F31: PJ | G31: PJa
B32: =CONVENTIONS!K29 -> IMP | C32: =_xlfn.TEXTJOIN(",",TRUE,IF(LEFT(Regions!$C$3,1)<>"*",Regions!$C$3,""),IF(LEFT(Regions!$D$3,1)<>"*",Regions!$D$3,"")) -> IE,National | D32: =CONVENTIONS!E29 -> IMPBIOWPE_S1 | E32: =CONVENTIONS!F29 -> Import of Wood Pellets - Step 1 | F32: PJ | G32: PJa
B33: =CONVENTIONS!K30 -> IMP | C33: =_xlfn.TEXTJOIN(",",TRUE,IF(LEFT(Regions!$C$3,1)<>"*",Regions!$C$3,""),IF(LEFT(Regions!$D$3,1)<>"*",Regions!$D$3,"")) -> IE,National | D33: =CONVENTIONS!E30 -> IMPBIOWPE_S2 | E33: =CONVENTIONS!F30 -> Import of Wood Pellets - Step 2 | F33: PJ | G33: PJa
B34: =CONVENTIONS!K31 -> IMP | C34: =_xlfn.TEXTJOIN(",",TRUE,IF(LEFT(Regions!$C$3,1)<>"*",Regions!$C$3,""),IF(LEFT(Regions!$D$3,1)<>"*",Regions!$D$3,"")) -> IE,National | D34: =CONVENTIONS!E31 -> IMPBIOWPE_S3 | E34: =CONVENTIONS!F31 -> Import of Wood Pellets - Step 3 | F34: PJ | G34: PJa
B35: =CONVENTIONS!K32 -> IMP | C35: =_xlfn.TEXTJOIN(",",TRUE,IF(LEFT(Regions!$C$3,1)<>"*",Regions!$C$3,""),IF(LEFT(Regions!$D$3,1)<>"*",Regions!$D$3,"")) -> IE,National | D35: =CONVENTIONS!E32 -> IMPBIOWPE_S4 | E35: =CONVENTIONS!F32 -> Import of Wood Pellets - Step 4 | F35: PJ | G35: PJa
B36: =CONVENTIONS!K33 -> IMP | C36: =_xlfn.TEXTJOIN(",",TRUE,IF(LEFT(Regions!$C$3,1)<>"*",Regions!$C$3,""),IF(LEFT(Regions!$D$3,1)<>"*",Regions!$D$3,"")) -> IE,National | D36: =CONVENTIONS!E33 -> IMPBIOWCH_S1 | E36: =CONVENTIONS!F33 -> Import of Wood Chip - Step 1 | F36: PJ | G36: PJa
B37: =CONVENTIONS!K34 -> IMP | C37: =_xlfn.TEXTJOIN(",",TRUE,IF(LEFT(Regions!$C$3,1)<>"*",Regions!$C$3,""),IF(LEFT(Regions!$D$3,1)<>"*",Regions!$D$3,"")) -> IE,National | D37: =CONVENTIONS!E34 -> IMPBIOWCH_S2 | E37: =CONVENTIONS!F34 -> Import of Wood Chip - Step 2 | F37: PJ | G37: PJa
B38: =CONVENTIONS!K35 -> IMP | C38: =_xlfn.TEXTJOIN(",",TRUE,IF(LEFT(Regions!$C$3,1)<>"*",Regions!$C$3,""),IF(LEFT(Regions!$D$3,1)<>"*",Regions!$D$3,"")) -> IE,National | D38: =CONVENTIONS!E35 -> IMPBIOWCH_S3 | E38: =CONVENTIONS!F35 -> Import of Wood Chip - Step 3 | F38: PJ | G38: PJa
B39: =CONVENTIONS!K36 -> IMP | C39: =_xlfn.TEXTJOIN(",",TRUE,IF(LEFT(Regions!$C$3,1)<>"*",Regions!$C$3,""),IF(LEFT(Regions!$D$3,1)<>"*",Regions!$D$3,"")) -> IE,National | D39: =CONVENTIONS!E36 -> IMPBIOWCH_S4 | E39: =CONVENTIONS!F36 -> Import of Wood Chip - Step 4 | F39: PJ | G39: PJa
B40: \I:Domestic potentials
B41: =CONVENTIONS!K37 -> MIN | C41: =_xlfn.TEXTJOIN(",",TRUE,IF(LEFT(Regions!$C$3,1)<>"*",Regions!$C$3,""),IF(LEFT(Regions!$D$3,1)<>"*",Regions!$D$3,"")) -> IE,National | D41: =CONVENTIONS!E37 -> MINGASNAT_S1 | E41: =CONVENTIONS!F37 -> Domestic Potential of Natural Gas - Step 1 | F41: PJ | G41: PJa
B42: =CONVENTIONS!K38 -> MIN | C42: =_xlfn.TEXTJOIN(",",TRUE,IF(LEFT(Regions!$C$3,1)<>"*",Regions!$C$3,""),IF(LEFT(Regions!$D$3,1)<>"*",Regions!$D$3,"")) -> IE,National | D42: =CONVENTIONS!E38 -> MINGASNAT_S2 | E42: =CONVENTIONS!F38 -> Domestic Potential of Natural Gas - Step 2 | F42: PJ | G42: PJa
B43: =CONVENTIONS!K39 -> MIN | C43: =_xlfn.TEXTJOIN(",",TRUE,IF(LEFT(Regions!$C$3,1)<>"*",Regions!$C$3,""),IF(LEFT(Regions!$D$3,1)<>"*",Regions!$D$3,"")) -> IE,National | D43: =CONVENTIONS!E39 -> MINPEAT_S1 | E43: =CONVENTIONS!F39 -> Domestic Potential of Peat - Step 1 | F43: PJ | G43: PJa
...

Sheet SUP_FuelTech
B1: Fuel Techs - Sectoral infrastructure
E3: ~FI_T
B4: Region | C4: TechName | D4: Comm-IN | E4: Comm-OUT | F4: EFF | G4: Life | H4: Share-I | I4: Pasti | J4: INVCOST | K4: NCAP_BND~UP~0
B5: * | I5: PJa | J5: €/GJa | K5: Interpolation
B6: =Processes!C87 -> IE,National | C6: =Processes!D87 -> FT-SUPNGA | D6: =Commodities!C21 -> GASNAT | E6: =Commodities!C53 -> SUPNGA | F6: 1
B7: =Processes!C88 -> IE,National | C7: =Processes!D88 -> FT-SUPCOA | D7: =Commodities!C7 -> COAHAR | E7: =Commodities!C52 -> SUPCOA | F7: 1
B8: =Processes!C89 -> IE,National | C8: =Processes!D89 -> FT-SUPWAS | D8: =Commodities!C27 -> MSWAS | E8: =Commodities!C56 -> SUPWAS | F8: 1
B9: =Processes!C90 -> IE,National | C9: =Processes!D90 -> FT-SUPBIO | D9: =_xlfn.TEXTJOIN(", ",TRUE,Commodities!C37,Commodities!C41,Commodities!C42) -> BIOWOO, BIOWPE, BIOWCH | E9: =Commodities!C54 -> SUPBIO | F9: 1
B10: =Processes!C91 -> IE,National | C10: =Processes!D91 -> FT-SUPELC | D10: ELCC | E10: =Commodities!C55 -> SUPELC | F10: 1

Sheet Imports_Fossil
B1: Fossil Fuels Import Prices
G3: ~FI_T: IRE_PRICE
C4: Region | D4: TechName | E4: *TechDesc | F4: Other_Indexes | G4: Comm-OUT | H4: 2018~MEUR2018 | I4: 2019~MEUR2019 | J4: 2025~MEUR2019 | K4: 2030~MEUR2019 | L4: 2035~MEUR2019 | M4: 2040~MEUR2019 | N4: *Source/Ratio
C5: *Region Name | D5: *Technology Name | E5: Technology Description | F5: import/Export | G5: Output Commodity | I5: €/GJ | J5: €/GJ | K5: €/GJ | L5: €/GJ | M5: €/GJ
C6: =Processes!C11 -> IE,National | D6: =Processes!D11 -> IMPOILCRD | E6: =Processes!E11 -> Import of Crude Oil | F6: IMP | G6: =Commodities!C11 -> OILCRD | H6: =F55 -> 10.080858 | I6: =Imports_Fossil!F37 -> 9.8525376 | J6: =Imports_Fossil!G37 -> 11.103653 | K6: =Imports_Fossil!H37 -> 11.885601 | L6: =Imports_Fossil!I37 -> 12.667548 | M6: =Imports_Fossil!J37 -> 13.293106 | N6: WEO2019, WEO2020
C7: =Processes!C19 -> IE,National | D7: =Processes!D19 -> IMPGASNAT_UK | E7: =Processes!E19 -> Import of Natural Gas - UK | F7: IMP | G7: =Commodities!C21 -> GASNAT | H7: =F56 -> 6.0993956 | I7: =Imports_Fossil!F38 -> 5.6724016 | J7: =Imports_Fossil!G38 -> 6.1803779 | K7: =Imports_Fossil!H38 -> 9.3975609 | L7: =Imports_Fossil!I38 -> 11.006152 | M7: =Imports_Fossil!J38 -> 12.890088 | N7: WEO2019, WEO2020 | R7: Coal prices | T7: https://www.eia.gov/energyexplained/coal/prices-and-outlook.php
C8: =Processes!C8 -> IE,National | D8: =Processes!D8 -> IMPCOAHAR | E8: =Processes!E8 -> Import of Hard Coal / Antracite | F8: IMP | G8: =Commodities!C7 -> COAHAR | H8: =F57 -> 1.8606832 | I8: =Imports_Fossil!F39 -> 1.3014677 | J8: =Imports_Fossil!G39 -> 1.3868099 | K8: =Imports_Fossil!H39 -> 1.7068429 | L8: =Imports_Fossil!I39 -> 1.8775272 | M8: =Imports_Fossil!J39 -> 2.06528 | N8: WEO2019, WEO2020
C9: =Processes!C7 -> IE,National | D9: =Processes!D7 -> IMPCOABIT | E9: =Processes!E7 -> Import of Bituminous Coal | F9: IMP | G9: =Commodities!C6 -> COABIT | H9: =H$8*$N$9 -> 1.7676491 | I9: =I$8*$N$9 -> 1.2363944 | J9: =J$8*$N$9 -> 1.3174694 | K9: =K$8*$N$9 -> 1.6215008 | L9: =L$8*$N$9 -> 1.7836509 | M9: =M$8*$N$9 -> 1.962016 | N9: 0.95 | R9: Type | S9: USD2019/short ton
C10: =Processes!C9 -> IE,National | D10: =Processes!D9 -> IMPCOACOK | E10: =Processes!E9 -> Import of Coke Coal | F10: IMP | G10: =Commodities!C8 -> COACOK | H10: =H$8*$N10 -> 2.3630677 | I10: =I$8*$N10 -> 1.652864 | J10: =J$8*$N10 -> 1.7612486 | K10: =K$8*$N10 -> 2.1676905 | L10: =L$8*$N10 -> 2.3844596 | M10: =M$8*$N10 -> 2.6229056 | N10: 1.27 | R10: Bituminous | S10: 58.93
C11: =Processes!C10 -> IE,National | D11: =Processes!D10 -> IMPCOALIG | E11: =Processes!E10 -> Import of Lignite / Brown Coal | F11: IMP | G11: =Commodities!C9 -> COALIG | H11: =H$8*$N11 -> 1.6291696 | I11: =I$8*$N11 -> 1.139534 | J11: =J$8*$N11 -> 1.2142575 | K11: =K$8*$N11 -> 1.4944708 | L11: =L$8*$N11 -> 1.6439179 | M11: =M$8*$N11 -> 1.8083096 | N11: 0.87557604 | R11: lignite | S11: 19.86
C12: =Processes!C20 -> IE,National | D12: =Processes!D20 -> IMPGASLNG_GLOBAL | E12: =Processes!E20 -> Import of Liquified Natural Gas | F12: IMP | G12: =Commodities!C22 -> GASLNG | H12: =H$7*$N12 -> 6.507802 | I12: =I$7*$N12 -> 6.0522172 | J12: =J$7*$N12 -> 6.5942068 | K12: =K$7*$N12 -> 10.026808 | L12: =L$7*$N12 -> 11.743108 | M12: =M$7*$N12 -> 13.753189 | N12: 1.0669585 | R12: anthracite | S12: 102.22
C13: =Processes!C14 -> IE,National | D13: =Processes!D14 -> IMPOILDST | E13: =Processes!E14 -> Import of Diesel Oil | F13: IMP | G13: =Commodities!C15 -> OILDST | H13: =H$6*$N13 -> 15.417783 | I13: =I$6*$N13 -> 15.068587 | J13: =J$6*$N13 -> 16.982058 | K13: =K$6*$N13 -> 18.177978 | L13: =L$6*$N13 -> 19.373897 | M13: =M$6*$N13 -> 20.330633 | N13: 1.5294118
C14: =Processes!C16 -> IE,National | D14: =Processes!D16 -> IMPOILGSL | E14: =Processes!E16 -> Import of Gasoline | F14: IMP | G14: =Commodities!C17 -> OILGSL | H14: =H$6*$N14 -> 16.603766 | I14: =I$6*$N14 -> 16.227709 | J14: =J$6*$N14 -> 18.28837 | K14: =K$6*$N14 -> 19.576284 | L14: =L$6*$N14 -> 20.864197 | M14: =M$6*$N14 -> 21.894528 | N14: 1.6470588
C15: =Processes!C13 -> IE,National | D15: =Processes!D13 -> IMPOILHFO | E15: =Processes!E13 -> Import of Heavy Fuel Oil | F15: IMP | G15: =Commodities!C14 -> OILHFO | H15: =H$6*$N15 -> 8.1654951 | I15: =I$6*$N15 -> 7.9805554 | J15: =J$6*$N15 -> 8.9939593 | K15: =K$6*$N15 -> 9.6273367 | L15: =L$6*$N15 -> 10.260714 | M15: =M$6*$N15 -> 10.767416 | N15: 0.81
C16: =Processes!C12 -> IE,National | D16: =Processes!D12 -> IMPOILKER | E16: =Processes!E12 -> Import of Kerosene | F16: IMP | G16: =Commodities!C13 -> OILKER | H16: =H$6*$N16 -> 16.603766 | I16: =I$6*$N16 -> 16.227709 | J16: =J$6*$N16 -> 18.28837 | K16: =K$6*$N16 -> 19.576284 | L16: =L$6*$N16 -> 20.864197 | M16: =M$6*$N16 -> 21.894528 | N16: 1.6470588
C17: =Processes!C15 -> IE,National | D17: =Processes!D15 -> IMPOILLPG | E17: =Processes!E15 -> Import of Liquified Petroleum Gas | F17: IMP | G17: =Commodities!C16 -> OILLPG | H17: =H$6*$N17 -> 13.045816 | I17: =I$6*$N17 -> 12.750343 | J17: =J$6*$N17 -> 14.369434 | K17: =K$6*$N17 -> 15.381366 | L17: =L$6*$N17 -> 16.393298 | M17: =M$6*$N17 -> 17.202843 | N17: 1.2941176
C18: =Processes!C17 -> IE,National | D18: =Processes!D17 -> IMPOILCOK | E18: =Processes!E17 -> Import of Petroleum Coke | F18: IMP | G18: =Commodities!C18 -> OILCOK | H18: =H$6*$N18 -> 16.603766 | I18: =I$6*$N18 -> 16.227709 | J18: =J$6*$N18 -> 18.28837 | K18: =K$6*$N18 -> 19.576284 | L18: =L$6*$N18 -> 20.864197 | M18: =M$6*$N18 -> 21.894528 | N18: 1.6470588
C19: =Processes!C21 -> IE,National | D19: =Processes!D21 -> IMPNUCURM | E19: =Processes!E21 -> Import of Uranium | F19: IMP | G19: =Commodities!C23 -> NUCURM
C20: =Processes!C18 -> IE,National | D20: =Processes!D18 -> IMPOILNEU | E20: =Processes!E18 -> Import of Oil for Non-Energy uses | F20: IMP | G20: =Commodities!C20 -> OILNEU | H20: =H6 -> 10.080858 | I20: =I6 -> 9.8525376 | J20: =J6 -> 11.103653 | K20: =K6 -> 11.885601 | L20: =L6 -> 12.667548 | M20: =M6 -> 13.293106
C24: Fossil fuels import prices | G24: Stated Policies | K24: Sustainable Development | M24: Delayed Recovery
C25: Real Terms (2019 Prices) | D25: unit | E25: 2010 | F25: 2019 | G25: 2025 | H25: 2030 | I25: 2035 | J25: 2040 | K25: 2025 | L25: 2040 | M25: 2025 | N25: 2040
C26: IEA crude oil | D26: $2019/barrel | E26: 91 | F26: 63 | G26: 71 | H26: 76 | I26: 81 | J26: 85 | K26: 57 | L26: 53 | M26: 59 | N26: 71
C27: Natural Gas - EU | D27: $2019/MBtu | E27: 8.7 | F27: 6.7 | G27: 7.3 | H27: 11.1 | I27: 13 | J27: =I27*(1+(I27/H27-1)) -> 15.225225 | K27: 4.8 | L27: 4.9 | M27: 6.3 | N27: 7.6
C28: Steam coal - EU | D28: $2019/tonne | E28: 108 | F28: 61 | G28: 65 | H28: 80 | I28: 88 | J28: =I28*(1+(I28/H28-1)) -> 96.8 | K28: 57 | L28: 55 | M28: 60 | N28: 64
C29: Source: Table 2.2 - Fossil fuel prices by scenario - WEO 2020, IEA
C31: Conversion to from USD to EUR | E31: =E25 -> 2010 | F31: =F25 -> 2019 | G31: =G25 -> 2025 | H31: =H25 -> 2030 | I31: =I25 -> 2035 | J31: =J25 -> 2040 | K31: =K25 -> 2025 | L31: =L25 -> 2040 | ... N31: =N25 -> 2040
C32: =C26 -> IEA crude oil | D32: €2019/barrel | E32: =E26/Conversions!$C$10 -> 81.288139 | F32: =F26/Conversions!$C$10 -> 56.276404 | G32: =G26/Conversions!$C$10 -> 63.422614 | H32: =H26/Conversions!$C$10 -> 67.888996 | I32: =I26/Conversions!$C$10 -> 72.355377 | J32: =J26/Conversions!$C$10 -> 75.928482 | K32: =K26/Conversions!$C$10 -> 50.916747 | L32: =L26/Conversions!$C$10 -> 47.343642 | ... N32: =N26/Conversions!$C$10 -> 63.422614
C33: =C27 -> Natural Gas - EU | D33: €2019/MBtu | E33: =E27/Conversions!$C$10 -> 7.7715034 | F33: =F27/Conversions!$C$10 -> 5.9849509 | G33: =G27/Conversions!$C$10 -> 6.5209167 | H33: =H27/Conversions!$C$10 -> 9.9153665 | I33: =I27/Conversions!$C$10 -> 11.612591 | J33: =J27/Conversions!$C$10 -> 13.600332 | K33: =K27/Conversions!$C$10 -> 4.287726 | L33: =L27/Conversions!$C$10 -> 4.3770537 | ... N33: =N27/Conversions!$C$10 -> 6.7888996
C34: =C28 -> Steam coal - EU | D34: €2019/tonne | E34: =E28/Conversions!$C$10 -> 96.473836 | F34: =F28/Conversions!$C$10 -> 54.489852 | G34: =G28/Conversions!$C$10 -> 58.062957 | H34: =H28/Conversions!$C$10 -> 71.462101 | I34: =I28/Conversions!$C$10 -> 78.608311 | J34: =J28/Conversions!$C$10 -> 86.469142 | K34: =K28/Conversions!$C$10 -> 50.916747 | L34: =L28/Conversions!$C$10 -> 49.130194 | ... N34: =N28/Conversions!$C$10 -> 57.16968
C36: Conversion to EUR/GJ | E36: =E25 -> 2010 | F36: =F25 -> 2019 | G36: =G25 -> 2025 | H36: =H25 -> 2030 | I36: =I25 -> 2035 | J36: =J25 -> 2040 | K36: =K25 -> 2025 | L36: =L25 -> 2040 | ... N36: =N25 -> 2040
C37: =C26 -> IEA crude oil | D37: €2019/GJ | E37: =E32/Conversions!$C$5 -> 14.231443 | F37: =F32/Conversions!$C$5 -> 9.8525376 | G37: =G32/Conversions!$C$5 -> 11.103653 | H37: =H32/Conversions!$C$5 -> 11.885601 | I37: =I32/Conversions!$C$5 -> 12.667548 | J37: =J32/Conversions!$C$5 -> 13.293106 | K37: =K32/Conversions!$C$5 -> 8.9142007 | L37: =L32/Conversions!$C$5 -> 8.2886427 | ... N37: =N32/Conversions!$C$5 -> 11.103653
C38: =C27 -> Natural Gas - EU | D38: €2019/GJ | E38: =E33/Conversions!$C$3 -> 7.3656558 | F38: =F33/Conversions!$C$3 -> 5.6724016 | G38: =G33/Conversions!$C$3 -> 6.1803779 | H38: =H33/Conversions!$C$3 -> 9.3975609 | I38: =I33/Conversions!$C$3 -> 11.006152 | J38: =J33/Conversions!$C$3 -> 12.890088 | K38: =K33/Conversions!$C$3 -> 4.0638101 | L38: =L33/Conversions!$C$3 -> 4.1484728 | ... N38: =N33/Conversions!$C$3 -> 6.434366
C39: =C28 -> Steam coal - EU | D39: €2019/GJ | E39: =E34/(Conversions!$C$2*1000) -> 2.304238 | F39: =F34/(Conversions!$C$2*1000) -> 1.3014677 | G39: =G34/(Conversions!$C$2*1000) -> 1.3868099 | H39: =H34/(Conversions!$C$2*1000) -> 1.7068429 | I39: =I34/(Conversions!$C$2*1000) -> 1.8775272 | J39: =J34/(Conversions!$C$2*1000) -> 2.06528 | K39: =K34/(Conversions!$C$2*1000) -> 1.2161256 | L39: =L34/(Conversions!$C$2*1000) -> 1.1734545 | ... N39: =N34/(Conversions!$C$2*1000) -> 1.3654744
C42: Fossil fuels import prices | G42: Stated Policies | K42: Sustainable Development | M42: Current Policies
C43: Real Terms (2018 Prices) | D43: unit | E43: 2010 | F43: 2018 | G43: 2025 | H43: 2030 | I43: 2035 | J43: 2040 | K43: 2025 | L43: 2040 | M43: 2025 | N43: 2040
C44: IEA crude oil | D44: $2018/barrel | E44: 90 | F44: 68 | G44: 81 | H44: 88 | I44: 96 | J44: 103 | K44: 62 | L44: 59 | M44: 111 | N44: 134
C45: Natural Gas - EU | D45: $2018/MBtu | E45: 8.6 | F45: 7.6 | G45: 8 | H45: 8 | I45: 8.4 | J45: 8.9 | K45: 7.5 | L45: 7.5 | M45: 8.9 | N45: 9.9
C46: Steam coal - EU | D46: $2018/tonne | E46: 106 | F46: 92 | G46: 75 | H46: 76 | I46: 78 | J46: 78 | K46: 58 | L46: 60 | M46: 83 | N46: 90
C47: Source: Table B.4 - Fossil fuel prices by scenario - WEO 2019, IEA
C49: Conversion to from USD to EUR | E49: =E43 -> 2010 | F49: =F43 -> 2018 | G49: =G43 -> 2025 | H49: =H43 -> 2030 | I49: =I43 -> 2035 | J49: =J43 -> 2040 | K49: =K43 -> 2025 | L49: =L43 -> 2040 | ... N49: =N43 -> 2040
...

Sheet Import CO2
B2: ~FI_Process
B3: Sets | C3: Region | D3: TechName | E3: TechDesc | F3: Tact | G3: Tcap | H3: Tslvl | I3: PrimaryCG | J3: Vintage
B4: \I: Process Set Membership | D4: Technology name | E4: Description | F4: Activity unit | G4: Capacity unit | H4: TimeSlice level of Process Activity | I4: Primary Commodity Group | J4: Vintage Tracking
B5: MIN | C5: =_xlfn.TEXTJOIN(",",TRUE,IF(LEFT(Regions!$C$3,1)<>"*",Regions!$C$3,""),IF(LEFT(Regions!$D$3,1)<>"*",Regions!$D$3,"")) -> IE,National | D5: MINCO2-CAL | E5: Domestic CO2 calibration | F5: PJ | G5: Pja
E9: ~FI_T
B10: Region | C10: TechName | D10: TechDesc | E10: Comm-OUT | F10: CUM | G10: COST~2018 | H10: ACT_BND~2023 | I10: ACT_BND~0
B11: *Region Name | C11: *Technology Name | D11: Technology Description | F11: PJ | G11: Euro/GJ
B12: =Processes!C60 -> IE,National | C12: =D5 -> MINCO2-CAL | D12: Domestic CO2 calibration | E12: AGRCO2N | F12: 1000000 | G12: 0.0001 | H12: 0 | I12: 5
E13: INDCO2N
E14: INDCO2P
E15: PWRCO2N
E16: RSDCO2
E17: SRVCO2N
E18: TRACO2N

Sheet Imports_Bio
B2: Imported Bioenergy costs (€/GJ) | E2: FI_T: MEUR2010
B3: Region | C3: TechName | D3: *TechDesc | E3: Comm-OUT | F3: COST~2015 | G3: COST~2020 | H3: COST~2025 | I3: COST~2030 | J3: COST~2040 | K3: COST~2050 | L3: *Notes
B4: \I:Region Name | C4: \I:Technology Name | D4: Technology Description | E4: Output Commodity | F4: €/GJ | G4: €/GJ | H4: €/GJ | I4: €/GJ | J4: €/GJ | K4: €/GJ
B5: =Processes!C23 -> IE,National | C5: =Processes!D23 -> IMPBIOETH1G_S1 | D5: =Processes!E23 -> Import of Ethanol 1st generation - Step 1 | E5: =Commodities!$C$30 -> BIOETH1G | F5: ='SEAI-AEA_BioData'!K$23 -> 18.176173 | G5: ='SEAI-AEA_BioData'!L$23 -> 17.579058 | H5: ='SEAI-AEA_BioData'!M$23 -> 16.59979 | I5: ='SEAI-AEA_BioData'!N$23 -> 15.883252
B6: =Processes!C24 -> IE,National | C6: =Processes!D24 -> IMPBIOETH1G_S2 | D6: =Processes!E24 -> Import of Ethanol 1st generation - Step 2 | E6: =Commodities!$C$30 -> BIOETH1G | F6: ='SEAI-AEA_BioData'!K$33 -> 18.916595 | G6: ='SEAI-AEA_BioData'!L$33 -> 19.083787 | H6: ='SEAI-AEA_BioData'!M$33 -> 18.916595 | I6: ='SEAI-AEA_BioData'!N$33 -> 19.131556 | J6: =I6*Imports_Fossil!$I$37/Imports_Fossil!$H$37 -> 20.390211 | K6: =I6*Imports_Fossil!$J$37/Imports_Fossil!$H$37 -> 21.397135
B7: =Processes!C25 -> IE,National | C7: =Processes!D25 -> IMPBIOETH1G_S3 | D7: =Processes!E25 -> Import of Ethanol 1st generation - Step 3 | E7: =Commodities!$C$30 -> BIOETH1G | F7: ='SEAI-AEA_BioData'!K$44 -> 19.680902 | G7: ='SEAI-AEA_BioData'!L$44 -> 20.684055 | H7: ='SEAI-AEA_BioData'!M$44 -> 21.758861 | I7: ='SEAI-AEA_BioData'!N$44 -> 23.550205 | J7: =I7*Imports_Fossil!$I$37/Imports_Fossil!$H$37 -> 25.099561 | K7: =I7*Imports_Fossil!$J$37/Imports_Fossil!$H$37 -> 26.339046
B8: =Processes!C26 -> IE,National | C8: =Processes!D26 -> IMPBIOETH1G_S4 | D8: =Processes!E26 -> Import of Ethanol 1st generation - Step 4 | E8: =Commodities!$C$30 -> BIOETH1G | F8: ='SEAI-AEA_BioData'!K$55 -> 20.636285 | G8: ='SEAI-AEA_BioData'!L$55 -> 22.714245 | H8: ='SEAI-AEA_BioData'!M$55 -> 25.174358 | I8: ='SEAI-AEA_BioData'!N$55 -> 28.757046 | J8: =I8*Imports_Fossil!$I$37/Imports_Fossil!$H$37 -> 30.648957 | K8: =I8*Imports_Fossil!$J$37/Imports_Fossil!$H$37 -> 32.162486
B9: =Processes!C27 -> IE,National | C9: =Processes!D27 -> IMPBIODST1G_S1 | D9: =Processes!E27 -> Import of Biodiesel 1st generation - Step 1 | E9: =Commodities!$C$32 -> BIODST1G | F9: ='SEAI-AEA_BioData'!K$25 -> 31.360466 | G9: ='SEAI-AEA_BioData'!L$25 -> 33.175695 | H9: ='SEAI-AEA_BioData'!M$25 -> 31.862043 | I9: ='SEAI-AEA_BioData'!N$25 -> 31.336582
B10: =Processes!C28 -> IE,National | C10: =Processes!D28 -> IMPBIODST1G_S2 | D10: =Processes!E28 -> Import of Biodiesel 1st generation - Step 2 | E10: =Commodities!$C$32 -> BIODST1G | F10: ='SEAI-AEA_BioData'!K$35 -> 32.650234 | G10: ='SEAI-AEA_BioData'!L$35 -> 35.826884 | H10: ='SEAI-AEA_BioData'!M$35 -> 35.970192 | I10: ='SEAI-AEA_BioData'!N$35 -> 37.021114 | J10: =I10*Imports_Fossil!$I$37/Imports_Fossil!$H$37 -> 39.456714 | K10: =I10*Imports_Fossil!$J$37/Imports_Fossil!$H$37 -> 41.405193
