Workbook
Name FID_1: [1]AGR_Fuels!$A$2

Sheet Cover
A16: TIMES-Ireland Model
A19: Document type: | B19: Base Year Template
A20: Sector(s): | B20: Agriculture sector (AGR)
A21: Purpose: | B21: Specify base year data and define sector structure
A23: Expanding AFOLU dynamics in TIM (starting from Agri-TIMES)
A26: Current working person | B26: Neha Jaggeshar (Neha.Jaggeshar@ucc.ie)

Sheet AGR_Processes
B1: Fixed layout table
B3: * Define the Processes used in this workbook
B5: Processes
B6: ~FI_Process
B7: Sets | C7: Region | D7: TechName | E7: TechDesc | F7: Tact | G7: Tcap | H7: Tslvl | I7: PrimaryCG | J7: Vintage
B8: *Process Set Membership | C8: Region Name | D8: Technology Name | E8: Technology Description | F8: Activity Unit | G8: Capacity Unit | H8: TimeSlice level of Process Activity | I8: Primary Commodity Group | J8: Vintage Tracking
B9: MIN | C9: IE,National | D9: GRALANDPOT | E9: Grassland potential | F9: Mha | G9: Mha | J9: NO
B10: MIN | C10: IE,National | D10: CROPLANDPOT | E10: Cropland potential | F10: Mha | G10: Mha | J10: NO
B11: MIN | C11: IE,National | D11: WTPTLANDPOT | E11: Wet land and peat land potential | F11: Mha | G11: Mha | J11: NO
B12: MIN | C12: IE,National | D12: SETLANDPOT | E12: Settlement land potential | F12: Mha | G12: Mha | J12: NO
B13: MIN | C13: IE,National | D13: OTHLANDPOT | E13: Other land potential | F13: Mha | G13: Mha | J13: NO
B14: MIN | C14: IE,National | D14: IRL_Landarea | E14: Total land resource in Ireland | F14: Mha | G14: Mha | J14: NO
B15: PRE | C15: IE,National | D15: APASCAT100 | E15: Dairy cattle pasture system | F15: Mha | G15: Mha | J15: NO
B16: PRE | C16: IE,National | D16: APASCAT200 | E16: Non diary cattle pasture system | F16: Mha | G16: Mha | J16: NO
B17: PRE | C17: IE,National | D17: APASSHE100 | E17: Sheep pasture system | F17: Mha | G17: Mha | J17: NO
B18: PRE | C18: IE,National | D18: APASOTH100 | E18: Other animals pasture system | F18: Mha | G18: Mha | J18: NO
B19: PRE | C19: IE,National | D19: ALIVCAT100 | E19: Dairy cattle rearing | F19: Mlitre | G19: Mhead | J19: NO
B20: PRE | C20: IE,National | D20: ALIVCAT200 | E20: Non diary cattle rearing | F20: Mhead | G20: Mhead | J20: NO
... B84: PRE | C84: IE,National | D84: ADGSPOU101 | E84: Poultry Manure/Slurry Digester (manure to biogas) | F84: PJ | G84: GW | J84: NO
B85: CHP | C85: IE,National | D85: CHPAGRICBGS101 | E85: Biogas Internal Combustion CHP - Small | F85: PJ | G85: GW | H85: DAYNITE | J85: NO
B86: CHP | C86: IE,National | D86: CHPAGRICBGS201 | E86: Biogas Internal Combustion CHP - Large | F86: PJ | G86: GW | H86: DAYNITE | J86: NO
B87: PRE | C87: IE,National | D87: ANRGTIL110 | E87: Energy use for tillage production | F87: PJ | G87: PJa | J87: NO

Sheet AGR_Comm
B1: Fixed layout table
B4: * Define the commodities used in this workbook
B6: Commodities
B7: ~FI_Comm
B8: Csets | C8: Region | D8: CommName | E8: CommDesc | F8: Unit | G8: LimType | H8: CTSLvl | I8: PeakTS | J8: Ctype
B9: *Commodity Set Membership | C9: Region Name | D9: Commodity Name | E9: Commodity Description | F9: Unit | G9: Sense of the Balance EQN. | H9: Timeslice Level | I9: Peak Monitoring | J9: Electricity Indicator
B10: MAT | C10: IE,National | D10: GRALAND | E10: Grassland | F10: Mha
C11: IE,National | D11: CROLAND | E11: Cropland | F11: Mha
C12: IE,National | D12: WTPTLAND | E12: Wet land and peat land | F12: Mha
C13: IE,National | D13: SETLAND | E13: Settlement land | F13: Mha
C14: IE,National | D14: OTHLAND | E14: Other land | F14: Mha
C15: IE,National | D15: APASCAT1 | E15: Diary cattle pasture land | F15: Mha
C16: IE,National | D16: APASCAT2 | E16: Non diary cattle pasture land | F16: Mha
C17: IE,National | D17: APASSHE | E17: Sheep pasture land | F17: Mha
C18: IE,National | D18: APASOTH | E18: Other animals pasture land | F18: Mha
B19: DEM | C19: IE,National | D19: ADCAT | E19: Diary cattle demand | F19: Mlitre
C20: IE,National | D20: ANDCAT | E20: Non diary cattle demand | F20: Mhead
C21: IE,National | D21: ASHE | E21: Sheep demand | F21: Mhead
C22: IE,National | D22: APIG | E22: Pig demand | F22: Mhead
C23: IE,National | D23: APOU | E23: Poultry demand | F23: Mhead
C24: IE,National | D24: AOTH | E24: Other animals demand | F24: Mhead
C25: IE,National | D25: AWHE | E25: Wheat Demand | F25: Mtonne
C26: IE,National | D26: AOAT | E26: Oats demand | F26: Mtonne
C27: IE,National | D27: ABAR | E27: Barley demand | F27: Mtonne
C28: IE,National | D28: APUL | E28: Pulses (Beans and peas) demand | F28: Mtonne
C29: IE,National | D29: APOT | E29: Potatoes demand | F29: Mtonne
C30: IE,National | D30: AOSR | E30: Oil Seed rape demand | F30: Mtonne
B31: MAT | C31: IE,National | D31: ACATMAN | E31: Cattle manure | F31: Mtonne | G31: UP
C32: IE,National | D32: ASHEMAN | E32: Sheep manure | F32: Mtonne | G32: UP
C33: IE,National | D33: APIGMAN | E33: Pig manure | F33: Mtonne | G33: UP
C34: IE,National | D34: APOUMAN | E34: Poultry manure | F34: Mtonne | G34: UP
C35: IE,National | D35: AOTHMAN | E35: Other animal manure | F35: Mtonne | G35: UP
B36: NRG | C36: IE,National | D36: AGRDST | E36: Diesel oil in agriculture | F36: PJ
C37: IE,National | D37: AGRELC | E37: Electricity use in agriculture | F37: PJ | H37: DAYNITE | J37: ELC
C38: IE,National | D38: AGRBGS | E38: Biogas production | F38: PJ | H38: SEASON
C39: IE,National | D39: ANRGCAT1 | E39: Diary cattle rearing energy flow | F39: PJ
C40: IE,National | D40: ANRGCAT2 | E40: Non diary cattle rearing energy flow | F40: PJ
C41: IE,National | D41: ANRGSHE | E41: Sheep rearing energy flow | F41: PJ
C42: IE,National | D42: ANRGPIG | E42: Pig rearing energy flow | F42: PJ
C43: IE,National | D43: ANRGPOU | E43: Poultry rearing energy flow | F43: PJ
...

Sheet AGR_Fuel Tech
A1: Fuel Techs - Sectoral infrastructure
E4: ~FI_T | K4: ~FI_Process
B5: Region | C5: TechName | D5: Comm-IN | E5: Comm-OUT | F5: EFF | G5: Life | K5: Sets | L5: Region | M5: TechName | N5: TechDesc | O5: Tact | P5: Tcap | Q5: Tslvl | R5: PrimaryCG
B6: IE,National | C6: FT-AGRBGS | D6: BIOGAS1G | E6: AGRBGS | F6: 1 | G6: 100 | K6: PRE | L6: IE,National | M6: FT-AGRBGS | N6: Fuel tech - Biogas (AGR) | O6: PJ | P6: PJa
B7: IE,National | D7: BIOGAS2G | L7: IE,National | M7: FT-AGRBDL | N7: Fuel tech - Biodiesel (AGR) | O7: PJ | P7: PJa
B8: IE,National | C8: FT-AGRBDL | D8: BIODST1G | E8: AGRBDL | F8: 1 | G8: 100 | L8: IE,National | M8: FT-AGRBIO | N8: Fuel tech - Biomass (AGR) | O8: PJ | P8: PJa
B9: IE,National | D9: BIODST2G | L9: IE,National | M9: FT-AGRDST | N9: Fuel tech - Diesel (AGR) | O9: PJ | P9: PJa
B10: IE,National | C10: FT-AGRBIO | D10: BIOWPE | E10: AGRBIO | F10: 1 | G10: 100 | L10: IE,National | M10: FT-AGRELC | N10: Fuel tech - Electricity (AGR) | O10: PJ | P10: PJa | Q10: DAYNITE
B11: IE,National | D11: BIOWCH | L11: IE,National | M11: FT-AGRGAS | N11: Fuel tech - Natural Gas (AGR) | O11: PJ | P11: PJa
B12: IE,National | C12: FT-AGRDST | D12: OILDST | E12: AGRDST | F12: 1 | G12: 100 | L12: IE,National | M12: FT-AGRGEO | N12: Fuel tech - Geothermal (AGR) | O12: PJ | P12: PJa
B13: IE,National | C13: FT-AGRELC | D13: ELCD | E13: AGRELC | F13: 1 | G13: 100 | L13: IE,National | M13: FT-AGRHET | N13: Fuel tech - Heat (AGR) | O13: PJ | P13: PJa | Q13: DAYNITE
B14: IE,National | C14: FT-AGRGAS | D14: GASNAT | E14: AGRGAS | F14: 1 | G14: 100 | L14: IE,National | M14: FT-AGRLPG | N14: Fuel tech - Liquefied Petroleum Gas (AGR) | O14: PJ | P14: PJa
B15: IE,National | C15: FT-AGRGEO | D15: RENGEO | E15: AGRGEO | F15: 1 | G15: 100 | L15: IE,National | M15: FT-AGRSOL | N15: Fuel tech - Solar (AGR) | O15: PJ | P15: PJa
B16: IE,National | C16: FT-AGRHET | D16: HETD | E16: AGRHET | F16: 1 | G16: 100 | L16: IE,National | M16: FT-AGRH2G | N16: Fuel tech - Hydrogen gaseous (AGR) | O16: PJ | P16: PJa
B17: IE,National | C17: FT-AGRLPG | D17: OILLPG | E17: AGRLPG | F17: 1 | G17: 100 | L17: IE,National | M17: FT-AGRH2L | N17: Fuel tech - Hydrogen liquid (AGR) | O17: PJ | P17: PJa
B18: IE,National | C18: FT-AGRSOL | D18: RENSOL | E18: AGRSOL | F18: 1 | G18: 100
B19: IE,National | C19: FT-AGRH2G | D19: SUPH2GD | E19: AGRH2G | F19: 1 | G19: 100
B20: IE,National | C20: FT-AGRH2L | D20: SUPH2LD | E20: AGRH2L | F20: 1 | G20: 100
L43: ]

Sheet AGR_Energy use
E2: ~FI_T
B3: TechName | C3: *TechDesc | D3: Comm-IN | E3: Comm-OUT | F3: Input | G3: Output | H3: CAP2ACT | I3: Life | J3: Start | K3: EFF | L3: Share-I~UP~2015 | M3: Share-I~UP~2050 | N3: Share-I~UP~0 | O3: Share-I~LO~2012 | P3: FLO_COST
B4: *Technology Name | C4: Technology Description | D4: Input Commodity | E4: Output Commodity | I4: years | L4: Input Share | M4: Input Share | N4: I/E rule | O4: Input Share
B5: =AGR_Processes!D25 -> ANRGCAT100 | C5: =AGR_Processes!E25 -> Dairy cattle rearing energy use | D5: AGRELC | F5: =Base_Calc!H4/SUM(Base_Calc!H4,Base_Calc!L4) -> 0.2 | H5: 1 | I5: 10
D6: AGRDST | F6: =Base_Calc!L4/SUM(Base_Calc!L4, Base_Calc!H4) -> 0.8
E7: =AGR_Comm!D39 -> ANRGCAT1 | G7: 1
B8: =AGR_Processes!D26 -> ANRGCAT200 | C8: =AGR_Processes!E26 -> Non diary cattle rearing energy use | D8: AGRELC | F8: =Base_Calc!H5/SUM(Base_Calc!H5,Base_Calc!L5) -> 0.29 | H8: 1 | I8: 10
D9: AGRDST | F9: =Base_Calc!L5/SUM(Base_Calc!L5, Base_Calc!H5) -> 0.71
E10: =AGR_Comm!D40 -> ANRGCAT2 | G10: 1
B11: =AGR_Processes!D27 -> ANRGSHE100 | C11: =AGR_Processes!E27 -> Sheep pasture rearing use | D11: AGRELC | F11: =Base_Calc!H6/SUM(Base_Calc!H6,Base_Calc!L6) -> 0.33 | H11: 1 | I11: 10
D12: AGRDST | F12: =Base_Calc!L6/SUM(Base_Calc!L6,Base_Calc!H6) -> 0.67
E13: =AGR_Comm!D41 -> ANRGSHE | G13: 1
B14: =AGR_Processes!D28 -> ANRGPIG100 | C14: =AGR_Processes!E28 -> Pig pasture rearing energy use | D14: AGRELC | F14: =Base_Calc!H7/SUM(Base_Calc!H7,Base_Calc!L7) -> 0.4 | H14: 1 | I14: 10
D15: AGRDST | F15: =Base_Calc!L7/SUM(Base_Calc!L7,Base_Calc!H7) -> 0.6
E16: =AGR_Comm!D42 -> ANRGPIG | G16: 1
B17: =AGR_Processes!D29 -> ANRGPOU100 | C17: =AGR_Processes!E29 -> Poultry rearing energy use | D17: AGRELC | F17: =Base_Calc!H8/SUM(Base_Calc!H8,Base_Calc!L8) -> 0.35 | H17: 1 | I17: 10
D18: AGRDST | F18: =Base_Calc!L8/SUM(Base_Calc!L8,Base_Calc!H8) -> 0.65
E19: =AGR_Comm!D43 -> ANRGPOU | G19: 1
B20: =AGR_Processes!D30 -> ANRGOTH100 | C20: =AGR_Processes!E30 -> Other animals rearing energy use | D20: AGRELC | F20: =Base_Calc!H9/SUM(Base_Calc!H9,Base_Calc!L9) -> 0.3 | H20: 1 | I20: 10
D21: AGRDST | F21: =Base_Calc!L9/SUM(Base_Calc!L9,Base_Calc!H9) -> 0.7
E22: =AGR_Comm!D44 -> ANRGOTH | G22: 1
B23: =AGR_Processes!D31 -> ANGRTIL100 | C23: Energy use for tillage production | D23: AGRELC | F23: =Base_Calc!H14/SUM(Base_Calc!H14,Base_Calc!L14) -> 0.11012236 | H23: 1 | I23: 10
D24: AGRDST | F24: =Base_Calc!L14/SUM(Base_Calc!L14,Base_Calc!H14) -> 0.88987764
E25: =AGR_Comm!D45 -> ANRGTIL | G25: 1
B30: Energy sources for new practices
F31: FI_T
B32: TechName | C32: *TechDesc | D32: Comm-IN | E32: Comm-OUT | F32: Input~2018 | G32: Output~2018 | H32: CAP2ACT | I32: Life | J32: Start | K32: EFF | L32: Share-I~UP~2020 | M32: Share-I~UP~2050 | N32: Share-I~UP~0 | O32: Share-I~LO~2018 | P32: FLO_COST
B33: *Technology Name | C33: Technology Description | D33: Input Commodity | E33: Output Commodity | I33: years | L33: Input Share | M33: Input Share | N33: I/E rule | O33: Input Share
B34: ANRGCAT110 | C34: Dairy Cattle BY - Energy Use (New pratices) | D34: AGRBDL | H34: 1 | I34: 1 | J34: 2018 | K34: 10 | L34: 0.015 | M34: 0.64678635 | N34: 5 | P34: 10
D35: AGRBIO | L35: 0.01 | M35: 0.1 | N35: 5 | P35: 15
D36: AGRELC | L36: 0.21066878 | M36: 0.2872756 | N36: 5 | O36: 0.19151707 | P36: 20
D37: AGRGAS | L37: 0.073 | M37: 0.1095 | N37: 5 | P37: 12
D38: AGRGEO | L38: 0 | M38: 0.01 | N38: 5 | P38: 30
D39: AGRLPG | L39: 0.015 | M39: 0.1 | N39: 5 | P39: 0
D40: AGRDST | L40: 1 | M40: 1 | N40: 5
D41: AGRSOL | L41: 0 | M41: 0.04 | N41: 5 | P41: 30
E42: ANRGCAT1
B43: ANRGCAT210 | C43: Non-Dairy Cattle BY - Energy Use (New pratices) | D43: AGRBDL | H43: 1 | I43: 1 | J43: 2018 | K43: 10 | L43: 0.015 | M43: 0.64678635 | N43: 5 | P43: 10
D44: AGRBIO | L44: 0.01 | M44: 0.1 | N44: 5 | P44: 15
D45: AGRELC | L45: 0.21066878 | M45: 0.2872756 | N45: 5 | O45: 0.19151707 | P45: 20
...

Sheet AGR_Livestock
B3: Flexible layout of the column headers
B5: * Characterize processes
E7: ~FI_T
B8: TechName | C8: *TechDesc | D8: Comm-IN | E8: Comm-OUT | F8: Input | G8: Output | H8: FLO_EMIS+ | I8: AFA~FX | J8: Life | K8: CAP2ACT | L8: EFF | M8: env_act~AGRLIVCH4 | N8: env_act~AGRLIVN2O | O8: NCAP_PASTI~2018 | P8: ACT_BND~FX | Q8: ACT_BND~FX~0 | R8: NCAP_BND~UP | S8: NCAP_BND~UP~0
B9: *Technology Name | C9: Technology Description | D9: Input (Land in Mha and Energy in PJ) | E9: Output Commodity | J9: years | K9: Capacity to Activity Factor | M9: kt per Mhead | N9: kt per activity based - Mhead or Mha | O9: Existing land capacity (Mha)
B10: =AGR_Processes!D14 -> IRL_Landarea | C10: Total land area In Ireland | E10: =AGR_Comm!D74 -> IRL_Land | J10: 100 | K10: 1
B11: =AGR_Processes!D69 -> GRALAND_00 | C11: =AGR_Processes!E69 -> Grassland remaining as grassland | D11: =AGR_Comm!D74 -> IRL_Land | E11: GRALAND | F11: 1 | G11: 1 | J11: 100 | K11: 1 | P11: 4.409 | Q11: 5
B12: GRALAND_Mgt | C12: Managed grassland - final area after LUC | D12: GRALAND | E12: GRALAND_use | F12: 1 | G12: 1 | J12: 100 | K12: 1
B13: =AGR_Processes!D15 -> APASCAT100 | C13: =AGR_Processes!E15 -> Dairy cattle pasture system | D13: =AGR_Comm!D63 -> GRALAND_use | E13: =AGR_Comm!$D$15 -> APASCAT1 | F13: 1 | G13: 1 | J13: 1 | K13: 1 | N13: 1.561
B14: =AGR_Processes!D16 -> APASCAT200 | C14: =AGR_Processes!E16 -> Non diary cattle pasture system | D14: =AGR_Comm!D63 -> GRALAND_use | E14: =AGR_Comm!$D$16 -> APASCAT2 | F14: 1 | G14: 1 | J14: 1 | K14: 1 | N14: 0.878
B15: =AGR_Processes!D17 -> APASSHE100 | C15: =AGR_Processes!E17 -> Sheep pasture system | D15: =AGR_Comm!D63 -> GRALAND_use | E15: =AGR_Comm!$D$17 -> APASSHE | F15: 1 | G15: 1 | J15: 1 | K15: 1 | N15: 1.427
B16: =AGR_Processes!D18 -> APASOTH100 | C16: =AGR_Processes!E18 -> Other animals pasture system | D16: =AGR_Comm!D63 -> GRALAND_use | E16: =AGR_Comm!$D$18 -> APASOTH | F16: 1 | G16: 1 | J16: 1 | K16: 1 | N16: 0.813
B17: =AGR_Processes!D19 -> ALIVCAT100 | C17: =AGR_Processes!E19 -> Dairy cattle rearing | D17: =AGR_Comm!$D$15 -> APASCAT1 | F17: =Base_Calc!Q4/Base_Calc!$W$4 -> 6.9979006e-05 | J17: 1 | K17: 5716 | M17: =Base_Calc!AF4/Base_Calc!W4 -> 0.022802659 | N17: =Base_Calc!AN4/Base_Calc!W4 -> 0.00037788663
D18: =AGR_Comm!$D$39 -> ANRGCAT1 | F18: =(Base_Calc!H4+Base_Calc!L4)/Base_Calc!$W$4 -> 0.00029916025
E19: =AGR_Comm!$D$19 -> ADCAT | G19: 1
E20: =AGR_Comm!D31 -> ACATMAN | G20: =Manure_MGT_Digest!K4/Manure_MGT_Digest!I4 -> 0.00089964974
B21: =AGR_Processes!D20 -> ALIVCAT200 | C21: =AGR_Processes!E20 -> Non diary cattle rearing | D21: =AGR_Comm!$D$16 -> APASCAT2 | F21: 0.4 | J21: 1 | K21: 1 | M21: =Base_Calc!AF5 -> 49.48 | N21: =Base_Calc!AN5 -> 0.8836
D22: =AGR_Comm!$D$40 -> ANRGCAT2 | F22: =Base_Calc!H5+Base_Calc!L5 -> 1.11
E23: =AGR_Comm!$D$20 -> ANDCAT | G23: 1
E24: =AGR_Comm!D31 -> ACATMAN | G24: =Manure_MGT_Digest!K5 -> 7.118
B25: =AGR_Processes!D21 -> ALIVSHE100 | C25: =AGR_Processes!E21 -> Sheep rearing | D25: =AGR_Comm!$D$17 -> APASSHE | F25: =Base_Calc!Q6 -> 0.13 | J25: 1 | K25: 1 | M25: =Base_Calc!AF6 -> 7.85 | N25: =Base_Calc!AN6 -> 0.046
D26: =AGR_Comm!$D$41 -> ANRGSHE | F26: =Base_Calc!H6+Base_Calc!L6 -> 0.16
E27: =AGR_Comm!$D$21 -> ASHE | G27: 1
E28: ASHEMAN | G28: =Manure_MGT_Digest!K6 -> 0.364
B29: =AGR_Processes!D22 -> ALIVPIG100 | C29: =AGR_Processes!E22 -> Pigs rearing | D29: =AGR_Comm!D42 -> ANRGPIG | F29: =Base_Calc!H7+Base_Calc!L7 -> 0.17 | J29: 1 | K29: 1 | M29: =Base_Calc!AF7 -> 14.26 | N29: =Base_Calc!AN7 -> 0.27
E30: APIG | G30: 1
E31: =AGR_Comm!D33 -> APIGMAN | G31: =Manure_MGT_Digest!K7 -> 2.0857
B32: =AGR_Processes!D23 -> ALIVPOU100 | C32: =AGR_Processes!E23 -> Poultry rearing | D32: =AGR_Comm!$D$43 -> ANRGPOU | F32: =Base_Calc!H8+Base_Calc!L8 -> 0.02 | J32: 1 | K32: 1 | M32: =Base_Calc!AF8 -> 0.2 | N32: =Base_Calc!AN8 -> 0.0154
E33: APOU | G33: 1
E34: =AGR_Comm!D34 -> APOUMAN | G34: =Manure_MGT_Digest!K8 -> 0.042
B35: =AGR_Processes!D24 -> ALIVOTH100 | C35: =AGR_Processes!E24 -> Other animals rearing | D35: =AGR_Comm!$D$18 -> APASOTH | F35: =Base_Calc!Q9 -> 0.05 | J35: 1 | K35: 1 | M35: =Base_Calc!AF9 -> 1.23 | N35: =Base_Calc!AN9 -> 0.041
D36: =AGR_Comm!$D$44 -> ANRGOTH | F36: =Base_Calc!H9+Base_Calc!L9 -> 0.9
E37: =AGR_Comm!$D$24 -> AOTH | G37: 1
B38: =AGR_Processes!D68 -> GRA_STOCK | C38: Residual grassland | D38: GRALAND_use | K38: 1
B44: Manure to energy pathways
E45: ~FI_T
B46: TechName | C46: *TechDesc | D46: Comm-IN | E46: Comm-OUT | F46: CAP2ACT | G46: Life | H46: Start | I46: EFF~2018 | J46: INVCOST | K46: INVCOST~2035 | L46: VAROM | M46: FIXOM | N46: AF | O46: CHPR | P46: CHPR~2025 | Q46: NCAP_DRATE | R46: FLO_DELIV
B47: *Technology Name | C47: Technology Description
B48: ADGSCAT101 | C48: Cattle Manure/Slurry Digester (manure to biogas) | D48: ACATMAN | E48: AGRBGS | F48: 31.54 | G48: 20 | H48: 2018 | I48: 0.75 | J48: 2778 | L48: 1 | M48: 56 | N48: 0.9 | Q48: 0.09
B49: ADGSPIG101 | C49: Pigs Manure/Slurry Digester (manure to biogas) | D49: APIGMAN | E49: AGRBGS | F49: 31.54 | G49: 20 | H49: 2018 | I49: 0.27 | J49: 2778 | L49: 1 | M49: 56 | N49: 0.9 | Q49: 0.09
...

Sheet AGR_Tillage
D3: ~FI_T: MEUR2000
B4: TechName | C4: *TechDesc | D4: Comm-IN | E4: Comm-OUT | F4: Input | G4: Output | H4: CAP2ACT | I4: env_act~AGRTILN2O | J4: LIFE | K4: ACT_BND~FX | L4: ACT_BND~FX~0
B5: *Technology Name | C5: Technology Description | D5: Input Commodity | E5: Output Commodity | I5: Kt per Mtonnes
B6: *CROPLANDPOT | C6: *Cropland potential | E6: *CROLAND | J6: 100
B7: CROLAND_Mgt | C7: Cropland management | D7: =AGR_Comm!D74 -> IRL_Land | E7: CROLAND_use | F7: 1 | G7: 1 | H7: 1 | J7: 100 | K7: 0.7467 | L7: 5
B8: ATILWHE100 | C8: Wheat Production | D8: CROLAND_use | F8: =Base_Calc!Q18 -> 0.11 | I8: =Base_Calc!AN18 -> 0.107 | J8: 1
D9: ANRGTIL | F9: =Base_Calc!P18 -> 0.55042939
E10: AWHE | G10: 1
B11: ATILOAT100 | C11: Oat production | D11: CROLAND_use | F11: =Base_Calc!Q17 -> 0.133 | I11: =Base_Calc!AN17 -> 0.115 | J11: 1
D12: ANRGTIL | F12: =Base_Calc!P17 -> 0.21894364
E13: AOAT | G13: 1
B14: ATILBAR100 | C14: Barley production | D14: CROLAND_use | F14: =Base_Calc!Q16 -> 0.18 | I14: =Base_Calc!AN16 -> 0.127 | J14: 1
D15: ANRGTIL | F15: =Base_Calc!P16 -> 1.3904192
E16: ABAR | G16: 1
B17: ATILPUL100 | C17: Pulses (Beans and peas) production | D17: CROLAND_use | F17: =Base_Calc!Q14 -> 0.21 | I17: =Base_Calc!AN14 -> 0.185 | J17: 1
D18: ANRGTIL | F18: =Base_Calc!P14 -> 0.086074071
E19: APUL | G19: 1
B20: ATILPOT100 | C20: Potatoes production | D20: CROLAND_use | F20: =Base_Calc!Q15 -> 0.0296 | I20: =Base_Calc!AN15 -> 0.024 | J20: 1
D21: ANRGTIL | F21: =Base_Calc!P15 -> 0.34112012
E22: APOT | G22: 1
B23: =AGR_Processes!D67 -> CRO_STOCK | C23: Residual cropland | D23: CROLAND_use | H23: 1

Sheet AGR_Bioenergy
B2: Cropland for energy
E3: ~FI_T | S3: FI_T
B4: TechName | C4: *TechDesc | D4: Comm-IN | E4: Comm-OUT | F4: EFF | G4: Input | H4: Output | I4: LIFE | J4: FLO_DELIV | K4: CAP2ACT | L4: AFA~FX | M4: env_act~AGRTILN2O | Q4: TechName | R4: *TechDesc | S4: Comm-IN | T4: Comm-OUT | U4: EFF | V4: Input~2018 | W4: Output~2018 | X4: CAP2ACT | Y4: AFA~FX | Z4: ENV_ACT~AGRTILN2O
B5: *Technology Name | C5: Technology Description | D5: Input Commodity | E5: Output Commodity | F5: GJ/ha(cons) | J5: €/GJ | K5: GJ/ha(contr) | M5: Kt / PJ | Q5: *Technology Name | R5: Technology Description | S5: Input Commodity | T5: Output Commodity | U5: GJ/ha(cons) | X5: GJ/ha(contr) | Z5: Kt / PJ
B6: =AGR_Processes!D70 -> GRALAND_ENERGY | C6: Grassland allocated for energy | D6: GRALAND_use | E6: =AGR_Comm!D65 -> GRA_ENERGY | F6: 1 | I6: 100 | K6: 1 | L6: 1 | Q6: ABIOCRP11 | R6: Wheat for ethanol production - RSV1 | S6: CROLAND_use | V6: 0.015151515 | X6: 44 | Y6: 1 | Z6: 0.017189167
B7: =AGR_Processes!D71 -> CROPLAND_ENERGY | C7: Cropland allocated for energy | D7: CROLAND_use | E7: =AGR_Comm!D66 -> CRO_ENERGY | F7: 1 | I7: 100 | K7: 1 | L7: 1 | S7: ANRGTIL | V7: 0.046329141
B8: ABIOCRP11 | C8: Wheat for ethanol production - RSV1 | D8: CRO_ENERGY | G8: 0.015151515 | I8: 1 | K8: 44 | M8: 0.017189167 | T8: BIOWHE | W8: 1
D9: ANRGTIL | G9: 0.046329141 | Q9: ABIOCRP12 | R9: Wheat for ethanol production - RSV2 | S9: CROLAND_use | V9: 0.015151515 | X9: 44 | Y9: 1 | Z9: 0.017189167
E10: BIOWHE | H10: 1 | S10: ANRGTIL | V10: 0.046329141
B11: ABIOCRP31 | C11: Miscanthus Crops for biomass - RSV 1 | D11: CRO_ENERGY | G11: 0.00640899 | I11: 1 | K11: 156.03083 | M11: 0.0072709032 | T11: BIOWHE | W11: 1
D12: ANRGTIL | G12: 0.019596918 | Q12: ABIOCRP13 | R12: Wheat for ethanol production - RSV3 | S12: CROLAND_use | V12: 0.015151515 | X12: 44 | Y12: 1 | Z12: 0.017189167
E13: BIOWOO | H13: 1 | S13: ANRGTIL | V13: 0.046329141
B14: ABIOCRP41 | C14: Willow Crops for biomass - RSV 1 | D14: CRO_ENERGY | G14: 0.006042762 | I14: 1 | K14: 82.74362 | M14: 0.006855423 | T14: BIOWHE | W14: 1
D15: ANRGTIL | G15: 0.018477094 | Q15: ABIOCRP31 | R15: Miscanthus Crops for biomass - RSV 1 | S15: CROLAND_use | V15: 0.00640899 | X15: 156.03083 | Y15: 1 | Z15: 0.0072709032
E16: BIOWOO | H16: 1 | S16: ANRGTIL | V16: 0.019596918
B17: ABIOGAS11 | C17: Grass for biogas production - RSV 1 | D17: GRA_ENERGY | G17: 0.0062902549 | I17: 1 | K17: 158.97607 | M17: 0.006711702 | T17: BIOWOO | W17: 1
D18: ANRGTIL | G18: 0.019233859 | Q18: ABIOCRP32 | R18: Miscanthus Crops for biomass - RSV 2 | S18: CROLAND_use | V18: 0.00640899 | X18: 156.03083 | Y18: 1 | Z18: 0.0072709032
E19: BIOGRA | H19: 1 | S19: ANRGTIL | V19: 0.019596918
B20: ABIOCRP21 | C20: OSR for biodiesel production - RSV 1 | D20: CRO_ENERGY | G20: 0.02173913 | I20: 1 | K20: 9.2 | M20: 0.010809742 | T20: BIOWOO | W20: 1
D21: ANRGTIL | G21: 0.066472246 | Q21: ABIOCRP33 | R21: Miscanthus Crops for biomass - RSV 3 | S21: CROLAND_use | V21: 0.00640899 | X21: 156.03083 | Y21: 1 | Z21: 0.0072709032
E22: BIOOSR | H22: 1 | S22: ANRGTIL | V22: 0.019596918
T23: BIOWOO | W23: 1
Q24: ABIOCRP41 | R24: Willow Crops for biomass - RSV 1 | S24: CROLAND_use | V24: 0.006042762 | X24: 82.74362 | Y24: 1 | Z24: 0.006855423
S25: ANRGTIL | V25: 0.018477094
T26: BIOWOO | W26: 1
Q27: ABIOCRP42 | R27: Willow Crops for biomass - RSV 2 | S27: CROLAND_use | V27: 0.006042762 | X27: 82.74362 | Y27: 1 | Z27: 0.006855423
S28: ANRGTIL | V28: 0.018477094
T29: BIOWOO | W29: 1
Q30: ABIOCRP43 | R30: Willow Crops for biomass - RSV 3 | S30: CROLAND_use | V30: 0.006042762 | X30: 82.74362 | Y30: 1 | Z30: 0.006855423
S31: ANRGTIL | V31: 0.018477094
T32: BIOWOO | W32: 1
Q33: ABIOGAS11 | R33: Grass for biogas production - RSV 1 | S33: GRALAND_use | V33: 0.0062902549 | X33: 158.97607 | Y33: 1 | Z33: 0.006711702
S34: ANRGTIL | V34: 0.019233859
T35: BIOGRA | W35: 1
Q36: ABIOGAS12 | R36: Grass for biogas production - RSV 2 | S36: GRALAND_use | V36: 0.0062902549 | X36: 158.97607 | Y36: 1 | Z36: 0.006711702
S37: ANRGTIL | V37: 0.019233859
T38: BIOGRA | W38: 1
Q39: ABIOGAS13 | R39: Grass for biogas production - RSV 3 | S39: GRALAND_use | V39: 0.0062902549 | X39: 158.97607 | Y39: 1 | Z39: 0.006711702
S40: ANRGTIL | V40: 0.019233859
T41: BIOGRA | W41: 1
...

Sheet EMISSION
B5: ~COMEMI
A6: Region | B6: CommName | C6: AGRDST | D6: AGRGAS | E6: AGRLPG | F6: *Unit
A7: IE,National | B7: =AGR_Comm!D58 -> AGRCO2N | C7: 74.1 | D7: 56.1 | E7: 63.1 | F7: kt/PJ

Sheet Land Area
B2: Land area
B4: Table 6.1 Ireland: Land use categories 1990-2021 | L4: Table 6.1 Ireland: Land use categories 1990-2022
B5: % of total land area | I5: '000 hectares | M5: % of total land area | S5: '000 hectares
B6: Year | C6: Grassland | D6: Wetlands (including peatlands) | E6: Forest | F6: Cropland | G6: Settlement | H6: Other land | I6: Total | L6: Year | M6: Grassland | N6: Wetlands (including peatlands) | O6: Forest | P6: Cropland | Q6: Settlement | R6: Other land | S6: Total
B7: 1990-1994 average | C7: 0.61683928 | D7: 0.18832815 | E7: 0.072648593 | F7: 0.10503832 | G7: 0.014687085 | H7: 0.0024585757 | I7: 7111.7854 | L7: 1990-1994 average | M7: 61.9 | N7: 18.8 | O7: 7.3 | P7: 10.5 | Q7: 1.5 | R7: 0.1 | S7: 7111.8
B8: 1995-1999 average | C8: 0.6109237 | D8: 0.18128271 | E8: 0.085260602 | F8: 0.10500977 | G8: 0.015054716 | H8: 0.0024685045 | I8: 7111.7854 | L8: 1995-1999 average | M8: 61.3 | N8: 18.1 | O8: 8.5 | P8: 10.5 | Q8: 1.5 | R8: 0.1 | S8: 7111.8
B9: 2000-2004 average | C9: 0.60634385 | D9: 0.17595134 | E9: 0.094556355 | F9: 0.10496695 | G9: 0.015674009 | H9: 0.0025074923 | I9: 7111.7854 | L9: 2000-2004 average | M9: 60.8 | N9: 17.6 | O9: 9.5 | P9: 10.5 | Q9: 1.6 | R9: 0.1 | S9: 7111.8
B10: 2005-2009 average | C10: 0.60213762 | D10: 0.17327619 | E10: 0.10031198 | F10: 0.104914 | G10: 0.016636652 | H10: 0.0027235564 | I10: 7111.7854 | L10: 2005-2009 average | M10: 60.4 | N10: 17.3 | O10: 10 | P10: 10.5 | Q10: 1.7 | R10: 0.1 | S10: 7111.8
B11: 2010-2014 average | C11: 0.59792798 | D11: 0.17278872 | E11: 0.10435377 | F11: 0.10488438 | G11: 0.017261737 | H11: 0.0027834079 | I11: 7111.7892 | L11: 2010-2014 average | M11: 60 | N11: 17.3 | O11: 10.4 | P11: 10.5 | Q11: 1.7 | R11: 0.1 | S11: 7111.8
B13: 2015 | C13: 0.59561055 | D13: 0.17269727 | E13: 0.10663744 | F13: 0.10487718 | G13: 0.017399479 | H13: 0.0027780771 | I13: 7111.7854 | L13: 2015 | M13: 59.7 | N13: 17.3 | O13: 10.7 | P13: 10.5 | Q13: 1.7 | R13: 0.1 | S13: 7111.8
B14: 2016 | C14: 0.59484997 | D14: 0.17262295 | E14: 0.1074389 | F14: 0.10487418 | G14: 0.017437903 | H14: 0.0027760984 | I14: 7111.7854 | L14: 2016 | M14: 59.7 | N14: 17.3 | O14: 10.7 | P14: 10.5 | Q14: 1.7 | R14: 0.1 | S14: 7111.8
B15: 2017 | C15: 0.59410286 | D15: 0.17256664 | E15: 0.10818589 | F15: 0.10487141 | G15: 0.017498923 | H15: 0.0027742764 | I15: 7111.7854 | L15: 2017 | M15: 59.6 | N15: 17.2 | O15: 10.8 | P15: 10.5 | Q15: 1.8 | R15: 0.1 | S15: 7111.8
B16: 2018 | C16: 0.59363644 | D16: 0.1724486 | E16: 0.10872499 | F16: 0.10486873 | G16: 0.017548718 | H16: 0.0027725158 | I16: 7111.7854 | L16: 2018 | M16: 59.5 | N16: 17.2 | O16: 10.9 | P16: 10.5 | Q16: 1.8 | R16: 0.1 | S16: 7111.8
B17: 2019 | C17: 0.59314107 | D17: 0.17240006 | E17: 0.10920606 | F17: 0.10486445 | G17: 0.017618648 | H17: 0.0027697175 | I17: 7111.7854 | L17: 2019 | M17: 59.5 | N17: 17.2 | O17: 10.9 | P17: 10.5 | Q17: 1.8 | R17: 0.1 | S17: 7111.8
B18: 2020 | C18: 0.59279273 | D18: 0.17235809 | E18: 0.10953481 | F18: 0.10485988 | G18: 0.017687782 | H18: 0.0027667111 | I18: 7111.7854 | L18: 2020 | M18: 59.5 | N18: 17.2 | O18: 10.9 | P18: 10.5 | Q18: 1.8 | R18: 0.1 | S18: 7111.8
B19: 2021 | C19: 0.59247105 | D19: 0.17233616 | E19: 0.10981835 | F19: 0.10485447 | G19: 0.017756808 | H19: 0.0027631565 | I19: 7111.7854 | L19: 2021 | M19: 59.4 | N19: 17.2 | O19: 10.9 | P19: 10.5 | Q19: 1.8 | R19: 0.1 | S19: 7111.8
B20: Source: Environmental Protection Agency | L20: 2022 | M20: 59.4 | N20: 17.2 | O20: 11 | P20: 10.5 | Q20: 1.8 | R20: 0.1 | S20: 7111.8
L21: Source: Environmental Protection Agency
B22: Land use in 000 Hectares | C22: Grassland | D22: Wetlands (including peatlands) | E22: Forest | F22: Cropland | G22: Settlement | H22: Other land | I22: Total | L22: Land use in 000 Hectares | M22: Grassland | N22: Wetlands (including peatlands) | O22: Forest | P22: Cropland | Q22: Settlement | R22: Other land | S22: Total
B24: 1990-1994 average | C24: 4386.8285 | D24: 1339.3494 | E24: 516.6612 | F24: 747.00995 | G24: 104.4514 | H24: 17.484863 | I24: 7111.7854 | L24: 1990-1994 average | M24: =(M7/100)*S7 -> 4402.2042 | N24: =(N7/100)*S7 -> 1337.0184 | O24: =(O7/100)*$S$7 -> 519.1614 | P24: =(P7/100)*$S$7 -> 746.739 | Q24: =(Q7/100)*$S$7 -> 106.677 | R24: =(R7/100)*$S$7 -> 7.1118 | S24: 7111.7854
B25: 1995-1999 average | C25: 4344.7582 | D25: 1289.2437 | E25: 606.3551 | F25: 746.80692 | G25: 107.06591 | H25: 17.555474 | I25: 7111.7854 | L25: 1995-1999 average | M25: =(M8/100)*S8 -> 4359.5334 | N25: =(N8/100)*S8 -> 1287.2358 | O25: =(O8/100)*$S$7 -> 604.503 | P25: =(P8/100)*$S$7 -> 746.739 | Q25: =(Q8/100)*$S$7 -> 106.677 | R25: =(R8/100)*$S$7 -> 7.1118 | S25: 7111.7854
B26: 2000-2004 average | C26: 4312.1873 | D26: 1251.3282 | E26: 672.4645 | F26: 746.50245 | G26: 111.47019 | H26: 17.832747 | I26: 7111.7854 | L26: 2000-2004 average | M26: =(M9/100)*S9 -> 4323.9744 | N26: =(N9/100)*S9 -> 1251.6768 | O26: =(O9/100)*$S$7 -> 675.621 | P26: =(P9/100)*$S$7 -> 746.739 | Q26: =(Q9/100)*$S$7 -> 113.7888 | R26: =(R9/100)*$S$7 -> 7.1118 | S26: 7111.7854
B27: 2005-2009 average | C27: 4282.2735 | D27: 1232.3031 | E27: 713.39726 | F27: 746.12584 | G27: 118.3163 | H27: 19.369348 | I27: 7111.7854 | L27: 2005-2009 average | M27: =(M10/100)*S10 -> 4295.5272 | N27: =(N10/100)*S10 -> 1230.3414 | O27: =(O10/100)*$S$7 -> 711.18 | P27: =(P10/100)*$S$7 -> 746.739 | Q27: =(Q10/100)*$S$7 -> 120.9006 | R27: =(R10/100)*$S$7 -> 7.1118 | S27: 7111.7854
B28: 2010-2014 average | C28: 4252.3377 | D28: 1228.837 | E28: 742.142 | F28: 745.91563 | G28: 122.76184 | H28: 19.79501 | I28: 7111.7892 | L28: 2010-2014 average | M28: =(M11/100)*S11 -> 4267.08 | N28: =(N11/100)*S11 -> 1230.3414 | O28: =(O11/100)*$S$7 -> 739.6272 | P28: =(P11/100)*$S$7 -> 746.739 | Q28: =(Q11/100)*$S$7 -> 120.9006 | R28: =(R11/100)*$S$7 -> 7.1118 | S28: 7111.7892
B30: 2015 | C30: 4235.8544 | D30: 1228.1859 | E30: 758.38259 | F30: 745.86403 | G30: 123.74136 | H30: 19.757088 | I30: 7111.7854 | L30: 2015 | M30: =(M13/100)*S13 -> 4245.7446 | N30: =(N13/100)*S13 -> 1230.3414 | O30: =(O13/100)*$S$7 -> 760.9626 | P30: =(P13/100)*$S$7 -> 746.739 | Q30: =(Q13/100)*$S$7 -> 120.9006 | R30: =(R13/100)*$S$7 -> 7.1118 | S30: 7111.7854
B31: 2016 | C31: 4230.4453 | D31: 1227.6574 | E31: 764.08239 | F31: 745.84264 | G31: 124.01462 | H31: 19.743016 | I31: 7111.7854 | L31: 2016 | M31: =(M14/100)*S14 -> 4245.7446 | N31: =(N14/100)*S14 -> 1230.3414 | O31: =(O14/100)*$S$7 -> 760.9626 | P31: =(P14/100)*$S$7 -> 746.739 | Q31: =(Q14/100)*$S$7 -> 120.9006 | R31: =(R14/100)*$S$7 -> 7.1118 | S31: 7111.7854
B32: 2017 | C32: 4225.132 | D32: 1227.2569 | E32: 769.39481 | F32: 745.82295 | G32: 124.44859 | H32: 19.730058 | I32: 7111.7854 | L32: 2017 | M32: =(M15/100)*S15 -> 4238.6328 | N32: =(N15/100)*S15 -> 1223.2296 | O32: =(O15/100)*$S$7 -> 768.0744 | P32: =(P15/100)*$S$7 -> 746.739 | Q32: =(Q15/100)*$S$7 -> 128.0124 | R32: =(R15/100)*$S$7 -> 7.1118 | S32: 7111.7854
B33: 2018 | C33: 4221.8149 | D33: 1226.4175 | E33: 773.2288 | F33: 745.80392 | G33: 124.80272 | H33: 19.717537 | I33: 7111.7854 | L33: 2018 | M33: =(M16/100)*S16 -> 4231.521 | N33: =(N16/100)*S16 -> 1223.2296 | O33: =(O16/100)*$S$7 -> 775.1862 | P33: =(P16/100)*$S$7 -> 746.739 | Q33: =(Q16/100)*$S$7 -> 128.0124 | R33: =(R16/100)*$S$7 -> 7.1118 | S33: 7111.7854
B34: 2019 | C34: 4218.292 | D34: 1226.0722 | E34: 776.65006 | F34: 745.77343 | G34: 125.30004 | H34: 19.697636 | I34: 7111.7854 | L34: 2019 | M34: =(M17/100)*S17 -> 4231.521 | N34: =(N17/100)*S17 -> 1223.2296 | O34: =(O17/100)*$S$7 -> 775.1862 | P34: =(P17/100)*$S$7 -> 746.739 | Q34: =(Q17/100)*$S$7 -> 128.0124 | R34: =(R17/100)*$S$7 -> 7.1118 | S34: 7111.7854
B35: 2020 | C35: 4215.8147 | D35: 1225.7737 | E35: 778.98806 | F35: 745.74093 | G35: 125.79171 | H35: 19.676255 | I35: 7111.7854 | L35: 2020 | M35: =(M18/100)*S18 -> 4231.521 | N35: =(N18/100)*S18 -> 1223.2296 | O35: =(O18/100)*$S$7 -> 775.1862 | P35: =(P18/100)*$S$7 -> 746.739 | Q35: =(Q18/100)*$S$7 -> 128.0124 | R35: =(R18/100)*$S$7 -> 7.1118 | S35: 7111.7854
B36: 2021 | C36: 4213.527 | D36: 1225.6177 | E36: 781.00454 | F36: 745.70251 | G36: 126.28261 | H36: 19.650976 | I36: 7111.7854 | L36: 2021 | M36: =(M19/100)*S19 -> 4224.4092 | N36: =(N19/100)*S19 -> 1223.2296 | O36: =(O19/100)*$S$7 -> 775.1862 | P36: =(P19/100)*$S$7 -> 746.739 | Q36: =(Q19/100)*$S$7 -> 128.0124 | R36: =(R19/100)*$S$7 -> 7.1118 | S36: 7111.7854
L37: 2022 | M37: =(M20/100)*S20 -> 4224.4092 | N37: =(N20/100)*S20 -> 1223.2296 | O37: =(O20/100)*$S$7 -> 782.298 | P37: =(P20/100)*$S$7 -> 746.739 | Q37: =(Q20/100)*$S$7 -> 128.0124 | R37: =(R20/100)*$S$7 -> 7.1118 | S37: 7111.7854
A38: 1000 ha = 0.001 Mha | B38: Land in Mha | C38: Grassland | D38: Wetlands (including peatlands) | E38: Forest | F38: Cropland | G38: Settlement | H38: Other land | I38: Total | K38: 1000 ha = 0.001 Mha | L38: Land in Mha | M38: Grassland | N38: Wetlands (including peatlands) | O38: Forest | P38: Cropland | Q38: Settlement | R38: Other land | S38: Total
B39: 2015 | C39: =C30*0.001 -> 4.2358544 | D39: =D30*0.001 -> 1.2281859 | E39: =E30*0.001 -> 0.75838259 | F39: =F30*0.001 -> 0.74586403 | G39: =G30*0.001 -> 0.12374136 | H39: =H30*0.001 -> 0.019757088 | I39: =I30*0.001 -> 7.1117854 | L39: 2015 | M39: =M30/1000 -> 4.2457446 | N39: =N30/1000 -> 1.2303414 | O39: =O30/1000 -> 0.7609626 | P39: =P30/1000 -> 0.746739 | Q39: =Q30/1000 -> 0.1209006 | R39: =R30/1000 -> 0.0071118 | S39: =S30/1000 -> 7.1117854
B40: 2016 | C40: =C31*0.001 -> 4.2304453 | D40: =D31*0.001 -> 1.2276574 | E40: =E31*0.001 -> 0.76408239 | F40: =F31*0.001 -> 0.74584264 | G40: =G31*0.001 -> 0.12401462 | H40: =H31*0.001 -> 0.019743016 | I40: =I31*0.001 -> 7.1117854 | L40: 2016 | M40: =M31/1000 -> 4.2457446 | N40: =N31/1000 -> 1.2303414 | O40: =O31/1000 -> 0.7609626 | P40: =P31/1000 -> 0.746739 | Q40: =Q31/1000 -> 0.1209006 | R40: =R31/1000 -> 0.0071118 | S40: =S31/1000 -> 7.1117854
B41: 2017 | C41: =C32*0.001 -> 4.225132 | D41: =D32*0.001 -> 1.2272569 | E41: =E32*0.001 -> 0.76939481 | F41: =F32*0.001 -> 0.74582295 | G41: =G32*0.001 -> 0.12444859 | H41: =H32*0.001 -> 0.019730058 | I41: =I32*0.001 -> 7.1117854 | L41: 2017 | M41: =M32/1000 -> 4.2386328 | N41: =N32/1000 -> 1.2232296 | O41: =O32/1000 -> 0.7680744 | P41: =P32/1000 -> 0.746739 | Q41: =Q32/1000 -> 0.1280124 | R41: =R32/1000 -> 0.0071118 | S41: =S32/1000 -> 7.1117854
B42: 2018 | C42: =C33*0.001 -> 4.2218149 | D42: =D33*0.001 -> 1.2264175 | E42: =E33*0.001 -> 0.7732288 | F42: =F33*0.001 -> 0.74580392 | G42: =G33*0.001 -> 0.12480272 | H42: =H33*0.001 -> 0.019717537 | I42: =I33*0.001 -> 7.1117854 | L42: 2018 | M42: =M33/1000 -> 4.231521 | N42: =N33/1000 -> 1.2232296 | O42: =O33/1000 -> 0.7751862 | P42: =P33/1000 -> 0.746739 | Q42: =Q33/1000 -> 0.1280124 | R42: =R33/1000 -> 0.0071118 | S42: =S33/1000 -> 7.1117854
B43: 2019 | C43: =C34*0.001 -> 4.218292 | D43: =D34*0.001 -> 1.2260722 | E43: =E34*0.001 -> 0.77665006 | F43: =F34*0.001 -> 0.74577343 | G43: =G34*0.001 -> 0.12530004 | H43: =H34*0.001 -> 0.019697636 | I43: =I34*0.001 -> 7.1117854 | L43: 2019 | M43: =M34/1000 -> 4.231521 | N43: =N34/1000 -> 1.2232296 | O43: =O34/1000 -> 0.7751862 | P43: =P34/1000 -> 0.746739 | Q43: =Q34/1000 -> 0.1280124 | R43: =R34/1000 -> 0.0071118 | S43: =S34/1000 -> 7.1117854
B44: 2020 | C44: =C35*0.001 -> 4.2158147 | D44: =D35*0.001 -> 1.2257737 | E44: =E35*0.001 -> 0.77898806 | F44: =F35*0.001 -> 0.74574093 | G44: =G35*0.001 -> 0.12579171 | H44: =H35*0.001 -> 0.019676255 | I44: =I35*0.001 -> 7.1117854 | L44: 2020 | M44: =M35/1000 -> 4.231521 | N44: =N35/1000 -> 1.2232296 | O44: =O35/1000 -> 0.7751862 | P44: =P35/1000 -> 0.746739 | Q44: =Q35/1000 -> 0.1280124 | R44: =R35/1000 -> 0.0071118 | S44: =S35/1000 -> 7.1117854
B45: 2021 | C45: =C36*0.001 -> 4.213527 | D45: =D36*0.001 -> 1.2256177 | E45: =E36*0.001 -> 0.78100454 | F45: =F36*0.001 -> 0.74570251 | G45: =G36*0.001 -> 0.12628261 | H45: =H36*0.001 -> 0.019650976 | I45: =I36*0.001 -> 7.1117854 | L45: 2021 | M45: =M36/1000 -> 4.2244092 | N45: =N36/1000 -> 1.2232296 | O45: =O36/1000 -> 0.7751862 | P45: =P36/1000 -> 0.746739 | Q45: =Q36/1000 -> 0.1280124 | R45: =R36/1000 -> 0.0071118 | S45: =S36/1000 -> 7.1117854
...

Sheet Base_Calc
A1: Sector | B1: Process | C1: Type | D1: TIMES Code | E1: Description | F1: Capacity Unit | G1: Activity Unit | H1: Input Commodities | I1: Input Commodities | J1: Input Commodities | K1: Input Commodities | P1: Energy use | V1: Output Commodities
H2: *ELC Consumption~2012 | I2: ELC Consumption~2030 | J2: ELC Consumption~2040 | K2: ELC Consumption~2050 | L2: *Diesel Consumption~2012 | M2: Diesel Consumption~2030 | N2: Diesel Consumption~2040 | O2: Diesel Consumption~2050 | P2: Total | Q2: Land Consumption~2020 | R2: Land Consumption~2025 | S2: Land Consumption~2030 | T2: Land Consumption~2040 | U2: Land Consumption~2050 | V2: Head | W2: Milk | X2: Land | Y2: Tillage~2020 | Z2: Tillage ~2025 | AA2: Tillage~2030 | AB2: Tillage ~2035 | AC2: Tillage~2040 | AD2: Tillage ~2045 | AE2: Tillage~2050 | AF2: CH4~2018 | AG2: CH4~2022 | AH2: CH4~2025 | AI2: CH4~2030 | AJ2: CH4~2035 | AK2: CH4~2040 | AL2: CH4~2045 | AM2: CH4~2050 | AN2: N2O~2020 | AO2: N2O~2022 | AP2: N2O~2025 | AQ2: N2O~2030 | AR2: N2O~2035 | AS2: N2O~2040 | AT2: N2O~2045 | AU2: N2O~2050
H3: PJ/CapUnit | I3: PJ/CapUnit | J3: PJ/CapUnit | K3: PJ/CapUnit | L3: PJ/CapUnit | M3: PJ/CapUnit | N3: PJ/CapUnit | O3: PJ/CapUnit | Q3: Mha/Capunit | R3: Mha/CapUnit | S3: Mha/CapUnit | T3: Mha/CapUnit | U3: Mha/CapUnit | V3: Mhead/CapUnit | W3: Ml/CapUnit | Y3: Mtonne/CapUnit | Z3: Mtonne/CapUnit | AA3: Mtonne/CapUnit | AB3: Mtonne/CapUnit | AC3: Mtonne/CapUnit | AD3: Mtonne/CapUnit | AE3: Mtonne/CapUnit | AF3: kt/CapUnit | AG3: kt/CapUnit | AH3: kt/CapUnit | AI3: kt/CapUnit | AJ3: kt/CapUnit | AK3: kt/CapUnit | AL3: kt/CapUnit | AM3: kt/CapUnit | AN3: kt/CapUnit | AO3: kt/CapUnit | AP3: kt/CapUnit | AQ3: kt/CapUnit | AR3: kt/CapUnit | AS3: kt/CapUnit | AT3: kt/CapUnit | AU3: kt/CapUnit
A4: Livestock | B4: Cattle | C4: Dairy | D4: ALIVCAT100 | E4: Dairy Cattle rearing | F4: Mhead | G4: Mlitres | H4: 0.342 | I4: 0.342 | J4: 0.342 | K4: 0.342 | L4: 1.368 | M4: 1.368 | N4: 1.368 | O4: 1.368 | P4: =I4+M4 -> 1.71 | Q4: 0.4 | R4: 0.4 | S4: 0.4 | T4: 0.4 | U4: 0.4 | V4: 1 | W4: 5716 | X4: - | Y4: - | Z4: - | AA4: - | AB4: - | AC4: - | AD4: - | AE4: - | AF4: 130.34 | AG4: 130.34 | AH4: 130.34 | AI4: 130.34 | AJ4: 130.34 | AK4: 130.34 | AL4: 130.34 | AM4: 130.34 | AN4: 2.16 | AO4: 2.16 | AP4: 2.16 | AQ4: 2.16 | AR4: 2.16 | AS4: 2.16 | AT4: 2.16 | AU4: 2.16
C5: Non-Dairy | D5: ALIVCAT200 | E5: Non-Dairy Cattle rearing | F5: Mhead | G5: Mhead | H5: 0.3219 | I5: 0.3219 | J5: 0.3219 | K5: 0.3219 | L5: 0.7881 | M5: 0.7881 | N5: 0.7881 | O5: 0.7881 | P5: =I5+M5 -> 1.11 | Q5: 0.45 | R5: 0.45 | S5: 0.45 | T5: 0.45 | U5: 0.45 | V5: 1 | W5: - | X5: - | Y5: - | Z5: - | AA5: - | AB5: - | AC5: - | AD5: - | AE5: - | AF5: 49.48 | AG5: 49.48 | AH5: 49.48 | AI5: 49.48 | AJ5: 49.48 | AK5: 49.48 | AL5: 49.48 | AM5: 49.48 | AN5: 0.8836 | AO5: 0.8836 | AP5: 0.8836 | AQ5: 0.8836 | AR5: 0.8836 | AS5: 0.8836 | AT5: 0.8836 | AU5: 0.8836
B6: Sheep | D6: ALIVSHE100 | E6: Sheep rearing | F6: Mhead | G6: Mhead | H6: 0.0528 | I6: 0.0528 | J6: 0.0528 | K6: 0.0528 | L6: 0.1072 | M6: 0.1072 | N6: 0.1072 | O6: 0.1072 | P6: =I6+M6 -> 0.16 | Q6: 0.13 | R6: 0.13 | S6: 0.13 | T6: 0.13 | U6: 0.13 | V6: 1 | W6: - | X6: - | Y6: - | Z6: - | AA6: - | AB6: - | AC6: - | AD6: - | AE6: - | AF6: 7.85 | AG6: 7.85 | AH6: 7.85 | AI6: 7.85 | AJ6: 7.85 | AK6: 7.85 | AL6: 7.85 | AM6: 7.85 | AN6: 0.046 | AO6: 0.046 | AP6: 0.046 | AQ6: 0.046 | AR6: 0.046 | AS6: 0.046 | AT6: 0.046 | AU6: 0.046
B7: Pigs | D7: ALIVPIG100 | E7: Pigs rearing | F7: Mhead | G7: Mhead | H7: 0.068 | I7: 0.068 | J7: 0.068 | K7: 0.068 | L7: 0.102 | M7: 0.102 | N7: 0.102 | O7: 0.102 | P7: =I7+M7 -> 0.17 | Q7: 0 | R7: 0 | S7: 0 | T7: 0 | U7: 0 | V7: 1 | W7: - | X7: - | Y7: - | Z7: - | AA7: - | AB7: - | AC7: - | AD7: - | AE7: - | AF7: 14.26 | AG7: 14.26 | AH7: 14.26 | AI7: 14.26 | AJ7: 14.26 | AK7: 14.26 | AL7: 14.26 | AM7: 14.26 | AN7: 0.27 | AO7: 0.27 | AP7: 0.27 | AQ7: 0.27 | AR7: 0.27 | AS7: 0.27 | AT7: 0.27 | AU7: 0.27
B8: Poultry | D8: ALIVPOU100 | E8: Poultry rearing | F8: Mhead | G8: Mhead | H8: 0.007 | I8: 0.007 | J8: 0.007 | K8: 0.007 | L8: 0.013 | M8: 0.013 | N8: 0.013 | O8: 0.013 | P8: =I8+M8 -> 0.02 | Q8: 0 | R8: 0 | S8: 0 | T8: 0 | U8: 0 | V8: 1 | W8: - | X8: - | Y8: - | Z8: - | AA8: - | AB8: - | AC8: - | AD8: - | AE8: - | AF8: 0.2 | AG8: 0.2 | AH8: 0.2 | AI8: 0.2 | AJ8: 0.2 | AK8: 0.2 | AL8: 0.2 | AM8: 0.2 | AN8: 0.0154 | AO8: 0.0154 | AP8: 0.0154 | AQ8: 0.0154 | AR8: 0.0154 | AS8: 0.0154 | AT8: 0.0154 | AU8: 0.0154
B9: Other | D9: ALIVOTH100 | E9: Other animals rearing | F9: Mhead | G9: Mhead | H9: 0.27 | I9: 0.27 | J9: 0.27 | K9: 0.27 | L9: 0.63 | M9: 0.63 | N9: 0.63 | O9: 0.63 | P9: =I9+M9 -> 0.9 | Q9: 0.05 | R9: 0.05 | S9: 0.05 | T9: 0.05 | U9: 0.05 | V9: 1 | W9: - | X9: - | Y9: - | Z9: - | AA9: - | AB9: - | AC9: - | AD9: - | AE9: - | AF9: 1.23 | AG9: 1.23 | AH9: 1.23 | AI9: 1.23 | AJ9: 1.23 | AK9: 1.23 | AL9: 1.23 | AM9: 1.23 | AN9: 0.041 | AO9: 0.041 | AP9: 0.041 | AQ9: 0.041 | AR9: 0.041 | AS9: 0.041 | AT9: 0.041 | AU9: 0.041
A10: Pasture | B10: Cattle | C10: Dairy | D10: APASCAT100 | E10: Dairy Cattle pasture system | F10: Mha | G10: Mha | H10: - | I10: - | J10: - | K10: - | L10: - | M10: - | N10: - | O10: - | Q10: 1 | R10: 1 | S10: 1 | T10: 1 | U10: 1 | V10: - | W10: - | X10: 1 | Y10: - | Z10: - | AA10: - | AB10: - | AC10: - | AD10: - | AE10: - | AF10: - | AH10: - | AI10: - | AJ10: - | AK10: - | AL10: - | AM10: - | AN10: 1.924 | AO10: 1.924 | AP10: 1.924 | AQ10: 1.924 | AR10: 1.924 | AS10: 1.924 | AT10: 1.924 | AU10: 1.924
C11: Non-Dairy | D11: APASCAT200 | E11: Non-Dairy Cattle pasture system | F11: Mha | G11: Mha | H11: - | I11: - | J11: - | K11: - | L11: - | M11: - | N11: - | O11: - | Q11: 1 | R11: 1 | S11: 1 | T11: 1 | U11: 1 | V11: - | W11: - | X11: 1 | Y11: - | Z11: - | AA11: - | AB11: - | AC11: - | AD11: - | AE11: - | AF11: - | AH11: - | AI11: - | AJ11: - | AK11: - | AL11: - | AM11: - | AN11: 1.22 | AO11: 1.22 | AP11: 1.22 | AQ11: 1.22 | AR11: 1.22 | AS11: 1.22 | AT11: 1.22 | AU11: 1.22
B12: Sheep | D12: APASSHE100 | E12: Sheep pasture system | F12: Mha | G12: Mha | H12: - | I12: - | J12: - | K12: - | L12: - | M12: - | N12: - | O12: - | Q12: 1 | R12: 1 | S12: 1 | T12: 1 | U12: 1 | V12: - | W12: - | X12: 1 | Y12: - | Z12: - | AA12: - | AB12: - | AC12: - | AD12: - | AE12: - | AF12: - | AH12: - | AI12: - | AJ12: - | AK12: - | AL12: - | AM12: - | AN12: 1.66 | AO12: 1.66 | AP12: 1.66 | AQ12: 1.66 | AR12: 1.66 | AS12: 1.66 | AT12: 1.66 | AU12: 1.66
B13: Other | D13: APASOTH100 | E13: Other animals pasture system | F13: Mha | G13: Mha | H13: - | I13: - | J13: - | K13: - | L13: - | M13: - | N13: - | O13: - | Q13: 1 | R13: 1 | S13: 1 | T13: 1 | U13: 1 | V13: - | W13: - | X13: 1 | Y13: - | Z13: - | AA13: - | AB13: - | AC13: - | AD13: - | AE13: - | AF13: - | AH13: - | AI13: - | AJ13: - | AK13: - | AL13: - | AM13: - | AN13: 1.5 | AO13: 1.5 | AP13: 1.5 | AQ13: 1.5 | AR13: 1.5 | AS13: 1.5 | AT13: 1.5 | AU13: 1.5
A14: Tillage | B14: Pulses (beans and peas) | D14: ATILPUL100 | E14: Pulses production | F14: Mha | G14: Mtonne | H14: 0.3366 | I14: 0.3366 | J14: 0.3366 | K14: 0.3366 | L14: 2.72 | M14: 2.72 | N14: 2.72 | O14: 2.72 | P14: =N47 -> 0.086074071 | Q14: 0.21 | R14: 0.21 | S14: 0.21 | T14: 0.21 | U14: 0.21 | V14: - | W14: - | X14: - | AF14: - | AH14: - | AI14: - | AJ14: - | AK14: - | AL14: - | AM14: - | AN14: 0.185 | AO14: 0.185 | AP14: 0.185 | AQ14: 0.185 | AR14: 0.185 | AS14: 0.185 | AT14: 0.185 | AU14: 0.185
B15: Potatoes | D15: ATILPOT100 | E15: Potato production | F15: Mha | G15: Mtonne | H15: 0.3366 | I15: 0.3366 | J15: 0.3366 | K15: 0.3366 | L15: 2.72 | M15: 2.72 | N15: 2.72 | O15: 2.72 | P15: =N49 -> 0.34112012 | Q15: 0.0296 | R15: 0.0296 | S15: 0.0296 | T15: 0.0296 | U15: 0.0296 | V15: - | W15: - | X15: - | AF15: - | AH15: - | AI15: - | AJ15: - | AK15: - | AL15: - | AM15: - | AN15: 0.024 | AO15: 0.024 | AP15: 0.024 | AQ15: 0.024 | AR15: 0.024 | AS15: 0.024 | AT15: 0.024 | AU15: 0.024
B16: Barley | D16: ATILBAR100 | E16: Barley production | F16: Mha | G16: Mtonne | H16: 0.3366 | I16: 0.3366 | J16: 0.3366 | K16: 0.3366 | L16: 2.72 | M16: 2.72 | N16: 2.72 | O16: 2.72 | P16: =N46 -> 1.3904192 | Q16: 0.18 | R16: 0.18 | S16: 0.18 | T16: 0.18 | U16: 0.18 | V16: - | W16: - | X16: - | AF16: - | AH16: - | AI16: - | AJ16: - | AK16: - | AL16: - | AM16: - | AN16: 0.127 | AO16: 0.127 | AP16: 0.127 | AQ16: 0.127 | AR16: 0.127 | AS16: 0.127 | AT16: 0.127 | AU16: 0.127
B17: Oats | D17: ATILOAT100 | E17: Oat production | F17: Mha | G17: Mtonne | H17: 0.3366 | I17: 0.3366 | J17: 0.3366 | K17: 0.3366 | L17: 2.72 | M17: 2.72 | N17: 2.72 | O17: 2.72 | P17: =N45 -> 0.21894364 | Q17: 0.133 | R17: 0.133 | S17: 0.133 | T17: 0.133 | U17: 0.133 | V17: - | W17: - | X17: - | AF17: - | AH17: - | AI17: - | AJ17: - | AK17: - | AL17: - | AM17: - | AN17: 0.115 | AO17: 0.115 | AP17: 0.115 | AQ17: 0.115 | AR17: 0.115 | AS17: 0.115 | AT17: 0.115 | AU17: 0.115
B18: Wheat | D18: ATILWHE100 | E18: Wheat production | F18: Mha | G18: Mtonne | H18: 0.3366 | I18: 0.3366 | J18: 0.3366 | K18: 0.3366 | L18: 2.72 | M18: 2.72 | N18: 2.72 | O18: 2.72 | P18: =N44 -> 0.55042939 | Q18: 0.11 | R18: 0.11 | S18: 0.11 | T18: 0.11 | U18: 0.11 | V18: - | W18: - | X18: - | AF18: - | AH18: - | AI18: - | AJ18: - | AK18: - | AL18: - | AM18: - | AN18: 0.107 | AO18: 0.107 | AP18: 0.107 | AQ18: 0.107 | AR18: 0.107 | AS18: 0.107 | AT18: 0.107 | AU18: 0.107
B19: Oil seed rape | D19: ATILOSR100 | E19: Oil seed rape production | F19: Mha | G19: Mtonne | H19: 0.68310438 | I19: 0.68310438 | J19: 0.68310438 | K19: 0.68310438 | L19: 3.4673193 | M19: 3.5177979 | N19: 2.4721171 | O19: 2.2249054 | P19: 0.117 | Q19: 0.227 | R19: 0.227 | S19: 0.227 | T19: 0.227 | U19: 0.227 | V19: - | W19: - | X19: - | AF19: - | AH19: - | AI19: - | AJ19: - | AK19: - | AL19: - | AM19: - | AN19: 0.102 | AO19: 0.102 | AP19: 0.102 | AQ19: 0.102 | AR19: 0.102 | AS19: 0.102 | AT19: 0.102 | AU19: 0.102
AF20: EF_AGR TIMLEAF - FINAL.xlsx
AF21: All emission factors calculaed in above file
AN22: *Note: For poultry, we combine all N20 emissions together in the livestock part (kton per Mhead) as there is no grazing
A32: For energy consumption (diesel and electricity), we use estimates from literature (ENERGY USE IN AGRICULTURE - EU review) in terms of percentage | N32: Total energy | O32: 2.69
B33: Diesel | C33: Electricity | N33: Calculate based on % ha
A34: Dairy | B34: 0.8 | C34: 0.2
A35: Beef | B35: 0.71 | C35: 0.29 | K35: Land used | L35: % | N35: Energy use Pj
A36: Sheep | B36: 0.67 | C36: 0.33 | J36: Wheat | K36: 0.062382 | L36: 0.200649 | N36: 0.613986
A37: Pig | B37: 0.6 | C37: 0.4 | J37: Oats | K37: 0.024282 | L37: 0.078102 | N37: 0.238991
A38: Poultry | B38: 0.65 | C38: 0.35 | J38: Barley | K38: 0.193236 | L38: 0.621539 | N38: 1.901908
A39: Other | B39: 0.7 | C39: 0.3 | D39: No specific values given for other animals - we assume 70-30 share | J39: Beans and peas | K39: 0.010173 | L39: 0.03272 | N39: 0.100124
J40: Oil seed rape | K40: 0.011891 | L40: 0.038247 | N40: 0.117035
J41: Potatoes | K41: 0.008936 | L41: 0.028744 | N41: 0.087955
A42: We calculate the new distribution of energy from the old values from Agri TIMES, based on these percentage | K42: 0.3109 | L42: 1 | N42: 3.06
M43: %
B44: Total energy use Agri TIMES (PJ/Mhead) | C44: Diesel | D44: Elec | J44: Wheat | K44: 519.9 | L44: =K44/1000 -> 0.5199 | M44: =L44/$L$50 -> 0.20462059 | N44: =M44*2.69 -> 0.55042939
A45: Dairy | B45: 1.71 | C45: =0.8*B45 -> 1.368 | D45: =0.2*B45 -> 0.342 | J45: Oats | K45: 206.8 | L45: =K45/1000 -> 0.2068 | M45: =L45/$L$50 -> 0.081391688 | N45: =M45*2.69 -> 0.21894364
A46: Non Dairy | B46: 1.11 | C46: =B35*B46 -> 0.7881 | D46: =C35*B35 -> 0.2059 | J46: Barley | K46: 1313.3 | L46: =K46/1000 -> 1.3133 | M46: =L46/$L$50 -> 0.51688445 | N46: =M46*2.69 -> 1.3904192
A47: Sheep | B47: 0.16 | C47: =B36*B47 -> 0.1072 | D47: =C36*B47 -> 0.0528 | J47: Beans and peas | K47: 81.3 | L47: =K47/1000 -> 0.0813 | M47: =L47/$L$50 -> 0.031997796 | N47: =M47*2.69 -> 0.086074071
A48: Pigs | B48: 0.17 | C48: =B37*B48 -> 0.102 | D48: =C37*B48 -> 0.068 | J48: Oil seed rape | K48: 97.3 | L48: =K48/1000 -> 0.0973 | M48: =L48/$L$50 -> 0.038295025 | N48: =M48*2.69 -> 0.10301362
A49: Poultry | B49: 0.02 | C49: =B38*B49 -> 0.013 | D49: =C38*B49 -> 0.007 | J49: Potatoes | K49: 322.2 | L49: =K49/1000 -> 0.3222 | M49: =L49/$L$50 -> 0.12681045 | N49: =M49*2.69 -> 0.34112012
...

Sheet BIOENERGY_CALC
A1: Sector | B1: Process | C1: Type | D1: TIMES Code | E1: Description | F1: Capacity Unit | G1: Activity Unit | H1: Activity Cost~2012 | I1: Delivery costs~2012 | J1: Life | K1: Start | L1: Efficiency (contracted) | M1: Efficiency (consumed) | N1: Input Commodities | P1: Input Commodities | AH1: Output Commodities | BE1: Constraints and Notes
N2: *ELC Consumption~2005 | O2: *ELC Consumption~2006 | P2: ELC Consumption~2012 | Q2: ELC Consumption~2050 | R2: *Diesel Consumption~2005 | S2: *Diesel Consumption~2006 | T2: Diesel Consumption~2012 | U2: Diesel Consumption~2050 | V2: Water Consumption | W2: *Land Consumption~2005 | X2: *Land Consumption~2006 | Y2: Land Consumption~2012 | Z2: Land Consumption~2015 | AA2: Land Consumption~2020 | AB2: Land Consumption~2025 | AC2: Land Consumption~2030 | AD2: Land Consumption~2035 | AE2: Land Consumption~2040 | AF2: Land Consumption~2045 | AG2: Land Consumption~2050 | AH2: Bioenergy | AI2: *N2O~2005 | AJ2: *N2O~2006 | AK2: N2O~2012 | AL2: N2O~2015 | AM2: N2O~2020 | AN2: N2O~2025 | AO2: N2O~2030 | AP2: N2O~2035 | AQ2: N2O~2040 | AR2: N2O~2045 | AS2: N2O~2050 | AT2: *CO2,eq~2005 | AU2: *CO2,eq~2006 | AV2: CO2,eq~2012 | AW2: CO2,eq~2015 | AX2: CO2,eq~2020 | AY2: CO2,eq~2025 | AZ2: CO2,eq~2030 | BA2: CO2,eq~2035 | BB2: CO2,eq~2040 | BC2: CO2,eq~2045 | BD2: CO2,eq~2050
H3: M€/ActUnit | I3: M€/ActUnit | L3: GJ/ha | M3: GJ/ha | N3: PJ/Consumed Land | O3: PJ/Consumed Land | P3: PJ/Consumed Land | Q3: PJ/Consumed Land | R3: PJ/Consumed Land | S3: PJ/Consumed Land | T3: PJ/Consumed Land | U3: PJ/Consumed Land | V3: Mlitres/CapUnit | W3: Mha/CapUnit | X3: Mha/CapUnit | Y3: Mha/CapUnit | Z3: Mha/CapUnit | AA3: Mha/CapUnit | AB3: Mha/CapUnit | AC3: Mha/CapUnit | AD3: Mha/CapUnit | AE3: Mha/CapUnit | AF3: Mha/CapUnit | AG3: Mha/CapUnit | AH3: PJ/Capunit | AI3: kt/Mha(Cons) | AJ3: kt/Mha(Cons) | AK3: kt/Mha(Cons) | AL3: kt/Mha(Cons) | AM3: kt/Mha(Cons) | AN3: kt/Mha(Cons) | AO3: kt/Mha(Cons) | AP3: kt/Mha(Cons) | AQ3: kt/Mha(Cons) | AR3: kt/Mha(Cons) | AS3: kt/Mha(Cons) | AT3: kt/Mha(Cons) | AU3: kt/Mha(Cons) | AV3: kt/Mha(Cons) | AW3: kt/Mha(Cons) | AX3: kt/Mha(Cons) | AY3: kt/Mha(Cons) | AZ3: kt/Mha(Cons) | BA3: kt/Mha(Cons) | BB3: kt/Mha(Cons) | BC3: kt/Mha(Cons) | BD3: kt/Mha(Cons)
A4: Tillage | B4: Bioenergy crop | C4: Wheat-R1 | D4: ABIOCRP11 | E4: Wheat for ethanol production - RSV1 | F4: Mha (contracted) | G4: PJ | H4: 50 | K4: 2012 | L4: 44 | M4: 66 | N4: 0.68310438 | O4: 0.67717051 | P4: 0.5856062 | Q4: 0.46848496 | R4: 3.4673193 | S4: 3.5177979 | T4: 2.4721171 | U4: 2.2249054 | W4: 1 | X4: 1 | Y4: 1 | Z4: 1 | AA4: 1 | AB4: 1 | AC4: 1 | AD4: 1 | AE4: 1 | AF4: 1 | AG4: 1 | AH4: 44 | AI4: =Base_Calc!$AN$18 -> 0.107 | AJ4: =Base_Calc!$AN$18 -> 0.107 | AK4: =Base_Calc!$AN$18 -> 0.107 | AL4: =Base_Calc!$AN$18 -> 0.107 | AM4: =Base_Calc!$AN$18 -> 0.107 | AN4: =Base_Calc!$AN$18 -> 0.107 | AO4: =Base_Calc!$AN$18 -> 0.107 | AP4: =Base_Calc!$AN$18 -> 0.107 | ... AS4: =Base_Calc!$AN$18 -> 0.107
C5: Wheat-R2 | D5: ABIOCRP12 | E5: Wheat for ethanol production - RSV2 | F5: Mha (contracted) | G5: PJ | H5: 50 | K5: 2012 | L5: 44 | M5: 66 | N5: 0.68310438 | O5: 0.67717051 | P5: 0.5856062 | Q5: 0.46848496 | R5: 3.4673193 | S5: 3.5177979 | T5: 2.4721171 | U5: 2.2249054 | W5: 1 | X5: 1 | Y5: 1 | Z5: 1 | AA5: 1 | AB5: 1 | AC5: 1 | AD5: 1 | AE5: 1 | AF5: 1 | AG5: 1 | AH5: 44 | AI5: =Base_Calc!$AN$18 -> 0.107 | AJ5: =Base_Calc!$AN$18 -> 0.107 | AK5: =Base_Calc!$AN$18 -> 0.107 | AL5: =Base_Calc!$AN$18 -> 0.107 | AM5: =Base_Calc!$AN$18 -> 0.107 | AN5: =Base_Calc!$AN$18 -> 0.107 | AO5: =Base_Calc!$AN$18 -> 0.107 | AP5: =Base_Calc!$AN$18 -> 0.107 | ... AS5: =Base_Calc!$AN$18 -> 0.107
C6: Wheat-R3 | D6: ABIOCRP13 | E6: Wheat for ethanol production - RSV3 | F6: Mha (contracted) | G6: PJ | H6: 50 | K6: 2012 | L6: 44 | M6: 66 | N6: 0.68310438 | O6: 0.67717051 | P6: 0.5856062 | Q6: 0.46848496 | R6: 3.4673193 | S6: 3.5177979 | T6: 2.4721171 | U6: 2.2249054 | W6: 1 | X6: 1 | Y6: 1 | Z6: 1 | AA6: 1 | AB6: 1 | AC6: 1 | AD6: 1 | AE6: 1 | AF6: 1 | AG6: 1 | AH6: 44 | AI6: =Base_Calc!$AN$18 -> 0.107 | AJ6: =Base_Calc!$AN$18 -> 0.107 | AK6: =Base_Calc!$AN$18 -> 0.107 | AL6: =Base_Calc!$AN$18 -> 0.107 | AM6: =Base_Calc!$AN$18 -> 0.107 | AN6: =Base_Calc!$AN$18 -> 0.107 | AO6: =Base_Calc!$AN$18 -> 0.107 | AP6: =Base_Calc!$AN$18 -> 0.107 | ... AS6: =Base_Calc!$AN$18 -> 0.107
C7: Micanthus-R1 | D7: ABIOCRP31 | E7: Miscanthus Crops for biomass - RSV 1 | F7: Mha (contracted) | G7: PJ | H7: 50 | K7: 2012 | L7: 156.03083 | M7: 156.03083 | N7: 0.68310438 | O7: 0.67717051 | P7: 0.5856062 | Q7: 0.46848496 | R7: 3.4673193 | S7: 3.5177979 | T7: 2.4721171 | U7: 2.2249054 | W7: 1 | X7: 1 | Y7: 1 | Z7: 1 | AA7: 1 | AB7: 1 | AC7: 1 | AD7: 1 | AE7: 1 | AF7: 1 | AG7: 1 | AH7: 156.03083 | AI7: =Base_Calc!$AN$18 -> 0.107 | AJ7: =Base_Calc!$AN$18 -> 0.107 | AK7: =Base_Calc!$AN$18 -> 0.107 | AL7: =Base_Calc!$AN$18 -> 0.107 | AM7: =Base_Calc!$AN$18 -> 0.107 | AN7: =Base_Calc!$AN$18 -> 0.107 | AO7: =Base_Calc!$AN$18 -> 0.107 | AP7: =Base_Calc!$AN$18 -> 0.107 | ... AS7: =Base_Calc!$AN$18 -> 0.107 | BE7: Assumed the same emissions factors of Wheat
C8: Micanthus-R2 | D8: ABIOCRP32 | E8: Miscanthus Crops for biomass - RSV 2 | F8: Mha (contracted) | G8: PJ | H8: 50 | K8: 2012 | L8: 156.03083 | M8: 156.03083 | N8: 0.68310438 | O8: 0.67717051 | P8: 0.5856062 | Q8: 0.46848496 | R8: 3.4673193 | S8: 3.5177979 | T8: 2.4721171 | U8: 2.2249054 | W8: 1 | X8: 1 | Y8: 1 | Z8: 1 | AA8: 1 | AB8: 1 | AC8: 1 | AD8: 1 | AE8: 1 | AF8: 1 | AG8: 1 | AH8: 156.03083 | AI8: =Base_Calc!$AN$18 -> 0.107 | AJ8: =Base_Calc!$AN$18 -> 0.107 | AK8: =Base_Calc!$AN$18 -> 0.107 | AL8: =Base_Calc!$AN$18 -> 0.107 | AM8: =Base_Calc!$AN$18 -> 0.107 | AN8: =Base_Calc!$AN$18 -> 0.107 | AO8: =Base_Calc!$AN$18 -> 0.107 | AP8: =Base_Calc!$AN$18 -> 0.107 | ... AS8: =Base_Calc!$AN$18 -> 0.107 | BE8: Assumed the same emissions factors of Wheat
C9: Micanthus-R3 | D9: ABIOCRP33 | E9: Miscanthus Crops for biomass - RSV 3 | F9: Mha (contracted) | G9: PJ | H9: 50 | K9: 2012 | L9: 156.03083 | M9: 156.03083 | N9: 0.68310438 | O9: 0.67717051 | P9: 0.5856062 | Q9: 0.46848496 | R9: 3.4673193 | S9: 3.5177979 | T9: 2.4721171 | U9: 2.2249054 | W9: 1 | X9: 1 | Y9: 1 | Z9: 1 | AA9: 1 | AB9: 1 | AC9: 1 | AD9: 1 | AE9: 1 | AF9: 1 | AG9: 1 | AH9: 156.03083 | AI9: =Base_Calc!$AN$18 -> 0.107 | AJ9: =Base_Calc!$AN$18 -> 0.107 | AK9: =Base_Calc!$AN$18 -> 0.107 | AL9: =Base_Calc!$AN$18 -> 0.107 | AM9: =Base_Calc!$AN$18 -> 0.107 | AN9: =Base_Calc!$AN$18 -> 0.107 | AO9: =Base_Calc!$AN$18 -> 0.107 | AP9: =Base_Calc!$AN$18 -> 0.107 | ... AS9: =Base_Calc!$AN$18 -> 0.107 | BE9: Assumed the same emissions factors of Wheat
C10: Willow-R1 | D10: ABIOCRP41 | E10: Willow Crops for biomass - RSV 1 | F10: Mha (contracted) | G10: PJ | H10: 50 | K10: 2012 | L10: 82.74362 | M10: 165.48724 | N10: 0.68310438 | O10: 0.67717051 | P10: 0.5856062 | Q10: 0.46848496 | R10: 3.4673193 | S10: 3.5177979 | T10: 2.4721171 | U10: 2.2249054 | W10: 1 | X10: 1 | Y10: 1 | Z10: 1 | AA10: 1 | AB10: 1 | AC10: 1 | AD10: 1 | AE10: 1 | AF10: 1 | AG10: 1 | AH10: 82.74362 | AI10: =Base_Calc!$AN$18 -> 0.107 | AJ10: =Base_Calc!$AN$18 -> 0.107 | AK10: =Base_Calc!$AN$18 -> 0.107 | AL10: =Base_Calc!$AN$18 -> 0.107 | AM10: =Base_Calc!$AN$18 -> 0.107 | AN10: =Base_Calc!$AN$18 -> 0.107 | AO10: =Base_Calc!$AN$18 -> 0.107 | AP10: =Base_Calc!$AN$18 -> 0.107 | ... AS10: =Base_Calc!$AN$18 -> 0.107 | BE10: Assumed the same emissions factors of Wheat
C11: Willow-R2 | D11: ABIOCRP42 | E11: Willow Crops for biomass - RSV 2 | F11: Mha (contracted) | G11: PJ | H11: 50 | K11: 2012 | L11: 82.74362 | M11: 165.48724 | N11: 0.68310438 | O11: 0.67717051 | P11: 0.5856062 | Q11: 0.46848496 | R11: 3.4673193 | S11: 3.5177979 | T11: 2.4721171 | U11: 2.2249054 | W11: 1 | X11: 1 | Y11: 1 | Z11: 1 | AA11: 1 | AB11: 1 | AC11: 1 | AD11: 1 | AE11: 1 | AF11: 1 | AG11: 1 | AH11: 82.74362 | AI11: =Base_Calc!$AN$18 -> 0.107 | AJ11: =Base_Calc!$AN$18 -> 0.107 | AK11: =Base_Calc!$AN$18 -> 0.107 | AL11: =Base_Calc!$AN$18 -> 0.107 | AM11: =Base_Calc!$AN$18 -> 0.107 | AN11: =Base_Calc!$AN$18 -> 0.107 | AO11: =Base_Calc!$AN$18 -> 0.107 | AP11: =Base_Calc!$AN$18 -> 0.107 | ... AS11: =Base_Calc!$AN$18 -> 0.107 | BE11: Assumed the same emissions factors of Wheat
C12: Willow-R3 | D12: ABIOCRP43 | E12: Willow Crops for biomass - RSV 3 | F12: Mha (contracted) | G12: PJ | H12: 50 | K12: 2012 | L12: 82.74362 | M12: 165.48724 | N12: 0.68310438 | O12: 0.67717051 | P12: 0.5856062 | Q12: 0.46848496 | R12: 3.4673193 | S12: 3.5177979 | T12: 2.4721171 | U12: 2.2249054 | W12: 1 | X12: 1 | Y12: 1 | Z12: 1 | AA12: 1 | AB12: 1 | AC12: 1 | AD12: 1 | AE12: 1 | AF12: 1 | AG12: 1 | AH12: 82.74362 | AI12: =Base_Calc!$AN$18 -> 0.107 | AJ12: =Base_Calc!$AN$18 -> 0.107 | AK12: =Base_Calc!$AN$18 -> 0.107 | AL12: =Base_Calc!$AN$18 -> 0.107 | AM12: =Base_Calc!$AN$18 -> 0.107 | AN12: =Base_Calc!$AN$18 -> 0.107 | AO12: =Base_Calc!$AN$18 -> 0.107 | AP12: =Base_Calc!$AN$18 -> 0.107 | ... AS12: =Base_Calc!$AN$18 -> 0.107 | BE12: Assumed the same emissions factors of Wheat
C13: Grass-R1 | D13: ABIOGAS11 | E13: Grass for biogas production - RSV 1 | F13: Mha (contracted) | G13: PJ | H13: 50 | K13: 2012 | L13: 158.97607 | M13: 158.97607 | N13: 0.68310438 | O13: 0.67717051 | P13: 0.5856062 | Q13: 0.46848496 | R13: 3.4673193 | S13: 3.5177979 | T13: 2.4721171 | U13: 2.2249054 | W13: 1 | X13: 1 | Y13: 1 | Z13: 1 | AA13: 1 | AB13: 1 | AC13: 1 | AD13: 1 | AE13: 1 | AF13: 1 | AG13: 1 | AH13: 158.97607 | AI13: 1.067 | AJ13: 1.067 | AK13: 1.067 | AL13: 1.067 | AM13: 1.067 | AN13: 1.067 | AO13: 1.067 | AP13: 1.067 | AQ13: 1.067 | AR13: 1.067 | AS13: 1.067 | BE13: Assumed the same emissions factors of pasture land
C14: Grass-R2 | D14: ABIOGAS12 | E14: Grass for biogas production - RSV 2 | F14: Mha (contracted) | G14: PJ | H14: 50 | K14: 2012 | L14: 158.97607 | M14: 158.97607 | N14: 0.68310438 | O14: 0.67717051 | P14: 0.5856062 | Q14: 0.46848496 | R14: 3.4673193 | S14: 3.5177979 | T14: 2.4721171 | U14: 2.2249054 | W14: 1 | X14: 1 | Y14: 1 | Z14: 1 | AA14: 1 | AB14: 1 | AC14: 1 | AD14: 1 | AE14: 1 | AF14: 1 | AG14: 1 | AH14: 158.97607 | AI14: 1.067 | AJ14: 1.067 | AK14: 1.067 | AL14: 1.067 | AM14: 1.067 | AN14: 1.067 | AO14: 1.067 | AP14: 1.067 | AQ14: 1.067 | AR14: 1.067 | AS14: 1.067
C15: Grass-R3 | D15: ABIOGAS13 | E15: Grass for biogas production - RSV 3 | F15: Mha (contracted) | G15: PJ | H15: 50 | K15: 2012 | L15: 158.97607 | M15: 158.97607 | N15: 0.68310438 | O15: 0.67717051 | P15: 0.5856062 | Q15: 0.46848496 | R15: 3.4673193 | S15: 3.5177979 | T15: 2.4721171 | U15: 2.2249054 | W15: 1 | X15: 1 | Y15: 1 | Z15: 1 | AA15: 1 | AB15: 1 | AC15: 1 | AD15: 1 | AE15: 1 | AF15: 1 | AG15: 1 | AH15: 158.97607 | AI15: 1.067 | AJ15: 1.067 | AK15: 1.067 | AL15: 1.067 | AM15: 1.067 | AN15: 1.067 | AO15: 1.067 | AP15: 1.067 | AQ15: 1.067 | AR15: 1.067 | AS15: 1.067
C16: Oil Seed Rape-R1 | D16: ABIOCRP21 | E16: OSR for biodiesel production - RSV 1 | F16: Mha (contracted) | G16: PJ | H16: 50 | K16: 2012 | L16: 9.2 | M16: 46 | N16: 0.68310438 | O16: 0.67717051 | P16: 0.5856062 | Q16: 0.46848496 | R16: 3.4673193 | S16: 3.5177979 | T16: 2.4721171 | U16: 2.2249054 | W16: 1 | X16: 1 | Y16: 1 | Z16: 1 | AA16: 1 | AB16: 1 | AC16: 1 | AD16: 1 | AE16: 1 | AF16: 1 | AG16: 1 | AH16: 9.2 | AI16: =Base_Calc!$AN$19 -> 0.102 | AJ16: =Base_Calc!$AN$19 -> 0.102 | AK16: =Base_Calc!$AN$19 -> 0.102 | AL16: =Base_Calc!$AN$19 -> 0.102 | AM16: =Base_Calc!$AN$19 -> 0.102 | AN16: =Base_Calc!$AN$19 -> 0.102 | AO16: =Base_Calc!$AN$19 -> 0.102 | AP16: =Base_Calc!$AN$19 -> 0.102 | ... AS16: =Base_Calc!$AN$19 -> 0.102 | BE16: Assumed the same emissions factors of Wheat
