Workbook
Name FID_1: [1]AGR_Fuels!$A$2

Sheet Cover
B9: TIMLEAF model
A13: Document type: | B13: New Technologies
A14: Sector(s): | B14: Agricultural sector (AGR)
A15: Purpose: | B15: Define processes in agr for methane abatement
A17: Original developer(s): | B17: Neha Jaggeshar (Neha.Jaggeshar@ucc.ie)
A20: Current maintainer(s): | B20: Neha Jaggeshar (Neha.Jaggeshar@ucc.ie)
A23: Part of TIMLEAF version | B23: 1
A24: Model repository:
A25: Licence:
A28: Technologies included: | B28: Manure acidification (ACD)
B29: Anaerobic digestion (AD)
B30: Methane Inhibitors

Sheet ACD
A2: ~FI_Process
A3: Sets | B3: TechName | C3: TechDesc | D3: Tact | E3: Tcap | F3: Tslvl | G3: PrimaryCG | H3: Vintage
A4: \I: Process Set Membership | B4: Technology Name | C4: Technology Description | D4: Activity Unit | E4: Capacity Unit | F4: Timeslice Operational Level | G4: Operational Commodity Group | H4: Vintage Tracking
A5: PRE | B5: ALIVCAT104 | C5: Dairy cattle - Manure acidification | D5: Mlitre | E5: Mhead | H5: NO
B6: ALIVCAT204 | C6: Non Dairy cattle - Manure acidification | D6: Mhead | E6: Mhead | H6: NO
B7: ALIVSHE104 | C7: Sheep - Manure acidification | D7: Mhead | E7: Mhead | H7: NO
D11: ~FI_T
A12: TechName | B12: *TechDesc | C12: Comm-IN | D12: Comm-OUT | E12: Input | F12: Output | G12: CAP2ACT | H12: AF | I12: ENV_ACT~AGRLIVCH4 | J12: ENV_ACT~AGRLIVN2O | K12: Start | L12: ACT_COST | M12: VAROM
A13: Technology Name | B13: Technology Description | L13: MEUR/Mhead | M13: MEUR/Mhead
A14: =B5 -> ALIVCAT104 | B14: =C5 -> Dairy cattle - Manure acidification | C14: APASCAT1 | E14: 7e-05 | G14: 5716 | H14: 1 | I14: ='Input Data'!D17/ACD!G14 -> 0.021127432 | J14: ='Input Data'!E17/ACD!G14 -> 0.00037839398 | K14: 2040 | M14: ='Input Data'!L24 -> 85.797376
C15: ANRGCAT1 | E15: 0.00029916025
D16: ADCAT | F16: 1
D17: ACATMAN | F17: 0.0009
A18: =B6 -> ALIVCAT204 | B18: =C6 -> Non Dairy cattle - Manure acidification | C18: APASCAT2 | E18: 0.4 | G18: 1 | H18: 1 | I18: ='Input Data'!D18 -> 45.1288 | J18: ='Input Data'!E18 -> 0.8836 | K18: 2040 | M18: ='Input Data'!L25 -> 38.986752
C19: ANRGCAT2 | E19: 1.11
D20: ANDCAT | F20: 1
D21: ACATMAN | F21: 7.118
A22: =B7 -> ALIVSHE104 | B22: =C7 -> Sheep - Manure acidification | C22: APASSHE | E22: 0.13 | G22: 1 | H22: 1 | I22: ='Input Data'!D19 -> 7.2136 | J22: ='Input Data'!E19 -> 0.046 | K22: 2040 | M22: ='Input Data'!L26 -> 5.702144
C23: ANRGSHE | E23: 0.16
D24: ASHE | F24: 1
D25: ASHEMAN | F25: 0.364

Sheet AD
D3: ~FI_T
A4: TechName | B4: *TechDesc | C4: Comm-IN | D4: Comm-OUT | E4: Input | F4: Output | G4: CAP2ACT | H4: Life | I4: START | J4: env_act~AGRLIVCH4 | K4: env_act~AGRLIVN2O | L4: AF | M4: NCAP_DRATE
A5: Technology Name | B5: Technology Description
A6: ALIVCAT102 | B6: Dairy cattle manure digester | C6: APASCAT1 | E6: 7e-05 | G6: 5716 | H6: 20 | I6: 2040 | J6: 0.022146606 | K6: 0.000292162 | L6: 1 | M6: 0.09
C7: ANRGCAT11 | E7: 0.0003
D8: ADCAT | F8: 1
D9: ACATMAN | F9: 0.001
A10: ALIVCAT202 | B10: Non diary cattle manure digester | C10: APASCAT2 | E10: 0.4 | G10: 1 | H10: 20 | I10: 2040 | J10: 47.77 | K10: 0.68 | L10: 1 | M10: 0.09
C11: ANRGCAT21 | E11: 1.11
D12: ANDCAT | F12: 1
D13: ACATMAN | F13: 7.118571
A14: ALIVPIG102 | B14: Pigs manure digester | C14: ANRGPIG2 | E14: 0.17 | G14: 1 | H14: 20 | I14: 2040 | J14: 10.47 | K14: 0.01 | L14: 1 | M14: 0.09
D15: APIG | F15: 1
D16: APIGMAN | F16: 2.085714
A17: ALIVPOU102 | B17: Poultry manure digester | C17: ANRGPOU2 | E17: 0.02 | G17: 1 | H17: 20 | I17: 2045 | J17: 0.16 | K17: 0.2 | L17: 1 | M17: 0.09
D18: APOU | F18: 1
D19: APOUMAN | F19: 0.04
A20: ANRGCAT103 | B20: Dairy cattle manure mgt - energy use | C20: AGRELC | E20: 0.19 | G20: 1 | H20: 10 | I20: 2040
C21: AGRDST | E21: 0.81
D22: ANRGCAT11 | F22: 1
A23: ANRGCAT203 | B23: Non diary cattle manure mgt- energy use | C23: AGRELC | E23: 0.3 | G23: 1 | H23: 10 | I23: 2040
C24: AGRDST | E24: 0.7
D25: ANRGCAT21 | F25: 1
A26: ANRGPIG103 | B26: Pig manure mgt- energy use | C26: AGRELC | E26: 0.45 | G26: 1 | H26: 10 | I26: 2045
C27: AGRDST | E27: 0.55
D28: ANRGPIG2 | F28: 1
A29: ANRGPOU103 | B29: Poultry manure mgt- energy use | C29: AGRELC | E29: 0.3 | G29: 1 | H29: 10 | I29: 2035
C30: AGRDST | E30: 0.7
D31: ANRGPOU2 | F31: 1

Sheet CH4 inhibitors
A2: ~FI_Process
A3: Sets | B3: TechName | C3: TechDesc | D3: Tact | E3: Tcap | F3: Tslvl | G3: PrimaryCG | H3: Vintage
A4: \I: Process Set Membership | B4: Technology Name | C4: Technology Description | D4: Activity Unit | E4: Capacity Unit | F4: Timeslice Operational Level | G4: Operational Commodity Group | H4: Vintage Tracking
A5: PRE | B5: ALIVCAT105 | C5: Dairy cattle - CH4 inhibitors | D5: Mlitre | E5: Mhead | H5: NO
B6: ALIVCAT205 | C6: Non Dairy cattle - CH4 inhibitors | D6: Mhead | E6: Mhead | H6: NO
D11: ~FI_T
A12: TechName | B12: *TechDesc | C12: Comm-IN | D12: Comm-OUT | E12: Input | F12: Output | G12: CAP2ACT | H12: AF | I12: ENV_ACT~AGRLIVCH4 | J12: ENV_ACT~AGRLIVN2O | K12: Start | L12: ACT_COST | M12: VAROM
A13: Technology Name | B13: Technology Description | L13: MEUR/Mhead | M13: MEUR/Mhead
A14: =B5 -> ALIVCAT105 | B14: =C5 -> Dairy cattle - CH4 inhibitors | C14: APASCAT1 | E14: 7e-05 | G14: 5716 | H14: 1 | I14: ='Input Data'!D88/5716 -> 0.016641008 | J14: ='Input Data'!E88/5716 -> 0.00037788663 | K14: 2040
C15: ANRGCAT1 | E15: 0.00029916025
D16: ADCAT | F16: 1
D17: ACATMAN | F17: 0.0009
A18: =B6 -> ALIVCAT205 | B18: =C6 -> Non Dairy cattle - CH4 inhibitors | C18: APASCAT2 | E18: 0.4 | G18: 1 | H18: 1 | I18: ='Input Data'!D89 -> 36.4 | J18: ='Input Data'!E89 -> 0.88 | K18: 2040
C19: ANRGCAT2 | E19: 1.11
D20: ANDCAT | F20: 1
D21: ACATMAN | F21: 7.118

Sheet Manure to energy 
I4: Total manure in tonnes | J4: Gross energy output in GJ | K4: Energy per tonne manure | Q4: CRT 2025
Q7: Cattle | R7: 2018
Q8: Number of days housed
Q9: Dairy Cows | R9: 124
H10: Beef | I10: 257.02 | J10: =(6.11*8760*3.6)/1000 -> 192.68496 | K10: =J10/I10 -> 0.74968858 | Q10: Suckler Cows | R10: 151
H11: Dairy | I11: 347.49 | J11: =(6.51*8760*3.6)/1000 -> 205.29936 | K11: =J11/I11 -> 0.59080653 | Q11: Dairy Heifer | R11: 151
H12: Sheep | I12: 67.39 | J12: =(2.9*8760*3.6)/1000 -> 91.4544 | K12: =J12/I12 -> 1.3570916 | Q12: Other Heifer | R12: 151
H13: Pigs | I13: 6302.4 | J13: =(54.31*8760*3.6)/1000 -> 1712.7202 | K13: =J13/I13 -> 0.27175682 | Q13: Under 1yr-male | R13: 148
H14: Poultry | I14: 650.68 | J14: =(86.67*8760*3.6)/1000 -> 2733.2251 | K14: =J14/I14 -> 4.2005673 | Q14: Under 1yr-female | R14: 148
Q15: One to 2yrs-male | R15: 147
Q16: One to 2yrs-female | R16: 151
Q17: Over 2yrs-male | R17: 152
H18: Beef | I18: 642.56 | J18: =(15.29*8760*3.6)/1000 -> 482.18544 | K18: =J18/I18 -> 0.7504131 | Q18: Over 2yrs-female | R18: 145
H19: Dairy | I19: 788.75 | J19: =(14.77*8760*3.6)/1000 -> 465.78672 | K19: =J19/I19 -> 0.59053784 | Q19: Bulls | R19: 155
H20: Sheep | I20: 92.16 | J20: =(4.04*8760*3.6)/1000 -> 127.40544 | K20: =J20/I20 -> 1.3824375
H21: Pigs | I21: 101678.57 | J21: =(876.32*8760*3.6)/1000 -> 27635.628 | K21: =J21/I21 -> 0.27179402 | Q21: Pigs
H22: Poultry | I22: 2111.79 | J22: =(281.27*8760*3.6)/1000 -> 8870.1307 | K22: =J22/I22 -> 4.2002901 | Q22: Gilts in pig | R22: 365
Q23: Gilts not yet served | R23: 365
Q24: Sows in pig | R24: 365
Q25: Other sows for breeding | R25: 365
Q26: Boars | R26: 365
Q27: Pigs > 20 kg | R27: 365
Q28: Pigs < 20 kg | R28: 365
Q29: Poultry
Q30: Laying hens | R30: 365
Q31: Broilers | R31: 365
B32: AD for cattle, pigs and poultry | Q32: Turkeys | R32: 365
Q33: Ducks | R33: 365
B34: Livestock | C34: Weekly manure | D34: Housing period (days) | E34: Housing in weeks | F34: Annual manure (m3) per head | G34: tonnne per head | Q34: Geese | R34: 365
B35: Dairy | C35: 0.29 | D35: 124 | E35: =D35/7 -> 17.714286 | F35: =C35*E35 -> 5.1371429 | G35: =F35 -> 5.1371429 | Q35: Animal Category | R35: Days housed
B36: Non dairy | C36: 0.33 | D36: 151 | E36: =D36/7 -> 21.571429 | F36: =C36*E36 -> 7.1185714 | G36: =F36 -> 7.1185714
B37: pig | C37: 0.04 | D37: 365 | E37: =D37/7 -> 52.142857 | F37: =C37*E37 -> 2.0857143 | G37: =F37 -> 2.0857143 | Q37: Sheep
B38: poultry | C38: =0.81*10^-3 -> 0.00081 | D38: 365 | E38: =D38/7 -> 52.142857 | F38: =C38*E38 -> 0.042235714 | G38: =F38 -> 0.042235714 | Q38: Lowland Ewes | R38: 84
B39: Sheep | C39: 0.03 | D39: 85 | E39: =D39/7 -> 12.142857 | F39: =C39*E39 -> 0.36428571 | G39: =F39 -> 0.36428571 | Q39: Upland Ewes | R39: 85
Q40: Lowland Rams | R40: 56
Q41: Upland Rams | R41: 56
Q42: Lowland Other Sheep>1yrs | R42: 67
Q43: Upland Other Sheep>1yrs | R43: 67
Q44: Lowland lambs | R44: 28
Q45: Upland lambs | R45: 28

Sheet input_ad
A3: Sector | B3: Process | C3: Type | D3: TIMES Code | E3: Description | F3: Capacity Unit | G3: Activity Unit | H3: Investment Cost | I3: Variable O&M Cost | J3: Fixed O&M Cost | K3: Life | L3: Start | M3: Efficiency | N3: Input Commodities | AB3: Output Commodities | AF3: Constraints and Notes
N4: ELC Consumption~2012 | O4: ELC Consumption~2050 | P4: Diesel Consumption~2012 | Q4: Diesel Consumption~2050 | R4: Water Consumption | S4: Land Consumption~2012 | T4: Land Consumption~2015 | U4: Land Consumption~2020 | V4: Land Consumption~2025 | W4: Land Consumption~2030 | X4: Land Consumption~2035 | Y4: Land Consumption~2040 | Z4: Land Consumption~2045 | AA4: Land Consumption~2050 | AB4: Head | AC4: Milk | AD4: Land | AE4: Manure/Slurry
H5: M€/CapUnit | I5: M€/ActUnit | J5: M€/CapUnit | M5: GJ/tonne | N5: PJ/CapUnit | O5: PJ/CapUnit | P5: PJ/CapUnit | Q5: PJ/CapUnit | R5: Mlitres/CapUnit | S5: Mha/CapUnit | T5: Mha/CapUnit | U5: Mha/CapUnit | V5: Mha/CapUnit | W5: Mha/CapUnit | X5: Mha/CapUnit | Y5: Mha/CapUnit | Z5: Mha/CapUnit | AA5: Mha/CapUnit | AB5: Mhead/CapUnit | AC5: Ml/CapUnit | AE5: Mtonne/CapUnit
A6: AD part | D6: ALIVCAT102 | E6: Dairy Cattle rearing (Manure Digester) | F6: Mhead | G6: Mlitres | H6: - | I6: - | J6: - | K6: 1 | L6: 2020 | M6: - | N6: 0.32806427 | O6: 0.26245142 | P6: 1.3849124 | Q6: 1.2464212 | S6: 0.4 | T6: 0.4 | U6: 0.4 | V6: 0.4 | W6: 0.4 | X6: 0.4 | Y6: 0.4 | Z6: 0.4 | AA6: 0.4 | AC6: 5716 | AD6: - | AE6: ='Manure to energy '!G35 -> 5.1371429
D7: ALIVCAT202 | E7: Non-Cattle rearing (Manure Digester) | F7: Mhead | G7: Mhead | H7: - | I7: - | J7: - | K7: 1 | L7: 2020 | M7: - | N7: 0.21255452 | O7: 0.17004362 | P7: 0.89729185 | Q7: 0.80756266 | S7: 0.45 | T7: 0.45 | U7: 0.45 | V7: 0.45 | W7: 0.45 | X7: 0.45 | Y7: 0.45 | Z7: 0.45 | AA7: 0.45 | AC7: - | AD7: - | AE7: ='Manure to energy '!G36 -> 7.1185714
D8: ALIVSHE102 | E8: Sheep rearing (AD) | F8: Mhead | G8: Mhead | S8: 0.13 | T8: 0.13 | U8: 0.13 | V8: 0.13 | W8: 0.13 | X8: 0.13 | Y8: 0.13 | Z8: 0.13 | AA8: 0.13 | AE8: ='Manure to energy '!G39 -> 0.36428571
D9: ALIVPIG102 | E9: Pigs rearing (Manure Digester) | F9: Mhead | G9: Mhead | H9: - | I9: - | J9: - | K9: 1 | L9: 2020 | M9: - | N9: 0.031983645 | O9: 0.025586916 | P9: 0.13501789 | Q9: 0.1215161 | S9: 0 | T9: 0 | U9: 0 | V9: 0 | W9: 0 | X9: 0 | Y9: 0 | Z9: 0 | AA9: 0 | AC9: - | AD9: - | AE9: ='Manure to energy '!G37 -> 2.0857143
D10: ALIVPOU102 | E10: Poultry rearing (Manure Digester) | F10: Mhead | G10: Mhead | H10: - | I10: - | J10: - | K10: 1 | L10: 2020 | M10: - | N10: 0.0029767551 | O10: 0.0023814041 | P10: 0.012566273 | Q10: 0.011309645 | S10: 0 | T10: 0 | U10: 0 | V10: 0 | W10: 0 | X10: 0 | Y10: 0 | Z10: 0 | AA10: 0 | AC10: - | AD10: - | AE10: ='Manure to energy '!G38 -> 0.042235714
D11: ALIVOTH102 | E11: Other animals (AD) | F11: Mhead | G11: Mhead | S11: 0.05 | T11: 0.05 | U11: 0.05 | V11: 0.05 | W11: 0.05 | X11: 0.05 | Y11: 0.05 | Z11: 0.05 | AA11: 0.05 | AE11: 0
A12: Biogas plant | B12: Cattle | D12: ADGSCAT101 | E12: Cattle Manure/Slurry Digester (manure to biogas) | F12: GW | G12: PJ | H12: 2777.7778 | I12: 1.0493827 | J12: 55.555556 | K12: 20 | L12: 2020 | M12: ='Manure to energy '!K18 -> 0.7504131 | N12: - | O12: - | P12: - | Q12: - | S12: - | T12: - | U12: - | V12: - | W12: - | X12: - | Y12: - | Z12: - | AA12: - | AB12: - | AC12: - | AD12: - | AE12: -
B13: Pigs | D13: ADGSPIG101 | E13: Pigs Manure/Slurry Digester (manure to biogas) | F13: GW | G13: PJ | H13: 2777.7778 | I13: 1.0493827 | J13: 55.555556 | K13: 20 | L13: 2020 | M13: ='Manure to energy '!K21 -> 0.27179402 | N13: - | O13: - | P13: - | Q13: - | S13: - | T13: - | U13: - | V13: - | W13: - | X13: - | Y13: - | Z13: - | AA13: - | AB13: - | AC13: - | AD13: - | AE13: -
B14: Poultry | D14: ADGSPOUT101 | E14: Poultry Manure/Slurry Digester (manure to biogas) | F14: GW | G14: PJ | H14: 2777.7778 | I14: 1.0493827 | J14: 55.555556 | K14: 20 | L14: 2020 | M14: ='Manure to energy '!K22 -> 4.2002901 | N14: - | O14: - | P14: - | Q14: - | S14: - | T14: - | U14: - | V14: - | W14: - | X14: - | Y14: - | Z14: - | AA14: - | AB14: - | AC14: - | AD14: - | AE14: -

Sheet Input Data
B2: Year 2018 | D2: CH4 emissions | E2: CH4 emissions | F2: CH4 emissions | G2: CH4 emissions | I2: N20 emissions | J2: N20 emissions | L2: EF CH4 | M2: EF N20 | O2: EF N20 left on pasture
D3: enteric fermentation ktCH4 /Mhead | E3: enteric fermentation ktCH4 | F3: manure management (MM)ktCH4 / Mhead | G3: MM ktCH4 | I3: Manure management + manure applied to soils ktN20/ Mhead | J3: Manure management + applied to soils ktN20 | L3: KtCH4/Mhead | M3: KtN20/Mhead | O3: KtN20 / Mha
A4: Animal stock | B4: Mhead
A5: Dairy Cattle | B5: 1.425 | D5: 117.4 | E5: 167.295 | F5: 12.94 | G5: 18.4395 | I5: 2.1629 | J5: 3.0821325 | L5: 130.34 | M5: 2.1629 | O5: 1.924
A6: Non dairy cattle | B6: 5.836 | D6: 43.6 | E6: 254.4496 | F6: 5.88 | G6: 34.31568 | I6: 0.8836 | J6: 5.1566896 | L6: 49.48 | M6: 0.8836 | O6: 1.22
A7: Sheep | B7: 5.1477 | D7: 6.99 | E7: 35.982423 | F7: 0.86 | G7: 4.427022 | I7: 0.046 | J7: 0.2367942 | L7: 7.85 | M7: 0.046 | O7: 1.66
A8: Pig | B8: 1.597 | D8: 1.2 | E8: 1.9164 | F8: 13.06 | G8: 20.85682 | I8: 0.014737 | J8: 0.023534989 | L8: 14.26 | M8: 0.014737 | O8: 0
A9: Poultry | B9: 17.384 | D9: 0 | E9: 0 | F9: 0.22 | G9: 3.82448 | I9: 0.26486 | J9: 4.6043262 | L9: 0.22 | M9: 0.26486 | O9: 0
A10: Other | B10: 0.224 | D10: 0.1 | E10: 0.0224 | F10: 1.128 | G10: 0.252672 | I10: 0.01736 | J10: 0.00388864 | L10: 1.228 | M10: 0.01736 | O10: 1.5
D13: CH4 | E13: N20 | G13: Species | H13: Cost (MEUR/Ktco2EQ)
A14: Acidification | C14: ACD | D14: 0.74 | H14: LESS | I14: CLOVER | J14: MSC | K14: ACD | L14: Methane Inhibitors
G15: Dairy Cattle | H15: 0.175 | I15: -0.11 | J15: -0.11 | K15: 0.32 | L15: 0.215
A16: Animal stock | C16: NEW EF | D16: EF CH4 | E16: EF N20 | G16: Non dairy cattle | H16: 0.175 | I16: -0.11 | J16: -0.11 | K16: 0.32 | L16: 0.215
A17: Dairy Cattle | D17: 120.7644 | E17: 2.1629 | G17: Sheep | H17: 0.175 | I17: -0.11 | J17: -0.11 | K17: 0.32 | L17: 0.215
A18: Non dairy cattle | D18: 45.1288 | E18: 0.8836 | G18: Pig | H18: 0.175 | I18: -0.11 | J18: -0.11 | K18: 0.32 | L18: 0.215
A19: Sheep | D19: 7.2136 | E19: 0.046 | G19: Poultry | H19: 0.175 | I19: -0.11 | J19: -0.11 | K19: 0.32 | L19: 0.215
A20: Pig | D20: 4.5956 | E20: 0.014737 | G20: Other | H20: 0.175 | I20: -0.11 | J20: -0.11 | K20: 0.32 | L20: 0.215
A21: Poultry | D21: 0.0572 | E21: 0.26486
A22: Other | D22: 0.39328 | E22: 0.01736 | H22: Abated emissions
G23: ACD | H23: CH4 /Mhead | I23: N20 /Mhead | J23: ktco2eq /Mhead | L23: COST MEUR/Mhead
D24: CH4 | E24: N20 | G24: Dairy Cattle | H24: 9.5756 | I24: 0 | J24: 268.1168 | L24: 85.797376
A25: Methane inbitors | C25: MSC | D25: 0.3 | E25: 0 | G25: Non dairy cattle | H25: 4.3512 | I25: 0 | J25: 121.8336 | L25: 38.986752
G26: Sheep | H26: 0.6364 | I26: 0 | J26: 17.8192 | L26: 5.702144
A27: Animal stock | C27: NEW EF | D27: EF CH4 | E27: EF N20 | G27: Pig | H27: 9.6644 | I27: 0 | J27: 270.6032 | L27: 86.593024
A28: Dairy Cattle | D28: 95.12 | E28: 2.1629 | G28: Poultry | H28: 0.1628 | I28: 0 | J28: 4.5584 | L28: 1.458688
A29: Non dairy cattle | D29: 36.4 | E29: 0.8836 | G29: Other | H29: 0.83472 | I29: 0 | J29: 23.37216 | L29: 7.4790912
A30: Sheep | D30: 5.753 | E30: 0.046
A31: Pig | D31: 13.9 | E31: 0.014737
A32: Poultry | D32: 0.22 | E32: 0.26486 | H32: Abated emissions
A33: Other | D33: 1.198 | E33: 0.01736 | G33: MSC | H33: CH4 /Mhead | I33: N20 /Mhead | J33: ktco2eq /Mhead | L33: COST MEUR/Mhead
G34: Dairy Cattle | H34: 1.5528 | I34: 0 | J34: 43.4784 | L34: -4.782624
D35: CH4 | E35: N20 | G35: Non dairy cattle | H35: 0.7056 | I35: 0 | J35: 19.7568 | L35: -2.173248
A36: Manure storage cover | C36: MSC | D36: 0.12 | E36: 0 | G36: Sheep | H36: 0.1032 | I36: 0 | J36: 2.8896 | L36: -0.317856
G37: Pig | H37: 1.5672 | I37: 0 | J37: 43.8816 | L37: -4.826976
A38: Animal stock | C38: NEW EF | D38: EF CH4 | E38: EF N20 | G38: Poultry | H38: 0.0264 | I38: 0 | J38: 0.7392 | L38: -0.081312
A39: Dairy Cattle | D39: 128.7872 | E39: 2.1629 | G39: Other | H39: 0.13536 | I39: 0 | J39: 3.79008 | L39: -0.4169088
A40: Non dairy cattle | D40: 48.7744 | E40: 0.8836
A41: Sheep | D41: 7.7468 | E41: 0.046 | H41: Abated emissions
A42: Pig | D42: 12.6928 | E42: 0.014737 | G42: Clover | H42: CH4 /Mha | I42: N20 /Mha | J42: ktco2eq /Mha | L42: COST MEUR/Mha
A43: Poultry | D43: 0.1936 | E43: 0.26486 | G43: Dairy Cattle | H43: 0 | I43: 0.7696 | J43: 203.944 | L43: -22.43384
...
