Workbook

Sheet Cover
A16: TIMES-Ireland Model
A19: Document type: | B19: New Technologies - Transformation
A20: Sector(s): | B20: Service sector (SRV)
A21: Purpose: | B21: Transform techno-economic data
A23: Original developer(s):
A26: Current maintainer(s): | B26: Olexandr Balyk (UCC, olexandr.balyk@ucc.ie)
A29: Part of TIM version: | B29: 1
A30: Model repository: | B30: https://github.com/MaREI-EPMG/TIMES-Ireland-model
A31: Licence: | B31: CC BY-NC-SA 4.0 (unless specified otherwise)
B32: https://creativecommons.org/licenses/by-nc-sa/4.0/

Sheet Legend
A3: Sector: | B3: Services | C3: SRV
A4: Tab colour legend
B5: ="Veda Fill table" -> Veda Fill table
B6: VEDA-TIMES data input tables
A8: Cell colour legend
A9: aaa | B9: Model input
A10: aaa | B10: Model input based on own assumptions
B11: Calculated value (not recommended to directly modify)
A14: Codes for processes and commodities names
A15: Dimension | B15: Short code | C15: Full code
A16: Sub-sectors
A17: Commercial Services | C17: CS
A18: Public Services | C18: PU
A19: Thermal uses
A20: Space heating | C20: SH
A21: Water heating | C21: WH
A22: Space cooling | C22: SC
A23: Other uses
A24: Cooking | C24: CK
A25: Building lighting | C25: LIG
A26: Refrigeration | C26: REF
A27: Other appliances | C27: OEL
A28: Data centers | C28: DCE
A29: Public lighting | C29: PLIG
A30: Other services | C30: OTS
A31: Fuels
A32: Solids | B32: COA | C32: SRVCOA
A33: LPG | B33: LPG | C33: SRVLPG
A34: Oil | B34: OIL | C34: SRVOIL
A35: Natural Gas | B35: GAS | C35: SRVGAS
A36: Biomass | B36: BIO | C36: SRVBIO
A37: Biogas | B37: BGS | C37: SRVBGS
A38: Solar | B38: SOL | C38: SRVSOL
A39: Electricity | B39: ELC | C39: SRVELC
A40: Ambient Heat | B40: AHT | C40: SRVAHT
A41: District heating | B41: HET | C41: SRVHET
A42: Wind | B42: WIN | C42: SRVWIN
A43: Hydrogen (gaseous) | B43: H2G | C43: SRVH2G
... A46: Ethanol | B46: ETH | C46: SRVETH

Sheet AFA
A1: AFA for SRV techs
A2: ~TFM_INS
A3: Attribute | B3: PSET_PN | C3: Cset_CN | D3: AllRegions | F3: Type | G3: Fuel | H3: Reference Tech
A4: *Space Heat
A5: * | B5: ="S-SH-"&F5&"_"&G5&"*" -> S-SH-PU_COA* | C5: SRVSH-PU | D5: =SUMIFS('BY_S-SH'!$L$2:$L$100,'BY_S-SH'!$C$2:$C$100,AFA!H5,'BY_S-SH'!$A$2:$A$100,"BASE",'BY_S-SH'!$B$2:$B$100,"AFA") -> 0.11415525 | F5: =Legend!$C$18 -> PU | G5: =Legend!B32 -> COA | H5: ="S-SH-"&F5&"_"&G5&"*" -> S-SH-PU_COA*
A6: AFC | B6: ="S-SH-"&F6&"_"&G6&"*" -> S-SH-PU_LPG* | C6: SRVSH-PU | D6: =SUMIFS('BY_S-SH'!$L$2:$L$100,'BY_S-SH'!$C$2:$C$100,AFA!H6,'BY_S-SH'!$A$2:$A$100,"BASE",'BY_S-SH'!$B$2:$B$100,"AFA") -> 0.11415525 | F6: =Legend!$C$18 -> PU | G6: =Legend!B33 -> LPG | H6: ="S-SH-"&F6&"_"&G6&"*" -> S-SH-PU_LPG*
A7: AFC | B7: ="S-SH-"&F7&"_"&G7&"*" -> S-SH-PU_OIL* | C7: SRVSH-PU | D7: =SUMIFS('BY_S-SH'!$L$2:$L$100,'BY_S-SH'!$C$2:$C$100,AFA!H7,'BY_S-SH'!$A$2:$A$100,"BASE",'BY_S-SH'!$B$2:$B$100,"AFA") -> 0.11415525 | F7: =Legend!$C$18 -> PU | G7: =Legend!B34 -> OIL | H7: ="S-SH-"&F7&"_"&G7&"*" -> S-SH-PU_OIL*
A8: AFC | B8: ="S-SH-"&F8&"_"&G8&"*" -> S-SH-PU_GAS* | C8: SRVSH-PU | D8: =SUMIFS('BY_S-SH'!$L$2:$L$100,'BY_S-SH'!$C$2:$C$100,AFA!H8,'BY_S-SH'!$A$2:$A$100,"BASE",'BY_S-SH'!$B$2:$B$100,"AFA") -> 0.11415525 | F8: =Legend!$C$18 -> PU | G8: =Legend!B35 -> GAS | H8: ="S-SH-"&F8&"_"&G8&"*" -> S-SH-PU_GAS*
A9: AFC | B9: ="S-SH-"&F9&"_"&G9&"*" -> S-SH-PU_BIO* | C9: SRVSH-PU | D9: =SUMIFS('BY_S-SH'!$L$2:$L$100,'BY_S-SH'!$C$2:$C$100,AFA!H9,'BY_S-SH'!$A$2:$A$100,"BASE",'BY_S-SH'!$B$2:$B$100,"AFA") -> 0.11415525 | F9: =Legend!$C$18 -> PU | G9: =Legend!B36 -> BIO | H9: ="S-SH-"&F9&"_"&G9&"*" -> S-SH-PU_BIO*
A10: AFC | B10: ="S-SH-"&F10&"_"&G10&"*, -*N1" -> S-SH-PU_ELC*, -*N1 | C10: SRVSH-PU | D10: =SUMIFS('BY_S-SH'!$L$2:$L$100,'BY_S-SH'!$C$2:$C$100,AFA!H10,'BY_S-SH'!$A$2:$A$100,"BASE",'BY_S-SH'!$B$2:$B$100,"AFA") -> 0.11415525 | F10: =Legend!$C$18 -> PU | G10: =Legend!B39 -> ELC | H10: ="S-SH-"&F10&"_"&G10&"-HP*" -> S-SH-PU_ELC-HP*
A11: AFC | B11: ="S-SH-"&F11&"_"&G11&"*N1" -> S-SH-PU_ELC*N1 | C11: SRVSH-PU | D11: =SUMIFS('BY_S-SH'!$L$2:$L$100,'BY_S-SH'!$C$2:$C$100,AFA!H11,'BY_S-SH'!$A$2:$A$100,"BASE",'BY_S-SH'!$B$2:$B$100,"AFA") -> 0.11415525 | F11: =Legend!$C$18 -> PU | G11: =Legend!B39 -> ELC | H11: ="S-SH-"&F11&"_"&G11&"_X0" -> S-SH-PU_ELC_X0
A12: AFC | B12: ="S-SH-"&F12&"_"&G12&"*" -> S-SH-PU_HET* | C12: SRVSH-PU | D12: =SUMIFS('BY_S-SH'!$L$2:$L$100,'BY_S-SH'!$C$2:$C$100,AFA!H12,'BY_S-SH'!$A$2:$A$100,"BASE",'BY_S-SH'!$B$2:$B$100,"AFA") -> 0.11415525 | F12: =Legend!$C$18 -> PU | G12: =Legend!B41 -> HET | H12: =H8 -> S-SH-PU_GAS*
A13: * | B13: ="S-SH-"&F13&"_"&G13&"*" -> S-SH-CS_COA* | C13: SRVSH-CS | D13: =SUMIFS('BY_S-SH'!$L$2:$L$100,'BY_S-SH'!$C$2:$C$100,AFA!H13,'BY_S-SH'!$A$2:$A$100,"BASE",'BY_S-SH'!$B$2:$B$100,"AFA") -> 0.11415525 | F13: =Legend!$C$17 -> CS | G13: =G5 -> COA | H13: ="S-SH-"&F13&"_"&G13&"*" -> S-SH-CS_COA*
A14: AFC | B14: ="S-SH-"&F14&"_"&G14&"*" -> S-SH-CS_LPG* | C14: SRVSH-CS | D14: =SUMIFS('BY_S-SH'!$L$2:$L$100,'BY_S-SH'!$C$2:$C$100,AFA!H14,'BY_S-SH'!$A$2:$A$100,"BASE",'BY_S-SH'!$B$2:$B$100,"AFA") -> 0.11415525 | F14: =Legend!$C$17 -> CS | G14: =G6 -> LPG | H14: ="S-SH-"&F14&"_"&G14&"*" -> S-SH-CS_LPG*
A15: AFC | B15: ="S-SH-"&F15&"_"&G15&"*" -> S-SH-CS_OIL* | C15: SRVSH-CS | D15: =SUMIFS('BY_S-SH'!$L$2:$L$100,'BY_S-SH'!$C$2:$C$100,AFA!H15,'BY_S-SH'!$A$2:$A$100,"BASE",'BY_S-SH'!$B$2:$B$100,"AFA") -> 0.11643836 | F15: =Legend!$C$17 -> CS | G15: =G7 -> OIL | H15: ="S-SH-"&F15&"_"&G15&"*" -> S-SH-CS_OIL*
A16: AFC | B16: ="S-SH-"&F16&"_"&G16&"*" -> S-SH-CS_GAS* | C16: SRVSH-CS | D16: =SUMIFS('BY_S-SH'!$L$2:$L$100,'BY_S-SH'!$C$2:$C$100,AFA!H16,'BY_S-SH'!$A$2:$A$100,"BASE",'BY_S-SH'!$B$2:$B$100,"AFA") -> 0.11415525 | F16: =Legend!$C$17 -> CS | G16: =G8 -> GAS | H16: ="S-SH-"&F16&"_"&G16&"*" -> S-SH-CS_GAS*
A17: AFC | B17: ="S-SH-"&F17&"_"&G17&"*" -> S-SH-CS_BIO* | C17: SRVSH-CS | D17: =SUMIFS('BY_S-SH'!$L$2:$L$100,'BY_S-SH'!$C$2:$C$100,AFA!H17,'BY_S-SH'!$A$2:$A$100,"BASE",'BY_S-SH'!$B$2:$B$100,"AFA") -> 0.11415525 | F17: =Legend!$C$17 -> CS | G17: =G9 -> BIO | H17: ="S-SH-"&F17&"_"&G17&"*" -> S-SH-CS_BIO*
A18: AFC | B18: ="S-SH-"&F18&"_"&G18&"*, -*N1" -> S-SH-CS_ELC*, -*N1 | C18: SRVSH-CS | D18: =SUMIFS('BY_S-SH'!$L$2:$L$100,'BY_S-SH'!$C$2:$C$100,AFA!H18,'BY_S-SH'!$A$2:$A$100,"BASE",'BY_S-SH'!$B$2:$B$100,"AFA") -> 0.11415525 | F18: =Legend!$C$17 -> CS | G18: =G10 -> ELC | H18: ="S-SH-"&F18&"_"&G18&"-HP*" -> S-SH-CS_ELC-HP*
A19: AFC | B19: ="S-SH-"&F19&"_"&G19&"*N1" -> S-SH-CS_ELC*N1 | C19: SRVSH-CS | D19: =SUMIFS('BY_S-SH'!$L$2:$L$100,'BY_S-SH'!$C$2:$C$100,AFA!H19,'BY_S-SH'!$A$2:$A$100,"BASE",'BY_S-SH'!$B$2:$B$100,"AFA") -> 0.11415525 | F19: =Legend!$C$17 -> CS | G19: =G11 -> ELC | H19: ="S-SH-"&F19&"_"&G19&"_X0" -> S-SH-CS_ELC_X0
A20: AFC | B20: ="S-SH-"&F20&"_"&G20&"*" -> S-SH-CS_HET* | C20: SRVSH-CS | D20: =SUMIFS('BY_S-SH'!$L$2:$L$100,'BY_S-SH'!$C$2:$C$100,AFA!H20,'BY_S-SH'!$A$2:$A$100,"BASE",'BY_S-SH'!$B$2:$B$100,"AFA") -> 0.11415525 | F20: =Legend!$C$17 -> CS | G20: =G12 -> HET | H20: =H16 -> S-SH-CS_GAS*
A21: *Water Heat
A22: * | B22: ="S-WH-"&F22&"_"&G22&"*" -> S-WH-PU_COA* | D22: =SUMIFS('BY_S-WH'!$L$2:$L$100,'BY_S-WH'!$C$2:$C$100,AFA!H22,'BY_S-WH'!$A$2:$A$100,"BASE",'BY_S-WH'!$B$2:$B$100,"AFA") -> 0.02283105 | F22: =Legend!$C$18 -> PU | G22: =Legend!B32 -> COA | H22: ="S-WH-"&F22&"_"&G22&"*" -> S-WH-PU_COA*
A23: AFA | B23: ="S-WH-"&F23&"_"&G23&"*" -> S-WH-PU_LPG* | D23: =SUMIFS('BY_S-WH'!$L$2:$L$100,'BY_S-WH'!$C$2:$C$100,AFA!H23,'BY_S-WH'!$A$2:$A$100,"BASE",'BY_S-WH'!$B$2:$B$100,"AFA") -> 0.02283105 | F23: =Legend!$C$18 -> PU | G23: =Legend!B33 -> LPG | H23: ="S-WH-"&F23&"_"&G23&"*" -> S-WH-PU_LPG*
A24: * | B24: ="S-WH-"&F24&"_"&G24&"*" -> S-WH-PU_OIL* | D24: =SUMIFS('BY_S-WH'!$L$2:$L$100,'BY_S-WH'!$C$2:$C$100,AFA!H24,'BY_S-WH'!$A$2:$A$100,"BASE",'BY_S-WH'!$B$2:$B$100,"AFA") -> 0.02283105 | F24: =Legend!$C$18 -> PU | G24: =Legend!B34 -> OIL | H24: ="S-WH-"&F24&"_"&G24&"*" -> S-WH-PU_OIL*
A25: AFA | B25: ="S-WH-"&F25&"_"&G25&"*" -> S-WH-PU_GAS* | D25: =SUMIFS('BY_S-WH'!$L$2:$L$100,'BY_S-WH'!$C$2:$C$100,AFA!H25,'BY_S-WH'!$A$2:$A$100,"BASE",'BY_S-WH'!$B$2:$B$100,"AFA") -> 0.02283105 | F25: =Legend!$C$18 -> PU | G25: =Legend!B35 -> GAS | H25: ="S-WH-"&F25&"_"&G25&"*" -> S-WH-PU_GAS*
A26: AFA | B26: ="S-WH-"&F26&"_"&G26&"*" -> S-WH-PU_BIO* | D26: =SUMIFS('BY_S-WH'!$L$2:$L$100,'BY_S-WH'!$C$2:$C$100,AFA!H26,'BY_S-WH'!$A$2:$A$100,"BASE",'BY_S-WH'!$B$2:$B$100,"AFA") -> 0.02283105 | F26: =Legend!$C$18 -> PU | G26: =Legend!B36 -> BIO | H26: ="S-WH-"&F26&"_"&G26&"*" -> S-WH-PU_BIO*
A27: AFA | B27: ="S-WH-"&F27&"_"&G27&"*" -> S-WH-PU_SOL* | D27: =SUMIFS('BY_S-WH'!$L$2:$L$100,'BY_S-WH'!$C$2:$C$100,AFA!H27,'BY_S-WH'!$A$2:$A$100,"BASE",'BY_S-WH'!$B$2:$B$100,"AFA") -> 0.02283105 | F27: =Legend!$C$18 -> PU | G27: =Legend!B38 -> SOL | H27: ="S-WH-"&F27&"_"&G27&"*" -> S-WH-PU_SOL*
A28: AFA | B28: ="S-WH-"&F28&"_"&G28&"*" -> S-WH-PU_ELC* | D28: =SUMIFS('BY_S-WH'!$L$2:$L$100,'BY_S-WH'!$C$2:$C$100,AFA!H28,'BY_S-WH'!$A$2:$A$100,"BASE",'BY_S-WH'!$B$2:$B$100,"AFA") -> 0.02283105 | F28: =Legend!$C$18 -> PU | G28: =Legend!B39 -> ELC | H28: ="S-WH-"&F28&"_"&G28&"*" -> S-WH-PU_ELC*
A29: * | B29: ="S-WH-"&F29&"_"&G29&"*" -> S-WH-CS_COA* | D29: =SUMIFS('BY_S-WH'!$L$2:$L$100,'BY_S-WH'!$C$2:$C$100,AFA!H29,'BY_S-WH'!$A$2:$A$100,"BASE",'BY_S-WH'!$B$2:$B$100,"AFA") -> 0.02283105 | F29: =Legend!$C$17 -> CS | G29: =G22 -> COA | H29: ="S-WH-"&F29&"_"&G29&"*" -> S-WH-CS_COA*
A30: AFA | B30: ="S-WH-"&F30&"_"&G30&"*" -> S-WH-CS_LPG* | D30: =SUMIFS('BY_S-WH'!$L$2:$L$100,'BY_S-WH'!$C$2:$C$100,AFA!H30,'BY_S-WH'!$A$2:$A$100,"BASE",'BY_S-WH'!$B$2:$B$100,"AFA") -> 0.02283105 | F30: =Legend!$C$17 -> CS | G30: =G23 -> LPG | H30: ="S-WH-"&F30&"_"&G30&"*" -> S-WH-CS_LPG*
A31: * | B31: ="S-WH-"&F31&"_"&G31&"*" -> S-WH-CS_OIL* | D31: =SUMIFS('BY_S-WH'!$L$2:$L$100,'BY_S-WH'!$C$2:$C$100,AFA!H31,'BY_S-WH'!$A$2:$A$100,"BASE",'BY_S-WH'!$B$2:$B$100,"AFA") -> 0.023287671 | F31: =Legend!$C$17 -> CS | G31: =G24 -> OIL | H31: ="S-WH-"&F31&"_"&G31&"*" -> S-WH-CS_OIL*
A32: AFA | B32: ="S-WH-"&F32&"_"&G32&"*" -> S-WH-CS_GAS* | D32: =SUMIFS('BY_S-WH'!$L$2:$L$100,'BY_S-WH'!$C$2:$C$100,AFA!H32,'BY_S-WH'!$A$2:$A$100,"BASE",'BY_S-WH'!$B$2:$B$100,"AFA") -> 0.02283105 | F32: =Legend!$C$17 -> CS | G32: =G25 -> GAS | H32: ="S-WH-"&F32&"_"&G32&"*" -> S-WH-CS_GAS*
A33: AFA | B33: ="S-WH-"&F33&"_"&G33&"*" -> S-WH-CS_BIO* | D33: =SUMIFS('BY_S-WH'!$L$2:$L$100,'BY_S-WH'!$C$2:$C$100,AFA!H33,'BY_S-WH'!$A$2:$A$100,"BASE",'BY_S-WH'!$B$2:$B$100,"AFA") -> 0.02283105 | F33: =Legend!$C$17 -> CS | G33: =G26 -> BIO | H33: ="S-WH-"&F33&"_"&G33&"*" -> S-WH-CS_BIO*
A34: AFA | B34: ="S-WH-"&F34&"_"&G34&"*" -> S-WH-CS_SOL* | D34: =SUMIFS('BY_S-WH'!$L$2:$L$100,'BY_S-WH'!$C$2:$C$100,AFA!H34,'BY_S-WH'!$A$2:$A$100,"BASE",'BY_S-WH'!$B$2:$B$100,"AFA") -> 0.02283105 | F34: =Legend!$C$17 -> CS | G34: =G27 -> SOL | H34: ="S-WH-"&F34&"_"&G34&"*" -> S-WH-CS_SOL*
A35: AFA | B35: ="S-WH-"&F35&"_"&G35&"*" -> S-WH-CS_ELC* | D35: =SUMIFS('BY_S-WH'!$L$2:$L$100,'BY_S-WH'!$C$2:$C$100,AFA!H35,'BY_S-WH'!$A$2:$A$100,"BASE",'BY_S-WH'!$B$2:$B$100,"AFA") -> 0.02283105 | F35: =Legend!$C$17 -> CS | G35: =G28 -> ELC | H35: ="S-WH-"&F35&"_"&G35&"*" -> S-WH-CS_ELC*
A36: *Water Heat (dual techs)
A37: * | B37: ="S-SH-"&F37&"_"&G37&"*" -> S-SH-PU_COA* | C37: SRVWH-PU | D37: =SUMIFS('BY_S-WH'!$L$2:$L$100,'BY_S-WH'!$C$2:$C$100,AFA!H37,'BY_S-WH'!$A$2:$A$100,"BASE",'BY_S-WH'!$B$2:$B$100,"AFA") -> 0.02283105 | F37: =Legend!$C$18 -> PU | G37: =Legend!B32 -> COA | H37: ="S-WH-"&F37&"_"&G37&"*" -> S-WH-PU_COA*
A38: AFC | B38: ="S-SH-"&F38&"_"&G38&"*" -> S-SH-PU_LPG* | C38: SRVWH-PU | D38: =SUMIFS('BY_S-WH'!$L$2:$L$100,'BY_S-WH'!$C$2:$C$100,AFA!H38,'BY_S-WH'!$A$2:$A$100,"BASE",'BY_S-WH'!$B$2:$B$100,"AFA") -> 0.02283105 | F38: =Legend!$C$18 -> PU | G38: =Legend!B33 -> LPG | H38: ="S-WH-"&F38&"_"&G38&"*" -> S-WH-PU_LPG*
A39: AFC | B39: ="S-SH-"&F39&"_"&G39&"*" -> S-SH-PU_OIL* | C39: SRVWH-PU | D39: =SUMIFS('BY_S-WH'!$L$2:$L$100,'BY_S-WH'!$C$2:$C$100,AFA!H39,'BY_S-WH'!$A$2:$A$100,"BASE",'BY_S-WH'!$B$2:$B$100,"AFA") -> 0.02283105 | F39: =Legend!$C$18 -> PU | G39: =Legend!B34 -> OIL | H39: ="S-WH-"&F39&"_"&G39&"*" -> S-WH-PU_OIL*
A40: AFC | B40: ="S-SH-"&F40&"_"&G40&"*" -> S-SH-PU_GAS* | C40: SRVWH-PU | D40: =SUMIFS('BY_S-WH'!$L$2:$L$100,'BY_S-WH'!$C$2:$C$100,AFA!H40,'BY_S-WH'!$A$2:$A$100,"BASE",'BY_S-WH'!$B$2:$B$100,"AFA") -> 0.02283105 | F40: =Legend!$C$18 -> PU | G40: =Legend!B35 -> GAS | H40: ="S-WH-"&F40&"_"&G40&"*" -> S-WH-PU_GAS*
...

Sheet EFF
A1: EFF for SRV techs
A2: ~TFM_UPD
A3: Attribute | B3: PSET_PN | C3: Cset_CN | D3: AllRegions | F3: Type | G3: Fuel | H3: Reference Tech
A4: *Space Heat
A5: * | B5: ="S-SH-"&F5&"_"&G5&"*" -> S-SH-PU_COA* | C5: SRVSH-PU | D5: ="*"&SUMIFS('BY_S-SH'!$L$2:$L$100,'BY_S-SH'!$C$2:$C$100,EFF!H5,'BY_S-SH'!$A$2:$A$100,"BASE",'BY_S-SH'!$B$2:$B$100,"EFF") -> *0.33 | F5: =Legend!$C$18 -> PU | G5: =Legend!B32 -> COA | H5: ="S-SH-"&F5&"_"&G5&"*" -> S-SH-PU_COA*
A6: CEFF | B6: ="S-SH-"&F6&"_"&G6&"*" -> S-SH-PU_LPG* | C6: SRVSH-PU | D6: ="*"&SUMIFS('BY_S-SH'!$L$2:$L$100,'BY_S-SH'!$C$2:$C$100,EFF!H6,'BY_S-SH'!$A$2:$A$100,"BASE",'BY_S-SH'!$B$2:$B$100,"EFF") -> *0.33 | F6: =Legend!$C$18 -> PU | G6: =Legend!B33 -> LPG | H6: ="S-SH-"&F6&"_"&G6&"*" -> S-SH-PU_LPG*
A7: CEFF | B7: ="S-SH-"&F7&"_"&G7&"*" -> S-SH-PU_OIL* | C7: SRVSH-PU | D7: ="*"&SUMIFS('BY_S-SH'!$L$2:$L$100,'BY_S-SH'!$C$2:$C$100,EFF!H7,'BY_S-SH'!$A$2:$A$100,"BASE",'BY_S-SH'!$B$2:$B$100,"EFF") -> *0.658355844897252 | F7: =Legend!$C$18 -> PU | G7: =Legend!B34 -> OIL | H7: ="S-SH-"&F7&"_"&G7&"*" -> S-SH-PU_OIL*
A8: CEFF | B8: ="S-SH-"&F8&"_"&G8&"*" -> S-SH-PU_GAS* | C8: SRVSH-PU | D8: ="*"&SUMIFS('BY_S-SH'!$L$2:$L$100,'BY_S-SH'!$C$2:$C$100,EFF!H8,'BY_S-SH'!$A$2:$A$100,"BASE",'BY_S-SH'!$B$2:$B$100,"EFF") -> *0.772996170863213 | F8: =Legend!$C$18 -> PU | G8: =Legend!B35 -> GAS | H8: ="S-SH-"&F8&"_"&G8&"*" -> S-SH-PU_GAS*
A9: CEFF | B9: ="S-SH-"&F9&"_"&G9&"*" -> S-SH-PU_BIO* | C9: SRVSH-PU | D9: ="*"&SUMIFS('BY_S-SH'!$L$2:$L$100,'BY_S-SH'!$C$2:$C$100,EFF!H9,'BY_S-SH'!$A$2:$A$100,"BASE",'BY_S-SH'!$B$2:$B$100,"EFF") -> *0.634904433373713 | F9: =Legend!$C$18 -> PU | G9: =Legend!B36 -> BIO | H9: ="S-SH-"&F9&"_"&G9&"*" -> S-SH-PU_BIO*
A10: CEFF | B10: ="S-SH-"&F10&"_"&G10&"*, -*N1" -> S-SH-PU_ELC*, -*N1 | C10: SRVSH-PU | D10: ="*"&SUMIFS('BY_S-SH'!$L$2:$L$100,'BY_S-SH'!$C$2:$C$100,EFF!H10,'BY_S-SH'!$A$2:$A$100,"BASE",'BY_S-SH'!$B$2:$B$100,"EFF") -> *2.1 | F10: =Legend!$C$18 -> PU | G10: =Legend!B39 -> ELC | H10: ="S-SH-"&F10&"_"&G10&"-HP*" -> S-SH-PU_ELC-HP*
A11: CEFF | B11: ="S-SH-"&F11&"_"&G11&"*N1" -> S-SH-PU_ELC*N1 | C11: SRVSH-PU | D11: ="*"&SUMIFS('BY_S-SH'!$L$2:$L$100,'BY_S-SH'!$C$2:$C$100,EFF!H11,'BY_S-SH'!$A$2:$A$100,"BASE",'BY_S-SH'!$B$2:$B$100,"EFF") -> *0.815955112591535 | F11: =Legend!$C$18 -> PU | G11: =Legend!B39 -> ELC | H11: ="S-SH-"&F11&"_"&G11&"_X0" -> S-SH-PU_ELC_X0
A12: CEFF | B12: ="S-SH-"&F12&"_"&G12&"*" -> S-SH-PU_HET* | C12: SRVSH-PU | D12: ="*"&SUMIFS('BY_S-SH'!$L$2:$L$100,'BY_S-SH'!$C$2:$C$100,EFF!H12,'BY_S-SH'!$A$2:$A$100,"BASE",'BY_S-SH'!$B$2:$B$100,"EFF") -> *0.772996170863213 | F12: =Legend!$C$18 -> PU | G12: =Legend!B41 -> HET | H12: =H8 -> S-SH-PU_GAS*
A13: * | B13: ="S-SH-"&F13&"_"&G13&"*" -> S-SH-CS_COA* | C13: SRVSH-CS | D13: ="*"&SUMIFS('BY_S-SH'!$L$2:$L$100,'BY_S-SH'!$C$2:$C$100,EFF!H13,'BY_S-SH'!$A$2:$A$100,"BASE",'BY_S-SH'!$B$2:$B$100,"EFF") -> *0.33 | F13: =Legend!$C$17 -> CS | G13: =G5 -> COA | H13: ="S-SH-"&F13&"_"&G13&"*" -> S-SH-CS_COA*
A14: CEFF | B14: ="S-SH-"&F14&"_"&G14&"*" -> S-SH-CS_LPG* | C14: SRVSH-CS | D14: ="*"&SUMIFS('BY_S-SH'!$L$2:$L$100,'BY_S-SH'!$C$2:$C$100,EFF!H14,'BY_S-SH'!$A$2:$A$100,"BASE",'BY_S-SH'!$B$2:$B$100,"EFF") -> *0.33 | F14: =Legend!$C$17 -> CS | G14: =G6 -> LPG | H14: ="S-SH-"&F14&"_"&G14&"*" -> S-SH-CS_LPG*
A15: CEFF | B15: ="S-SH-"&F15&"_"&G15&"*" -> S-SH-CS_OIL* | C15: SRVSH-CS | D15: ="*"&SUMIFS('BY_S-SH'!$L$2:$L$100,'BY_S-SH'!$C$2:$C$100,EFF!H15,'BY_S-SH'!$A$2:$A$100,"BASE",'BY_S-SH'!$B$2:$B$100,"EFF") -> *0.658355844897252 | F15: =Legend!$C$17 -> CS | G15: =G7 -> OIL | H15: ="S-SH-"&F15&"_"&G15&"*" -> S-SH-CS_OIL*
A16: CEFF | B16: ="S-SH-"&F16&"_"&G16&"*" -> S-SH-CS_GAS* | C16: SRVSH-CS | D16: ="*"&SUMIFS('BY_S-SH'!$L$2:$L$100,'BY_S-SH'!$C$2:$C$100,EFF!H16,'BY_S-SH'!$A$2:$A$100,"BASE",'BY_S-SH'!$B$2:$B$100,"EFF") -> *0.772996170863213 | F16: =Legend!$C$17 -> CS | G16: =G8 -> GAS | H16: ="S-SH-"&F16&"_"&G16&"*" -> S-SH-CS_GAS*
A17: CEFF | B17: ="S-SH-"&F17&"_"&G17&"*" -> S-SH-CS_BIO* | C17: SRVSH-CS | D17: ="*"&SUMIFS('BY_S-SH'!$L$2:$L$100,'BY_S-SH'!$C$2:$C$100,EFF!H17,'BY_S-SH'!$A$2:$A$100,"BASE",'BY_S-SH'!$B$2:$B$100,"EFF") -> *0.634904433373713 | F17: =Legend!$C$17 -> CS | G17: =G9 -> BIO | H17: ="S-SH-"&F17&"_"&G17&"*" -> S-SH-CS_BIO*
A18: CEFF | B18: ="S-SH-"&F18&"_"&G18&"*, -*N1" -> S-SH-CS_ELC*, -*N1 | C18: SRVSH-CS | D18: ="*"&SUMIFS('BY_S-SH'!$L$2:$L$100,'BY_S-SH'!$C$2:$C$100,EFF!H18,'BY_S-SH'!$A$2:$A$100,"BASE",'BY_S-SH'!$B$2:$B$100,"EFF") -> *2.1 | F18: =Legend!$C$17 -> CS | G18: =G10 -> ELC | H18: ="S-SH-"&F18&"_"&G18&"-HP*" -> S-SH-CS_ELC-HP*
A19: CEFF | B19: ="S-SH-"&F19&"_"&G19&"*N1" -> S-SH-CS_ELC*N1 | C19: SRVSH-CS | D19: ="*"&SUMIFS('BY_S-SH'!$L$2:$L$100,'BY_S-SH'!$C$2:$C$100,EFF!H19,'BY_S-SH'!$A$2:$A$100,"BASE",'BY_S-SH'!$B$2:$B$100,"EFF") -> *0.815955112591535 | F19: =Legend!$C$17 -> CS | G19: =G11 -> ELC | H19: ="S-SH-"&F19&"_"&G19&"_X0" -> S-SH-CS_ELC_X0
A20: CEFF | B20: ="S-SH-"&F20&"_"&G20&"*" -> S-SH-CS_HET* | C20: SRVSH-CS | D20: ="*"&SUMIFS('BY_S-SH'!$L$2:$L$100,'BY_S-SH'!$C$2:$C$100,EFF!H20,'BY_S-SH'!$A$2:$A$100,"BASE",'BY_S-SH'!$B$2:$B$100,"EFF") -> *0.772996170863213 | F20: =Legend!$C$17 -> CS | G20: =G12 -> HET | H20: =H16 -> S-SH-CS_GAS*
A21: *Water Heat
A22: * | B22: ="S-WH-"&F22&"_"&G22&"*" -> S-WH-PU_COA* | C22: SRVWH-PU | D22: ="*"&SUMIFS('BY_S-WH'!$L$2:$L$100,'BY_S-WH'!$C$2:$C$100,EFF!H22,'BY_S-WH'!$A$2:$A$100,"BASE",'BY_S-WH'!$B$2:$B$100,"EFF") -> *0.33 | F22: =Legend!$C$18 -> PU | G22: =Legend!B32 -> COA | H22: ="S-WH-"&F22&"_"&G22&"*" -> S-WH-PU_COA*
A23: CEFF | B23: ="S-WH-"&F23&"_"&G23&"*" -> S-WH-PU_LPG* | C23: SRVWH-PU | D23: ="*"&SUMIFS('BY_S-WH'!$L$2:$L$100,'BY_S-WH'!$C$2:$C$100,EFF!H23,'BY_S-WH'!$A$2:$A$100,"BASE",'BY_S-WH'!$B$2:$B$100,"EFF") -> *0.33 | F23: =Legend!$C$18 -> PU | G23: =Legend!B33 -> LPG | H23: ="S-WH-"&F23&"_"&G23&"*" -> S-WH-PU_LPG*
A24: * | B24: ="S-WH-"&F24&"_"&G24&"*" -> S-WH-PU_OIL* | C24: SRVWH-PU | D24: ="*"&SUMIFS('BY_S-WH'!$L$2:$L$100,'BY_S-WH'!$C$2:$C$100,EFF!H24,'BY_S-WH'!$A$2:$A$100,"BASE",'BY_S-WH'!$B$2:$B$100,"EFF") -> *0.598349636734699 | F24: =Legend!$C$18 -> PU | G24: =Legend!B34 -> OIL | H24: ="S-WH-"&F24&"_"&G24&"*" -> S-WH-PU_OIL*
A25: CEFF | B25: ="S-WH-"&F25&"_"&G25&"*" -> S-WH-PU_GAS* | C25: SRVWH-PU | D25: ="*"&SUMIFS('BY_S-WH'!$L$2:$L$100,'BY_S-WH'!$C$2:$C$100,EFF!H25,'BY_S-WH'!$A$2:$A$100,"BASE",'BY_S-WH'!$B$2:$B$100,"EFF") -> *0.630247578537095 | F25: =Legend!$C$18 -> PU | G25: =Legend!B35 -> GAS | H25: ="S-WH-"&F25&"_"&G25&"*" -> S-WH-PU_GAS*
A26: CEFF | B26: ="S-WH-"&F26&"_"&G26&"*" -> S-WH-PU_BIO* | C26: SRVWH-PU | D26: ="*"&SUMIFS('BY_S-WH'!$L$2:$L$100,'BY_S-WH'!$C$2:$C$100,EFF!H26,'BY_S-WH'!$A$2:$A$100,"BASE",'BY_S-WH'!$B$2:$B$100,"EFF") -> *0.33 | F26: =Legend!$C$18 -> PU | G26: =Legend!B36 -> BIO | H26: ="S-WH-"&F26&"_"&G26&"*" -> S-WH-PU_BIO*
A27: CEFF | B27: ="S-WH-"&F27&"_"&G27&"*" -> S-WH-PU_SOL* | C27: SRVWH-PU | D27: ="*"&SUMIFS('BY_S-WH'!$L$2:$L$100,'BY_S-WH'!$C$2:$C$100,EFF!H27,'BY_S-WH'!$A$2:$A$100,"BASE",'BY_S-WH'!$B$2:$B$100,"EFF") -> *1 | F27: =Legend!$C$18 -> PU | G27: =Legend!B38 -> SOL | H27: ="S-WH-"&F27&"_"&G27&"*" -> S-WH-PU_SOL*
A28: CEFF | B28: ="S-WH-"&F28&"_"&G28&"*" -> S-WH-PU_ELC* | C28: SRVWH-PU | D28: ="*"&SUMIFS('BY_S-WH'!$L$2:$L$100,'BY_S-WH'!$C$2:$C$100,EFF!H28,'BY_S-WH'!$A$2:$A$100,"BASE",'BY_S-WH'!$B$2:$B$100,"EFF") -> *0.779153388160945 | F28: =Legend!$C$18 -> PU | G28: =Legend!B39 -> ELC | H28: ="S-WH-"&F28&"_"&G28&"*" -> S-WH-PU_ELC*
A29: * | B29: ="S-WH-"&F29&"_"&G29&"*" -> S-WH-CS_COA* | C29: SRVWH-CS | D29: ="*"&SUMIFS('BY_S-WH'!$L$2:$L$100,'BY_S-WH'!$C$2:$C$100,EFF!H29,'BY_S-WH'!$A$2:$A$100,"BASE",'BY_S-WH'!$B$2:$B$100,"EFF") -> *0.33 | F29: =Legend!$C$17 -> CS | G29: =G22 -> COA | H29: ="S-WH-"&F29&"_"&G29&"*" -> S-WH-CS_COA*
A30: CEFF | B30: ="S-WH-"&F30&"_"&G30&"*" -> S-WH-CS_LPG* | C30: SRVWH-CS | D30: ="*"&SUMIFS('BY_S-WH'!$L$2:$L$100,'BY_S-WH'!$C$2:$C$100,EFF!H30,'BY_S-WH'!$A$2:$A$100,"BASE",'BY_S-WH'!$B$2:$B$100,"EFF") -> *0.33 | F30: =Legend!$C$17 -> CS | G30: =G23 -> LPG | H30: ="S-WH-"&F30&"_"&G30&"*" -> S-WH-CS_LPG*
A31: * | B31: ="S-WH-"&F31&"_"&G31&"*" -> S-WH-CS_OIL* | C31: SRVWH-CS | D31: ="*"&SUMIFS('BY_S-WH'!$L$2:$L$100,'BY_S-WH'!$C$2:$C$100,EFF!H31,'BY_S-WH'!$A$2:$A$100,"BASE",'BY_S-WH'!$B$2:$B$100,"EFF") -> *0.598349636734699 | F31: =Legend!$C$17 -> CS | G31: =G24 -> OIL | H31: ="S-WH-"&F31&"_"&G31&"*" -> S-WH-CS_OIL*
A32: CEFF | B32: ="S-WH-"&F32&"_"&G32&"*" -> S-WH-CS_GAS* | C32: SRVWH-CS | D32: ="*"&SUMIFS('BY_S-WH'!$L$2:$L$100,'BY_S-WH'!$C$2:$C$100,EFF!H32,'BY_S-WH'!$A$2:$A$100,"BASE",'BY_S-WH'!$B$2:$B$100,"EFF") -> *0.630247578537095 | F32: =Legend!$C$17 -> CS | G32: =G25 -> GAS | H32: ="S-WH-"&F32&"_"&G32&"*" -> S-WH-CS_GAS*
A33: CEFF | B33: ="S-WH-"&F33&"_"&G33&"*" -> S-WH-CS_BIO* | C33: SRVWH-CS | D33: ="*"&SUMIFS('BY_S-WH'!$L$2:$L$100,'BY_S-WH'!$C$2:$C$100,EFF!H33,'BY_S-WH'!$A$2:$A$100,"BASE",'BY_S-WH'!$B$2:$B$100,"EFF") -> *0.33 | F33: =Legend!$C$17 -> CS | G33: =G26 -> BIO | H33: ="S-WH-"&F33&"_"&G33&"*" -> S-WH-CS_BIO*
A34: CEFF | B34: ="S-WH-"&F34&"_"&G34&"*" -> S-WH-CS_SOL* | C34: SRVWH-CS | D34: ="*"&SUMIFS('BY_S-WH'!$L$2:$L$100,'BY_S-WH'!$C$2:$C$100,EFF!H34,'BY_S-WH'!$A$2:$A$100,"BASE",'BY_S-WH'!$B$2:$B$100,"EFF") -> *1 | F34: =Legend!$C$17 -> CS | G34: =G27 -> SOL | H34: ="S-WH-"&F34&"_"&G34&"*" -> S-WH-CS_SOL*
A35: CEFF | B35: ="S-WH-"&F35&"_"&G35&"*" -> S-WH-CS_ELC* | C35: SRVWH-CS | D35: ="*"&SUMIFS('BY_S-WH'!$L$2:$L$100,'BY_S-WH'!$C$2:$C$100,EFF!H35,'BY_S-WH'!$A$2:$A$100,"BASE",'BY_S-WH'!$B$2:$B$100,"EFF") -> *0.779153388160945 | F35: =Legend!$C$17 -> CS | G35: =G28 -> ELC | H35: ="S-WH-"&F35&"_"&G35&"*" -> S-WH-CS_ELC*
A36: *Water Heat (dual techs)
A37: * | B37: ="S-SH-"&F37&"_"&G37&"*" -> S-SH-PU_COA* | C37: SRVWH-PU | D37: ="*"&SUMIFS('BY_S-WH'!$L$2:$L$100,'BY_S-WH'!$C$2:$C$100,EFF!H37,'BY_S-WH'!$A$2:$A$100,"BASE",'BY_S-WH'!$B$2:$B$100,"EFF") -> *0.33 | F37: =Legend!$C$18 -> PU | G37: =Legend!B32 -> COA | H37: ="S-WH-"&F37&"_"&G37&"*" -> S-WH-PU_COA*
A38: CEFF | B38: ="S-SH-"&F38&"_"&G38&"*" -> S-SH-PU_LPG* | C38: SRVWH-PU | D38: ="*"&SUMIFS('BY_S-WH'!$L$2:$L$100,'BY_S-WH'!$C$2:$C$100,EFF!H38,'BY_S-WH'!$A$2:$A$100,"BASE",'BY_S-WH'!$B$2:$B$100,"EFF") -> *0.33 | F38: =Legend!$C$18 -> PU | G38: =Legend!B33 -> LPG | H38: ="S-WH-"&F38&"_"&G38&"*" -> S-WH-PU_LPG*
A39: CEFF | B39: ="S-SH-"&F39&"_"&G39&"*" -> S-SH-PU_OIL* | C39: SRVWH-PU | D39: ="*"&SUMIFS('BY_S-WH'!$L$2:$L$100,'BY_S-WH'!$C$2:$C$100,EFF!H39,'BY_S-WH'!$A$2:$A$100,"BASE",'BY_S-WH'!$B$2:$B$100,"EFF") -> *0.598349636734699 | F39: =Legend!$C$18 -> PU | G39: =Legend!B34 -> OIL | H39: ="S-WH-"&F39&"_"&G39&"*" -> S-WH-PU_OIL*
A40: CEFF | B40: ="S-SH-"&F40&"_"&G40&"*" -> S-SH-PU_GAS* | C40: SRVWH-PU | D40: ="*"&SUMIFS('BY_S-WH'!$L$2:$L$100,'BY_S-WH'!$C$2:$C$100,EFF!H40,'BY_S-WH'!$A$2:$A$100,"BASE",'BY_S-WH'!$B$2:$B$100,"EFF") -> *0.630247578537095 | F40: =Legend!$C$18 -> PU | G40: =Legend!B35 -> GAS | H40: ="S-WH-"&F40&"_"&G40&"*" -> S-WH-PU_GAS*
...

Sheet FillTable
B1: Fill Table to capture Base-Year Efficiencies
B3: ~TFM_Fill-R: w=BY_S-SH; Hcol=Region
B4: Scenario | C4: LimType | D4: Attribute | E4: Year | F4: AllRegions | G4: Pset_CI | H4: Pset_PN | I4: Pset_CO | J4: Cset_CN
B5: BASE | D5: AFA | E5: 2018 | F5: 1 | H5: S-SH*
B6: BASE | D6: EFF | E6: 2018 | F6: 1 | H6: S-SH*
B8: ~TFM_Fill-R: w=BY_S-WH; Hcol=Region
B9: Scenario | C9: LimType | D9: Attribute | E9: Year | F9: AllRegions | G9: Pset_CI | H9: Pset_PN | I9: Pset_CO | J9: Cset_CN
B10: BASE | D10: AFA | E10: 2018 | F10: 1 | H10: S-WH*
B11: BASE | D11: EFF | E11: 2018 | F11: 1 | H11: S-WH*
B13: ~TFM_Fill-R: w=BY_S-SC; Hcol=Region
B14: Scenario | C14: LimType | D14: Attribute | E14: Year | F14: AllRegions | G14: Pset_CI | H14: Pset_PN | I14: Pset_CO | J14: Cset_CN
B15: BASE | D15: AFA | E15: 2018 | F15: 1 | H15: S-SC*
B16: BASE | D16: EFF | E16: 2018 | F16: 1 | H16: S-SC*
B18: ~TFM_Fill-R: w=BY_S-EAP; Hcol=Region
B19: Scenario | C19: LimType | D19: Attribute | E19: Year | F19: AllRegions | G19: Pset_CI | H19: Pset_PN | I19: Pset_CO | J19: Cset_CN
B20: BASE | D20: EFF | E20: 2018 | F20: 1 | H20: S-LIG*, S-REF*, S-OEL*, S-PLIG*
B21: BASE | D21: Stock | E21: 2018 | F21: 1 | H21: S-PLIG*

Sheet Regions
C3: {=INDEX(C5:C7,$A$4)} -> IE | D3: {=INDEX(D5:D7,$A$4)} -> National | E3: {=INDEX(E5:E7,$A$4)} -> IE-CW | F3: {=INDEX(F5:F7,$A$4)} -> IE-D | G3: {=INDEX(G5:G7,$A$4)} -> IE-KE | H3: {=INDEX(H5:H7,$A$4)} -> IE-KK | I3: {=INDEX(I5:I7,$A$4)} -> IE-LS | J3: {=INDEX(J5:J7,$A$4)} -> IE-LD | ... AD3: {=INDEX(AD5:AD7,$A$4)} -> IE-MN
A4: 1
A5: Development | C5: IE | D5: National | E5: =Regions!A11 -> IE-CW | F5: =Regions!A16 -> IE-D | G5: =Regions!A19 -> IE-KE | H5: =Regions!A20 -> IE-KK | I5: =Regions!A21 -> IE-LS | J5: =Regions!A24 -> IE-LD | K5: =Regions!A25 -> IE-LH | L5: =Regions!A27 -> IE-MH | M5: =Regions!A29 -> IE-OY | N5: =Regions!A34 -> IE-WH | O5: =Regions!A35 -> IE-WX | P5: =Regions!A36 -> IE-WW | Q5: =Regions!A13 -> IE-CE | R5: =Regions!A14 -> IE-CO | S5: =Regions!A18 -> IE-KY | T5: =Regions!A23 -> IE-LK | U5: =Regions!A32 -> IE-TA | V5: =Regions!A33 -> IE-WD | W5: =Regions!A17 -> IE-G | X5: =Regions!A22 -> IE-LM | Y5: =Regions!A26 -> IE-MO | Z5: =Regions!A30 -> IE-RN | AA5: =Regions!A31 -> IE-SO | AB5: =Regions!A12 -> IE-CN | AC5: =Regions!A15 -> IE-DL | AD5: =Regions!A28 -> IE-MN
A6: Single-region | C6: =C5 -> IE | D6: ="*"&D5 -> *National | E6: ="*"&E5 -> *IE-CW | F6: ="*"&F5 -> *IE-D | G6: ="*"&G5 -> *IE-KE | H6: ="*"&H5 -> *IE-KK | I6: ="*"&I5 -> *IE-LS | J6: ="*"&J5 -> *IE-LD | K6: ="*"&K5 -> *IE-LH | ... AD6: ="*"&AD5 -> *IE-MN
A7: Multi-region | C7: ="*"&C5 -> *IE | D7: =D5 -> National | E7: =E5 -> IE-CW | F7: =F5 -> IE-D | G7: =G5 -> IE-KE | H7: =H5 -> IE-KK | I7: =I5 -> IE-LS | J7: =J5 -> IE-LD | K7: =K5 -> IE-LH | ... AD7: =AD5 -> IE-MN
A10: Code | B10: County name
A11: IE-CW | B11: Carlow
A12: IE-CN | B12: Cavan
A13: IE-CE | B13: Clare
A14: IE-CO | B14: Cork
A15: IE-DL | B15: Donegal
A16: IE-D | B16: Dublin
A17: IE-G | B17: Galway
A18: IE-KY | B18: Kerry
A19: IE-KE | B19: Kildare
A20: IE-KK | B20: Kilkenny
A21: IE-LS | B21: Laois
... A36: IE-WW | B36: Wicklow
A37: Source: https://en.wikipedia.org/wiki/ISO_3166-2:IE

Sheet TechSelection
B3: ~TFM_AVA
B4: PSET_SET | C4: PSET_PN | D4: PSET_PD | E4: PSET_CO | F4: PSET_CI | G4: Allregions | H4: =Regions!C3 -> IE | I4: =Regions!D3 -> National
C5: * | G5: 0 | H5: 1 | I5: 1

Sheet BY_S-SH
A1: scenario | B1: attribute | C1: process | D1: commodity | E1: lim_type | F1: time_slice | G1: year | H1: commodity_group | I1: currency | J1: stage | K1: sow | L1: IE | M1: National | N1: year2
A2: BASE | B2: AFA | C2: S-SH-CS_BIO_X0 | D2: - | E2: UP | F2: - | G2: 2018 | H2: - | I2: - | J2: - | K2: - | L2: 0.11415525 | M2: 0.11415525 | N2: -
A3: BASE | B3: AFA | C3: S-SH-CS_COA_X0 | D3: - | E3: UP | F3: - | G3: 2018 | H3: - | I3: - | J3: - | K3: - | L3: 0.11415525 | M3: 0.11415525 | N3: -
A4: BASE | B4: AFA | C4: S-SH-CS_ELC-HP_X0 | D4: - | E4: UP | F4: - | G4: 2018 | H4: - | I4: - | J4: - | K4: - | L4: 0.11415525 | M4: 0.11415525 | N4: -
A5: BASE | B5: AFA | C5: S-SH-CS_ELC_X0 | D5: - | E5: UP | F5: - | G5: 2018 | H5: - | I5: - | J5: - | K5: - | L5: 0.11415525 | M5: 0.11415525 | N5: -
A6: BASE | B6: AFA | C6: S-SH-CS_GAS_X0 | D6: - | E6: UP | F6: - | G6: 2018 | H6: - | I6: - | J6: - | K6: - | L6: 0.11415525 | M6: 0.11415525 | N6: -
A7: BASE | B7: AFA | C7: S-SH-CS_LPG_X0 | D7: - | E7: UP | F7: - | G7: 2018 | H7: - | I7: - | J7: - | K7: - | L7: 0.11415525 | M7: 0.11415525 | N7: -
A8: BASE | B8: AFA | C8: S-SH-CS_OIL_X0 | D8: - | E8: UP | F8: - | G8: 2018 | H8: - | I8: - | J8: - | K8: - | L8: 0.11643836 | M8: 0.11643836 | N8: -
A9: BASE | B9: AFA | C9: S-SH-CS_SOL_X0 | D9: - | E9: UP | F9: - | G9: 2018 | H9: - | I9: - | J9: - | K9: - | L9: 0.11415525 | M9: 0.11415525 | N9: -
A10: BASE | B10: AFA | C10: S-SH-PU_BIO_X0 | D10: - | E10: UP | F10: - | G10: 2018 | H10: - | I10: - | J10: - | K10: - | L10: 0.11415525 | M10: 0.11415525 | N10: -
A11: BASE | B11: AFA | C11: S-SH-PU_COA_X0 | D11: - | E11: UP | F11: - | G11: 2018 | H11: - | I11: - | J11: - | K11: - | L11: 0.11415525 | M11: 0.11415525 | N11: -
A12: BASE | B12: AFA | C12: S-SH-PU_ELC-HP_X0 | D12: - | E12: UP | F12: - | G12: 2018 | H12: - | I12: - | J12: - | K12: - | L12: 0.11415525 | M12: 0.11415525 | N12: -
A13: BASE | B13: AFA | C13: S-SH-PU_ELC_X0 | D13: - | E13: UP | F13: - | G13: 2018 | H13: - | I13: - | J13: - | K13: - | L13: 0.11415525 | M13: 0.11415525 | N13: -
... A33: BASE | B33: EFF | C33: S-SH-PU_SOL_X0 | D33: - | E33: - | F33: ANNUAL | G33: 2018 | H33: - | I33: - | J33: - | K33: - | L33: 0.33 | M33: 0.33 | N33: -

Sheet BY_S-WH
A1: scenario | B1: attribute | C1: process | D1: commodity | E1: lim_type | F1: time_slice | G1: year | H1: commodity_group | I1: currency | J1: stage | K1: sow | L1: IE | M1: National | N1: year2
A2: BASE | B2: AFA | C2: S-WH-CS_BIO_X0 | D2: - | E2: UP | F2: - | G2: 2018 | H2: - | I2: - | J2: - | K2: - | L2: 0.02283105 | M2: 0.02283105 | N2: -
A3: BASE | B3: AFA | C3: S-WH-CS_COA_X0 | D3: - | E3: UP | F3: - | G3: 2018 | H3: - | I3: - | J3: - | K3: - | L3: 0.02283105 | M3: 0.02283105 | N3: -
A4: BASE | B4: AFA | C4: S-WH-CS_ELC_X0 | D4: - | E4: UP | F4: - | G4: 2018 | H4: - | I4: - | J4: - | K4: - | L4: 0.02283105 | M4: 0.02283105 | N4: -
A5: BASE | B5: AFA | C5: S-WH-CS_GAS_X0 | D5: - | E5: UP | F5: - | G5: 2018 | H5: - | I5: - | J5: - | K5: - | L5: 0.02283105 | M5: 0.02283105 | N5: -
A6: BASE | B6: AFA | C6: S-WH-CS_LPG_X0 | D6: - | E6: UP | F6: - | G6: 2018 | H6: - | I6: - | J6: - | K6: - | L6: 0.02283105 | M6: 0.02283105 | N6: -
A7: BASE | B7: AFA | C7: S-WH-CS_OIL_X0 | D7: - | E7: UP | F7: - | G7: 2018 | H7: - | I7: - | J7: - | K7: - | L7: 0.023287671 | M7: 0.023287671 | N7: -
A8: BASE | B8: AFA | C8: S-WH-CS_SOL_X0 | D8: - | E8: UP | F8: - | G8: 2018 | H8: - | I8: - | J8: - | K8: - | L8: 0.02283105 | M8: 0.02283105 | N8: -
A9: BASE | B9: AFA | C9: S-WH-PU_BIO_X0 | D9: - | E9: UP | F9: - | G9: 2018 | H9: - | I9: - | J9: - | K9: - | L9: 0.02283105 | M9: 0.02283105 | N9: -
A10: BASE | B10: AFA | C10: S-WH-PU_COA_X0 | D10: - | E10: UP | F10: - | G10: 2018 | H10: - | I10: - | J10: - | K10: - | L10: 0.02283105 | M10: 0.02283105 | N10: -
A11: BASE | B11: AFA | C11: S-WH-PU_ELC_X0 | D11: - | E11: UP | F11: - | G11: 2018 | H11: - | I11: - | J11: - | K11: - | L11: 0.02283105 | M11: 0.02283105 | N11: -
A12: BASE | B12: AFA | C12: S-WH-PU_GAS_X0 | D12: - | E12: UP | F12: - | G12: 2018 | H12: - | I12: - | J12: - | K12: - | L12: 0.02283105 | M12: 0.02283105 | N12: -
A13: BASE | B13: AFA | C13: S-WH-PU_LPG_X0 | D13: - | E13: UP | F13: - | G13: 2018 | H13: - | I13: - | J13: - | K13: - | L13: 0.02283105 | M13: 0.02283105 | N13: -
... A29: BASE | B29: EFF | C29: S-WH-PU_SOL_X0 | D29: - | E29: - | F29: ANNUAL | G29: 2018 | H29: - | I29: - | J29: - | K29: - | L29: 1 | M29: 1 | N29: -

Sheet BY_S-SC
A1: scenario | B1: attribute | C1: process | D1: commodity | E1: lim_type | F1: time_slice | G1: year | H1: commodity_group | I1: currency | J1: stage | K1: sow | L1: IE | M1: National | N1: year2
A2: BASE | B2: AFA | C2: S-SC-CS_ELC_X0 | D2: - | E2: UP | F2: - | G2: 2018 | H2: - | I2: - | J2: - | K2: - | L2: 0.034246575 | M2: 0.034246575 | N2: -
A3: BASE | B3: AFA | C3: S-SC-CS_GAS_X0 | D3: - | E3: UP | F3: - | G3: 2018 | H3: - | I3: - | J3: - | K3: - | L3: 0.034246575 | M3: 0.034246575 | N3: -
A4: BASE | B4: AFA | C4: S-SC-PU_ELC_X0 | D4: - | E4: UP | F4: - | G4: 2018 | H4: - | I4: - | J4: - | K4: - | L4: 0.034246575 | M4: 0.034246575 | N4: -
A5: BASE | B5: AFA | C5: S-SC-PU_GAS_X0 | D5: - | E5: UP | F5: - | G5: 2018 | H5: - | I5: - | J5: - | K5: - | L5: 0.034246575 | M5: 0.034246575 | N5: -
A6: BASE | B6: EFF | C6: S-SC-CS_ELC_X0 | D6: - | E6: - | F6: ANNUAL | G6: 2018 | H6: - | I6: - | J6: - | K6: - | L6: 2.7466472 | M6: 2.7466472 | N6: -
A7: BASE | B7: EFF | C7: S-SC-CS_GAS_X0 | D7: - | E7: - | F7: ANNUAL | G7: 2018 | H7: - | I7: - | J7: - | K7: - | L7: 2.7679849 | M7: 2.7679849 | N7: -
A8: BASE | B8: EFF | C8: S-SC-PU_ELC_X0 | D8: - | E8: - | F8: ANNUAL | G8: 2018 | H8: - | I8: - | J8: - | K8: - | L8: 2.7466472 | M8: 2.7466472 | N8: -
A9: BASE | B9: EFF | C9: S-SC-PU_GAS_X0 | D9: - | E9: - | F9: ANNUAL | G9: 2018 | H9: - | I9: - | J9: - | K9: - | L9: 2.7679849 | M9: 2.7679849 | N9: -

Sheet BY_S-EAP
A1: scenario | B1: attribute | C1: process | D1: commodity | E1: lim_type | F1: time_slice | G1: year | H1: commodity_group | I1: currency | J1: stage | K1: sow | L1: IE | M1: National | N1: year2
A2: BASE | B2: EFF | C2: S-LIG-CS_ELC_X0 | D2: - | E2: - | F2: ANNUAL | G2: 2018 | H2: - | I2: - | J2: - | K2: - | L2: 2.4973572 | M2: 2.4973572 | N2: -
A3: BASE | B3: EFF | C3: S-LIG-PU_ELC_X0 | D3: - | E3: - | F3: ANNUAL | G3: 2018 | H3: - | I3: - | J3: - | K3: - | L3: 4.3260777 | M3: 4.3260777 | N3: -
A4: BASE | B4: EFF | C4: S-OEL-CS_ELC_X0 | D4: - | E4: - | F4: ANNUAL | G4: 2018 | H4: - | I4: - | J4: - | K4: - | L4: 1 | M4: 1 | N4: -
A5: BASE | B5: EFF | C5: S-OEL-PU_ELC_X0 | D5: - | E5: - | F5: ANNUAL | G5: 2018 | H5: - | I5: - | J5: - | K5: - | L5: 1 | M5: 1 | N5: -
A6: BASE | B6: EFF | C6: S-PLIG-PU_X1 | D6: - | E6: - | F6: ANNUAL | G6: 2018 | H6: - | I6: - | J6: - | K6: - | L6: 0.48784295 | M6: 0.48784295 | N6: -
A7: BASE | B7: EFF | C7: S-PLIG-PU_X2 | D7: - | E7: - | F7: ANNUAL | G7: 2018 | H7: - | I7: - | J7: - | K7: - | L7: 0.37305638 | M7: 0.37305638 | N7: -
A8: BASE | B8: EFF | C8: S-PLIG-PU_X3 | D8: - | E8: - | F8: ANNUAL | G8: 2018 | H8: - | I8: - | J8: - | K8: - | L8: 0.31709792 | M8: 0.31709792 | N8: -
A9: BASE | B9: EFF | C9: S-PLIG-PU_X4 | D9: - | E9: - | F9: ANNUAL | G9: 2018 | H9: - | I9: - | J9: - | K9: - | L9: 1.2683917 | M9: 1.2683917 | N9: -
A10: BASE | B10: EFF | C10: S-REF-CS_ELC_X0 | D10: - | E10: - | F10: ANNUAL | G10: 2018 | H10: - | I10: - | J10: - | K10: - | L10: 33.491554 | M10: 33.491554 | N10: -
A11: BASE | B11: EFF | C11: S-REF-PU_ELC_X0 | D11: - | E11: - | F11: ANNUAL | G11: 2018 | H11: - | I11: - | J11: - | K11: - | L11: 58.016156 | M11: 58.016156 | N11: -
A12: BASE | B12: Stock | C12: S-PLIG-PU_X1 | D12: - | E12: - | F12: - | G12: 2018 | H12: - | I12: - | J12: - | K12: - | L12: 0.0192 | M12: 0.0192 | N12: -
A13: BASE | B13: Stock | C13: S-PLIG-PU_X2 | D13: - | E13: - | F13: - | G13: 2018 | H13: - | I13: - | J13: - | K13: - | L13: 0.072 | M13: 0.072 | N13: -
... A15: BASE | B15: Stock | C15: S-PLIG-PU_X4 | D15: - | E15: - | F15: - | G15: 2018 | H15: - | I15: - | J15: - | K15: - | L15: 0.0048 | M15: 0.0048 | N15: -
