Workbook
Name FID_1: [1]AGR_Fuels!$A$2

Sheet Cover
C1: TIMLEAF Model
A4: Document type: | B4: New Technologies
A5: Sector(s): | B5: Agricultural sector (AGR)
A6: Purpose: | B6: Define processes in agr for methane abatement
A8: Original developer(s): | B8: Neha Jaggeshar (Neha.Jaggeshar@ucc.ie)
A11: Current maintainer(s): | B11: Neha Jaggeshar (Neha.Jaggeshar@ucc.ie)
A14: Part of TIMLEAF version | B14: 1
A15: Model repository:
A16: Licence:
A19: Technologies included: | B19: Low emission slurry spreading (LESS)
B20: Manure storage cover (MSC)
B21: Clover Inclusion

Sheet LESS 
E3: ~FI_T
B4: TechName | C4: *TechDesc | D4: Comm-IN | E4: Comm-OUT | F4: Input | G4: Output | H4: Start | I4: AF | J4: Life | K4: CAP2ACT | L4: ENV_ACT~AGRLIVCH4 | M4: ENV_ACT~AGRLIVN2O | N4: VAROM
B5: *Technology Name | C5: Technology Description | D5: Input (Land in Mha and Energy in PJ) | E5: Output Commodity | J5: years | K5: Capacity to Activity Factor | L5: kt per Mhead (activity based) | N5: MEUR/Mhead
B6: ALIVCAT101 | C6: Dairy cattle rearing + LESS | D6: APASCAT1 | F6: 7e-05 | H6: 2021 | I6: 1 | J6: 1 | K6: 5716 | L6: 0.0228 | M6: 0.00021
D7: ANRGCAT1 | F7: 0.0003
E8: ADCAT | G8: 1
E9: ACATMAN | G9: 0.0009
B10: ALIVCAT201 | C10: Non diary cattle rearing + LESS | D10: APASCAT2 | F10: 0.4 | H10: 2021 | I10: 1 | J10: 1 | K10: 1 | L10: 49.48 | M10: 0.48598
D11: ANRGCAT2 | F11: 1.11
E12: ANDCAT | G12: 1
E13: ACATMAN | G13: 7.118
B14: ALIVSHE101 | C14: Sheep rearing + LESS | D14: APASSHE | F14: 0.13 | H14: 2025 | I14: 1 | J14: 1 | K14: 1 | L14: 7.85 | M14: 0.0253
D15: ANRGSHE | F15: 0.16
E16: ASHE | G16: 1
E17: ASHEMAN | G17: 0.364
D25: LESS - low emission slurry spreading
C26: ~FI_Process
B27: Sets | C27: Region | D27: TechName | E27: TechDesc | F27: Tact | G27: Tcap | H27: Tslvl | I27: PrimaryCG | J27: Vintage
B28: *Process Set Membership | C28: Region Name | D28: Technology Name | E28: Technology Description | F28: Activity Unit | G28: Capacity Unit | H28: TimeSlice level of Process Activity | I28: Primary Commodity Group | J28: Vintage Tracking
B29: PRE | C29: IE,National | D29: ALIVCAT101 | E29: Dairy cattle rearing + LESS | F29: Mlitre | G29: Mhead | J29: NO
C30: IE,National | D30: ALIVCAT201 | E30: Non diary cattle rearing + LESS | F30: Mhead | G30: Mhead | J30: NO
C31: IE,National | D31: ALIVSHE101 | E31: Sheep rearing + LESS | F31: Mhead | G31: Mhead | J31: NO
C32: IE,National | D32: ALIVPIG101 | E32: Pigs rearing + LESS | F32: Mhead | G32: Mhead | J32: NO
C33: IE,National | D33: ALIVOTH101 | E33: Other animals rearing + LESS | F33: Mhead | G33: Mhead | J33: NO

Sheet MSC
A4: ~FI_Process
A5: Sets | B5: TechName | C5: TechDesc | D5: Tact | E5: Tcap | F5: Tslvl | G5: PrimaryCG | H5: Vintage
A6: \I: Process Set Membership | B6: Technology Name | C6: Technology Description | D6: Activity Unit | E6: Capacity Unit | F6: Timeslice Operational Level | G6: Operational Commodity Group | H6: Vintage Tracking
A7: PRE | B7: ALIVCAT103 | C7: Dairy cattle - Manure storage cover | D7: Mlitre | E7: Mhead | H7: NO
B8: ALIVCAT203 | C8: Non Dairy cattle - Manure storage cover | D8: Mhead | E8: Mhead | H8: NO
B9: ALIVSHE103 | C9: Sheep - Manure storage cover | D9: Mhead | E9: Mhead | H9: NO
B15: *Notes - Manure cover is already widely used around in ireland - as per EUROSTAT data almost 80% of famrs using it
D19: ~FI_T
A20: TechName | B20: *TechDesc | C20: Comm-IN | D20: Comm-OUT | E20: Input | F20: Output | G20: CAP2ACT | H20: AF | I20: ENV_ACT~AGRLIVCH4 | J20: ENV_ACT~AGRLIVN2O | K20: Start | L20: VAROM | M20: Life
A21: Technology Name | B21: Technology Description | L21: MEUR/Mhead
A22: =B7 -> ALIVCAT103 | B22: =C7 -> Dairy cattle - Manure storage cover | C22: APASCAT1 | E22: 7e-05 | G22: 5716 | H22: 1 | I22: =EF!D39/5716 -> 0.022531491 | J22: =EF!E39/MSC!G22 -> 0.00037788663 | K22: 2021 | M22: 10
C23: ANRGCAT1 | E23: 0.0003
D24: ADCAT | F24: 1
D25: ACATMAN | F25: 0.001
A26: =B8 -> ALIVCAT203 | B26: =C8 -> Non Dairy cattle - Manure storage cover | C26: APASCAT2 | E26: 0.4 | G26: 1 | H26: 1 | I26: =EF!D40 -> 48.77 | J26: =EF!E40 -> 0.88 | K26: 2021 | M26: 10
C27: ANRGCAT2 | E27: 1.11
D28: ANDCAT | F28: 1
D29: ACATMAN | F29: 7.118
A30: =B9 -> ALIVSHE103 | B30: =C9 -> Sheep - Manure storage cover | C30: APASSHE | E30: 0.13 | G30: 1 | H30: 1 | I30: =EF!D41 -> 7.75 | J30: =EF!E41 -> 0.05 | K30: 2021 | M30: 10
C31: ANRGSHE | E31: 0.16
D32: ASHE | F32: 1
D33: ASHEMAN | F33: 0.364

Sheet Clover Inclusion
E3: ~FI_T
B4: TechName | C4: *TechDesc | D4: Comm-IN | E4: Comm-OUT | F4: Input | G4: Input~2040 | H4: Input~2050 | I4: Output | J4: Output~2025 | K4: Output~2035 | L4: Start | M4: AF | N4: Life | O4: CAP2ACT | P4: ENV_ACT~AGRLIVN2O | Q4: VAROM | R4: FIXOM
B5: *Technology Name | C5: Technology Description | D5: Input (Land in Mha and Energy in PJ) | E5: Output Commodity | N5: years | O5: Capacity to Activity Factor | P5: kt per Mhead (activity based) | Q5: MEUR/Mha | R5: MEUR/Mha
B6: =D17 -> APASCAT100_Clover | C6: =E17 -> Dairy pasture - clover inclusion | D6: GRALAND_use | E6: APASCAT1 | F6: 1 | I6: 1 | L6: 2021 | M6: 1 | N6: 5 | O6: 1 | P6: =EF!E76 -> 1.1544
B7: =D18 -> APASCAT200_Clover | C7: =E18 -> Nondairy pasture - clover inclusion | D7: GRALAND_use | E7: APASCAT2 | F7: 1 | I7: 1 | L7: 2021 | M7: 1 | N7: 5 | O7: 1 | P7: =EF!E77 -> 0.732
B8: =D19 -> APASSHE100_Clover | C8: =E19 -> Sheep pasture - clover inclusion | D8: GRALAND_use | E8: APASSHE | F8: 1 | I8: 1 | L8: 2021 | M8: 1 | N8: 5 | O8: 1 | P8: =EF!E78 -> 0.996
C14: ~FI_Process
B15: Sets | C15: Region | D15: TechName | E15: TechDesc | F15: Tact | G15: Tcap | H15: Tslvl | I15: PrimaryCG | J15: Vintage
B16: *Process Set Membership | C16: Region Name | D16: Technology Name | E16: Technology Description | F16: Activity Unit | G16: Capacity Unit | H16: TimeSlice level of Process Activity | I16: Primary Commodity Group | J16: Vintage Tracking
B17: PRE | C17: IE,National | D17: APASCAT100_Clover | E17: Dairy pasture - clover inclusion | F17: Mha | G17: Mha | J17: NO
C18: IE,National | D18: APASCAT200_Clover | E18: Nondairy pasture - clover inclusion | F18: Mha | G18: Mha | J18: NO
C19: IE,National | D19: APASSHE100_Clover | E19: Sheep pasture - clover inclusion | F19: Mha | G19: Mha | J19: NO
C28: Adoption rate
B29: clover inclusion on farms | C29: 2018 | D29: 2025 | E29: 2035 | F29: 2040 | G29: 2050 | H29: 2070
B30: Dairy | C30: 0.1 | D30: 0.15 | E30: 0.2 | F30: 0.25 | G30: 0.3 | H30: 0.4
B31: Non dairy | C31: 0.1 | D31: 0.15 | E31: 0.2 | F31: 0.25 | G31: 0.3 | H31: 0.4
B32: sheep | C32: 0.05 | D32: 0.1 | E32: 0.15 | F32: 0.2 | G32: 0.25 | H32: 0.3

Sheet EF
B2: Year 2018 | D2: CH4 emissions | E2: CH4 emissions | F2: CH4 emissions | G2: CH4 emissions | I2: N20 emissions | J2: N20 emissions | L2: EF CH4 | M2: EF N20 | O2: EF N20 left on pasture
D3: enteric fermentation ktCH4 /Mhead | E3: enteric fermentation ktCH4 | F3: manure management (MM)ktCH4 / Mhead | G3: MM ktCH4 | I3: Manure management + manure applied to soils ktN20/ Mhead | J3: Manure management + applied to soils ktN20 | L3: KtCH4/Mhead | M3: KtN20/Mhead | O3: KtN20 / Mha
A4: Animal stock | B4: Mhead
A5: Dairy Cattle | B5: 1.425 | D5: 117.4 | E5: 167.295 | F5: 12.94 | G5: 18.4395 | I5: 2.1629 | J5: 3.0821325 | L5: 130.34 | M5: 2.1629 | O5: 1.924
A6: Non dairy cattle | B6: 5.836 | D6: 43.6 | E6: 254.4496 | F6: 5.88 | G6: 34.31568 | I6: 0.8836 | J6: 5.1566896 | L6: 49.48 | M6: 0.8836 | O6: 1.22
A7: Sheep | B7: 5.1477 | D7: 6.99 | E7: 35.982423 | F7: 0.86 | G7: 4.427022 | I7: 0.046 | J7: 0.2367942 | L7: 7.85 | M7: 0.046 | O7: 1.66
A8: Pig | B8: 1.597 | D8: 1.2 | E8: 1.9164 | F8: 13.06 | G8: 20.85682 | I8: 0.014737 | J8: 0.023534989 | L8: 14.26 | M8: 0.014737 | O8: 0
A9: Poultry | B9: 17.384 | D9: 0 | E9: 0 | F9: 0.22 | G9: 3.82448 | I9: 0.26486 | J9: 4.6043262 | L9: 0.22 | M9: 0.26486 | O9: 0
A10: Other | B10: 0.224 | D10: 0.1 | E10: 0.0224 | F10: 1.128 | G10: 0.252672 | I10: 0.01736 | J10: 0.00388864 | L10: 1.228 | M10: 0.01736 | O10: 1.5
D13: CH4 | E13: N20 | G13: Species | H13: Cost (MEUR/Ktco2EQ)
A14: Acidification | C14: ACD | D14: 0.74 | H14: LESS | I14: CLOVER | J14: MSC | K14: ACD | L14: Methane Inhibitors
G15: Dairy Cattle | H15: 0.175 | I15: -0.11 | J15: -0.11 | K15: 0.32 | L15: 0.215
A16: Animal stock | C16: NEW EF | D16: EF CH4 | E16: EF N20 | G16: Non dairy cattle | H16: 0.175 | I16: -0.11 | J16: -0.11 | K16: 0.32 | L16: 0.215
A17: Dairy Cattle | D17: 120.76 | E17: 2.16 | G17: Sheep | H17: 0.175 | I17: -0.11 | J17: -0.11 | K17: 0.32 | L17: 0.215
A18: Non dairy cattle | D18: 45.13 | E18: 0.88 | G18: Pig | H18: 0.175 | I18: -0.11 | J18: -0.11 | K18: 0.32 | L18: 0.215
A19: Sheep | D19: 7.21 | E19: 0.05 | G19: Poultry | H19: 0.175 | I19: -0.11 | J19: -0.11 | K19: 0.32 | L19: 0.215
A20: Pig | D20: 4.6 | E20: 0.01 | G20: Other | H20: 0.175 | I20: -0.11 | J20: -0.11 | K20: 0.32 | L20: 0.215
A21: Poultry | D21: 0.06 | E21: 0.26
A22: Other | D22: 0.39 | E22: 0.02 | H22: Abated emissions
G23: ACD | H23: CH4 /Mhead | I23: N20 /Mhead | J23: ktco2eq /Mhead | L23: COST MEUR/Mhead
D24: CH4 | E24: N20 | G24: Dairy Cattle | H24: 9.5756 | I24: 0 | J24: 268.1168 | L24: 85.797376
A25: Methane inbitors | C25: MSC | D25: 0.3 | E25: 0 | G25: Non dairy cattle | H25: 4.3512 | I25: 0 | J25: 121.8336 | L25: 38.986752
G26: Sheep | H26: 0.6364 | I26: 0 | J26: 17.8192 | L26: 5.702144
A27: Animal stock | C27: NEW EF | D27: EF CH4 | E27: EF N20 | G27: Pig | H27: 9.6644 | I27: 0 | J27: 270.6032 | L27: 86.593024
A28: Dairy Cattle | D28: 95.12 | E28: 2.16 | G28: Poultry | H28: 0.1628 | I28: 0 | J28: 4.5584 | L28: 1.458688
A29: Non dairy cattle | D29: 36.4 | E29: 0.88 | G29: Other | H29: 0.83472 | I29: 0 | J29: 23.37216 | L29: 7.4790912
A30: Sheep | D30: 5.75 | E30: 0.05
A31: Pig | D31: 13.9 | E31: 0.01
A32: Poultry | D32: 0.22 | E32: 0.26 | H32: Abated emissions
A33: Other | D33: 1.2 | E33: 0.02 | G33: MSC | H33: CH4 /Mhead | I33: N20 /Mhead | J33: ktco2eq /Mhead | L33: COST MEUR/Mhead
G34: Dairy Cattle | H34: 1.55 | I34: 0 | J34: 43.4784 | L34: -4.782624
D35: CH4 | E35: N20 | G35: Non dairy cattle | H35: 0.71 | I35: 0 | J35: 19.7568 | L35: -2.173248
A36: Manure storage cover | C36: MSC | D36: 0.12 | E36: 0 | G36: Sheep | H36: 0.1 | I36: 0 | J36: 2.8896 | L36: -0.317856
G37: Pig | H37: 1.57 | I37: 0 | J37: 43.8816 | L37: -4.826976
A38: Animal stock | C38: NEW EF | D38: EF CH4 | E38: EF N20 | G38: Poultry | H38: 0.03 | I38: 0 | J38: 0.7392 | L38: -0.081312
A39: Dairy Cattle | D39: 128.79 | E39: 2.16 | G39: Other | H39: 0.14 | I39: 0 | J39: 3.79008 | L39: -0.4169088
A40: Non dairy cattle | D40: 48.77 | E40: 0.88
A41: Sheep | D41: 7.75 | E41: 0.05 | H41: Abated emissions
A42: Pig | D42: 12.69 | E42: 0.01 | G42: Clover | H42: CH4 /Mha | I42: N20 /Mha | J42: ktco2eq /Mha | L42: COST MEUR/Mha
A43: Poultry | D43: 0.19 | E43: 0.26 | G43: Dairy Cattle | H43: 0 | I43: 0.77 | J43: 203.944 | L43: -22.43384
...

Sheet Extra
A3: TAMS 3 EXPLANATORY NOTES | E3: https://assets.gov.ie/static/documents/tams-3-explanatory-notes-on-costings-rev7.pdf | N3: Slurry Storage: The Role of TAMS | Tirlán FarmLife | T3: Number of Irish farms without covered slurry storage down by 36pc since 2010 | Irish Independent
A5: Geomembrane lined slurry + COVER
I9: Now, calculate example costs for 100 cows, 22 weeks storage, slurry generation rate 0.41 m³/cow/week:
B22: COST PER COW | D22: 258.17
B25: Weeks OF STORAGE | C25: Cost per cow (€)
B26: 16 | C26: 215.29
B27: 18 | C27: 229.63
B28: 20 | C28: 244.05
B29: 22 | C29: 258.17
C30: 236.785
A32: Only cover
T33: Storage Weeks | U33: Cover Cost (€) | V33: Cost per Cow (€)
T34: 16 | U34: 4621 | V34: 46.21
T35: 18 | U35: 5077 | V35: 50.77
T36: 20 | U36: 6475 | V36: 64.75
T37: 22 | U37: 6004 | V37: 60.04
V38: 55.4425

Sheet Extra_2
I4: Cost
A5: Method | C5: Mitigation Potential | E5: Source | H5: Species | I5: Acidification | J5: Manure Storage Covers | K5: Daily/Weekly Manure Removal
C6: CH₄ | D6: N₂O | H6: Asses | I6: 0 | J6: 0 | K6: 100
A7: Daily/Weekly Manure Removal | B7: DWR | C7: 0.55 | D7: 0.41 | E7: Mohankumar Sajeev, Winiwarter & Amon (2018) | H7: Buffalo | I7: 350 | J7: 19.529 | K7: 100
A8: Anaerobic Digestion | B8: ANDIG | C8: 0.29 | D8: 0.23 | E8: Mohankumar Sajeev, Winiwarter & Amon (2018) | H8: Camels | I8: 0 | J8: 0 | K8: 100
A9: Acidification | B9: ACD | C9: 0.74 | D9: 0.17 | E9: Mukherji et al. (2023) | H9: Cattle, dairy | I9: 350 | J9: 19.529 | K9: 100
A10: Manure Storage Covers | B10: MSC | C10: 0.12 | D10: -5 | E10: Mohankumar Sajeev, Winiwarter & Amon (2018) | H10: Cattle, non-dairy | I10: 350 | J10: 19.529 | K10: 100
H11: Goats | I11: 0 | J11: 0 | K11: 100
H12: Horses | I12: 417 | J12: 15.408 | K12: 100
B13: Gas | C13: CO2_eq Potential | H13: Llamas | I13: 0 | J13: 0 | K13: 100
B14: CH4 | C14: 28 | H14: Mules and hinnies | I14: 0 | J14: 0 | K14: 100
B15: N2O | C15: 265 | D15: CONSISTENT WITH NIR | H15: Sheep | I15: 417 | J15: 15.408 | K15: 100
H16: Swine, breeding | I16: 483 | J16: 11.288 | K16: 100
H17: Swine, market | I17: 483 | J17: 11.288 | K17: 100
H18: Poultry | I18: 417 | J18: 15.408 | K18: 100
A20: Tech Description | B20: Tech Name | C20: Mitigation Potential | E20: Cost [DKK/KtCO2_eq] | F20: Source
C21: CH₄ | D21: N₂O
A22: Acidification | B22: ACD | C22: 0.55 | D22: 0.41 | E22: 350 | F22: Mohankumar Sajeev, Winiwarter & Amon (2018)
A23: Daily/Weekly Manure Removal | B23: DWR | C23: 0.74 | D23: 0.17 | E23: 19.529 | F23: Mukherji et al. (2023)
A24: Manure Storage Covers | B24: MSC | C24: 0.12 | D24: -5 | E24: 100 | F24: Mohankumar Sajeev, Winiwarter & Amon (2018)
B28: Technology Combination | C28: CH₄ | D28: N₂O | E28: Combined Reduction (%)=1−(1−R1​)×(1−R2​)
B29: ACD | C29: 0.55 | D29: 0.41 | E29: This method is standard in IPCC guidelines and life cycle assessments when combining mitigation actions
B30: DWR | C30: 0.74 | D30: 0.17
B31: MSC | C31: 0.12 | D31: 0
B32: ACD_DWR | C32: 0.883 | D32: 0.5103
B33: DWR_MSC | C33: 0.7712 | D33: 0.17
B34: MSC_ACD | C34: 0.94735 | D34: 0.41
B35: ACD_DWR_MSC | C35: 0.89704 | D35: 0.5103
B40: Species | C40: Cost (DKK/Ktco2EQ)
C41: Acidification | D41: Manure Storage Covers | E41: Daily/Weekly Manure Removal | F41: ACD_DWR | G41: DWR_MSC | H41: MSC_ACD | I41: ACD_DWR_MSC
B42: Cattle, dairy | C42: 350 | D42: 971 | E42: 100 | F42: 225 | G42: 535.5 | H42: 660.5 | I42: 473.66667
B43: Cattle, non-dairy | C43: 350 | D43: 971 | E43: 100 | F43: 225 | G43: 535.5 | H43: 660.5 | I43: 473.66667
B44: Swine, breeding | C44: 483 | D44: 44 | E44: 100 | F44: 291.5 | G44: 72 | H44: 263.5 | I44: 209
B45: Swine, market | C45: 483 | D45: 44 | E45: 100 | F45: 291.5 | G45: 72 | H45: 263.5 | I45: 209
B46: Poultry | C46: 417 | D46: 507 | E46: 100 | F46: 258.5 | G46: 303.5 | H46: 462 | I46: 341.33333
B48: Converting cost to MEUR / KTCO2EQ
B51: Species | C51: Cost (MEUR/Ktco2EQ)
C52: Acidification | D52: Manure Storage Covers | E52: Daily/Weekly Manure Removal | F52: ACD_DWR | G52: DWR_MSC | H52: MSC_ACD | I52: ACD_DWR_MSC
B53: Cattle, dairy | C53: 4.6979866e-05 | D53: 0.00013033557 | E53: 1.3422819e-05 | F53: 3.0201342e-05 | G53: 7.1879195e-05 | H53: 8.8657718e-05 | I53: 6.3579418e-05
B54: Cattle, non-dairy | C54: 4.6979866e-05 | D54: 0.00013033557 | E54: 1.3422819e-05 | F54: 3.0201342e-05 | G54: 7.1879195e-05 | H54: 8.8657718e-05 | I54: 6.3579418e-05
...
