Workbook

Sheet Cover
A16: TIMES-Ireland Model
A19: Document type: | B19: Scenario
A20: Sector(s): | B20: All sectors
A21: Purpose: | B21: Specify various assumptions to reflect current policies
A23: Original developer(s): | B23: Olexandr Balyk (UCC, olexandr.balyk@ucc.ie)
B24: Hannah Daly (UCC, h.daly@ucc.ie)
A26: Current maintainer(s): | B26: Olexandr Balyk (UCC, olexandr.balyk@ucc.ie)
A29: Part of TIM version: | B29: 1
A30: Model repository: | B30: https://github.com/MaREI-EPMG/TIMES-Ireland-model
A31: Licence: | B31: CC BY-NC-SA 4.0 (unless specified otherwise)
B32: https://creativecommons.org/licenses/by-nc-sa/4.0/

Sheet Regions
C3: {=IF(LEFT(INDEX(C5:C7,$A$4),1)<>"*",INDEX(C5:C7,$A$4),"")} -> IE | D3: {=IF(LEFT(INDEX(D5:D7,$A$4),1)<>"*",INDEX(D5:D7,$A$4),"")} -> National | E3: {=IF(LEFT(INDEX(E5:E7,$A$4),1)<>"*",INDEX(E5:E7,$A$4),"")} -> IE-CW | F3: {=IF(LEFT(INDEX(F5:F7,$A$4),1)<>"*",INDEX(F5:F7,$A$4),"")} -> IE-D | G3: {=IF(LEFT(INDEX(G5:G7,$A$4),1)<>"*",INDEX(G5:G7,$A$4),"")} -> IE-KE | H3: {=IF(LEFT(INDEX(H5:H7,$A$4),1)<>"*",INDEX(H5:H7,$A$4),"")} -> IE-KK | I3: {=IF(LEFT(INDEX(I5:I7,$A$4),1)<>"*",INDEX(I5:I7,$A$4),"")} -> IE-LS | J3: {=IF(LEFT(INDEX(J5:J7,$A$4),1)<>"*",INDEX(J5:J7,$A$4),"")} -> IE-LD | ... AD3: {=IF(LEFT(INDEX(AD5:AD7,$A$4),1)<>"*",INDEX(AD5:AD7,$A$4),"")} -> IE-MN
A4: 1
A5: Development | C5: IE | D5: National | E5: =Regions!A11 -> IE-CW | F5: =Regions!A16 -> IE-D | G5: =Regions!A19 -> IE-KE | H5: =Regions!A20 -> IE-KK | I5: =Regions!A21 -> IE-LS | J5: =Regions!A24 -> IE-LD | K5: =Regions!A25 -> IE-LH | L5: =Regions!A27 -> IE-MH | M5: =Regions!A29 -> IE-OY | N5: =Regions!A34 -> IE-WH | O5: =Regions!A35 -> IE-WX | P5: =Regions!A36 -> IE-WW | Q5: =Regions!A13 -> IE-CE | R5: =Regions!A14 -> IE-CO | S5: =Regions!A18 -> IE-KY | T5: =Regions!A23 -> IE-LK | U5: =Regions!A32 -> IE-TA | V5: =Regions!A33 -> IE-WD | W5: =Regions!A17 -> IE-G | X5: =Regions!A22 -> IE-LM | Y5: =Regions!A26 -> IE-MO | Z5: =Regions!A30 -> IE-RN | AA5: =Regions!A31 -> IE-SO | AB5: =Regions!A12 -> IE-CN | AC5: =Regions!A15 -> IE-DL | AD5: =Regions!A28 -> IE-MN
A6: Single-region | C6: =C5 -> IE | D6: =IF(LEFT(D5,1)<>"*","*"&D5,D5) -> *National | E6: =IF(LEFT(E5,1)<>"*","*"&E5,E5) -> *IE-CW | F6: =IF(LEFT(F5,1)<>"*","*"&F5,F5) -> *IE-D | G6: =IF(LEFT(G5,1)<>"*","*"&G5,G5) -> *IE-KE | H6: =IF(LEFT(H5,1)<>"*","*"&H5,H5) -> *IE-KK | I6: =IF(LEFT(I5,1)<>"*","*"&I5,I5) -> *IE-LS | J6: =IF(LEFT(J5,1)<>"*","*"&J5,J5) -> *IE-LD | K6: =IF(LEFT(K5,1)<>"*","*"&K5,K5) -> *IE-LH | ... AD6: =IF(LEFT(AD5,1)<>"*","*"&AD5,AD5) -> *IE-MN
A7: Multi-region | C7: ="*"&C5 -> *IE | D7: =D5 -> National | E7: =E5 -> IE-CW | F7: =F5 -> IE-D | G7: =G5 -> IE-KE | H7: =H5 -> IE-KK | I7: =I5 -> IE-LS | J7: =J5 -> IE-LD | K7: =K5 -> IE-LH | ... AD7: =AD5 -> IE-MN
A10: Code | B10: County name
A11: IE-CW | B11: Carlow
A12: IE-CN | B12: Cavan
A13: IE-CE | B13: Clare
A14: IE-CO | B14: Cork
A15: IE-DL | B15: Donegal
A16: IE-D | B16: Dublin
A17: IE-G | B17: Galway
A18: IE-KY | B18: Kerry
A19: IE-KE | B19: Kildare
A20: IE-KK | B20: Kilkenny
A21: IE-LS | B21: Laois
... A36: IE-WW | B36: Wicklow
A37: Source: https://en.wikipedia.org/wiki/ISO_3166-2:IE

Sheet PWR
B2: ~UC_Sets: R_E: | N2: ~UC_Sets: R_E:
B3: ~UC_Sets: T_E: | N3: ~UC_Sets: T_E:
G4: ~UC_T | S4: ~UC_T
B5: UC_N | C5: Pset_Set | D5: Pset_PN | E5: Cset_CN | F5: Year | G5: LimType | H5: UC_CAP | I5: UC_RHSRTS | J5: UC_Desc | N5: UC_N | O5: Pset_Set | P5: Pset_PN | Q5: Cset_CN | R5: Year | S5: LimType | T5: UC_CAP | U5: UC_RHSRTS | V5: UC_RHSRTS~0 | W5: UC_Desc
B6: UC_Max_PV_Cap | D6: P*SOL-PV* | F6: 2023 | G6: FX | H6: 1 | I6: 0.8 | J6: Minimum solar PV capacity | N6: UC_Max_BECCS_Cap | P6: P-RNW-ST-BIO-CCS05 | R6: 2023 | S6: UP | T6: 1 | U6: 0.5 | V6: 5 | W6: Maximum BECCS capacity allowed to install
B7: UC_Min_PV_Cap | D7: P*SOL-PV* | F7: 2025 | G7: LO | H7: 1 | I7: 2.5 | J7: Maximum solar PV capacity
B8: UC_Max_PV_Cap | D8: P*SOL-PV* | F8: 2025 | G8: UP | H8: 1 | I8: 5 | J8: Maximum solar PV capacity
B9: UC_Max_PV_Cap | D9: P*SOL-PV* | F9: 2030 | G9: UP | H9: 1 | I9: 8 | J9: Maximum solar PV capacity
B10: UC_Max_PV_Cap | D10: P*SOL-PV* | F10: 2040 | G10: UP | H10: 1 | I10: 10 | J10: Maximum solar PV capacity
F11: 0 | G11: UP | I11: 5
B15: ~TFM_INS
B16: TimeSlice | C16: LimType | D16: Attribute | E16: Year | F16: IE | G16: National | H16: Pset_Set | I16: Pset_PN | J16: Cset_CN
D17: NCAP_ILED | F17: 5 | G17: 5 | I17: P*CCS* | L17: - 5-year lead time for CCS
B18: ANNUAL | C18: UP | D18: ACT_BND | E18: 2023 | F18: 5 | G18: 5 | I18: P*COA*,P*PEA* | L18: - limit on coal power generation from 2023
B19: ANNUAL | C19: UP | D19: ACT_BND | E19: 2025 | F19: 0 | G19: 0 | I19: P*COA*,P*PEA* | L19: - no coal from 2025
B20: ANNUAL | C20: UP | D20: ACT_BND | E20: 0 | F20: 5 | G20: 5 | I20: P*COA*,P*PEA*
B23: ~TFM_INS
B24: TimeSlice | C24: LimType | D24: Attribute | E24: Year | F24: IE | G24: National | H24: Pset_Set | I24: Pset_PN | J24: Cset_CN
B25: ANNUAL | C25: UP | D25: ACT_BND | E25: 2023 | F25: 1.5 | G25: 1.5 | I25: FT-PWRDIS | L25: - limit on oil-based power generation
B26: ANNUAL | C26: UP | D26: ACT_BND | E26: 2023 | F26: 13.8 | G26: 13.8 | I26: FT-PWRHFO | L26: - limit on oil-based power generation
B27: ANNUAL | C27: UP | D27: ACT_BND | E27: 2026 | F27: 0 | G27: 0 | I27: FT-PWRDIS,FT-PWRHFO | L27: - no oil-based power generation
B28: ANNUAL | C28: UP | D28: ACT_BND | E28: 0 | F28: 5 | G28: 5 | I28: FT-PWRDIS,FT-PWRHFO
B29: ANNUAL | C29: UP | D29: ACT_BND | E29: 2026 | F29: 0 | G29: 0 | I29: P-TH*DIS*,P-TH*HFO*
B30: ANNUAL | C30: UP | D30: ACT_BND | E30: 0 | F30: 5 | G30: 5 | I30: P-TH*DIS*,P-TH*HFO*
B31: ANNUAL | C31: UP | D31: ACT_BND | E31: 2023 | F31: 110 | G31: 110 | I31: FT-PWRGAS | L31: - limit on gas-based power generation
B32: ANNUAL | C32: UP | D32: ACT_BND | E32: 2050 | F32: 110 | G32: 110 | I32: FT-PWRGAS | L32: - limit on gas-based power generation
B33: ANNUAL | C33: UP | D33: ACT_BND | E33: 0 | F33: 5 | G33: 5 | I33: FT-PWRGAS
B36: ~TFM_UPD
B37: TimeSlice | C37: LimType | D37: Attribute | E37: Year | F37: IE | G37: National | H37: Pset_Set | I37: Pset_PN | J37: Cset_CN
D38: NCAP_START | F38: 2035 | G38: 2035 | I38: P*OCE*
D39: NCAP_START | F39: 2025 | G39: 2025 | I39: P*W*OF* | L39: - no new offshore before 2025
D40: NCAP_START | F40: 2100 | G40: 2100 | I40: P*HY*DAM* | L40: - no new hydro (dam) during the modelling horizon
D41: NCAP_START | F41: 2100 | G41: 2100 | I41: P*HY*ROR* | L41: - no new hydro (ror) during the modelling horizon
D42: NCAP_START | F42: 2100 | G42: 2100 | I42: P-RNW-SOL-CSP* | L42: - no new CSP during the modelling horizon
D43: NCAP_START | F43: 2100 | G43: 2100 | I43: P-RNW-GEO* | L43: - no new GEO during the modelling horizon
D44: NCAP_START | F44: 2030 | G44: 2030 | I44: P*CCS* | L44: - no CCS before 2035
G48: ~UC_T
B49: UC_N | C49: Pset_Set | D49: Pset_PN | E49: Cset_CN | F49: Year | G49: LimType | H49: UC_CAP | I49: UC_RHSRTS | J49: UC_Desc
B50: UC_Max_WIN-Off_Cap | D50: P*WIN*OF* | F50: 2027 | G50: UP | H50: 1 | I50: 0.2 | J50: Max Wind Offshore Capacity
B51: UC_Max_WIN-Off_Cap | D51: P*WIN*OF* | F51: 2028 | G51: UP | H51: 1 | I51: 1.5 | J51: Max Wind Offshore Capacity
...

Sheet SYS
B2: ~TFM_UPD
B3: TimeSlice | C3: LimType | D3: Attribute | E3: Year | F3: =IF(Regions!C$3<>"",Regions!C$3,"*") -> IE | G3: =IF(Regions!C$3<>"",Regions!D$3,"*") -> National | H3: Pset_Set | I3: Pset_PN | J3: val_cond
D4: NCAP_START | F4: 2019 | G4: 2019 | I4: * | J4: 2020

Sheet SUP
A1: UC - Each Region/Period
B2: ="~UC_Sets: R_E: " & _xlfn.TEXTJOIN(",",TRUE,Regions!C3:D3) -> ~UC_Sets: R_E: IE,National
B3: ~UC_Sets: T_E:
H4: ~UC_T
B5: UC_N | C5: Pset_Set | D5: Pset_PN | E5: Pset_CI | F5: Pset_CO | G5: Year | H5: LimType | I5: UC_ACT | J5: UC_RHSRTS | K5: UC_Desc | M5: UC_N | N5: Pset_Set | O5: Pset_PN | P5: Pset_CI | Q5: Pset_CO | R5: Year | S5: LimType | T5: UC_ACT | U5: UC_RHSRTS | V5: UC_Desc
B6: UC_ZeroImpBIOWfrom2025 | D6: IMPBIOWCH* | G6: 2025 | H6: UP | I6: 1 | J6: 0 | K6: Zero import of wood chips from 2025 | M6: UC_ZeroImpBIOWfrom2025 | O6: IMPBIOW* | R6: 2025 | S6: UP | T6: 1 | U6: 0 | V6: Zero import of wood pellets and chips from 2025
G7: 0 | H7: UP | J7: 5 | R7: 0 | S7: UP | U7: 5
B8: UC_BIOIMPORTS_LIMIT | D8: IMPBIO* | G8: 2020 | H8: UP | I8: 1 | J8: 7.369 | K8: MAX BIOIMPORT LIMITS | M8: UC_BIOIMPORTS_LIMIT | O8: IMPBIO* | R8: 2020 | S8: UP | T8: 1 | U8: 7.369 | V8: MAX BIOIMPORT LIMITS
D9: IMPBIO* | G9: 2025 | H9: UP | I9: 1 | J9: =J8 -> 7.369
D10: IMPBIO* | G10: 2030 | H10: UP | I10: 1 | J10: =G59 -> 73.8 | O10: IMPBIO* | R10: 2030 | S10: UP | U10: 24.0741
D11: IMPBIO* | G11: 2040 | H11: UP | I11: 1 | J11: =I59 -> 147.6 | O11: IMPBIO* | R11: 2040 | S11: UP | U11: 48.1482
D12: IMPBIO* | G12: 2050 | H12: UP | I12: 1 | J12: =K59 -> 158.4 | O12: IMPBIO* | R12: 2050 | S12: UP | U12: 96.2964
D13: IMPBIO* | G13: 0 | H13: UP | J13: 5 | O13: IMPBIO* | R13: 0 | S13: UP | U13: 15
H16: ~UC_T
B17: UC_N | C17: Cset_CN | D17: Pset_Set | E17: Pset_PN | F17: Year | G17: LimType | H17: Other_indexes | I17: UC_IRE | J17: UC_RHSRTS | K17: UC_Desc
B18: *Units | J18: *Pja
B19: UC_MaxNetELCCImport | C19: ELCC | D19: IRE | E19: IMPELC* | F19: 2022 | G19: UP | H19: imp | I19: 1 | J19: 6 | K19: Maximum net electricity import
C20: ELCC | D20: IRE | E20: EXPELC* | F20: 2022 | H20: exp | I20: -1
F21: 0 | G21: UP | J21: 5
B27: ~TFM_INS
B28: TimeSlice | C28: LimType | D28: Attribute | E28: Year | F28: =IF(Regions!C$3<>"",Regions!C$3,"*") -> IE | G28: =IF(Regions!C$3<>"",Regions!D$3,"*") -> National | H28: Pset_Set | I28: Pset_PN | J28: TS_Filter
C29: UP | D29: ACT_BND | E29: 2025 | F29: 0 | G29: =F29 -> 0 | I29: IMPBIO*1G*2,IMPBIO*1G*3,IMPBIO*1G*4 | J29: 0 | L29: - limit import of 1G bio fuels
C30: =C29 -> UP | D30: =D29 -> ACT_BND | E30: 0 | F30: 5 | G30: =F30 -> 5 | I30: =I29 -> IMPBIO*1G*2,IMPBIO*1G*3,IMPBIO*1G*4
B33: ~TFM_INS
B34: TimeSlice | C34: LimType | D34: Attribute | E34: Year | F34: =IF(Regions!C$3<>"",Regions!C$3,"*") -> IE | G34: =IF(Regions!C$3<>"",Regions!D$3,"*") -> National | H34: Pset_CI | I34: Pset_PN
C35: UP | D35: ACT_BND | E35: 2018 | F35: 0.35 | G35: =F35 -> 0.35 | H35: HETC | I35: *GRID
C36: =C35 -> UP | D36: =D35 -> ACT_BND | E36: 0 | F36: 5 | G36: =F36 -> 5 | H36: HETC | I36: =I35 -> *GRID
C37: UP | D37: ACT_BND | E37: 2030 | F37: 0 | G37: =F37 -> 0 | I37: IMPH2G
C38: =C37 -> UP | D38: =D37 -> ACT_BND | E38: 0 | F38: 5 | G38: =F38 -> 5 | I38: =I37 -> IMPH2G
B41: ~TFM_UPD
B42: TimeSlice | C42: LimType | D42: Attribute | E42: Year | F42: =IF(Regions!C$3<>"",Regions!C$3,"*") -> IE | G42: =IF(Regions!D$3<>"",Regions!D$3,"*") -> National | H42: Pset_Set | I42: Pset_PN
D43: NCAP_START | F43: 2018 | G43: 2018 | I43: SBIORGAS* | M43: - enable biogas plants to cover eb
E53: Potential quantities of wood pellets available for import to Ireland (PJ)
B54: SEAI Heat Study | C54: Cost (€/MWh) | D54: Cost (€/GJ) | E54: 2020 | F54: 2025 | G54: 2030 | H54: 2035 | I54: 2040 | J54: 2045 | K54: 2050
B55: Import of Wood Pellets - Step 1 | C55: 34.7 | D55: 9.6388889 | E55: 1.8 | F55: 1.8 | G55: 1.8 | H55: 1.8 | I55: 3.6 | J55: 7.2 | K55: 7.2
B56: Import of Wood Pellets - Step 2 | C56: 34.7 | D56: 9.6388889 | E56: 0 | F56: 3.6 | G56: 18 | H56: 36 | I56: 54 | J56: 61.2 | K56: 61.2
B57: Import of Wood Pellets - Step 3 | C57: 36.6 | D57: 10.166667 | E57: 0 | F57: 0 | G57: 54 | H57: 54 | I57: 54 | J57: 54 | K57: 54
B58: Import of Wood Pellets - Step 4 | C58: 40.3 | D58: 11.194444 | E58: 0 | F58: 0 | G58: 0 | H58: 3.6 | I58: 36 | J58: 36 | K58: 36
D59: Totoal (PJ) | E59: 1.8 | F59: 5.4 | G59: 73.8 | H59: 95.4 | I59: 147.6 | J59: 158.4 | K59: 158.4
B60: Reference | C60: SEAI, 2022. Sustainable bioenergy for heat, National Heat study, Spatial Assessment of Resources and Evaluation of Costs and GHG Emissions

Sheet SRV
B3: ~TFM_INS
B4: TimeSlice | C4: LimType | D4: Attribute | E4: Year | F4: =IF(Regions!C$3<>"",Regions!C$3,"*") -> IE | G4: =IF(Regions!C$3<>"",Regions!D$3,"*") -> National | H4: Pset_CI | I4: Pset_PN
C5: UP | D5: NCAP_AFA | E5: 2018 | F5: 0.115 | G5: =F5 -> 0.115 | I5: S-SH-CS_ELC_N1
C6: UP | D6: NCAP_AFA | E6: 2018 | F6: 0.115 | G6: =F6 -> 0.115 | I6: S-SH-CS_ELC_N2
C7: UP | D7: NCAP_AFA | E7: 2018 | F7: 0.115 | G7: =F7 -> 0.115 | I7: S-SH-CS_ELC_N4
C8: UP | D8: NCAP_AFA | E8: 2018 | F8: 0.115 | G8: =F8 -> 0.115 | I8: S-SH-CS_ELC_N7
C9: UP | D9: NCAP_AFA | E9: 2018 | F9: 0.115 | G9: =F9 -> 0.115 | I9: S-SH-PU_ELC_N1
C10: UP | D10: NCAP_AFA | E10: 2018 | F10: 0.115 | G10: =F10 -> 0.115 | I10: S-SH-PU_ELC_N2
C11: UP | D11: NCAP_AFA | E11: 2018 | F11: 0.115 | G11: =F11 -> 0.115 | I11: S-SH-PU_ELC_N4
C12: UP | D12: NCAP_AFA | E12: 2018 | F12: 0.115 | G12: =F12 -> 0.115 | I12: S-SH-PU_ELC_N7

Sheet TRA
B3: ~TFM_UPD
B4: TimeSlice | C4: LimType | D4: Attribute | E4: Year | F4: Attrib_Cond | G4: Val_Cond | H4: =IF(Regions!C$3<>"",Regions!C$3,"*") -> IE | I4: =IF(Regions!D$3<>"",Regions!D$3,"*") -> National | J4: Pset_CO | K4: Pset_PN
D5: AFA | H5: *0.85 | I5: =H5 -> *0.85 | K5: T-CAR*1
B11: ="~UC_Sets: R_E: " & _xlfn.TEXTJOIN(",",TRUE,Regions!C3:D3) -> ~UC_Sets: R_E: IE,National
B12: ~UC_Sets: T_E:
G13: UC_T
B14: UC_N | C14: *UC_ATTR~RHS | D14: Pset_PN | E14: Pset_PD | F14: Year | G14: LimType | H14: UC_NCAP | I14: UC_TIME | J14: UC_TIME~0 | K14: UC_Desc | L14: UC_RHSRT | M14: UC_RHSRT~0
B15: UC_min_Car_sale | C15: NCAP,PERIOD | D15: T*CAR* | E15: *New | F15: 2025 | G15: LO | H15: 1 | I15: =MIN(C62:H62)/1000 -> 84.309 | J15: 5 | K15: Minimum new car sales | L15: 0 | M15: 5
D16: T*CAR* | E16: *New | F16: 2030 | G16: LO | H16: 1 | I16: =I15*1.1 -> 92.7399
D17: T*CAR* | E17: *New | F17: 2051 | G17: LO | H17: 1 | I17: 0
B18: UC_max_Car_sale | C18: NCAP,PERIOD | D18: T*CAR* | E18: *New | F18: 2025 | G18: UP | H18: 1 | I18: =1.2*MAX(C74:H74)/1000 -> 266.64 | J18: 5 | K18: Maximum new car sales | L18: 0 | M18: 5
D19: T*CAR* | E19: *New | F19: 2030 | G19: UP | H19: 1 | I19: =+I18*1.3 -> 346.632
D20: T*CAR* | E20: *New | F20: 2050 | G20: UP | H20: 1 | I20: =I18*5 -> 1333.2
B23: ="~UC_Sets: R_E: " & _xlfn.TEXTJOIN(",",TRUE,Regions!C3:D3) -> ~UC_Sets: R_E: IE,National
B24: ~UC_Sets: T_E:
G25: UC_T
B26: UC_N | C26: *UC_ATTR~RHS | D26: Pset_PN | E26: Pset_PD | F26: Year | G26: LimType | H26: UC_NCAP | I26: UC_TIME | J26: UC_TIME~0 | K26: UC_Desc | L26: UC_RHSRT | M26: UC_RHSRT~0
B27: UC_min_H_Truck_sale | C27: NCAP,PERIOD | D27: T-HGT* | E27: *New | F27: 2024 | G27: LO | H27: 1 | I27: =MIN(C78:H78)*0.5/1000 -> 1.0561541 | J27: 5 | K27: Minimum new heavy truck sales | L27: 0 | M27: 5
D28: T-HGT* | E28: *New | F28: 2040 | G28: LO | H28: 1 | I28: 0
D29: T-HGT* | E29: *New | F29: 2055 | G29: LO | H29: 1 | I29: 0
B30: UC_max_H_Truck_sale | C30: NCAP,PERIOD | D30: T-HGT* | E30: *New | F30: 2024 | G30: UP | H30: 1 | I30: =2*MAX(C78:H78)/1000 -> 5.3700765 | J30: 5 | K30: Maximum new heavy truck sales | L30: 0 | M30: 5
D31: T-HGT* | E31: *New | F31: 2040 | G31: UP | H31: 1 | I31: =I30*2 -> 10.740153
D32: T-HGT* | E32: *New | F32: 2050 | G32: UP | H32: 1 | I32: =I31*5 -> 53.700765
B35: ="~UC_Sets: R_E: " & _xlfn.TEXTJOIN(",",TRUE,Regions!C3:D3) -> ~UC_Sets: R_E: IE,National
B36: ~UC_Sets: T_E:
G37: UC_T
B38: UC_N | C38: *UC_ATTR~RHS | D38: Pset_PN | E38: Pset_PD | F38: Year | G38: LimType | H38: UC_NCAP | I38: UC_TIME | J38: UC_TIME~0 | K38: UC_Desc | L38: UC_RHSRT | M38: UC_RHSRT~0
B39: UC_min_M_Truck_sale | C39: NCAP,PERIOD | D39: T-MGT* | E39: *New | F39: 2024 | G39: LO | H39: 1 | I39: =MIN(C77:H77)*0.5/1000 -> 0.45905339 | J39: 5 | K39: Minimum new medium truck sales | L39: 0 | M39: 5
D40: T-MGT* | E40: *New | F40: 2040 | G40: LO | H40: 1 | I40: 0
D41: T-MGT* | E41: *New | F41: 2055 | G41: LO | H41: 1 | I41: 0
B42: UC_max_M_Truck_sale | C42: NCAP,PERIOD | D42: T-MGT* | E42: *New | F42: 2024 | G42: UP | H42: 1 | I42: =2*MAX(C77:H77)/1000 -> 2.3340834 | J42: 5 | K42: Maximum new medium truck sales | L42: 0 | M42: 5
D43: T-MGT* | E43: *New | F43: 2040 | G43: UP | H43: 1 | I43: =I42*2 -> 4.6681669
D44: T-MGT* | E44: *New | F44: 2050 | G44: UP | H44: 1 | I44: =I43*5 -> 23.340834
B47: ="~UC_Sets: R_E: " & _xlfn.TEXTJOIN(",",TRUE,Regions!C3:D3) -> ~UC_Sets: R_E: IE,National
B48: ~UC_Sets: T_E:
G49: UC_T
B50: UC_N | C50: *UC_ATTR~RHS | D50: Pset_PN | E50: Pset_PD | F50: Year | G50: LimType | H50: UC_NCAP | I50: UC_TIME | J50: UC_TIME~0 | K50: UC_Desc | L50: UC_RHSRT | M50: UC_RHSRT~0
B51: UC_min_L_Truck_sale | C51: NCAP,PERIOD | D51: T-LGT* | E51: *New | F51: 2024 | G51: LO | H51: 1 | I51: =MIN(C76:H76)*0.5/1000 -> 14.343833 | J51: 5 | K51: Minimum new light truck sales | L51: 0 | M51: 5
D52: T-LGT* | E52: *New | F52: 2040 | G52: LO | H52: 1 | I52: 0 | K52: Minimum new light truck sales
D53: T-LGT* | E53: *New | F53: 2051 | G53: LO | H53: 1 | I53: 0
...
