Workbook
Name CAGR: DEMANDS!$U$5
Name I_alku: "1.1."
Name I_loppu: "31.3."
Name II_alku: "1.4."
Name II_loppu: "30.6."
Name III_alku: "1.7."
Name III_loppu: "30.9."
Name IV_alku: "1.10."
Name IV_loppu: "31.12."

Sheet Cover
A16: TIMES-Ireland Model
A19: Document type: | B19: Scenario
A20: Sector(s): | B20: All end-use sectors
A21: Purpose: | B21: Specify end-use demand projections
A23: Original developer(s): | B23: Ankita Gaur (UCC, agaur@ucc.ie)
B24: Vahid Aryanpur (UCC, vahid.aryanpur@ucc.ie)
B25: Olexandr Balyk (UCC, olexandr.balyk@ucc.ie)
A26: Current maintainer(s): | B26: Ankita Gaur (UCC, agaur@ucc.ie)
B27: Vahid Aryanpur (UCC, vahid.aryanpur@ucc.ie)
B28: Olexandr Balyk (UCC, olexandr.balyk@ucc.ie)
B29: Neha Jaggeshar (UCC, Neha.Jaggeshar@ucc.ie)
A30: Part of TIM version: | B30: 1
A31: Model repository: | B31: https://github.com/MaREI-EPMG/TIMES-Ireland-model
A32: Licence: | B32: CC BY-NC-SA 4.0 (unless specified otherwise)
B33: https://creativecommons.org/licenses/by-nc-sa/4.0/

Sheet BY-Demands
C4: ~TFM_FILL
C5: Operation_Sum_Avg_Count | D5: Scenario Name | E5: TimeSlice | F5: LimType | G5: Attribute | H5: Year | I5: Cset_CN | J5: =Regions!C$3 -> IE | K5: =Regions!D$3 -> National | L5: =Regions!E$3 -> IE-CW | M5: =Regions!F$3 -> IE-D | N5: =Regions!G$3 -> IE-KE | O5: =Regions!H$3 -> IE-KK | P5: =Regions!I$3 -> IE-LS | Q5: =Regions!J$3 -> IE-LD | ... AK5: =Regions!AD$3 -> IE-MN
C6: A | D6: BASE | G6: COM_PROJ | H6: 2018 | I6: TRAPS | J6: 14.556561 | L6: 0.19075815 | M6: 3.8137078 | N6: 0.70334338 | O6: 0.32630593 | P6: 0.25725946 | Q6: 0.12926411 | R6: 0.37066642 | S6: 0.61012643 | T6: 0.25256358 | U6: 0.28627809 | V6: 0.49824919 | W6: 0.44072765 | X6: 0.38789418 | Y6: 1.6403529 | Z6: 0.50223766 | AA6: 0.59887773 | AB6: 0.54597893 | AC6: 0.36254755 | AD6: 0.81031809 | AE6: 0.10399822 | AF6: 0.43396473 | AG6: 0.2270113 | AH6: 0.20014422 | AI6: 0.22324074 | AJ6: 0.43304853 | AK6: 0.20769619
C7: A | D7: BASE | G7: COM_PROJ | H7: 2018 | I7: TRAPM | J7: 31.276119 | L7: 0.43519149 | M7: 7.6211536 | N7: 1.5519094 | O7: 0.73703192 | P7: 0.55451714 | Q7: 0.28568437 | R7: 0.76950577 | S7: 1.33595 | T7: 0.5661632 | U7: 0.63911186 | V7: 1.1334816 | W7: 0.96185938 | X7: 0.87235861 | Y7: 3.5254749 | Z7: 1.153887 | AA7: 1.2995737 | AB7: 1.2604325 | AC7: 0.79517788 | AD7: 1.7803554 | AE7: 0.23333731 | AF7: 0.98601598 | AG7: 0.5309014 | AH7: 0.43310683 | AI7: 0.47060177 | AJ7: 0.8666893 | AK7: 0.47664625
C8: A | D8: BASE | G8: COM_PROJ | H8: 2018 | I8: TRAPL | J8: 27.131578 | L8: 0.37389749 | M8: 6.6607449 | N8: 1.3457958 | O8: 0.64805463 | P8: 0.48149947 | Q8: 0.24792998 | R8: 0.67368746 | S8: 1.1456149 | T8: 0.49378011 | U8: 0.54722173 | V8: 0.97262647 | W8: 0.83286416 | X8: 0.74674766 | Y8: 3.0449423 | Z8: 1.0126394 | AA8: 1.1217785 | AB8: 1.0852428 | AC8: 0.68342924 | AD8: 1.5527405 | AE8: 0.20031586 | AF8: 0.86102306 | AG8: 0.4513161 | AH8: 0.37617526 | AI8: 0.40231788 | AJ8: 0.7410989 | AK8: 0.42809299
C9: A | D9: BASE | G9: COM_PROJ | H9: 2018 | I9: TRAF | J9: 10.702591 | L9: 0.177941 | M9: 2.6576908 | N9: 0.48228404 | O9: 0.31014967 | P9: 0.22090468 | Q9: 0.10660398 | R9: 0.27935991 | S9: 0.43225128 | T9: 0.20333601 | U9: 0.23152778 | V9: 0.46795619 | W9: 0.30871043 | X9: 0.30378727 | Y9: 1.6254277 | Z9: 0.44225677 | AA9: 0.49831114 | AB9: 0.40793969 | AC9: 0.37892083 | AD9: 0.60506097 | AE9: 0.08069347 | AF9: 0.3407838 | AG9: 0.15133441 | AH9: 0.16503079 | AI9: 0.19182704 | AJ9: 0.40087863 | AK9: 0.15458274
C10: A | D10: BASE | G10: COM_PROJ | H10: 2018 | I10: TTURS | J10: 7.7105748 | L10: 0.092186243 | M10: 2.1816898 | N10: 0.36028609 | O10: 0.16067985 | P10: 0.13714428 | Q10: 0.066182961 | R10: 0.20869339 | S10: 0.31582192 | T10: 0.12623712 | U10: 0.14373942 | V10: 0.24243499 | W10: 0.23061944 | X10: 0.19239255 | Y10: 0.87903045 | Z10: 0.23917223 | AA10: 0.31558713 | AB10: 0.25835368 | AC10: 0.18811616 | AD10: 0.41785635 | AE10: 0.051886742 | AF10: 0.2113214 | AG10: 0.10451185 | AH10: 0.10611652 | AI10: 0.12334679 | AJ10: 0.25776914 | AK10: 0.099398313
C11: A | D11: BASE | G11: COM_PROJ | H11: 2018 | I11: TNAV | J11: 3.5132998 | L11: 0.04200438 | M11: 0.99408029 | N11: 0.16416326 | O11: 0.073213282 | P11: 0.062489372 | Q11: 0.030156063 | R11: 0.095090502 | S11: 0.14390329 | T11: 0.057519557 | U11: 0.065494428 | V11: 0.11046476 | W11: 0.10508104 | X11: 0.087663078 | Y11: 0.40052753 | Z11: 0.10897809 | AA11: 0.14379631 | AB11: 0.11771806 | AC11: 0.085714551 | AD11: 0.19039497 | AE11: 0.023642035 | AF11: 0.09628795 | AG11: 0.047620506 | AH11: 0.048351665 | AI11: 0.056202586 | AJ11: 0.11745172 | AK11: 0.045290537
C12: A | D12: BASE | G12: COM_PROJ | H12: 2018 | I12: TOTH | J12: 20.831455 | L12: 0.24905712 | M12: 5.8942134 | N12: 0.97337536 | O12: 0.43410448 | P12: 0.37051906 | Q12: 0.17880474 | R12: 0.56382137 | S12: 0.85324769 | T12: 0.34105147 | U12: 0.38833698 | V12: 0.65498016 | W12: 0.6230584 | X12: 0.51978185 | Y12: 2.3748532 | Z12: 0.64616525 | AA12: 0.85261336 | AB12: 0.69798726 | AC12: 0.50822842 | AD12: 1.1289114 | AE12: 0.14018103 | AF12: 0.57092141 | AG12: 0.2823569 | AH12: 0.28669217 | AI12: 0.33324273 | AJ12: 0.69640802 | AK12: 0.26854178
C13: A | D13: BASE | G13: COM_PROJ | H13: 2018 | I13: TAVIDOM | J13: 0.2334932 | L13: 0 | M13: 0.13599128 | N13: 0 | O13: 0 | P13: 0 | Q13: 0 | R13: 0 | S13: 0 | T13: 0 | U13: 0 | V13: 0 | W13: 0 | X13: 0.047489541 | Y13: 0.00047056268 | Z13: 0.047235779 | AA13: 0 | AB13: 0 | AC13: 0 | AD13: 0 | AE13: 0 | AF13: 9.4112535e-05 | AG13: 0 | AH13: 0 | AI13: 0 | AJ13: 0 | AK13: 0
C14: A | D14: BASE | G14: COM_PROJ | H14: 2018 | I14: TAVIINT | J14: 45.968364 | L14: 0 | M14: 40.440163 | N14: 0 | O14: 0 | P14: 0 | Q14: 0 | R14: 0 | S14: 0 | T14: 0 | U14: 0 | V14: 0 | W14: 0 | X14: 2.3945076 | Y14: 2.214007 | Z14: 0.24127325 | AA14: 0 | AB14: 0 | AC14: 0 | AD14: 0 | AE14: 0 | AF14: 0.68881549 | AG14: 0 | AH14: 0 | AI14: 0 | AJ14: 0 | AK14: 0
C15: A | D15: BASE | G15: COM_PROJ | H15: 2018 | I15: RSDRF | J15: 1.1544546 | K15: 1.1544546
C16: A | D16: BASE | G16: COM_PROJ | H16: 2018 | I16: RSDCK | J16: 2.0006898 | K16: 2.0006898
C17: A | D17: BASE | G17: COM_PROJ | H17: 2018 | I17: RSDCW | J17: 0.788768 | K17: 0.788768
C18: A | D18: BASE | G18: COM_PROJ | H18: 2018 | I18: RSDCD | J18: 1.0516932 | K18: 1.0516932
C19: A | D19: BASE | G19: COM_PROJ | H19: 2018 | I19: RSDDW | J19: 0.84878652 | K19: 0.84878652
C20: A | D20: BASE | G20: COM_PROJ | H20: 2018 | I20: RSDOE | J20: 9.2169271 | K20: 9.2169271
C21: A | D21: BASE | G21: COM_PROJ | H21: 2018 | I21: RSDOA | J21: 0 | K21: 0
C22: A | D22: BASE | G22: COM_PROJ | H22: 2018 | I22: RSD_Apt | J22: 211.81988 | K22: 211.81988
C23: A | D23: BASE | G23: COM_PROJ | H23: 2018 | I23: RSD_Att | J23: 788.06472 | K23: 788.06472
C24: A | D24: BASE | G24: COM_PROJ | H24: 2018 | I24: RSD_Det | J24: 735.40673 | K24: 735.40673
C25: A | D25: BASE | G25: COM_PROJ | H25: 2018 | I25: INEM
C26: A | D26: BASE | G26: COM_PROJ | H26: 2018 | I26: IFAB
C27: A | D27: BASE | G27: COM_PROJ | H27: 2018 | I27: ITAP
C28: A | D28: BASE | G28: COM_PROJ | H28: 2018 | I28: IWAP | J28: 5 | K28: 5
C29: A | D29: BASE | G29: COM_PROJ | H29: 2018 | I29: IPX4
C30: A | D30: BASE | G30: COM_PROJ | H30: 2018 | I30: ICAF | J30: 5.7 | K30: 5.7
C31: A | D31: BASE | G31: COM_PROJ | H31: 2018 | I31: IRAP
C32: A | D32: BASE | G32: COM_PROJ | H32: 2018 | I32: IONM | J32: 2.4 | K32: 2.4
C33: A | D33: BASE | G33: COM_PROJ | H33: 2018 | I33: IMAP | J33: 16.5 | K33: 16.5
C34: A | D34: BASE | G34: COM_PROJ | H34: 2018 | I34: IMAE
C35: A | D35: BASE | G35: COM_PROJ | H35: 2018 | I35: IEOE
C36: A | D36: BASE | G36: COM_PROJ | H36: 2018 | I36: ITEM
C37: A | D37: BASE | G37: COM_PROJ | H37: 2018 | I37: IOMA | J37: 3.8 | K37: 3.8
C38: A | D38: BASE | G38: COM_PROJ | H38: 2018 | I38: ICON
C39: A | D39: BASE | G39: COM_PROJ | H39: 2018 | I39: SRV-CS | J39: 28.901665 | K39: 28.901665
C40: A | D40: BASE | G40: COM_PROJ | H40: 2018 | I40: SRV-PU | J40: 58.151542 | K40: 58.151542
C41: A | D41: BASE | G41: COM_PROJ | H41: 2018 | I41: SRVDCE-CS | J41: 5.629176 | K41: 5.629176
C42: A | D42: BASE | G42: COM_PROJ | H42: 2018 | I42: SRVPLIG-PU | J42: 0.48 | K42: 0.48
C47: Table 1 Metered Electricity Consumption 2015-2022
...

Sheet REG_TRA_DEMANDS
B2: ~TFM_DINS
B3: TimeSlice | C3: LimType | D3: Attribute | E3: Cset_CN | F3: Year | G3: =Regions!E$3 -> IE-CW | H3: =Regions!F$3 -> IE-D | I3: =Regions!G$3 -> IE-KE | J3: =Regions!H$3 -> IE-KK | K3: =Regions!I$3 -> IE-LS | L3: =Regions!J$3 -> IE-LD | M3: =Regions!K$3 -> IE-LH | N3: =Regions!L$3 -> IE-MH | ... AF3: =Regions!AD$3 -> IE-MN
D4: COM_PROJ | E4: =DEMANDS!$E$17 -> TRAPS | F4: 2020 | G4: =HLOOKUP(REG_TRA_DEMANDS!G$3,'BY-Demands'!$J$5:$AK$14,MATCH($E4,'BY-Demands'!$I$5:$I$14,0),FALSE)*HLOOKUP(REG_TRA_DEMANDS!$F4,DEMANDS!$G$2:$CK$25,MATCH($E4,DEMANDS!$E$2:$E$25,0),FALSE)/HLOOKUP(2018,DEMANDS!$G$2:$CK$25,MATCH($E4,DEMANDS!$E$2:$E$25,0),FALSE) -> 0.1410226 | H4: =HLOOKUP(REG_TRA_DEMANDS!H$3,'BY-Demands'!$J$5:$AK$14,MATCH($E4,'BY-Demands'!$I$5:$I$14,0),FALSE)*HLOOKUP(REG_TRA_DEMANDS!$F4,DEMANDS!$G$2:$CK$25,MATCH($E4,DEMANDS!$E$2:$E$25,0),FALSE)/HLOOKUP(2018,DEMANDS!$G$2:$CK$25,MATCH($E4,DEMANDS!$E$2:$E$25,0),FALSE) -> 2.8193762 | I4: =HLOOKUP(REG_TRA_DEMANDS!I$3,'BY-Demands'!$J$5:$AK$14,MATCH($E4,'BY-Demands'!$I$5:$I$14,0),FALSE)*HLOOKUP(REG_TRA_DEMANDS!$F4,DEMANDS!$G$2:$CK$25,MATCH($E4,DEMANDS!$E$2:$E$25,0),FALSE)/HLOOKUP(2018,DEMANDS!$G$2:$CK$25,MATCH($E4,DEMANDS!$E$2:$E$25,0),FALSE) -> 0.5199637 | J4: =HLOOKUP(REG_TRA_DEMANDS!J$3,'BY-Demands'!$J$5:$AK$14,MATCH($E4,'BY-Demands'!$I$5:$I$14,0),FALSE)*HLOOKUP(REG_TRA_DEMANDS!$F4,DEMANDS!$G$2:$CK$25,MATCH($E4,DEMANDS!$E$2:$E$25,0),FALSE)/HLOOKUP(2018,DEMANDS!$G$2:$CK$25,MATCH($E4,DEMANDS!$E$2:$E$25,0),FALSE) -> 0.2412296 | K4: =HLOOKUP(REG_TRA_DEMANDS!K$3,'BY-Demands'!$J$5:$AK$14,MATCH($E4,'BY-Demands'!$I$5:$I$14,0),FALSE)*HLOOKUP(REG_TRA_DEMANDS!$F4,DEMANDS!$G$2:$CK$25,MATCH($E4,DEMANDS!$E$2:$E$25,0),FALSE)/HLOOKUP(2018,DEMANDS!$G$2:$CK$25,MATCH($E4,DEMANDS!$E$2:$E$25,0),FALSE) -> 0.19018531 | L4: =HLOOKUP(REG_TRA_DEMANDS!L$3,'BY-Demands'!$J$5:$AK$14,MATCH($E4,'BY-Demands'!$I$5:$I$14,0),FALSE)*HLOOKUP(REG_TRA_DEMANDS!$F4,DEMANDS!$G$2:$CK$25,MATCH($E4,DEMANDS!$E$2:$E$25,0),FALSE)/HLOOKUP(2018,DEMANDS!$G$2:$CK$25,MATCH($E4,DEMANDS!$E$2:$E$25,0),FALSE) -> 0.095561634 | M4: =HLOOKUP(REG_TRA_DEMANDS!M$3,'BY-Demands'!$J$5:$AK$14,MATCH($E4,'BY-Demands'!$I$5:$I$14,0),FALSE)*HLOOKUP(REG_TRA_DEMANDS!$F4,DEMANDS!$G$2:$CK$25,MATCH($E4,DEMANDS!$E$2:$E$25,0),FALSE)/HLOOKUP(2018,DEMANDS!$G$2:$CK$25,MATCH($E4,DEMANDS!$E$2:$E$25,0),FALSE) -> 0.27402417 | N4: =HLOOKUP(REG_TRA_DEMANDS!N$3,'BY-Demands'!$J$5:$AK$14,MATCH($E4,'BY-Demands'!$I$5:$I$14,0),FALSE)*HLOOKUP(REG_TRA_DEMANDS!$F4,DEMANDS!$G$2:$CK$25,MATCH($E4,DEMANDS!$E$2:$E$25,0),FALSE)/HLOOKUP(2018,DEMANDS!$G$2:$CK$25,MATCH($E4,DEMANDS!$E$2:$E$25,0),FALSE) -> 0.4510508 | ... AF4: =HLOOKUP(REG_TRA_DEMANDS!AF$3,'BY-Demands'!$J$5:$AK$14,MATCH($E4,'BY-Demands'!$I$5:$I$14,0),FALSE)*HLOOKUP(REG_TRA_DEMANDS!$F4,DEMANDS!$G$2:$CK$25,MATCH($E4,DEMANDS!$E$2:$E$25,0),FALSE)/HLOOKUP(2018,DEMANDS!$G$2:$CK$25,MATCH($E4,DEMANDS!$E$2:$E$25,0),FALSE) -> 0.15354446
D5: COM_PROJ | E5: =DEMANDS!$E$17 -> TRAPS | F5: 2021 | G5: =HLOOKUP(REG_TRA_DEMANDS!G$3,'BY-Demands'!$J$5:$AK$14,MATCH($E5,'BY-Demands'!$I$5:$I$14,0),FALSE)*HLOOKUP(REG_TRA_DEMANDS!$F5,DEMANDS!$G$2:$CK$25,MATCH($E5,DEMANDS!$E$2:$E$25,0),FALSE)/HLOOKUP(2018,DEMANDS!$G$2:$CK$25,MATCH($E5,DEMANDS!$E$2:$E$25,0),FALSE) -> 0.17786262 | H5: =HLOOKUP(REG_TRA_DEMANDS!H$3,'BY-Demands'!$J$5:$AK$14,MATCH($E5,'BY-Demands'!$I$5:$I$14,0),FALSE)*HLOOKUP(REG_TRA_DEMANDS!$F5,DEMANDS!$G$2:$CK$25,MATCH($E5,DEMANDS!$E$2:$E$25,0),FALSE)/HLOOKUP(2018,DEMANDS!$G$2:$CK$25,MATCH($E5,DEMANDS!$E$2:$E$25,0),FALSE) -> 3.5558955 | I5: =HLOOKUP(REG_TRA_DEMANDS!I$3,'BY-Demands'!$J$5:$AK$14,MATCH($E5,'BY-Demands'!$I$5:$I$14,0),FALSE)*HLOOKUP(REG_TRA_DEMANDS!$F5,DEMANDS!$G$2:$CK$25,MATCH($E5,DEMANDS!$E$2:$E$25,0),FALSE)/HLOOKUP(2018,DEMANDS!$G$2:$CK$25,MATCH($E5,DEMANDS!$E$2:$E$25,0),FALSE) -> 0.65579632 | J5: =HLOOKUP(REG_TRA_DEMANDS!J$3,'BY-Demands'!$J$5:$AK$14,MATCH($E5,'BY-Demands'!$I$5:$I$14,0),FALSE)*HLOOKUP(REG_TRA_DEMANDS!$F5,DEMANDS!$G$2:$CK$25,MATCH($E5,DEMANDS!$E$2:$E$25,0),FALSE)/HLOOKUP(2018,DEMANDS!$G$2:$CK$25,MATCH($E5,DEMANDS!$E$2:$E$25,0),FALSE) -> 0.30424717 | K5: =HLOOKUP(REG_TRA_DEMANDS!K$3,'BY-Demands'!$J$5:$AK$14,MATCH($E5,'BY-Demands'!$I$5:$I$14,0),FALSE)*HLOOKUP(REG_TRA_DEMANDS!$F5,DEMANDS!$G$2:$CK$25,MATCH($E5,DEMANDS!$E$2:$E$25,0),FALSE)/HLOOKUP(2018,DEMANDS!$G$2:$CK$25,MATCH($E5,DEMANDS!$E$2:$E$25,0),FALSE) -> 0.23986834 | L5: =HLOOKUP(REG_TRA_DEMANDS!L$3,'BY-Demands'!$J$5:$AK$14,MATCH($E5,'BY-Demands'!$I$5:$I$14,0),FALSE)*HLOOKUP(REG_TRA_DEMANDS!$F5,DEMANDS!$G$2:$CK$25,MATCH($E5,DEMANDS!$E$2:$E$25,0),FALSE)/HLOOKUP(2018,DEMANDS!$G$2:$CK$25,MATCH($E5,DEMANDS!$E$2:$E$25,0),FALSE) -> 0.12052566 | M5: =HLOOKUP(REG_TRA_DEMANDS!M$3,'BY-Demands'!$J$5:$AK$14,MATCH($E5,'BY-Demands'!$I$5:$I$14,0),FALSE)*HLOOKUP(REG_TRA_DEMANDS!$F5,DEMANDS!$G$2:$CK$25,MATCH($E5,DEMANDS!$E$2:$E$25,0),FALSE)/HLOOKUP(2018,DEMANDS!$G$2:$CK$25,MATCH($E5,DEMANDS!$E$2:$E$25,0),FALSE) -> 0.34560882 | N5: =HLOOKUP(REG_TRA_DEMANDS!N$3,'BY-Demands'!$J$5:$AK$14,MATCH($E5,'BY-Demands'!$I$5:$I$14,0),FALSE)*HLOOKUP(REG_TRA_DEMANDS!$F5,DEMANDS!$G$2:$CK$25,MATCH($E5,DEMANDS!$E$2:$E$25,0),FALSE)/HLOOKUP(2018,DEMANDS!$G$2:$CK$25,MATCH($E5,DEMANDS!$E$2:$E$25,0),FALSE) -> 0.56888097 | ... AF5: =HLOOKUP(REG_TRA_DEMANDS!AF$3,'BY-Demands'!$J$5:$AK$14,MATCH($E5,'BY-Demands'!$I$5:$I$14,0),FALSE)*HLOOKUP(REG_TRA_DEMANDS!$F5,DEMANDS!$G$2:$CK$25,MATCH($E5,DEMANDS!$E$2:$E$25,0),FALSE)/HLOOKUP(2018,DEMANDS!$G$2:$CK$25,MATCH($E5,DEMANDS!$E$2:$E$25,0),FALSE) -> 0.19365562
D6: COM_PROJ | E6: =DEMANDS!$E$17 -> TRAPS | F6: 2022 | G6: =HLOOKUP(REG_TRA_DEMANDS!G$3,'BY-Demands'!$J$5:$AK$14,MATCH($E6,'BY-Demands'!$I$5:$I$14,0),FALSE)*HLOOKUP(REG_TRA_DEMANDS!$F6,DEMANDS!$G$2:$CK$25,MATCH($E6,DEMANDS!$E$2:$E$25,0),FALSE)/HLOOKUP(2018,DEMANDS!$G$2:$CK$25,MATCH($E6,DEMANDS!$E$2:$E$25,0),FALSE) -> 0.18420818 | H6: =HLOOKUP(REG_TRA_DEMANDS!H$3,'BY-Demands'!$J$5:$AK$14,MATCH($E6,'BY-Demands'!$I$5:$I$14,0),FALSE)*HLOOKUP(REG_TRA_DEMANDS!$F6,DEMANDS!$G$2:$CK$25,MATCH($E6,DEMANDS!$E$2:$E$25,0),FALSE)/HLOOKUP(2018,DEMANDS!$G$2:$CK$25,MATCH($E6,DEMANDS!$E$2:$E$25,0),FALSE) -> 3.6827582 | I6: =HLOOKUP(REG_TRA_DEMANDS!I$3,'BY-Demands'!$J$5:$AK$14,MATCH($E6,'BY-Demands'!$I$5:$I$14,0),FALSE)*HLOOKUP(REG_TRA_DEMANDS!$F6,DEMANDS!$G$2:$CK$25,MATCH($E6,DEMANDS!$E$2:$E$25,0),FALSE)/HLOOKUP(2018,DEMANDS!$G$2:$CK$25,MATCH($E6,DEMANDS!$E$2:$E$25,0),FALSE) -> 0.679193 | J6: =HLOOKUP(REG_TRA_DEMANDS!J$3,'BY-Demands'!$J$5:$AK$14,MATCH($E6,'BY-Demands'!$I$5:$I$14,0),FALSE)*HLOOKUP(REG_TRA_DEMANDS!$F6,DEMANDS!$G$2:$CK$25,MATCH($E6,DEMANDS!$E$2:$E$25,0),FALSE)/HLOOKUP(2018,DEMANDS!$G$2:$CK$25,MATCH($E6,DEMANDS!$E$2:$E$25,0),FALSE) -> 0.31510171 | K6: =HLOOKUP(REG_TRA_DEMANDS!K$3,'BY-Demands'!$J$5:$AK$14,MATCH($E6,'BY-Demands'!$I$5:$I$14,0),FALSE)*HLOOKUP(REG_TRA_DEMANDS!$F6,DEMANDS!$G$2:$CK$25,MATCH($E6,DEMANDS!$E$2:$E$25,0),FALSE)/HLOOKUP(2018,DEMANDS!$G$2:$CK$25,MATCH($E6,DEMANDS!$E$2:$E$25,0),FALSE) -> 0.24842606 | L6: =HLOOKUP(REG_TRA_DEMANDS!L$3,'BY-Demands'!$J$5:$AK$14,MATCH($E6,'BY-Demands'!$I$5:$I$14,0),FALSE)*HLOOKUP(REG_TRA_DEMANDS!$F6,DEMANDS!$G$2:$CK$25,MATCH($E6,DEMANDS!$E$2:$E$25,0),FALSE)/HLOOKUP(2018,DEMANDS!$G$2:$CK$25,MATCH($E6,DEMANDS!$E$2:$E$25,0),FALSE) -> 0.12482562 | M6: =HLOOKUP(REG_TRA_DEMANDS!M$3,'BY-Demands'!$J$5:$AK$14,MATCH($E6,'BY-Demands'!$I$5:$I$14,0),FALSE)*HLOOKUP(REG_TRA_DEMANDS!$F6,DEMANDS!$G$2:$CK$25,MATCH($E6,DEMANDS!$E$2:$E$25,0),FALSE)/HLOOKUP(2018,DEMANDS!$G$2:$CK$25,MATCH($E6,DEMANDS!$E$2:$E$25,0),FALSE) -> 0.35793902 | N6: =HLOOKUP(REG_TRA_DEMANDS!N$3,'BY-Demands'!$J$5:$AK$14,MATCH($E6,'BY-Demands'!$I$5:$I$14,0),FALSE)*HLOOKUP(REG_TRA_DEMANDS!$F6,DEMANDS!$G$2:$CK$25,MATCH($E6,DEMANDS!$E$2:$E$25,0),FALSE)/HLOOKUP(2018,DEMANDS!$G$2:$CK$25,MATCH($E6,DEMANDS!$E$2:$E$25,0),FALSE) -> 0.58917679 | ... AF6: =HLOOKUP(REG_TRA_DEMANDS!AF$3,'BY-Demands'!$J$5:$AK$14,MATCH($E6,'BY-Demands'!$I$5:$I$14,0),FALSE)*HLOOKUP(REG_TRA_DEMANDS!$F6,DEMANDS!$G$2:$CK$25,MATCH($E6,DEMANDS!$E$2:$E$25,0),FALSE)/HLOOKUP(2018,DEMANDS!$G$2:$CK$25,MATCH($E6,DEMANDS!$E$2:$E$25,0),FALSE) -> 0.20056462
D7: COM_PROJ | E7: =DEMANDS!$E$17 -> TRAPS | F7: 2023 | G7: =HLOOKUP(REG_TRA_DEMANDS!G$3,'BY-Demands'!$J$5:$AK$14,MATCH($E7,'BY-Demands'!$I$5:$I$14,0),FALSE)*HLOOKUP(REG_TRA_DEMANDS!$F7,DEMANDS!$G$2:$CK$25,MATCH($E7,DEMANDS!$E$2:$E$25,0),FALSE)/HLOOKUP(2018,DEMANDS!$G$2:$CK$25,MATCH($E7,DEMANDS!$E$2:$E$25,0),FALSE) -> 0.18487919 | H7: =HLOOKUP(REG_TRA_DEMANDS!H$3,'BY-Demands'!$J$5:$AK$14,MATCH($E7,'BY-Demands'!$I$5:$I$14,0),FALSE)*HLOOKUP(REG_TRA_DEMANDS!$F7,DEMANDS!$G$2:$CK$25,MATCH($E7,DEMANDS!$E$2:$E$25,0),FALSE)/HLOOKUP(2018,DEMANDS!$G$2:$CK$25,MATCH($E7,DEMANDS!$E$2:$E$25,0),FALSE) -> 3.6961733 | I7: =HLOOKUP(REG_TRA_DEMANDS!I$3,'BY-Demands'!$J$5:$AK$14,MATCH($E7,'BY-Demands'!$I$5:$I$14,0),FALSE)*HLOOKUP(REG_TRA_DEMANDS!$F7,DEMANDS!$G$2:$CK$25,MATCH($E7,DEMANDS!$E$2:$E$25,0),FALSE)/HLOOKUP(2018,DEMANDS!$G$2:$CK$25,MATCH($E7,DEMANDS!$E$2:$E$25,0),FALSE) -> 0.68166707 | J7: =HLOOKUP(REG_TRA_DEMANDS!J$3,'BY-Demands'!$J$5:$AK$14,MATCH($E7,'BY-Demands'!$I$5:$I$14,0),FALSE)*HLOOKUP(REG_TRA_DEMANDS!$F7,DEMANDS!$G$2:$CK$25,MATCH($E7,DEMANDS!$E$2:$E$25,0),FALSE)/HLOOKUP(2018,DEMANDS!$G$2:$CK$25,MATCH($E7,DEMANDS!$E$2:$E$25,0),FALSE) -> 0.31624952 | K7: =HLOOKUP(REG_TRA_DEMANDS!K$3,'BY-Demands'!$J$5:$AK$14,MATCH($E7,'BY-Demands'!$I$5:$I$14,0),FALSE)*HLOOKUP(REG_TRA_DEMANDS!$F7,DEMANDS!$G$2:$CK$25,MATCH($E7,DEMANDS!$E$2:$E$25,0),FALSE)/HLOOKUP(2018,DEMANDS!$G$2:$CK$25,MATCH($E7,DEMANDS!$E$2:$E$25,0),FALSE) -> 0.24933099 | L7: =HLOOKUP(REG_TRA_DEMANDS!L$3,'BY-Demands'!$J$5:$AK$14,MATCH($E7,'BY-Demands'!$I$5:$I$14,0),FALSE)*HLOOKUP(REG_TRA_DEMANDS!$F7,DEMANDS!$G$2:$CK$25,MATCH($E7,DEMANDS!$E$2:$E$25,0),FALSE)/HLOOKUP(2018,DEMANDS!$G$2:$CK$25,MATCH($E7,DEMANDS!$E$2:$E$25,0),FALSE) -> 0.12528032 | M7: =HLOOKUP(REG_TRA_DEMANDS!M$3,'BY-Demands'!$J$5:$AK$14,MATCH($E7,'BY-Demands'!$I$5:$I$14,0),FALSE)*HLOOKUP(REG_TRA_DEMANDS!$F7,DEMANDS!$G$2:$CK$25,MATCH($E7,DEMANDS!$E$2:$E$25,0),FALSE)/HLOOKUP(2018,DEMANDS!$G$2:$CK$25,MATCH($E7,DEMANDS!$E$2:$E$25,0),FALSE) -> 0.35924287 | N7: =HLOOKUP(REG_TRA_DEMANDS!N$3,'BY-Demands'!$J$5:$AK$14,MATCH($E7,'BY-Demands'!$I$5:$I$14,0),FALSE)*HLOOKUP(REG_TRA_DEMANDS!$F7,DEMANDS!$G$2:$CK$25,MATCH($E7,DEMANDS!$E$2:$E$25,0),FALSE)/HLOOKUP(2018,DEMANDS!$G$2:$CK$25,MATCH($E7,DEMANDS!$E$2:$E$25,0),FALSE) -> 0.59132296 | ... AF7: =HLOOKUP(REG_TRA_DEMANDS!AF$3,'BY-Demands'!$J$5:$AK$14,MATCH($E7,'BY-Demands'!$I$5:$I$14,0),FALSE)*HLOOKUP(REG_TRA_DEMANDS!$F7,DEMANDS!$G$2:$CK$25,MATCH($E7,DEMANDS!$E$2:$E$25,0),FALSE)/HLOOKUP(2018,DEMANDS!$G$2:$CK$25,MATCH($E7,DEMANDS!$E$2:$E$25,0),FALSE) -> 0.20129521
D8: COM_PROJ | E8: =DEMANDS!$E$17 -> TRAPS | F8: 2024 | G8: =HLOOKUP(REG_TRA_DEMANDS!G$3,'BY-Demands'!$J$5:$AK$14,MATCH($E8,'BY-Demands'!$I$5:$I$14,0),FALSE)*HLOOKUP(REG_TRA_DEMANDS!$F8,DEMANDS!$G$2:$CK$25,MATCH($E8,DEMANDS!$E$2:$E$25,0),FALSE)/HLOOKUP(2018,DEMANDS!$G$2:$CK$25,MATCH($E8,DEMANDS!$E$2:$E$25,0),FALSE) -> 0.18719018 | H8: =HLOOKUP(REG_TRA_DEMANDS!H$3,'BY-Demands'!$J$5:$AK$14,MATCH($E8,'BY-Demands'!$I$5:$I$14,0),FALSE)*HLOOKUP(REG_TRA_DEMANDS!$F8,DEMANDS!$G$2:$CK$25,MATCH($E8,DEMANDS!$E$2:$E$25,0),FALSE)/HLOOKUP(2018,DEMANDS!$G$2:$CK$25,MATCH($E8,DEMANDS!$E$2:$E$25,0),FALSE) -> 3.7423754 | I8: =HLOOKUP(REG_TRA_DEMANDS!I$3,'BY-Demands'!$J$5:$AK$14,MATCH($E8,'BY-Demands'!$I$5:$I$14,0),FALSE)*HLOOKUP(REG_TRA_DEMANDS!$F8,DEMANDS!$G$2:$CK$25,MATCH($E8,DEMANDS!$E$2:$E$25,0),FALSE)/HLOOKUP(2018,DEMANDS!$G$2:$CK$25,MATCH($E8,DEMANDS!$E$2:$E$25,0),FALSE) -> 0.69018791 | J8: =HLOOKUP(REG_TRA_DEMANDS!J$3,'BY-Demands'!$J$5:$AK$14,MATCH($E8,'BY-Demands'!$I$5:$I$14,0),FALSE)*HLOOKUP(REG_TRA_DEMANDS!$F8,DEMANDS!$G$2:$CK$25,MATCH($E8,DEMANDS!$E$2:$E$25,0),FALSE)/HLOOKUP(2018,DEMANDS!$G$2:$CK$25,MATCH($E8,DEMANDS!$E$2:$E$25,0),FALSE) -> 0.32020264 | K8: =HLOOKUP(REG_TRA_DEMANDS!K$3,'BY-Demands'!$J$5:$AK$14,MATCH($E8,'BY-Demands'!$I$5:$I$14,0),FALSE)*HLOOKUP(REG_TRA_DEMANDS!$F8,DEMANDS!$G$2:$CK$25,MATCH($E8,DEMANDS!$E$2:$E$25,0),FALSE)/HLOOKUP(2018,DEMANDS!$G$2:$CK$25,MATCH($E8,DEMANDS!$E$2:$E$25,0),FALSE) -> 0.25244763 | L8: =HLOOKUP(REG_TRA_DEMANDS!L$3,'BY-Demands'!$J$5:$AK$14,MATCH($E8,'BY-Demands'!$I$5:$I$14,0),FALSE)*HLOOKUP(REG_TRA_DEMANDS!$F8,DEMANDS!$G$2:$CK$25,MATCH($E8,DEMANDS!$E$2:$E$25,0),FALSE)/HLOOKUP(2018,DEMANDS!$G$2:$CK$25,MATCH($E8,DEMANDS!$E$2:$E$25,0),FALSE) -> 0.12684632 | M8: =HLOOKUP(REG_TRA_DEMANDS!M$3,'BY-Demands'!$J$5:$AK$14,MATCH($E8,'BY-Demands'!$I$5:$I$14,0),FALSE)*HLOOKUP(REG_TRA_DEMANDS!$F8,DEMANDS!$G$2:$CK$25,MATCH($E8,DEMANDS!$E$2:$E$25,0),FALSE)/HLOOKUP(2018,DEMANDS!$G$2:$CK$25,MATCH($E8,DEMANDS!$E$2:$E$25,0),FALSE) -> 0.36373341 | N8: =HLOOKUP(REG_TRA_DEMANDS!N$3,'BY-Demands'!$J$5:$AK$14,MATCH($E8,'BY-Demands'!$I$5:$I$14,0),FALSE)*HLOOKUP(REG_TRA_DEMANDS!$F8,DEMANDS!$G$2:$CK$25,MATCH($E8,DEMANDS!$E$2:$E$25,0),FALSE)/HLOOKUP(2018,DEMANDS!$G$2:$CK$25,MATCH($E8,DEMANDS!$E$2:$E$25,0),FALSE) -> 0.5987145 | ... AF8: =HLOOKUP(REG_TRA_DEMANDS!AF$3,'BY-Demands'!$J$5:$AK$14,MATCH($E8,'BY-Demands'!$I$5:$I$14,0),FALSE)*HLOOKUP(REG_TRA_DEMANDS!$F8,DEMANDS!$G$2:$CK$25,MATCH($E8,DEMANDS!$E$2:$E$25,0),FALSE)/HLOOKUP(2018,DEMANDS!$G$2:$CK$25,MATCH($E8,DEMANDS!$E$2:$E$25,0),FALSE) -> 0.2038114
D9: COM_PROJ | E9: =DEMANDS!$E$17 -> TRAPS | F9: 2025 | G9: =HLOOKUP(REG_TRA_DEMANDS!G$3,'BY-Demands'!$J$5:$AK$14,MATCH($E9,'BY-Demands'!$I$5:$I$14,0),FALSE)*HLOOKUP(REG_TRA_DEMANDS!$F9,DEMANDS!$G$2:$CK$25,MATCH($E9,DEMANDS!$E$2:$E$25,0),FALSE)/HLOOKUP(2018,DEMANDS!$G$2:$CK$25,MATCH($E9,DEMANDS!$E$2:$E$25,0),FALSE) -> 0.18953005 | H9: =HLOOKUP(REG_TRA_DEMANDS!H$3,'BY-Demands'!$J$5:$AK$14,MATCH($E9,'BY-Demands'!$I$5:$I$14,0),FALSE)*HLOOKUP(REG_TRA_DEMANDS!$F9,DEMANDS!$G$2:$CK$25,MATCH($E9,DEMANDS!$E$2:$E$25,0),FALSE)/HLOOKUP(2018,DEMANDS!$G$2:$CK$25,MATCH($E9,DEMANDS!$E$2:$E$25,0),FALSE) -> 3.7891551 | I9: =HLOOKUP(REG_TRA_DEMANDS!I$3,'BY-Demands'!$J$5:$AK$14,MATCH($E9,'BY-Demands'!$I$5:$I$14,0),FALSE)*HLOOKUP(REG_TRA_DEMANDS!$F9,DEMANDS!$G$2:$CK$25,MATCH($E9,DEMANDS!$E$2:$E$25,0),FALSE)/HLOOKUP(2018,DEMANDS!$G$2:$CK$25,MATCH($E9,DEMANDS!$E$2:$E$25,0),FALSE) -> 0.69881526 | J9: =HLOOKUP(REG_TRA_DEMANDS!J$3,'BY-Demands'!$J$5:$AK$14,MATCH($E9,'BY-Demands'!$I$5:$I$14,0),FALSE)*HLOOKUP(REG_TRA_DEMANDS!$F9,DEMANDS!$G$2:$CK$25,MATCH($E9,DEMANDS!$E$2:$E$25,0),FALSE)/HLOOKUP(2018,DEMANDS!$G$2:$CK$25,MATCH($E9,DEMANDS!$E$2:$E$25,0),FALSE) -> 0.32420518 | K9: =HLOOKUP(REG_TRA_DEMANDS!K$3,'BY-Demands'!$J$5:$AK$14,MATCH($E9,'BY-Demands'!$I$5:$I$14,0),FALSE)*HLOOKUP(REG_TRA_DEMANDS!$F9,DEMANDS!$G$2:$CK$25,MATCH($E9,DEMANDS!$E$2:$E$25,0),FALSE)/HLOOKUP(2018,DEMANDS!$G$2:$CK$25,MATCH($E9,DEMANDS!$E$2:$E$25,0),FALSE) -> 0.25560323 | L9: =HLOOKUP(REG_TRA_DEMANDS!L$3,'BY-Demands'!$J$5:$AK$14,MATCH($E9,'BY-Demands'!$I$5:$I$14,0),FALSE)*HLOOKUP(REG_TRA_DEMANDS!$F9,DEMANDS!$G$2:$CK$25,MATCH($E9,DEMANDS!$E$2:$E$25,0),FALSE)/HLOOKUP(2018,DEMANDS!$G$2:$CK$25,MATCH($E9,DEMANDS!$E$2:$E$25,0),FALSE) -> 0.1284319 | M9: =HLOOKUP(REG_TRA_DEMANDS!M$3,'BY-Demands'!$J$5:$AK$14,MATCH($E9,'BY-Demands'!$I$5:$I$14,0),FALSE)*HLOOKUP(REG_TRA_DEMANDS!$F9,DEMANDS!$G$2:$CK$25,MATCH($E9,DEMANDS!$E$2:$E$25,0),FALSE)/HLOOKUP(2018,DEMANDS!$G$2:$CK$25,MATCH($E9,DEMANDS!$E$2:$E$25,0),FALSE) -> 0.36828007 | N9: =HLOOKUP(REG_TRA_DEMANDS!N$3,'BY-Demands'!$J$5:$AK$14,MATCH($E9,'BY-Demands'!$I$5:$I$14,0),FALSE)*HLOOKUP(REG_TRA_DEMANDS!$F9,DEMANDS!$G$2:$CK$25,MATCH($E9,DEMANDS!$E$2:$E$25,0),FALSE)/HLOOKUP(2018,DEMANDS!$G$2:$CK$25,MATCH($E9,DEMANDS!$E$2:$E$25,0),FALSE) -> 0.60619843 | ... AF9: =HLOOKUP(REG_TRA_DEMANDS!AF$3,'BY-Demands'!$J$5:$AK$14,MATCH($E9,'BY-Demands'!$I$5:$I$14,0),FALSE)*HLOOKUP(REG_TRA_DEMANDS!$F9,DEMANDS!$G$2:$CK$25,MATCH($E9,DEMANDS!$E$2:$E$25,0),FALSE)/HLOOKUP(2018,DEMANDS!$G$2:$CK$25,MATCH($E9,DEMANDS!$E$2:$E$25,0),FALSE) -> 0.20635904
D10: COM_PROJ | E10: =DEMANDS!$E$17 -> TRAPS | F10: 2026 | G10: =HLOOKUP(REG_TRA_DEMANDS!G$3,'BY-Demands'!$J$5:$AK$14,MATCH($E10,'BY-Demands'!$I$5:$I$14,0),FALSE)*HLOOKUP(REG_TRA_DEMANDS!$F10,DEMANDS!$G$2:$CK$25,MATCH($E10,DEMANDS!$E$2:$E$25,0),FALSE)/HLOOKUP(2018,DEMANDS!$G$2:$CK$25,MATCH($E10,DEMANDS!$E$2:$E$25,0),FALSE) -> 0.19189918 | H10: =HLOOKUP(REG_TRA_DEMANDS!H$3,'BY-Demands'!$J$5:$AK$14,MATCH($E10,'BY-Demands'!$I$5:$I$14,0),FALSE)*HLOOKUP(REG_TRA_DEMANDS!$F10,DEMANDS!$G$2:$CK$25,MATCH($E10,DEMANDS!$E$2:$E$25,0),FALSE)/HLOOKUP(2018,DEMANDS!$G$2:$CK$25,MATCH($E10,DEMANDS!$E$2:$E$25,0),FALSE) -> 3.8365196 | I10: =HLOOKUP(REG_TRA_DEMANDS!I$3,'BY-Demands'!$J$5:$AK$14,MATCH($E10,'BY-Demands'!$I$5:$I$14,0),FALSE)*HLOOKUP(REG_TRA_DEMANDS!$F10,DEMANDS!$G$2:$CK$25,MATCH($E10,DEMANDS!$E$2:$E$25,0),FALSE)/HLOOKUP(2018,DEMANDS!$G$2:$CK$25,MATCH($E10,DEMANDS!$E$2:$E$25,0),FALSE) -> 0.70755045 | J10: =HLOOKUP(REG_TRA_DEMANDS!J$3,'BY-Demands'!$J$5:$AK$14,MATCH($E10,'BY-Demands'!$I$5:$I$14,0),FALSE)*HLOOKUP(REG_TRA_DEMANDS!$F10,DEMANDS!$G$2:$CK$25,MATCH($E10,DEMANDS!$E$2:$E$25,0),FALSE)/HLOOKUP(2018,DEMANDS!$G$2:$CK$25,MATCH($E10,DEMANDS!$E$2:$E$25,0),FALSE) -> 0.32825774 | K10: =HLOOKUP(REG_TRA_DEMANDS!K$3,'BY-Demands'!$J$5:$AK$14,MATCH($E10,'BY-Demands'!$I$5:$I$14,0),FALSE)*HLOOKUP(REG_TRA_DEMANDS!$F10,DEMANDS!$G$2:$CK$25,MATCH($E10,DEMANDS!$E$2:$E$25,0),FALSE)/HLOOKUP(2018,DEMANDS!$G$2:$CK$25,MATCH($E10,DEMANDS!$E$2:$E$25,0),FALSE) -> 0.25879827 | L10: =HLOOKUP(REG_TRA_DEMANDS!L$3,'BY-Demands'!$J$5:$AK$14,MATCH($E10,'BY-Demands'!$I$5:$I$14,0),FALSE)*HLOOKUP(REG_TRA_DEMANDS!$F10,DEMANDS!$G$2:$CK$25,MATCH($E10,DEMANDS!$E$2:$E$25,0),FALSE)/HLOOKUP(2018,DEMANDS!$G$2:$CK$25,MATCH($E10,DEMANDS!$E$2:$E$25,0),FALSE) -> 0.1300373 | M10: =HLOOKUP(REG_TRA_DEMANDS!M$3,'BY-Demands'!$J$5:$AK$14,MATCH($E10,'BY-Demands'!$I$5:$I$14,0),FALSE)*HLOOKUP(REG_TRA_DEMANDS!$F10,DEMANDS!$G$2:$CK$25,MATCH($E10,DEMANDS!$E$2:$E$25,0),FALSE)/HLOOKUP(2018,DEMANDS!$G$2:$CK$25,MATCH($E10,DEMANDS!$E$2:$E$25,0),FALSE) -> 0.37288357 | N10: =HLOOKUP(REG_TRA_DEMANDS!N$3,'BY-Demands'!$J$5:$AK$14,MATCH($E10,'BY-Demands'!$I$5:$I$14,0),FALSE)*HLOOKUP(REG_TRA_DEMANDS!$F10,DEMANDS!$G$2:$CK$25,MATCH($E10,DEMANDS!$E$2:$E$25,0),FALSE)/HLOOKUP(2018,DEMANDS!$G$2:$CK$25,MATCH($E10,DEMANDS!$E$2:$E$25,0),FALSE) -> 0.61377591 | ... AF10: =HLOOKUP(REG_TRA_DEMANDS!AF$3,'BY-Demands'!$J$5:$AK$14,MATCH($E10,'BY-Demands'!$I$5:$I$14,0),FALSE)*HLOOKUP(REG_TRA_DEMANDS!$F10,DEMANDS!$G$2:$CK$25,MATCH($E10,DEMANDS!$E$2:$E$25,0),FALSE)/HLOOKUP(2018,DEMANDS!$G$2:$CK$25,MATCH($E10,DEMANDS!$E$2:$E$25,0),FALSE) -> 0.20893853
D11: COM_PROJ | E11: =DEMANDS!$E$17 -> TRAPS | F11: 2027 | G11: =HLOOKUP(REG_TRA_DEMANDS!G$3,'BY-Demands'!$J$5:$AK$14,MATCH($E11,'BY-Demands'!$I$5:$I$14,0),FALSE)*HLOOKUP(REG_TRA_DEMANDS!$F11,DEMANDS!$G$2:$CK$25,MATCH($E11,DEMANDS!$E$2:$E$25,0),FALSE)/HLOOKUP(2018,DEMANDS!$G$2:$CK$25,MATCH($E11,DEMANDS!$E$2:$E$25,0),FALSE) -> 0.19429792 | H11: =HLOOKUP(REG_TRA_DEMANDS!H$3,'BY-Demands'!$J$5:$AK$14,MATCH($E11,'BY-Demands'!$I$5:$I$14,0),FALSE)*HLOOKUP(REG_TRA_DEMANDS!$F11,DEMANDS!$G$2:$CK$25,MATCH($E11,DEMANDS!$E$2:$E$25,0),FALSE)/HLOOKUP(2018,DEMANDS!$G$2:$CK$25,MATCH($E11,DEMANDS!$E$2:$E$25,0),FALSE) -> 3.8844761 | I11: =HLOOKUP(REG_TRA_DEMANDS!I$3,'BY-Demands'!$J$5:$AK$14,MATCH($E11,'BY-Demands'!$I$5:$I$14,0),FALSE)*HLOOKUP(REG_TRA_DEMANDS!$F11,DEMANDS!$G$2:$CK$25,MATCH($E11,DEMANDS!$E$2:$E$25,0),FALSE)/HLOOKUP(2018,DEMANDS!$G$2:$CK$25,MATCH($E11,DEMANDS!$E$2:$E$25,0),FALSE) -> 0.71639483 | J11: =HLOOKUP(REG_TRA_DEMANDS!J$3,'BY-Demands'!$J$5:$AK$14,MATCH($E11,'BY-Demands'!$I$5:$I$14,0),FALSE)*HLOOKUP(REG_TRA_DEMANDS!$F11,DEMANDS!$G$2:$CK$25,MATCH($E11,DEMANDS!$E$2:$E$25,0),FALSE)/HLOOKUP(2018,DEMANDS!$G$2:$CK$25,MATCH($E11,DEMANDS!$E$2:$E$25,0),FALSE) -> 0.33236096 | K11: =HLOOKUP(REG_TRA_DEMANDS!K$3,'BY-Demands'!$J$5:$AK$14,MATCH($E11,'BY-Demands'!$I$5:$I$14,0),FALSE)*HLOOKUP(REG_TRA_DEMANDS!$F11,DEMANDS!$G$2:$CK$25,MATCH($E11,DEMANDS!$E$2:$E$25,0),FALSE)/HLOOKUP(2018,DEMANDS!$G$2:$CK$25,MATCH($E11,DEMANDS!$E$2:$E$25,0),FALSE) -> 0.26203324 | L11: =HLOOKUP(REG_TRA_DEMANDS!L$3,'BY-Demands'!$J$5:$AK$14,MATCH($E11,'BY-Demands'!$I$5:$I$14,0),FALSE)*HLOOKUP(REG_TRA_DEMANDS!$F11,DEMANDS!$G$2:$CK$25,MATCH($E11,DEMANDS!$E$2:$E$25,0),FALSE)/HLOOKUP(2018,DEMANDS!$G$2:$CK$25,MATCH($E11,DEMANDS!$E$2:$E$25,0),FALSE) -> 0.13166277 | M11: =HLOOKUP(REG_TRA_DEMANDS!M$3,'BY-Demands'!$J$5:$AK$14,MATCH($E11,'BY-Demands'!$I$5:$I$14,0),FALSE)*HLOOKUP(REG_TRA_DEMANDS!$F11,DEMANDS!$G$2:$CK$25,MATCH($E11,DEMANDS!$E$2:$E$25,0),FALSE)/HLOOKUP(2018,DEMANDS!$G$2:$CK$25,MATCH($E11,DEMANDS!$E$2:$E$25,0),FALSE) -> 0.37754462 | N11: =HLOOKUP(REG_TRA_DEMANDS!N$3,'BY-Demands'!$J$5:$AK$14,MATCH($E11,'BY-Demands'!$I$5:$I$14,0),FALSE)*HLOOKUP(REG_TRA_DEMANDS!$F11,DEMANDS!$G$2:$CK$25,MATCH($E11,DEMANDS!$E$2:$E$25,0),FALSE)/HLOOKUP(2018,DEMANDS!$G$2:$CK$25,MATCH($E11,DEMANDS!$E$2:$E$25,0),FALSE) -> 0.62144811 | ... AF11: =HLOOKUP(REG_TRA_DEMANDS!AF$3,'BY-Demands'!$J$5:$AK$14,MATCH($E11,'BY-Demands'!$I$5:$I$14,0),FALSE)*HLOOKUP(REG_TRA_DEMANDS!$F11,DEMANDS!$G$2:$CK$25,MATCH($E11,DEMANDS!$E$2:$E$25,0),FALSE)/HLOOKUP(2018,DEMANDS!$G$2:$CK$25,MATCH($E11,DEMANDS!$E$2:$E$25,0),FALSE) -> 0.21155026
D12: COM_PROJ | E12: =DEMANDS!$E$17 -> TRAPS | F12: 2028 | G12: =HLOOKUP(REG_TRA_DEMANDS!G$3,'BY-Demands'!$J$5:$AK$14,MATCH($E12,'BY-Demands'!$I$5:$I$14,0),FALSE)*HLOOKUP(REG_TRA_DEMANDS!$F12,DEMANDS!$G$2:$CK$25,MATCH($E12,DEMANDS!$E$2:$E$25,0),FALSE)/HLOOKUP(2018,DEMANDS!$G$2:$CK$25,MATCH($E12,DEMANDS!$E$2:$E$25,0),FALSE) -> 0.19672664 | H12: =HLOOKUP(REG_TRA_DEMANDS!H$3,'BY-Demands'!$J$5:$AK$14,MATCH($E12,'BY-Demands'!$I$5:$I$14,0),FALSE)*HLOOKUP(REG_TRA_DEMANDS!$F12,DEMANDS!$G$2:$CK$25,MATCH($E12,DEMANDS!$E$2:$E$25,0),FALSE)/HLOOKUP(2018,DEMANDS!$G$2:$CK$25,MATCH($E12,DEMANDS!$E$2:$E$25,0),FALSE) -> 3.933032 | I12: =HLOOKUP(REG_TRA_DEMANDS!I$3,'BY-Demands'!$J$5:$AK$14,MATCH($E12,'BY-Demands'!$I$5:$I$14,0),FALSE)*HLOOKUP(REG_TRA_DEMANDS!$F12,DEMANDS!$G$2:$CK$25,MATCH($E12,DEMANDS!$E$2:$E$25,0),FALSE)/HLOOKUP(2018,DEMANDS!$G$2:$CK$25,MATCH($E12,DEMANDS!$E$2:$E$25,0),FALSE) -> 0.72534976 | J12: =HLOOKUP(REG_TRA_DEMANDS!J$3,'BY-Demands'!$J$5:$AK$14,MATCH($E12,'BY-Demands'!$I$5:$I$14,0),FALSE)*HLOOKUP(REG_TRA_DEMANDS!$F12,DEMANDS!$G$2:$CK$25,MATCH($E12,DEMANDS!$E$2:$E$25,0),FALSE)/HLOOKUP(2018,DEMANDS!$G$2:$CK$25,MATCH($E12,DEMANDS!$E$2:$E$25,0),FALSE) -> 0.33651547 | K12: =HLOOKUP(REG_TRA_DEMANDS!K$3,'BY-Demands'!$J$5:$AK$14,MATCH($E12,'BY-Demands'!$I$5:$I$14,0),FALSE)*HLOOKUP(REG_TRA_DEMANDS!$F12,DEMANDS!$G$2:$CK$25,MATCH($E12,DEMANDS!$E$2:$E$25,0),FALSE)/HLOOKUP(2018,DEMANDS!$G$2:$CK$25,MATCH($E12,DEMANDS!$E$2:$E$25,0),FALSE) -> 0.26530866 | L12: =HLOOKUP(REG_TRA_DEMANDS!L$3,'BY-Demands'!$J$5:$AK$14,MATCH($E12,'BY-Demands'!$I$5:$I$14,0),FALSE)*HLOOKUP(REG_TRA_DEMANDS!$F12,DEMANDS!$G$2:$CK$25,MATCH($E12,DEMANDS!$E$2:$E$25,0),FALSE)/HLOOKUP(2018,DEMANDS!$G$2:$CK$25,MATCH($E12,DEMANDS!$E$2:$E$25,0),FALSE) -> 0.13330855 | M12: =HLOOKUP(REG_TRA_DEMANDS!M$3,'BY-Demands'!$J$5:$AK$14,MATCH($E12,'BY-Demands'!$I$5:$I$14,0),FALSE)*HLOOKUP(REG_TRA_DEMANDS!$F12,DEMANDS!$G$2:$CK$25,MATCH($E12,DEMANDS!$E$2:$E$25,0),FALSE)/HLOOKUP(2018,DEMANDS!$G$2:$CK$25,MATCH($E12,DEMANDS!$E$2:$E$25,0),FALSE) -> 0.38226393 | N12: =HLOOKUP(REG_TRA_DEMANDS!N$3,'BY-Demands'!$J$5:$AK$14,MATCH($E12,'BY-Demands'!$I$5:$I$14,0),FALSE)*HLOOKUP(REG_TRA_DEMANDS!$F12,DEMANDS!$G$2:$CK$25,MATCH($E12,DEMANDS!$E$2:$E$25,0),FALSE)/HLOOKUP(2018,DEMANDS!$G$2:$CK$25,MATCH($E12,DEMANDS!$E$2:$E$25,0),FALSE) -> 0.62921621 | ... AF12: =HLOOKUP(REG_TRA_DEMANDS!AF$3,'BY-Demands'!$J$5:$AK$14,MATCH($E12,'BY-Demands'!$I$5:$I$14,0),FALSE)*HLOOKUP(REG_TRA_DEMANDS!$F12,DEMANDS!$G$2:$CK$25,MATCH($E12,DEMANDS!$E$2:$E$25,0),FALSE)/HLOOKUP(2018,DEMANDS!$G$2:$CK$25,MATCH($E12,DEMANDS!$E$2:$E$25,0),FALSE) -> 0.21419464
D13: COM_PROJ | E13: =DEMANDS!$E$17 -> TRAPS | F13: 2029 | G13: =HLOOKUP(REG_TRA_DEMANDS!G$3,'BY-Demands'!$J$5:$AK$14,MATCH($E13,'BY-Demands'!$I$5:$I$14,0),FALSE)*HLOOKUP(REG_TRA_DEMANDS!$F13,DEMANDS!$G$2:$CK$25,MATCH($E13,DEMANDS!$E$2:$E$25,0),FALSE)/HLOOKUP(2018,DEMANDS!$G$2:$CK$25,MATCH($E13,DEMANDS!$E$2:$E$25,0),FALSE) -> 0.19918572 | H13: =HLOOKUP(REG_TRA_DEMANDS!H$3,'BY-Demands'!$J$5:$AK$14,MATCH($E13,'BY-Demands'!$I$5:$I$14,0),FALSE)*HLOOKUP(REG_TRA_DEMANDS!$F13,DEMANDS!$G$2:$CK$25,MATCH($E13,DEMANDS!$E$2:$E$25,0),FALSE)/HLOOKUP(2018,DEMANDS!$G$2:$CK$25,MATCH($E13,DEMANDS!$E$2:$E$25,0),FALSE) -> 3.9821949 | I13: =HLOOKUP(REG_TRA_DEMANDS!I$3,'BY-Demands'!$J$5:$AK$14,MATCH($E13,'BY-Demands'!$I$5:$I$14,0),FALSE)*HLOOKUP(REG_TRA_DEMANDS!$F13,DEMANDS!$G$2:$CK$25,MATCH($E13,DEMANDS!$E$2:$E$25,0),FALSE)/HLOOKUP(2018,DEMANDS!$G$2:$CK$25,MATCH($E13,DEMANDS!$E$2:$E$25,0),FALSE) -> 0.73441664 | J13: =HLOOKUP(REG_TRA_DEMANDS!J$3,'BY-Demands'!$J$5:$AK$14,MATCH($E13,'BY-Demands'!$I$5:$I$14,0),FALSE)*HLOOKUP(REG_TRA_DEMANDS!$F13,DEMANDS!$G$2:$CK$25,MATCH($E13,DEMANDS!$E$2:$E$25,0),FALSE)/HLOOKUP(2018,DEMANDS!$G$2:$CK$25,MATCH($E13,DEMANDS!$E$2:$E$25,0),FALSE) -> 0.34072192 | K13: =HLOOKUP(REG_TRA_DEMANDS!K$3,'BY-Demands'!$J$5:$AK$14,MATCH($E13,'BY-Demands'!$I$5:$I$14,0),FALSE)*HLOOKUP(REG_TRA_DEMANDS!$F13,DEMANDS!$G$2:$CK$25,MATCH($E13,DEMANDS!$E$2:$E$25,0),FALSE)/HLOOKUP(2018,DEMANDS!$G$2:$CK$25,MATCH($E13,DEMANDS!$E$2:$E$25,0),FALSE) -> 0.26862502 | L13: =HLOOKUP(REG_TRA_DEMANDS!L$3,'BY-Demands'!$J$5:$AK$14,MATCH($E13,'BY-Demands'!$I$5:$I$14,0),FALSE)*HLOOKUP(REG_TRA_DEMANDS!$F13,DEMANDS!$G$2:$CK$25,MATCH($E13,DEMANDS!$E$2:$E$25,0),FALSE)/HLOOKUP(2018,DEMANDS!$G$2:$CK$25,MATCH($E13,DEMANDS!$E$2:$E$25,0),FALSE) -> 0.13497491 | M13: =HLOOKUP(REG_TRA_DEMANDS!M$3,'BY-Demands'!$J$5:$AK$14,MATCH($E13,'BY-Demands'!$I$5:$I$14,0),FALSE)*HLOOKUP(REG_TRA_DEMANDS!$F13,DEMANDS!$G$2:$CK$25,MATCH($E13,DEMANDS!$E$2:$E$25,0),FALSE)/HLOOKUP(2018,DEMANDS!$G$2:$CK$25,MATCH($E13,DEMANDS!$E$2:$E$25,0),FALSE) -> 0.38704223 | N13: =HLOOKUP(REG_TRA_DEMANDS!N$3,'BY-Demands'!$J$5:$AK$14,MATCH($E13,'BY-Demands'!$I$5:$I$14,0),FALSE)*HLOOKUP(REG_TRA_DEMANDS!$F13,DEMANDS!$G$2:$CK$25,MATCH($E13,DEMANDS!$E$2:$E$25,0),FALSE)/HLOOKUP(2018,DEMANDS!$G$2:$CK$25,MATCH($E13,DEMANDS!$E$2:$E$25,0),FALSE) -> 0.63708141 | ... AF13: =HLOOKUP(REG_TRA_DEMANDS!AF$3,'BY-Demands'!$J$5:$AK$14,MATCH($E13,'BY-Demands'!$I$5:$I$14,0),FALSE)*HLOOKUP(REG_TRA_DEMANDS!$F13,DEMANDS!$G$2:$CK$25,MATCH($E13,DEMANDS!$E$2:$E$25,0),FALSE)/HLOOKUP(2018,DEMANDS!$G$2:$CK$25,MATCH($E13,DEMANDS!$E$2:$E$25,0),FALSE) -> 0.21687207
D14: COM_PROJ | E14: =DEMANDS!$E$17 -> TRAPS | F14: 2030 | G14: =HLOOKUP(REG_TRA_DEMANDS!G$3,'BY-Demands'!$J$5:$AK$14,MATCH($E14,'BY-Demands'!$I$5:$I$14,0),FALSE)*HLOOKUP(REG_TRA_DEMANDS!$F14,DEMANDS!$G$2:$CK$25,MATCH($E14,DEMANDS!$E$2:$E$25,0),FALSE)/HLOOKUP(2018,DEMANDS!$G$2:$CK$25,MATCH($E14,DEMANDS!$E$2:$E$25,0),FALSE) -> 0.20167555 | H14: =HLOOKUP(REG_TRA_DEMANDS!H$3,'BY-Demands'!$J$5:$AK$14,MATCH($E14,'BY-Demands'!$I$5:$I$14,0),FALSE)*HLOOKUP(REG_TRA_DEMANDS!$F14,DEMANDS!$G$2:$CK$25,MATCH($E14,DEMANDS!$E$2:$E$25,0),FALSE)/HLOOKUP(2018,DEMANDS!$G$2:$CK$25,MATCH($E14,DEMANDS!$E$2:$E$25,0),FALSE) -> 4.0319723 | I14: =HLOOKUP(REG_TRA_DEMANDS!I$3,'BY-Demands'!$J$5:$AK$14,MATCH($E14,'BY-Demands'!$I$5:$I$14,0),FALSE)*HLOOKUP(REG_TRA_DEMANDS!$F14,DEMANDS!$G$2:$CK$25,MATCH($E14,DEMANDS!$E$2:$E$25,0),FALSE)/HLOOKUP(2018,DEMANDS!$G$2:$CK$25,MATCH($E14,DEMANDS!$E$2:$E$25,0),FALSE) -> 0.74359684 | J14: =HLOOKUP(REG_TRA_DEMANDS!J$3,'BY-Demands'!$J$5:$AK$14,MATCH($E14,'BY-Demands'!$I$5:$I$14,0),FALSE)*HLOOKUP(REG_TRA_DEMANDS!$F14,DEMANDS!$G$2:$CK$25,MATCH($E14,DEMANDS!$E$2:$E$25,0),FALSE)/HLOOKUP(2018,DEMANDS!$G$2:$CK$25,MATCH($E14,DEMANDS!$E$2:$E$25,0),FALSE) -> 0.34498094 | K14: =HLOOKUP(REG_TRA_DEMANDS!K$3,'BY-Demands'!$J$5:$AK$14,MATCH($E14,'BY-Demands'!$I$5:$I$14,0),FALSE)*HLOOKUP(REG_TRA_DEMANDS!$F14,DEMANDS!$G$2:$CK$25,MATCH($E14,DEMANDS!$E$2:$E$25,0),FALSE)/HLOOKUP(2018,DEMANDS!$G$2:$CK$25,MATCH($E14,DEMANDS!$E$2:$E$25,0),FALSE) -> 0.27198283 | L14: =HLOOKUP(REG_TRA_DEMANDS!L$3,'BY-Demands'!$J$5:$AK$14,MATCH($E14,'BY-Demands'!$I$5:$I$14,0),FALSE)*HLOOKUP(REG_TRA_DEMANDS!$F14,DEMANDS!$G$2:$CK$25,MATCH($E14,DEMANDS!$E$2:$E$25,0),FALSE)/HLOOKUP(2018,DEMANDS!$G$2:$CK$25,MATCH($E14,DEMANDS!$E$2:$E$25,0),FALSE) -> 0.1366621 | M14: =HLOOKUP(REG_TRA_DEMANDS!M$3,'BY-Demands'!$J$5:$AK$14,MATCH($E14,'BY-Demands'!$I$5:$I$14,0),FALSE)*HLOOKUP(REG_TRA_DEMANDS!$F14,DEMANDS!$G$2:$CK$25,MATCH($E14,DEMANDS!$E$2:$E$25,0),FALSE)/HLOOKUP(2018,DEMANDS!$G$2:$CK$25,MATCH($E14,DEMANDS!$E$2:$E$25,0),FALSE) -> 0.39188025 | N14: =HLOOKUP(REG_TRA_DEMANDS!N$3,'BY-Demands'!$J$5:$AK$14,MATCH($E14,'BY-Demands'!$I$5:$I$14,0),FALSE)*HLOOKUP(REG_TRA_DEMANDS!$F14,DEMANDS!$G$2:$CK$25,MATCH($E14,DEMANDS!$E$2:$E$25,0),FALSE)/HLOOKUP(2018,DEMANDS!$G$2:$CK$25,MATCH($E14,DEMANDS!$E$2:$E$25,0),FALSE) -> 0.64504493 | ... AF14: =HLOOKUP(REG_TRA_DEMANDS!AF$3,'BY-Demands'!$J$5:$AK$14,MATCH($E14,'BY-Demands'!$I$5:$I$14,0),FALSE)*HLOOKUP(REG_TRA_DEMANDS!$F14,DEMANDS!$G$2:$CK$25,MATCH($E14,DEMANDS!$E$2:$E$25,0),FALSE)/HLOOKUP(2018,DEMANDS!$G$2:$CK$25,MATCH($E14,DEMANDS!$E$2:$E$25,0),FALSE) -> 0.21958297
D15: COM_PROJ | E15: =DEMANDS!$E$17 -> TRAPS | F15: 2031 | G15: =HLOOKUP(REG_TRA_DEMANDS!G$3,'BY-Demands'!$J$5:$AK$14,MATCH($E15,'BY-Demands'!$I$5:$I$14,0),FALSE)*HLOOKUP(REG_TRA_DEMANDS!$F15,DEMANDS!$G$2:$CK$25,MATCH($E15,DEMANDS!$E$2:$E$25,0),FALSE)/HLOOKUP(2018,DEMANDS!$G$2:$CK$25,MATCH($E15,DEMANDS!$E$2:$E$25,0),FALSE) -> 0.20419649 | H15: =HLOOKUP(REG_TRA_DEMANDS!H$3,'BY-Demands'!$J$5:$AK$14,MATCH($E15,'BY-Demands'!$I$5:$I$14,0),FALSE)*HLOOKUP(REG_TRA_DEMANDS!$F15,DEMANDS!$G$2:$CK$25,MATCH($E15,DEMANDS!$E$2:$E$25,0),FALSE)/HLOOKUP(2018,DEMANDS!$G$2:$CK$25,MATCH($E15,DEMANDS!$E$2:$E$25,0),FALSE) -> 4.082372 | I15: =HLOOKUP(REG_TRA_DEMANDS!I$3,'BY-Demands'!$J$5:$AK$14,MATCH($E15,'BY-Demands'!$I$5:$I$14,0),FALSE)*HLOOKUP(REG_TRA_DEMANDS!$F15,DEMANDS!$G$2:$CK$25,MATCH($E15,DEMANDS!$E$2:$E$25,0),FALSE)/HLOOKUP(2018,DEMANDS!$G$2:$CK$25,MATCH($E15,DEMANDS!$E$2:$E$25,0),FALSE) -> 0.7528918 | J15: =HLOOKUP(REG_TRA_DEMANDS!J$3,'BY-Demands'!$J$5:$AK$14,MATCH($E15,'BY-Demands'!$I$5:$I$14,0),FALSE)*HLOOKUP(REG_TRA_DEMANDS!$F15,DEMANDS!$G$2:$CK$25,MATCH($E15,DEMANDS!$E$2:$E$25,0),FALSE)/HLOOKUP(2018,DEMANDS!$G$2:$CK$25,MATCH($E15,DEMANDS!$E$2:$E$25,0),FALSE) -> 0.3492932 | K15: =HLOOKUP(REG_TRA_DEMANDS!K$3,'BY-Demands'!$J$5:$AK$14,MATCH($E15,'BY-Demands'!$I$5:$I$14,0),FALSE)*HLOOKUP(REG_TRA_DEMANDS!$F15,DEMANDS!$G$2:$CK$25,MATCH($E15,DEMANDS!$E$2:$E$25,0),FALSE)/HLOOKUP(2018,DEMANDS!$G$2:$CK$25,MATCH($E15,DEMANDS!$E$2:$E$25,0),FALSE) -> 0.27538262 | L15: =HLOOKUP(REG_TRA_DEMANDS!L$3,'BY-Demands'!$J$5:$AK$14,MATCH($E15,'BY-Demands'!$I$5:$I$14,0),FALSE)*HLOOKUP(REG_TRA_DEMANDS!$F15,DEMANDS!$G$2:$CK$25,MATCH($E15,DEMANDS!$E$2:$E$25,0),FALSE)/HLOOKUP(2018,DEMANDS!$G$2:$CK$25,MATCH($E15,DEMANDS!$E$2:$E$25,0),FALSE) -> 0.13837037 | M15: =HLOOKUP(REG_TRA_DEMANDS!M$3,'BY-Demands'!$J$5:$AK$14,MATCH($E15,'BY-Demands'!$I$5:$I$14,0),FALSE)*HLOOKUP(REG_TRA_DEMANDS!$F15,DEMANDS!$G$2:$CK$25,MATCH($E15,DEMANDS!$E$2:$E$25,0),FALSE)/HLOOKUP(2018,DEMANDS!$G$2:$CK$25,MATCH($E15,DEMANDS!$E$2:$E$25,0),FALSE) -> 0.39677876 | N15: =HLOOKUP(REG_TRA_DEMANDS!N$3,'BY-Demands'!$J$5:$AK$14,MATCH($E15,'BY-Demands'!$I$5:$I$14,0),FALSE)*HLOOKUP(REG_TRA_DEMANDS!$F15,DEMANDS!$G$2:$CK$25,MATCH($E15,DEMANDS!$E$2:$E$25,0),FALSE)/HLOOKUP(2018,DEMANDS!$G$2:$CK$25,MATCH($E15,DEMANDS!$E$2:$E$25,0),FALSE) -> 0.65310799 | ... AF15: =HLOOKUP(REG_TRA_DEMANDS!AF$3,'BY-Demands'!$J$5:$AK$14,MATCH($E15,'BY-Demands'!$I$5:$I$14,0),FALSE)*HLOOKUP(REG_TRA_DEMANDS!$F15,DEMANDS!$G$2:$CK$25,MATCH($E15,DEMANDS!$E$2:$E$25,0),FALSE)/HLOOKUP(2018,DEMANDS!$G$2:$CK$25,MATCH($E15,DEMANDS!$E$2:$E$25,0),FALSE) -> 0.22232776
... D30: COM_PROJ | E30: =DEMANDS!$E$17 -> TRAPS | F30: 2070 | G30: =HLOOKUP(REG_TRA_DEMANDS!G$3,'BY-Demands'!$J$5:$AK$14,MATCH($E30,'BY-Demands'!$I$5:$I$14,0),FALSE)*HLOOKUP(REG_TRA_DEMANDS!$F30,DEMANDS!$G$2:$CK$25,MATCH($E30,DEMANDS!$E$2:$E$25,0),FALSE)/HLOOKUP(2018,DEMANDS!$G$2:$CK$25,MATCH($E30,DEMANDS!$E$2:$E$25,0),FALSE) -> 0.30138686 | H30: =HLOOKUP(REG_TRA_DEMANDS!H$3,'BY-Demands'!$J$5:$AK$14,MATCH($E30,'BY-Demands'!$I$5:$I$14,0),FALSE)*HLOOKUP(REG_TRA_DEMANDS!$F30,DEMANDS!$G$2:$CK$25,MATCH($E30,DEMANDS!$E$2:$E$25,0),FALSE)/HLOOKUP(2018,DEMANDS!$G$2:$CK$25,MATCH($E30,DEMANDS!$E$2:$E$25,0),FALSE) -> 6.025438 | I30: =HLOOKUP(REG_TRA_DEMANDS!I$3,'BY-Demands'!$J$5:$AK$14,MATCH($E30,'BY-Demands'!$I$5:$I$14,0),FALSE)*HLOOKUP(REG_TRA_DEMANDS!$F30,DEMANDS!$G$2:$CK$25,MATCH($E30,DEMANDS!$E$2:$E$25,0),FALSE)/HLOOKUP(2018,DEMANDS!$G$2:$CK$25,MATCH($E30,DEMANDS!$E$2:$E$25,0),FALSE) -> 1.1112419 | J30: =HLOOKUP(REG_TRA_DEMANDS!J$3,'BY-Demands'!$J$5:$AK$14,MATCH($E30,'BY-Demands'!$I$5:$I$14,0),FALSE)*HLOOKUP(REG_TRA_DEMANDS!$F30,DEMANDS!$G$2:$CK$25,MATCH($E30,DEMANDS!$E$2:$E$25,0),FALSE)/HLOOKUP(2018,DEMANDS!$G$2:$CK$25,MATCH($E30,DEMANDS!$E$2:$E$25,0),FALSE) -> 0.51554452 | K30: =HLOOKUP(REG_TRA_DEMANDS!K$3,'BY-Demands'!$J$5:$AK$14,MATCH($E30,'BY-Demands'!$I$5:$I$14,0),FALSE)*HLOOKUP(REG_TRA_DEMANDS!$F30,DEMANDS!$G$2:$CK$25,MATCH($E30,DEMANDS!$E$2:$E$25,0),FALSE)/HLOOKUP(2018,DEMANDS!$G$2:$CK$25,MATCH($E30,DEMANDS!$E$2:$E$25,0),FALSE) -> 0.40645509 | L30: =HLOOKUP(REG_TRA_DEMANDS!L$3,'BY-Demands'!$J$5:$AK$14,MATCH($E30,'BY-Demands'!$I$5:$I$14,0),FALSE)*HLOOKUP(REG_TRA_DEMANDS!$F30,DEMANDS!$G$2:$CK$25,MATCH($E30,DEMANDS!$E$2:$E$25,0),FALSE)/HLOOKUP(2018,DEMANDS!$G$2:$CK$25,MATCH($E30,DEMANDS!$E$2:$E$25,0),FALSE) -> 0.20422982 | M30: =HLOOKUP(REG_TRA_DEMANDS!M$3,'BY-Demands'!$J$5:$AK$14,MATCH($E30,'BY-Demands'!$I$5:$I$14,0),FALSE)*HLOOKUP(REG_TRA_DEMANDS!$F30,DEMANDS!$G$2:$CK$25,MATCH($E30,DEMANDS!$E$2:$E$25,0),FALSE)/HLOOKUP(2018,DEMANDS!$G$2:$CK$25,MATCH($E30,DEMANDS!$E$2:$E$25,0),FALSE) -> 0.58563154 | N30: =HLOOKUP(REG_TRA_DEMANDS!N$3,'BY-Demands'!$J$5:$AK$14,MATCH($E30,'BY-Demands'!$I$5:$I$14,0),FALSE)*HLOOKUP(REG_TRA_DEMANDS!$F30,DEMANDS!$G$2:$CK$25,MATCH($E30,DEMANDS!$E$2:$E$25,0),FALSE)/HLOOKUP(2018,DEMANDS!$G$2:$CK$25,MATCH($E30,DEMANDS!$E$2:$E$25,0),FALSE) -> 0.96396451 | ... AF30: =HLOOKUP(REG_TRA_DEMANDS!AF$3,'BY-Demands'!$J$5:$AK$14,MATCH($E30,'BY-Demands'!$I$5:$I$14,0),FALSE)*HLOOKUP(REG_TRA_DEMANDS!$F30,DEMANDS!$G$2:$CK$25,MATCH($E30,DEMANDS!$E$2:$E$25,0),FALSE)/HLOOKUP(2018,DEMANDS!$G$2:$CK$25,MATCH($E30,DEMANDS!$E$2:$E$25,0),FALSE) -> 0.32814798
D31: COM_PROJ | E31: =DEMANDS!$E$18 -> TRAPM | F31: 2020 | G31: =HLOOKUP(REG_TRA_DEMANDS!G$3,'BY-Demands'!$J$5:$AK$14,MATCH($E31,'BY-Demands'!$I$5:$I$14,0),FALSE)*HLOOKUP(REG_TRA_DEMANDS!$F31,DEMANDS!$G$2:$CK$25,MATCH($E31,DEMANDS!$E$2:$E$25,0),FALSE)/HLOOKUP(2018,DEMANDS!$G$2:$CK$25,MATCH($E31,DEMANDS!$E$2:$E$25,0),FALSE) -> 0.32193664 | H31: =HLOOKUP(REG_TRA_DEMANDS!H$3,'BY-Demands'!$J$5:$AK$14,MATCH($E31,'BY-Demands'!$I$5:$I$14,0),FALSE)*HLOOKUP(REG_TRA_DEMANDS!$F31,DEMANDS!$G$2:$CK$25,MATCH($E31,DEMANDS!$E$2:$E$25,0),FALSE)/HLOOKUP(2018,DEMANDS!$G$2:$CK$25,MATCH($E31,DEMANDS!$E$2:$E$25,0),FALSE) -> 5.6378139 | I31: =HLOOKUP(REG_TRA_DEMANDS!I$3,'BY-Demands'!$J$5:$AK$14,MATCH($E31,'BY-Demands'!$I$5:$I$14,0),FALSE)*HLOOKUP(REG_TRA_DEMANDS!$F31,DEMANDS!$G$2:$CK$25,MATCH($E31,DEMANDS!$E$2:$E$25,0),FALSE)/HLOOKUP(2018,DEMANDS!$G$2:$CK$25,MATCH($E31,DEMANDS!$E$2:$E$25,0),FALSE) -> 1.1480383 | J31: =HLOOKUP(REG_TRA_DEMANDS!J$3,'BY-Demands'!$J$5:$AK$14,MATCH($E31,'BY-Demands'!$I$5:$I$14,0),FALSE)*HLOOKUP(REG_TRA_DEMANDS!$F31,DEMANDS!$G$2:$CK$25,MATCH($E31,DEMANDS!$E$2:$E$25,0),FALSE)/HLOOKUP(2018,DEMANDS!$G$2:$CK$25,MATCH($E31,DEMANDS!$E$2:$E$25,0),FALSE) -> 0.54522569 | K31: =HLOOKUP(REG_TRA_DEMANDS!K$3,'BY-Demands'!$J$5:$AK$14,MATCH($E31,'BY-Demands'!$I$5:$I$14,0),FALSE)*HLOOKUP(REG_TRA_DEMANDS!$F31,DEMANDS!$G$2:$CK$25,MATCH($E31,DEMANDS!$E$2:$E$25,0),FALSE)/HLOOKUP(2018,DEMANDS!$G$2:$CK$25,MATCH($E31,DEMANDS!$E$2:$E$25,0),FALSE) -> 0.41020881 | L31: =HLOOKUP(REG_TRA_DEMANDS!L$3,'BY-Demands'!$J$5:$AK$14,MATCH($E31,'BY-Demands'!$I$5:$I$14,0),FALSE)*HLOOKUP(REG_TRA_DEMANDS!$F31,DEMANDS!$G$2:$CK$25,MATCH($E31,DEMANDS!$E$2:$E$25,0),FALSE)/HLOOKUP(2018,DEMANDS!$G$2:$CK$25,MATCH($E31,DEMANDS!$E$2:$E$25,0),FALSE) -> 0.21133747 | M31: =HLOOKUP(REG_TRA_DEMANDS!M$3,'BY-Demands'!$J$5:$AK$14,MATCH($E31,'BY-Demands'!$I$5:$I$14,0),FALSE)*HLOOKUP(REG_TRA_DEMANDS!$F31,DEMANDS!$G$2:$CK$25,MATCH($E31,DEMANDS!$E$2:$E$25,0),FALSE)/HLOOKUP(2018,DEMANDS!$G$2:$CK$25,MATCH($E31,DEMANDS!$E$2:$E$25,0),FALSE) -> 0.5692485 | N31: =HLOOKUP(REG_TRA_DEMANDS!N$3,'BY-Demands'!$J$5:$AK$14,MATCH($E31,'BY-Demands'!$I$5:$I$14,0),FALSE)*HLOOKUP(REG_TRA_DEMANDS!$F31,DEMANDS!$G$2:$CK$25,MATCH($E31,DEMANDS!$E$2:$E$25,0),FALSE)/HLOOKUP(2018,DEMANDS!$G$2:$CK$25,MATCH($E31,DEMANDS!$E$2:$E$25,0),FALSE) -> 0.98828047 | ... AF31: =HLOOKUP(REG_TRA_DEMANDS!AF$3,'BY-Demands'!$J$5:$AK$14,MATCH($E31,'BY-Demands'!$I$5:$I$14,0),FALSE)*HLOOKUP(REG_TRA_DEMANDS!$F31,DEMANDS!$G$2:$CK$25,MATCH($E31,DEMANDS!$E$2:$E$25,0),FALSE)/HLOOKUP(2018,DEMANDS!$G$2:$CK$25,MATCH($E31,DEMANDS!$E$2:$E$25,0),FALSE) -> 0.35260316
D32: COM_PROJ | E32: =DEMANDS!$E$18 -> TRAPM | F32: 2021 | G32: =HLOOKUP(REG_TRA_DEMANDS!G$3,'BY-Demands'!$J$5:$AK$14,MATCH($E32,'BY-Demands'!$I$5:$I$14,0),FALSE)*HLOOKUP(REG_TRA_DEMANDS!$F32,DEMANDS!$G$2:$CK$25,MATCH($E32,DEMANDS!$E$2:$E$25,0),FALSE)/HLOOKUP(2018,DEMANDS!$G$2:$CK$25,MATCH($E32,DEMANDS!$E$2:$E$25,0),FALSE) -> 0.38548331 | H32: =HLOOKUP(REG_TRA_DEMANDS!H$3,'BY-Demands'!$J$5:$AK$14,MATCH($E32,'BY-Demands'!$I$5:$I$14,0),FALSE)*HLOOKUP(REG_TRA_DEMANDS!$F32,DEMANDS!$G$2:$CK$25,MATCH($E32,DEMANDS!$E$2:$E$25,0),FALSE)/HLOOKUP(2018,DEMANDS!$G$2:$CK$25,MATCH($E32,DEMANDS!$E$2:$E$25,0),FALSE) -> 6.7506547 | I32: =HLOOKUP(REG_TRA_DEMANDS!I$3,'BY-Demands'!$J$5:$AK$14,MATCH($E32,'BY-Demands'!$I$5:$I$14,0),FALSE)*HLOOKUP(REG_TRA_DEMANDS!$F32,DEMANDS!$G$2:$CK$25,MATCH($E32,DEMANDS!$E$2:$E$25,0),FALSE)/HLOOKUP(2018,DEMANDS!$G$2:$CK$25,MATCH($E32,DEMANDS!$E$2:$E$25,0),FALSE) -> 1.3746481 | J32: =HLOOKUP(REG_TRA_DEMANDS!J$3,'BY-Demands'!$J$5:$AK$14,MATCH($E32,'BY-Demands'!$I$5:$I$14,0),FALSE)*HLOOKUP(REG_TRA_DEMANDS!$F32,DEMANDS!$G$2:$CK$25,MATCH($E32,DEMANDS!$E$2:$E$25,0),FALSE)/HLOOKUP(2018,DEMANDS!$G$2:$CK$25,MATCH($E32,DEMANDS!$E$2:$E$25,0),FALSE) -> 0.65284709 | K32: =HLOOKUP(REG_TRA_DEMANDS!K$3,'BY-Demands'!$J$5:$AK$14,MATCH($E32,'BY-Demands'!$I$5:$I$14,0),FALSE)*HLOOKUP(REG_TRA_DEMANDS!$F32,DEMANDS!$G$2:$CK$25,MATCH($E32,DEMANDS!$E$2:$E$25,0),FALSE)/HLOOKUP(2018,DEMANDS!$G$2:$CK$25,MATCH($E32,DEMANDS!$E$2:$E$25,0),FALSE) -> 0.4911794 | L32: =HLOOKUP(REG_TRA_DEMANDS!L$3,'BY-Demands'!$J$5:$AK$14,MATCH($E32,'BY-Demands'!$I$5:$I$14,0),FALSE)*HLOOKUP(REG_TRA_DEMANDS!$F32,DEMANDS!$G$2:$CK$25,MATCH($E32,DEMANDS!$E$2:$E$25,0),FALSE)/HLOOKUP(2018,DEMANDS!$G$2:$CK$25,MATCH($E32,DEMANDS!$E$2:$E$25,0),FALSE) -> 0.2530531 | M32: =HLOOKUP(REG_TRA_DEMANDS!M$3,'BY-Demands'!$J$5:$AK$14,MATCH($E32,'BY-Demands'!$I$5:$I$14,0),FALSE)*HLOOKUP(REG_TRA_DEMANDS!$F32,DEMANDS!$G$2:$CK$25,MATCH($E32,DEMANDS!$E$2:$E$25,0),FALSE)/HLOOKUP(2018,DEMANDS!$G$2:$CK$25,MATCH($E32,DEMANDS!$E$2:$E$25,0),FALSE) -> 0.68161173 | N32: =HLOOKUP(REG_TRA_DEMANDS!N$3,'BY-Demands'!$J$5:$AK$14,MATCH($E32,'BY-Demands'!$I$5:$I$14,0),FALSE)*HLOOKUP(REG_TRA_DEMANDS!$F32,DEMANDS!$G$2:$CK$25,MATCH($E32,DEMANDS!$E$2:$E$25,0),FALSE)/HLOOKUP(2018,DEMANDS!$G$2:$CK$25,MATCH($E32,DEMANDS!$E$2:$E$25,0),FALSE) -> 1.1833559 | ... AF32: =HLOOKUP(REG_TRA_DEMANDS!AF$3,'BY-Demands'!$J$5:$AK$14,MATCH($E32,'BY-Demands'!$I$5:$I$14,0),FALSE)*HLOOKUP(REG_TRA_DEMANDS!$F32,DEMANDS!$G$2:$CK$25,MATCH($E32,DEMANDS!$E$2:$E$25,0),FALSE)/HLOOKUP(2018,DEMANDS!$G$2:$CK$25,MATCH($E32,DEMANDS!$E$2:$E$25,0),FALSE) -> 0.42220304
D33: COM_PROJ | E33: =DEMANDS!$E$18 -> TRAPM | F33: 2022 | G33: =HLOOKUP(REG_TRA_DEMANDS!G$3,'BY-Demands'!$J$5:$AK$14,MATCH($E33,'BY-Demands'!$I$5:$I$14,0),FALSE)*HLOOKUP(REG_TRA_DEMANDS!$F33,DEMANDS!$G$2:$CK$25,MATCH($E33,DEMANDS!$E$2:$E$25,0),FALSE)/HLOOKUP(2018,DEMANDS!$G$2:$CK$25,MATCH($E33,DEMANDS!$E$2:$E$25,0),FALSE) -> 0.42024852 | H33: =HLOOKUP(REG_TRA_DEMANDS!H$3,'BY-Demands'!$J$5:$AK$14,MATCH($E33,'BY-Demands'!$I$5:$I$14,0),FALSE)*HLOOKUP(REG_TRA_DEMANDS!$F33,DEMANDS!$G$2:$CK$25,MATCH($E33,DEMANDS!$E$2:$E$25,0),FALSE)/HLOOKUP(2018,DEMANDS!$G$2:$CK$25,MATCH($E33,DEMANDS!$E$2:$E$25,0),FALSE) -> 7.3594696 | I33: =HLOOKUP(REG_TRA_DEMANDS!I$3,'BY-Demands'!$J$5:$AK$14,MATCH($E33,'BY-Demands'!$I$5:$I$14,0),FALSE)*HLOOKUP(REG_TRA_DEMANDS!$F33,DEMANDS!$G$2:$CK$25,MATCH($E33,DEMANDS!$E$2:$E$25,0),FALSE)/HLOOKUP(2018,DEMANDS!$G$2:$CK$25,MATCH($E33,DEMANDS!$E$2:$E$25,0),FALSE) -> 1.4986222 | J33: =HLOOKUP(REG_TRA_DEMANDS!J$3,'BY-Demands'!$J$5:$AK$14,MATCH($E33,'BY-Demands'!$I$5:$I$14,0),FALSE)*HLOOKUP(REG_TRA_DEMANDS!$F33,DEMANDS!$G$2:$CK$25,MATCH($E33,DEMANDS!$E$2:$E$25,0),FALSE)/HLOOKUP(2018,DEMANDS!$G$2:$CK$25,MATCH($E33,DEMANDS!$E$2:$E$25,0),FALSE) -> 0.71172479 | K33: =HLOOKUP(REG_TRA_DEMANDS!K$3,'BY-Demands'!$J$5:$AK$14,MATCH($E33,'BY-Demands'!$I$5:$I$14,0),FALSE)*HLOOKUP(REG_TRA_DEMANDS!$F33,DEMANDS!$G$2:$CK$25,MATCH($E33,DEMANDS!$E$2:$E$25,0),FALSE)/HLOOKUP(2018,DEMANDS!$G$2:$CK$25,MATCH($E33,DEMANDS!$E$2:$E$25,0),FALSE) -> 0.53547693 | L33: =HLOOKUP(REG_TRA_DEMANDS!L$3,'BY-Demands'!$J$5:$AK$14,MATCH($E33,'BY-Demands'!$I$5:$I$14,0),FALSE)*HLOOKUP(REG_TRA_DEMANDS!$F33,DEMANDS!$G$2:$CK$25,MATCH($E33,DEMANDS!$E$2:$E$25,0),FALSE)/HLOOKUP(2018,DEMANDS!$G$2:$CK$25,MATCH($E33,DEMANDS!$E$2:$E$25,0),FALSE) -> 0.27587496 | M33: =HLOOKUP(REG_TRA_DEMANDS!M$3,'BY-Demands'!$J$5:$AK$14,MATCH($E33,'BY-Demands'!$I$5:$I$14,0),FALSE)*HLOOKUP(REG_TRA_DEMANDS!$F33,DEMANDS!$G$2:$CK$25,MATCH($E33,DEMANDS!$E$2:$E$25,0),FALSE)/HLOOKUP(2018,DEMANDS!$G$2:$CK$25,MATCH($E33,DEMANDS!$E$2:$E$25,0),FALSE) -> 0.7430836 | N33: =HLOOKUP(REG_TRA_DEMANDS!N$3,'BY-Demands'!$J$5:$AK$14,MATCH($E33,'BY-Demands'!$I$5:$I$14,0),FALSE)*HLOOKUP(REG_TRA_DEMANDS!$F33,DEMANDS!$G$2:$CK$25,MATCH($E33,DEMANDS!$E$2:$E$25,0),FALSE)/HLOOKUP(2018,DEMANDS!$G$2:$CK$25,MATCH($E33,DEMANDS!$E$2:$E$25,0),FALSE) -> 1.2900781 | ... AF33: =HLOOKUP(REG_TRA_DEMANDS!AF$3,'BY-Demands'!$J$5:$AK$14,MATCH($E33,'BY-Demands'!$I$5:$I$14,0),FALSE)*HLOOKUP(REG_TRA_DEMANDS!$F33,DEMANDS!$G$2:$CK$25,MATCH($E33,DEMANDS!$E$2:$E$25,0),FALSE)/HLOOKUP(2018,DEMANDS!$G$2:$CK$25,MATCH($E33,DEMANDS!$E$2:$E$25,0),FALSE) -> 0.46027987
D34: COM_PROJ | E34: =DEMANDS!$E$18 -> TRAPM | F34: 2023 | G34: =HLOOKUP(REG_TRA_DEMANDS!G$3,'BY-Demands'!$J$5:$AK$14,MATCH($E34,'BY-Demands'!$I$5:$I$14,0),FALSE)*HLOOKUP(REG_TRA_DEMANDS!$F34,DEMANDS!$G$2:$CK$25,MATCH($E34,DEMANDS!$E$2:$E$25,0),FALSE)/HLOOKUP(2018,DEMANDS!$G$2:$CK$25,MATCH($E34,DEMANDS!$E$2:$E$25,0),FALSE) -> 0.42177934 | H34: =HLOOKUP(REG_TRA_DEMANDS!H$3,'BY-Demands'!$J$5:$AK$14,MATCH($E34,'BY-Demands'!$I$5:$I$14,0),FALSE)*HLOOKUP(REG_TRA_DEMANDS!$F34,DEMANDS!$G$2:$CK$25,MATCH($E34,DEMANDS!$E$2:$E$25,0),FALSE)/HLOOKUP(2018,DEMANDS!$G$2:$CK$25,MATCH($E34,DEMANDS!$E$2:$E$25,0),FALSE) -> 7.3862776 | I34: =HLOOKUP(REG_TRA_DEMANDS!I$3,'BY-Demands'!$J$5:$AK$14,MATCH($E34,'BY-Demands'!$I$5:$I$14,0),FALSE)*HLOOKUP(REG_TRA_DEMANDS!$F34,DEMANDS!$G$2:$CK$25,MATCH($E34,DEMANDS!$E$2:$E$25,0),FALSE)/HLOOKUP(2018,DEMANDS!$G$2:$CK$25,MATCH($E34,DEMANDS!$E$2:$E$25,0),FALSE) -> 1.5040811 | J34: =HLOOKUP(REG_TRA_DEMANDS!J$3,'BY-Demands'!$J$5:$AK$14,MATCH($E34,'BY-Demands'!$I$5:$I$14,0),FALSE)*HLOOKUP(REG_TRA_DEMANDS!$F34,DEMANDS!$G$2:$CK$25,MATCH($E34,DEMANDS!$E$2:$E$25,0),FALSE)/HLOOKUP(2018,DEMANDS!$G$2:$CK$25,MATCH($E34,DEMANDS!$E$2:$E$25,0),FALSE) -> 0.71431736 | K34: =HLOOKUP(REG_TRA_DEMANDS!K$3,'BY-Demands'!$J$5:$AK$14,MATCH($E34,'BY-Demands'!$I$5:$I$14,0),FALSE)*HLOOKUP(REG_TRA_DEMANDS!$F34,DEMANDS!$G$2:$CK$25,MATCH($E34,DEMANDS!$E$2:$E$25,0),FALSE)/HLOOKUP(2018,DEMANDS!$G$2:$CK$25,MATCH($E34,DEMANDS!$E$2:$E$25,0),FALSE) -> 0.53742749 | L34: =HLOOKUP(REG_TRA_DEMANDS!L$3,'BY-Demands'!$J$5:$AK$14,MATCH($E34,'BY-Demands'!$I$5:$I$14,0),FALSE)*HLOOKUP(REG_TRA_DEMANDS!$F34,DEMANDS!$G$2:$CK$25,MATCH($E34,DEMANDS!$E$2:$E$25,0),FALSE)/HLOOKUP(2018,DEMANDS!$G$2:$CK$25,MATCH($E34,DEMANDS!$E$2:$E$25,0),FALSE) -> 0.27687988 | M34: =HLOOKUP(REG_TRA_DEMANDS!M$3,'BY-Demands'!$J$5:$AK$14,MATCH($E34,'BY-Demands'!$I$5:$I$14,0),FALSE)*HLOOKUP(REG_TRA_DEMANDS!$F34,DEMANDS!$G$2:$CK$25,MATCH($E34,DEMANDS!$E$2:$E$25,0),FALSE)/HLOOKUP(2018,DEMANDS!$G$2:$CK$25,MATCH($E34,DEMANDS!$E$2:$E$25,0),FALSE) -> 0.7457904 | N34: =HLOOKUP(REG_TRA_DEMANDS!N$3,'BY-Demands'!$J$5:$AK$14,MATCH($E34,'BY-Demands'!$I$5:$I$14,0),FALSE)*HLOOKUP(REG_TRA_DEMANDS!$F34,DEMANDS!$G$2:$CK$25,MATCH($E34,DEMANDS!$E$2:$E$25,0),FALSE)/HLOOKUP(2018,DEMANDS!$G$2:$CK$25,MATCH($E34,DEMANDS!$E$2:$E$25,0),FALSE) -> 1.2947774 | ... AF34: =HLOOKUP(REG_TRA_DEMANDS!AF$3,'BY-Demands'!$J$5:$AK$14,MATCH($E34,'BY-Demands'!$I$5:$I$14,0),FALSE)*HLOOKUP(REG_TRA_DEMANDS!$F34,DEMANDS!$G$2:$CK$25,MATCH($E34,DEMANDS!$E$2:$E$25,0),FALSE)/HLOOKUP(2018,DEMANDS!$G$2:$CK$25,MATCH($E34,DEMANDS!$E$2:$E$25,0),FALSE) -> 0.46195651
D35: COM_PROJ | E35: =DEMANDS!$E$18 -> TRAPM | F35: 2024 | G35: =HLOOKUP(REG_TRA_DEMANDS!G$3,'BY-Demands'!$J$5:$AK$14,MATCH($E35,'BY-Demands'!$I$5:$I$14,0),FALSE)*HLOOKUP(REG_TRA_DEMANDS!$F35,DEMANDS!$G$2:$CK$25,MATCH($E35,DEMANDS!$E$2:$E$25,0),FALSE)/HLOOKUP(2018,DEMANDS!$G$2:$CK$25,MATCH($E35,DEMANDS!$E$2:$E$25,0),FALSE) -> 0.42810603 | H35: =HLOOKUP(REG_TRA_DEMANDS!H$3,'BY-Demands'!$J$5:$AK$14,MATCH($E35,'BY-Demands'!$I$5:$I$14,0),FALSE)*HLOOKUP(REG_TRA_DEMANDS!$F35,DEMANDS!$G$2:$CK$25,MATCH($E35,DEMANDS!$E$2:$E$25,0),FALSE)/HLOOKUP(2018,DEMANDS!$G$2:$CK$25,MATCH($E35,DEMANDS!$E$2:$E$25,0),FALSE) -> 7.4970718 | I35: =HLOOKUP(REG_TRA_DEMANDS!I$3,'BY-Demands'!$J$5:$AK$14,MATCH($E35,'BY-Demands'!$I$5:$I$14,0),FALSE)*HLOOKUP(REG_TRA_DEMANDS!$F35,DEMANDS!$G$2:$CK$25,MATCH($E35,DEMANDS!$E$2:$E$25,0),FALSE)/HLOOKUP(2018,DEMANDS!$G$2:$CK$25,MATCH($E35,DEMANDS!$E$2:$E$25,0),FALSE) -> 1.5266424 | J35: =HLOOKUP(REG_TRA_DEMANDS!J$3,'BY-Demands'!$J$5:$AK$14,MATCH($E35,'BY-Demands'!$I$5:$I$14,0),FALSE)*HLOOKUP(REG_TRA_DEMANDS!$F35,DEMANDS!$G$2:$CK$25,MATCH($E35,DEMANDS!$E$2:$E$25,0),FALSE)/HLOOKUP(2018,DEMANDS!$G$2:$CK$25,MATCH($E35,DEMANDS!$E$2:$E$25,0),FALSE) -> 0.72503212 | K35: =HLOOKUP(REG_TRA_DEMANDS!K$3,'BY-Demands'!$J$5:$AK$14,MATCH($E35,'BY-Demands'!$I$5:$I$14,0),FALSE)*HLOOKUP(REG_TRA_DEMANDS!$F35,DEMANDS!$G$2:$CK$25,MATCH($E35,DEMANDS!$E$2:$E$25,0),FALSE)/HLOOKUP(2018,DEMANDS!$G$2:$CK$25,MATCH($E35,DEMANDS!$E$2:$E$25,0),FALSE) -> 0.54548891 | L35: =HLOOKUP(REG_TRA_DEMANDS!L$3,'BY-Demands'!$J$5:$AK$14,MATCH($E35,'BY-Demands'!$I$5:$I$14,0),FALSE)*HLOOKUP(REG_TRA_DEMANDS!$F35,DEMANDS!$G$2:$CK$25,MATCH($E35,DEMANDS!$E$2:$E$25,0),FALSE)/HLOOKUP(2018,DEMANDS!$G$2:$CK$25,MATCH($E35,DEMANDS!$E$2:$E$25,0),FALSE) -> 0.28103308 | M35: =HLOOKUP(REG_TRA_DEMANDS!M$3,'BY-Demands'!$J$5:$AK$14,MATCH($E35,'BY-Demands'!$I$5:$I$14,0),FALSE)*HLOOKUP(REG_TRA_DEMANDS!$F35,DEMANDS!$G$2:$CK$25,MATCH($E35,DEMANDS!$E$2:$E$25,0),FALSE)/HLOOKUP(2018,DEMANDS!$G$2:$CK$25,MATCH($E35,DEMANDS!$E$2:$E$25,0),FALSE) -> 0.75697726 | N35: =HLOOKUP(REG_TRA_DEMANDS!N$3,'BY-Demands'!$J$5:$AK$14,MATCH($E35,'BY-Demands'!$I$5:$I$14,0),FALSE)*HLOOKUP(REG_TRA_DEMANDS!$F35,DEMANDS!$G$2:$CK$25,MATCH($E35,DEMANDS!$E$2:$E$25,0),FALSE)/HLOOKUP(2018,DEMANDS!$G$2:$CK$25,MATCH($E35,DEMANDS!$E$2:$E$25,0),FALSE) -> 1.3141991 | ... AF35: =HLOOKUP(REG_TRA_DEMANDS!AF$3,'BY-Demands'!$J$5:$AK$14,MATCH($E35,'BY-Demands'!$I$5:$I$14,0),FALSE)*HLOOKUP(REG_TRA_DEMANDS!$F35,DEMANDS!$G$2:$CK$25,MATCH($E35,DEMANDS!$E$2:$E$25,0),FALSE)/HLOOKUP(2018,DEMANDS!$G$2:$CK$25,MATCH($E35,DEMANDS!$E$2:$E$25,0),FALSE) -> 0.46888586
D36: COM_PROJ | E36: =DEMANDS!$E$18 -> TRAPM | F36: 2025 | G36: =HLOOKUP(REG_TRA_DEMANDS!G$3,'BY-Demands'!$J$5:$AK$14,MATCH($E36,'BY-Demands'!$I$5:$I$14,0),FALSE)*HLOOKUP(REG_TRA_DEMANDS!$F36,DEMANDS!$G$2:$CK$25,MATCH($E36,DEMANDS!$E$2:$E$25,0),FALSE)/HLOOKUP(2018,DEMANDS!$G$2:$CK$25,MATCH($E36,DEMANDS!$E$2:$E$25,0),FALSE) -> 0.43452763 | H36: =HLOOKUP(REG_TRA_DEMANDS!H$3,'BY-Demands'!$J$5:$AK$14,MATCH($E36,'BY-Demands'!$I$5:$I$14,0),FALSE)*HLOOKUP(REG_TRA_DEMANDS!$F36,DEMANDS!$G$2:$CK$25,MATCH($E36,DEMANDS!$E$2:$E$25,0),FALSE)/HLOOKUP(2018,DEMANDS!$G$2:$CK$25,MATCH($E36,DEMANDS!$E$2:$E$25,0),FALSE) -> 7.6095279 | I36: =HLOOKUP(REG_TRA_DEMANDS!I$3,'BY-Demands'!$J$5:$AK$14,MATCH($E36,'BY-Demands'!$I$5:$I$14,0),FALSE)*HLOOKUP(REG_TRA_DEMANDS!$F36,DEMANDS!$G$2:$CK$25,MATCH($E36,DEMANDS!$E$2:$E$25,0),FALSE)/HLOOKUP(2018,DEMANDS!$G$2:$CK$25,MATCH($E36,DEMANDS!$E$2:$E$25,0),FALSE) -> 1.549542 | J36: =HLOOKUP(REG_TRA_DEMANDS!J$3,'BY-Demands'!$J$5:$AK$14,MATCH($E36,'BY-Demands'!$I$5:$I$14,0),FALSE)*HLOOKUP(REG_TRA_DEMANDS!$F36,DEMANDS!$G$2:$CK$25,MATCH($E36,DEMANDS!$E$2:$E$25,0),FALSE)/HLOOKUP(2018,DEMANDS!$G$2:$CK$25,MATCH($E36,DEMANDS!$E$2:$E$25,0),FALSE) -> 0.7359076 | K36: =HLOOKUP(REG_TRA_DEMANDS!K$3,'BY-Demands'!$J$5:$AK$14,MATCH($E36,'BY-Demands'!$I$5:$I$14,0),FALSE)*HLOOKUP(REG_TRA_DEMANDS!$F36,DEMANDS!$G$2:$CK$25,MATCH($E36,DEMANDS!$E$2:$E$25,0),FALSE)/HLOOKUP(2018,DEMANDS!$G$2:$CK$25,MATCH($E36,DEMANDS!$E$2:$E$25,0),FALSE) -> 0.55367124 | L36: =HLOOKUP(REG_TRA_DEMANDS!L$3,'BY-Demands'!$J$5:$AK$14,MATCH($E36,'BY-Demands'!$I$5:$I$14,0),FALSE)*HLOOKUP(REG_TRA_DEMANDS!$F36,DEMANDS!$G$2:$CK$25,MATCH($E36,DEMANDS!$E$2:$E$25,0),FALSE)/HLOOKUP(2018,DEMANDS!$G$2:$CK$25,MATCH($E36,DEMANDS!$E$2:$E$25,0),FALSE) -> 0.28524857 | M36: =HLOOKUP(REG_TRA_DEMANDS!M$3,'BY-Demands'!$J$5:$AK$14,MATCH($E36,'BY-Demands'!$I$5:$I$14,0),FALSE)*HLOOKUP(REG_TRA_DEMANDS!$F36,DEMANDS!$G$2:$CK$25,MATCH($E36,DEMANDS!$E$2:$E$25,0),FALSE)/HLOOKUP(2018,DEMANDS!$G$2:$CK$25,MATCH($E36,DEMANDS!$E$2:$E$25,0),FALSE) -> 0.76833192 | N36: =HLOOKUP(REG_TRA_DEMANDS!N$3,'BY-Demands'!$J$5:$AK$14,MATCH($E36,'BY-Demands'!$I$5:$I$14,0),FALSE)*HLOOKUP(REG_TRA_DEMANDS!$F36,DEMANDS!$G$2:$CK$25,MATCH($E36,DEMANDS!$E$2:$E$25,0),FALSE)/HLOOKUP(2018,DEMANDS!$G$2:$CK$25,MATCH($E36,DEMANDS!$E$2:$E$25,0),FALSE) -> 1.333912 | ... AF36: =HLOOKUP(REG_TRA_DEMANDS!AF$3,'BY-Demands'!$J$5:$AK$14,MATCH($E36,'BY-Demands'!$I$5:$I$14,0),FALSE)*HLOOKUP(REG_TRA_DEMANDS!$F36,DEMANDS!$G$2:$CK$25,MATCH($E36,DEMANDS!$E$2:$E$25,0),FALSE)/HLOOKUP(2018,DEMANDS!$G$2:$CK$25,MATCH($E36,DEMANDS!$E$2:$E$25,0),FALSE) -> 0.47591915
