Workbook

Sheet Cover
A16: TIMES-Ireland Model
A19: Document type: | B19: Scenario
A20: Sector(s): | B20: Service sector (SRV)
A21: Purpose: | B21: Specify utilisation of ambient heat by heat pumps
A23: Original developer(s):
A26: Current maintainer(s): | B26: Olexandr Balyk (UCC, olexandr.balyk@ucc.ie)
A29: Part of TIM version: | B29: 1
A30: Model repository: | B30: https://github.com/MaREI-EPMG/TIMES-Ireland-model
A31: Licence: | B31: CC BY-NC-SA 4.0 (unless specified otherwise)
B32: https://creativecommons.org/licenses/by-nc-sa/4.0/

Sheet Legend
A1: TIMES-Ireland Model (TIM)
A3: Document type: | B3: Scenario file on User Constraints
A4: Sector: | B4: Services | C4: SRV
A5: Developer:
A6: Version date: | B6: 44315
A7: Description: | B7: Controller for Ambient Heat
A8: Source data: | B8: SubRes data
A11: Tab colour legend
B12: Veda fill table
B13: VEDA-TIMES data input tables
A15: Cell colour legend
A16: aaa | B16: Model input
A17: aaa | B17: Model input based on own assumptions
B18: Calculated value (not recommended to directly modify)
A21: Codes for processes and commodities names
A22: Dimension | B22: Short code | C22: Full code
A23: Sub-sectors
A24: Commercial Services | C24: CS
A25: Public Services | C25: PU
A26: Thermal uses
A27: Space heating | C27: SH
A28: Water heating | C28: WH
A29: Space cooling | C29: SC
A30: Other uses
A31: Cooking | C31: CK
A32: Building lighting | C32: LIG
A33: Refrigeration | C33: REF
A34: Other appliances | C34: OEL
A35: Data centers | C35: DCE
A36: Public lighting | C36: PLIG
A37: Other services | C37: OTS
A38: Fuels
A39: Solids | B39: COA | C39: SRVCOA
A40: LPG | B40: LPG | C40: SRVLPG
A41: Oil | B41: OIL | C41: SRVOIL
A42: Natural Gas | B42: GAS | C42: SRVGAS
A43: Biomass | B43: BIO | C43: SRVBIO
A44: Biogas | B44: BGS | C44: SRVBGS
A45: Solar | B45: SOL | C45: SRVSOL
A46: Electricity | B46: ELC | C46: SRVELC
...

Sheet Ambient Heat
B1: Input to control ambient heat per unit of heat produced
B3: ~TFM_INS-TS
B4: PSET_PN | C4: Attribute | D4: Cset_CN | E4: Other_Indexes | F4: 2018 | G4: 2030 | H4: 2040 | I4: 2050 | J4: 0
B5: \I: Public services HPs - SH
B6: S-SH-PU_ELC_N2 | C6: FLO_SHAR | D6: SRVAHT | E6: SRVSH-PU | F6: =MAX(0,1-(1/AVERAGEIFS(COP!$L$2:$L$500,COP!$C$2:$C$500,'Ambient Heat'!$B6,COP!$G$2:$G$500,'Ambient Heat'!F$4,COP!$D$2:$D$500,$E6))) -> 0.52380952 | G6: =MAX(0,1-(1/AVERAGEIFS(COP!$L$2:$L$500,COP!$C$2:$C$500,'Ambient Heat'!$B6,COP!$G$2:$G$500,'Ambient Heat'!G$4,COP!$D$2:$D$500,$E6))) -> 0.61389961 | H6: =MAX(0,1-(1/AVERAGEIFS(COP!$L$2:$L$500,COP!$C$2:$C$500,'Ambient Heat'!$B6,COP!$G$2:$G$500,'Ambient Heat'!H$4,COP!$D$2:$D$500,$E6))) -> 0.64285714 | I6: =MAX(0,1-(1/AVERAGEIFS(COP!$L$2:$L$500,COP!$C$2:$C$500,'Ambient Heat'!$B6,COP!$G$2:$G$500,'Ambient Heat'!I$4,COP!$D$2:$D$500,$E6))) -> 0.64285714 | J6: 5
B7: S-SH-PU_ELC_N3 | C7: FLO_SHAR | D7: SRVAHT | E7: SRVSH-PU | F7: =MAX(0,1-(1/AVERAGEIFS(COP!$L$2:$L$500,COP!$C$2:$C$500,'Ambient Heat'!$B7,COP!$G$2:$G$500,'Ambient Heat'!F$4,COP!$D$2:$D$500,$E7))) -> 0.52380952 | G7: =MAX(0,1-(1/AVERAGEIFS(COP!$L$2:$L$500,COP!$C$2:$C$500,'Ambient Heat'!$B7,COP!$G$2:$G$500,'Ambient Heat'!G$4,COP!$D$2:$D$500,$E7))) -> 0.61389961 | H7: =MAX(0,1-(1/AVERAGEIFS(COP!$L$2:$L$500,COP!$C$2:$C$500,'Ambient Heat'!$B7,COP!$G$2:$G$500,'Ambient Heat'!H$4,COP!$D$2:$D$500,$E7))) -> 0.64285714 | I7: =MAX(0,1-(1/AVERAGEIFS(COP!$L$2:$L$500,COP!$C$2:$C$500,'Ambient Heat'!$B7,COP!$G$2:$G$500,'Ambient Heat'!I$4,COP!$D$2:$D$500,$E7))) -> 0.64285714 | J7: 5
B8: S-SH-PU_ELC_N4 | C8: FLO_SHAR | D8: SRVAHT | E8: SRVSH-PU | F8: =MAX(0,1-(1/AVERAGEIFS(COP!$L$2:$L$500,COP!$C$2:$C$500,'Ambient Heat'!$B8,COP!$G$2:$G$500,'Ambient Heat'!F$4,COP!$D$2:$D$500,$E8))) -> 0.52380952 | G8: =MAX(0,1-(1/AVERAGEIFS(COP!$L$2:$L$500,COP!$C$2:$C$500,'Ambient Heat'!$B8,COP!$G$2:$G$500,'Ambient Heat'!G$4,COP!$D$2:$D$500,$E8))) -> 0.61389961 | H8: =MAX(0,1-(1/AVERAGEIFS(COP!$L$2:$L$500,COP!$C$2:$C$500,'Ambient Heat'!$B8,COP!$G$2:$G$500,'Ambient Heat'!H$4,COP!$D$2:$D$500,$E8))) -> 0.64285714 | I8: =MAX(0,1-(1/AVERAGEIFS(COP!$L$2:$L$500,COP!$C$2:$C$500,'Ambient Heat'!$B8,COP!$G$2:$G$500,'Ambient Heat'!I$4,COP!$D$2:$D$500,$E8))) -> 0.64285714 | J8: 5
B9: S-SH-PU_ELC_N5 | C9: FLO_SHAR | D9: SRVAHT | E9: SRVSH-PU | F9: =MAX(0,1-(1/AVERAGEIFS(COP!$L$2:$L$500,COP!$C$2:$C$500,'Ambient Heat'!$B9,COP!$G$2:$G$500,'Ambient Heat'!F$4,COP!$D$2:$D$500,$E9))) -> 0.52380952 | G9: =MAX(0,1-(1/AVERAGEIFS(COP!$L$2:$L$500,COP!$C$2:$C$500,'Ambient Heat'!$B9,COP!$G$2:$G$500,'Ambient Heat'!G$4,COP!$D$2:$D$500,$E9))) -> 0.61389961 | H9: =MAX(0,1-(1/AVERAGEIFS(COP!$L$2:$L$500,COP!$C$2:$C$500,'Ambient Heat'!$B9,COP!$G$2:$G$500,'Ambient Heat'!H$4,COP!$D$2:$D$500,$E9))) -> 0.64285714 | I9: =MAX(0,1-(1/AVERAGEIFS(COP!$L$2:$L$500,COP!$C$2:$C$500,'Ambient Heat'!$B9,COP!$G$2:$G$500,'Ambient Heat'!I$4,COP!$D$2:$D$500,$E9))) -> 0.64285714 | J9: 5
B10: S-SH-PU_ELC_N6 | C10: FLO_SHAR | D10: SRVAHT | E10: SRVSH-PU | F10: =MAX(0,1-(1/AVERAGEIFS(COP!$L$2:$L$500,COP!$C$2:$C$500,'Ambient Heat'!$B10,COP!$G$2:$G$500,'Ambient Heat'!F$4,COP!$D$2:$D$500,$E10))) -> 0.52380952 | G10: =MAX(0,1-(1/AVERAGEIFS(COP!$L$2:$L$500,COP!$C$2:$C$500,'Ambient Heat'!$B10,COP!$G$2:$G$500,'Ambient Heat'!G$4,COP!$D$2:$D$500,$E10))) -> 0.60493047 | H10: =MAX(0,1-(1/AVERAGEIFS(COP!$L$2:$L$500,COP!$C$2:$C$500,'Ambient Heat'!$B10,COP!$G$2:$G$500,'Ambient Heat'!H$4,COP!$D$2:$D$500,$E10))) -> 0.63181149 | I10: =MAX(0,1-(1/AVERAGEIFS(COP!$L$2:$L$500,COP!$C$2:$C$500,'Ambient Heat'!$B10,COP!$G$2:$G$500,'Ambient Heat'!I$4,COP!$D$2:$D$500,$E10))) -> 0.63181149 | J10: 5
B11: S-SH-PU_ELC_N7 | C11: FLO_SHAR | D11: SRVAHT | E11: SRVSH-PU | F11: =MAX(0,1-(1/AVERAGEIFS(COP!$L$2:$L$500,COP!$C$2:$C$500,'Ambient Heat'!$B11,COP!$G$2:$G$500,'Ambient Heat'!F$4,COP!$D$2:$D$500,$E11))) -> 0.56709957 | G11: =MAX(0,1-(1/AVERAGEIFS(COP!$L$2:$L$500,COP!$C$2:$C$500,'Ambient Heat'!$B11,COP!$G$2:$G$500,'Ambient Heat'!G$4,COP!$D$2:$D$500,$E11))) -> 0.64285714 | H11: =MAX(0,1-(1/AVERAGEIFS(COP!$L$2:$L$500,COP!$C$2:$C$500,'Ambient Heat'!$B11,COP!$G$2:$G$500,'Ambient Heat'!H$4,COP!$D$2:$D$500,$E11))) -> 0.68253968 | I11: =MAX(0,1-(1/AVERAGEIFS(COP!$L$2:$L$500,COP!$C$2:$C$500,'Ambient Heat'!$B11,COP!$G$2:$G$500,'Ambient Heat'!I$4,COP!$D$2:$D$500,$E11))) -> 0.68253968 | J11: 5
B12: S-SH-PU_ELC_N8 | C12: FLO_SHAR | D12: SRVAHT | E12: SRVSH-PU | F12: =MAX(0,1-(1/AVERAGEIFS(COP!$L$2:$L$500,COP!$C$2:$C$500,'Ambient Heat'!$B12,COP!$G$2:$G$500,'Ambient Heat'!F$4,COP!$D$2:$D$500,$E12))) -> 0.56709957 | G12: =MAX(0,1-(1/AVERAGEIFS(COP!$L$2:$L$500,COP!$C$2:$C$500,'Ambient Heat'!$B12,COP!$G$2:$G$500,'Ambient Heat'!G$4,COP!$D$2:$D$500,$E12))) -> 0.64285714 | H12: =MAX(0,1-(1/AVERAGEIFS(COP!$L$2:$L$500,COP!$C$2:$C$500,'Ambient Heat'!$B12,COP!$G$2:$G$500,'Ambient Heat'!H$4,COP!$D$2:$D$500,$E12))) -> 0.68253968 | I12: =MAX(0,1-(1/AVERAGEIFS(COP!$L$2:$L$500,COP!$C$2:$C$500,'Ambient Heat'!$B12,COP!$G$2:$G$500,'Ambient Heat'!I$4,COP!$D$2:$D$500,$E12))) -> 0.68253968 | J12: 5
B13: S-SH-PU_ELC_N9 | C13: FLO_SHAR | D13: SRVAHT | E13: SRVSH-PU | F13: =MAX(0,1-(1/AVERAGEIFS(COP!$L$2:$L$500,COP!$C$2:$C$500,'Ambient Heat'!$B13,COP!$G$2:$G$500,'Ambient Heat'!F$4,COP!$D$2:$D$500,$E13))) -> 0.52380952 | G13: =MAX(0,1-(1/AVERAGEIFS(COP!$L$2:$L$500,COP!$C$2:$C$500,'Ambient Heat'!$B13,COP!$G$2:$G$500,'Ambient Heat'!G$4,COP!$D$2:$D$500,$E13))) -> 0.57983193 | H13: =MAX(0,1-(1/AVERAGEIFS(COP!$L$2:$L$500,COP!$C$2:$C$500,'Ambient Heat'!$B13,COP!$G$2:$G$500,'Ambient Heat'!H$4,COP!$D$2:$D$500,$E13))) -> 0.59183673 | I13: =MAX(0,1-(1/AVERAGEIFS(COP!$L$2:$L$500,COP!$C$2:$C$500,'Ambient Heat'!$B13,COP!$G$2:$G$500,'Ambient Heat'!I$4,COP!$D$2:$D$500,$E13))) -> 0.59183673 | J13: 5
B14: S-SH-PU_GAS_N5 | C14: FLO_SHAR | D14: SRVAHT | E14: SRVSH-PU | F14: =MAX(0,1-(1/AVERAGEIFS(COP!$L$2:$L$500,COP!$C$2:$C$500,'Ambient Heat'!$B14,COP!$G$2:$G$500,'Ambient Heat'!F$4,COP!$D$2:$D$500,$E14))) -> 0.022562357 | G14: =MAX(0,1-(1/AVERAGEIFS(COP!$L$2:$L$500,COP!$C$2:$C$500,'Ambient Heat'!$B14,COP!$G$2:$G$500,'Ambient Heat'!G$4,COP!$D$2:$D$500,$E14))) -> 0.22379952 | H14: =MAX(0,1-(1/AVERAGEIFS(COP!$L$2:$L$500,COP!$C$2:$C$500,'Ambient Heat'!$B14,COP!$G$2:$G$500,'Ambient Heat'!H$4,COP!$D$2:$D$500,$E14))) -> 0.22379952 | I14: =MAX(0,1-(1/AVERAGEIFS(COP!$L$2:$L$500,COP!$C$2:$C$500,'Ambient Heat'!$B14,COP!$G$2:$G$500,'Ambient Heat'!I$4,COP!$D$2:$D$500,$E14))) -> 0.22379952 | J14: 5
B15: S-SH-PU_GAS_N6 | C15: FLO_SHAR | D15: SRVAHT | E15: SRVSH-PU | F15: =MAX(0,1-(1/AVERAGEIFS(COP!$L$2:$L$500,COP!$C$2:$C$500,'Ambient Heat'!$B15,COP!$G$2:$G$500,'Ambient Heat'!F$4,COP!$D$2:$D$500,$E15))) -> 0.12030612 | G15: =MAX(0,1-(1/AVERAGEIFS(COP!$L$2:$L$500,COP!$C$2:$C$500,'Ambient Heat'!$B15,COP!$G$2:$G$500,'Ambient Heat'!G$4,COP!$D$2:$D$500,$E15))) -> 0.14868334 | H15: =MAX(0,1-(1/AVERAGEIFS(COP!$L$2:$L$500,COP!$C$2:$C$500,'Ambient Heat'!$B15,COP!$G$2:$G$500,'Ambient Heat'!H$4,COP!$D$2:$D$500,$E15))) -> 0.17528699 | I15: =MAX(0,1-(1/AVERAGEIFS(COP!$L$2:$L$500,COP!$C$2:$C$500,'Ambient Heat'!$B15,COP!$G$2:$G$500,'Ambient Heat'!I$4,COP!$D$2:$D$500,$E15))) -> 0.17528699 | J15: 5
B16: \I: Commercial services HPs - SH
B17: S-SH-CS_ELC_N2 | C17: FLO_SHAR | D17: SRVAHT | E17: SRVSH-CS | F17: =MAX(0,1-(1/AVERAGEIFS(COP!$L$2:$L$500,COP!$C$2:$C$500,'Ambient Heat'!$B17,COP!$G$2:$G$500,'Ambient Heat'!F$4,COP!$D$2:$D$500,$E17))) -> 0.52380952 | G17: =MAX(0,1-(1/AVERAGEIFS(COP!$L$2:$L$500,COP!$C$2:$C$500,'Ambient Heat'!$B17,COP!$G$2:$G$500,'Ambient Heat'!G$4,COP!$D$2:$D$500,$E17))) -> 0.61389961 | H17: =MAX(0,1-(1/AVERAGEIFS(COP!$L$2:$L$500,COP!$C$2:$C$500,'Ambient Heat'!$B17,COP!$G$2:$G$500,'Ambient Heat'!H$4,COP!$D$2:$D$500,$E17))) -> 0.64285714 | I17: =MAX(0,1-(1/AVERAGEIFS(COP!$L$2:$L$500,COP!$C$2:$C$500,'Ambient Heat'!$B17,COP!$G$2:$G$500,'Ambient Heat'!I$4,COP!$D$2:$D$500,$E17))) -> 0.64285714 | J17: 5
B18: S-SH-CS_ELC_N3 | C18: FLO_SHAR | D18: SRVAHT | E18: SRVSH-CS | F18: =MAX(0,1-(1/AVERAGEIFS(COP!$L$2:$L$500,COP!$C$2:$C$500,'Ambient Heat'!$B18,COP!$G$2:$G$500,'Ambient Heat'!F$4,COP!$D$2:$D$500,$E18))) -> 0.52380952 | G18: =MAX(0,1-(1/AVERAGEIFS(COP!$L$2:$L$500,COP!$C$2:$C$500,'Ambient Heat'!$B18,COP!$G$2:$G$500,'Ambient Heat'!G$4,COP!$D$2:$D$500,$E18))) -> 0.61389961 | H18: =MAX(0,1-(1/AVERAGEIFS(COP!$L$2:$L$500,COP!$C$2:$C$500,'Ambient Heat'!$B18,COP!$G$2:$G$500,'Ambient Heat'!H$4,COP!$D$2:$D$500,$E18))) -> 0.64285714 | I18: =MAX(0,1-(1/AVERAGEIFS(COP!$L$2:$L$500,COP!$C$2:$C$500,'Ambient Heat'!$B18,COP!$G$2:$G$500,'Ambient Heat'!I$4,COP!$D$2:$D$500,$E18))) -> 0.64285714 | J18: 5
B19: S-SH-CS_ELC_N4 | C19: FLO_SHAR | D19: SRVAHT | E19: SRVSH-CS | F19: =MAX(0,1-(1/AVERAGEIFS(COP!$L$2:$L$500,COP!$C$2:$C$500,'Ambient Heat'!$B19,COP!$G$2:$G$500,'Ambient Heat'!F$4,COP!$D$2:$D$500,$E19))) -> 0.52380952 | G19: =MAX(0,1-(1/AVERAGEIFS(COP!$L$2:$L$500,COP!$C$2:$C$500,'Ambient Heat'!$B19,COP!$G$2:$G$500,'Ambient Heat'!G$4,COP!$D$2:$D$500,$E19))) -> 0.61389961 | H19: =MAX(0,1-(1/AVERAGEIFS(COP!$L$2:$L$500,COP!$C$2:$C$500,'Ambient Heat'!$B19,COP!$G$2:$G$500,'Ambient Heat'!H$4,COP!$D$2:$D$500,$E19))) -> 0.64285714 | I19: =MAX(0,1-(1/AVERAGEIFS(COP!$L$2:$L$500,COP!$C$2:$C$500,'Ambient Heat'!$B19,COP!$G$2:$G$500,'Ambient Heat'!I$4,COP!$D$2:$D$500,$E19))) -> 0.64285714 | J19: 5
B20: S-SH-CS_ELC_N5 | C20: FLO_SHAR | D20: SRVAHT | E20: SRVSH-CS | F20: =MAX(0,1-(1/AVERAGEIFS(COP!$L$2:$L$500,COP!$C$2:$C$500,'Ambient Heat'!$B20,COP!$G$2:$G$500,'Ambient Heat'!F$4,COP!$D$2:$D$500,$E20))) -> 0.52380952 | G20: =MAX(0,1-(1/AVERAGEIFS(COP!$L$2:$L$500,COP!$C$2:$C$500,'Ambient Heat'!$B20,COP!$G$2:$G$500,'Ambient Heat'!G$4,COP!$D$2:$D$500,$E20))) -> 0.61389961 | H20: =MAX(0,1-(1/AVERAGEIFS(COP!$L$2:$L$500,COP!$C$2:$C$500,'Ambient Heat'!$B20,COP!$G$2:$G$500,'Ambient Heat'!H$4,COP!$D$2:$D$500,$E20))) -> 0.64285714 | I20: =MAX(0,1-(1/AVERAGEIFS(COP!$L$2:$L$500,COP!$C$2:$C$500,'Ambient Heat'!$B20,COP!$G$2:$G$500,'Ambient Heat'!I$4,COP!$D$2:$D$500,$E20))) -> 0.64285714 | J20: 5
B21: S-SH-CS_ELC_N6 | C21: FLO_SHAR | D21: SRVAHT | E21: SRVSH-CS | F21: =MAX(0,1-(1/AVERAGEIFS(COP!$L$2:$L$500,COP!$C$2:$C$500,'Ambient Heat'!$B21,COP!$G$2:$G$500,'Ambient Heat'!F$4,COP!$D$2:$D$500,$E21))) -> 0.52380952 | G21: =MAX(0,1-(1/AVERAGEIFS(COP!$L$2:$L$500,COP!$C$2:$C$500,'Ambient Heat'!$B21,COP!$G$2:$G$500,'Ambient Heat'!G$4,COP!$D$2:$D$500,$E21))) -> 0.60493047 | H21: =MAX(0,1-(1/AVERAGEIFS(COP!$L$2:$L$500,COP!$C$2:$C$500,'Ambient Heat'!$B21,COP!$G$2:$G$500,'Ambient Heat'!H$4,COP!$D$2:$D$500,$E21))) -> 0.63181149 | I21: =MAX(0,1-(1/AVERAGEIFS(COP!$L$2:$L$500,COP!$C$2:$C$500,'Ambient Heat'!$B21,COP!$G$2:$G$500,'Ambient Heat'!I$4,COP!$D$2:$D$500,$E21))) -> 0.63181149 | J21: 5
B22: S-SH-CS_ELC_N7 | C22: FLO_SHAR | D22: SRVAHT | E22: SRVSH-CS | F22: =MAX(0,1-(1/AVERAGEIFS(COP!$L$2:$L$500,COP!$C$2:$C$500,'Ambient Heat'!$B22,COP!$G$2:$G$500,'Ambient Heat'!F$4,COP!$D$2:$D$500,$E22))) -> 0.56709957 | G22: =MAX(0,1-(1/AVERAGEIFS(COP!$L$2:$L$500,COP!$C$2:$C$500,'Ambient Heat'!$B22,COP!$G$2:$G$500,'Ambient Heat'!G$4,COP!$D$2:$D$500,$E22))) -> 0.64285714 | H22: =MAX(0,1-(1/AVERAGEIFS(COP!$L$2:$L$500,COP!$C$2:$C$500,'Ambient Heat'!$B22,COP!$G$2:$G$500,'Ambient Heat'!H$4,COP!$D$2:$D$500,$E22))) -> 0.68253968 | I22: =MAX(0,1-(1/AVERAGEIFS(COP!$L$2:$L$500,COP!$C$2:$C$500,'Ambient Heat'!$B22,COP!$G$2:$G$500,'Ambient Heat'!I$4,COP!$D$2:$D$500,$E22))) -> 0.68253968 | J22: 5
B23: S-SH-CS_ELC_N8 | C23: FLO_SHAR | D23: SRVAHT | E23: SRVSH-CS | F23: =MAX(0,1-(1/AVERAGEIFS(COP!$L$2:$L$500,COP!$C$2:$C$500,'Ambient Heat'!$B23,COP!$G$2:$G$500,'Ambient Heat'!F$4,COP!$D$2:$D$500,$E23))) -> 0.56709957 | G23: =MAX(0,1-(1/AVERAGEIFS(COP!$L$2:$L$500,COP!$C$2:$C$500,'Ambient Heat'!$B23,COP!$G$2:$G$500,'Ambient Heat'!G$4,COP!$D$2:$D$500,$E23))) -> 0.64285714 | H23: =MAX(0,1-(1/AVERAGEIFS(COP!$L$2:$L$500,COP!$C$2:$C$500,'Ambient Heat'!$B23,COP!$G$2:$G$500,'Ambient Heat'!H$4,COP!$D$2:$D$500,$E23))) -> 0.68253968 | I23: =MAX(0,1-(1/AVERAGEIFS(COP!$L$2:$L$500,COP!$C$2:$C$500,'Ambient Heat'!$B23,COP!$G$2:$G$500,'Ambient Heat'!I$4,COP!$D$2:$D$500,$E23))) -> 0.68253968 | J23: 5
B24: S-SH-CS_ELC_N9 | C24: FLO_SHAR | D24: SRVAHT | E24: SRVSH-CS | F24: =MAX(0,1-(1/AVERAGEIFS(COP!$L$2:$L$500,COP!$C$2:$C$500,'Ambient Heat'!$B24,COP!$G$2:$G$500,'Ambient Heat'!F$4,COP!$D$2:$D$500,$E24))) -> 0.52380952 | G24: =MAX(0,1-(1/AVERAGEIFS(COP!$L$2:$L$500,COP!$C$2:$C$500,'Ambient Heat'!$B24,COP!$G$2:$G$500,'Ambient Heat'!G$4,COP!$D$2:$D$500,$E24))) -> 0.57983193 | H24: =MAX(0,1-(1/AVERAGEIFS(COP!$L$2:$L$500,COP!$C$2:$C$500,'Ambient Heat'!$B24,COP!$G$2:$G$500,'Ambient Heat'!H$4,COP!$D$2:$D$500,$E24))) -> 0.59183673 | I24: =MAX(0,1-(1/AVERAGEIFS(COP!$L$2:$L$500,COP!$C$2:$C$500,'Ambient Heat'!$B24,COP!$G$2:$G$500,'Ambient Heat'!I$4,COP!$D$2:$D$500,$E24))) -> 0.59183673 | J24: 5
B25: S-SH-CS_GAS_N5 | C25: FLO_SHAR | D25: SRVAHT | E25: SRVSH-CS | F25: =MAX(0,1-(1/AVERAGEIFS(COP!$L$2:$L$500,COP!$C$2:$C$500,'Ambient Heat'!$B25,COP!$G$2:$G$500,'Ambient Heat'!F$4,COP!$D$2:$D$500,$E25))) -> 0.022562357 | G25: =MAX(0,1-(1/AVERAGEIFS(COP!$L$2:$L$500,COP!$C$2:$C$500,'Ambient Heat'!$B25,COP!$G$2:$G$500,'Ambient Heat'!G$4,COP!$D$2:$D$500,$E25))) -> 0.22379952 | H25: =MAX(0,1-(1/AVERAGEIFS(COP!$L$2:$L$500,COP!$C$2:$C$500,'Ambient Heat'!$B25,COP!$G$2:$G$500,'Ambient Heat'!H$4,COP!$D$2:$D$500,$E25))) -> 0.22379952 | I25: =MAX(0,1-(1/AVERAGEIFS(COP!$L$2:$L$500,COP!$C$2:$C$500,'Ambient Heat'!$B25,COP!$G$2:$G$500,'Ambient Heat'!I$4,COP!$D$2:$D$500,$E25))) -> 0.22379952 | J25: 5
B26: S-SH-CS_GAS_N6 | C26: FLO_SHAR | D26: SRVAHT | E26: SRVSH-CS | F26: =MAX(0,1-(1/AVERAGEIFS(COP!$L$2:$L$500,COP!$C$2:$C$500,'Ambient Heat'!$B26,COP!$G$2:$G$500,'Ambient Heat'!F$4,COP!$D$2:$D$500,$E26))) -> 0.12030612 | G26: =MAX(0,1-(1/AVERAGEIFS(COP!$L$2:$L$500,COP!$C$2:$C$500,'Ambient Heat'!$B26,COP!$G$2:$G$500,'Ambient Heat'!G$4,COP!$D$2:$D$500,$E26))) -> 0.14868334 | H26: =MAX(0,1-(1/AVERAGEIFS(COP!$L$2:$L$500,COP!$C$2:$C$500,'Ambient Heat'!$B26,COP!$G$2:$G$500,'Ambient Heat'!H$4,COP!$D$2:$D$500,$E26))) -> 0.17528699 | I26: =MAX(0,1-(1/AVERAGEIFS(COP!$L$2:$L$500,COP!$C$2:$C$500,'Ambient Heat'!$B26,COP!$G$2:$G$500,'Ambient Heat'!I$4,COP!$D$2:$D$500,$E26))) -> 0.17528699 | J26: 5
B27: \I: Public services HPs -WH
B28: S-SH-PU_ELC_N5 | C28: FLO_SHAR | D28: SRVAHT2 | E28: SRVWH-PU | F28: =MAX(0,1-(1/AVERAGEIFS(COP!$L$2:$L$500,COP!$C$2:$C$500,'Ambient Heat'!$B28,COP!$G$2:$G$500,'Ambient Heat'!F$4,COP!$D$2:$D$500,$E28))) -> 0.31972789 | G28: =MAX(0,1-(1/AVERAGEIFS(COP!$L$2:$L$500,COP!$C$2:$C$500,'Ambient Heat'!$B28,COP!$G$2:$G$500,'Ambient Heat'!G$4,COP!$D$2:$D$500,$E28))) -> 0.44842802 | H28: =MAX(0,1-(1/AVERAGEIFS(COP!$L$2:$L$500,COP!$C$2:$C$500,'Ambient Heat'!$B28,COP!$G$2:$G$500,'Ambient Heat'!H$4,COP!$D$2:$D$500,$E28))) -> 0.48979592 | I28: =MAX(0,1-(1/AVERAGEIFS(COP!$L$2:$L$500,COP!$C$2:$C$500,'Ambient Heat'!$B28,COP!$G$2:$G$500,'Ambient Heat'!I$4,COP!$D$2:$D$500,$E28))) -> 0.48979592 | J28: 5
B29: S-SH-PU_ELC_N6 | C29: FLO_SHAR | D29: SRVAHT2 | E29: SRVWH-PU | F29: =MAX(0,1-(1/AVERAGEIFS(COP!$L$2:$L$500,COP!$C$2:$C$500,'Ambient Heat'!$B29,COP!$G$2:$G$500,'Ambient Heat'!F$4,COP!$D$2:$D$500,$E29))) -> 0.65618016 | G29: =MAX(0,1-(1/AVERAGEIFS(COP!$L$2:$L$500,COP!$C$2:$C$500,'Ambient Heat'!$B29,COP!$G$2:$G$500,'Ambient Heat'!G$4,COP!$D$2:$D$500,$E29))) -> 0.67759616 | H29: =MAX(0,1-(1/AVERAGEIFS(COP!$L$2:$L$500,COP!$C$2:$C$500,'Ambient Heat'!$B29,COP!$G$2:$G$500,'Ambient Heat'!H$4,COP!$D$2:$D$500,$E29))) -> 0.69078541 | I29: =MAX(0,1-(1/AVERAGEIFS(COP!$L$2:$L$500,COP!$C$2:$C$500,'Ambient Heat'!$B29,COP!$G$2:$G$500,'Ambient Heat'!I$4,COP!$D$2:$D$500,$E29))) -> 0.69078541 | J29: 5
B30: S-SH-PU_GAS_N5 | C30: FLO_SHAR | D30: SRVAHT2 | E30: SRVWH-PU | F30: =MAX(0,1-(1/AVERAGEIFS(COP!$L$2:$L$500,COP!$C$2:$C$500,'Ambient Heat'!$B30,COP!$G$2:$G$500,'Ambient Heat'!F$4,COP!$D$2:$D$500,$E30))) -> 0 | G30: =MAX(0,1-(1/AVERAGEIFS(COP!$L$2:$L$500,COP!$C$2:$C$500,'Ambient Heat'!$B30,COP!$G$2:$G$500,'Ambient Heat'!G$4,COP!$D$2:$D$500,$E30))) -> 0 | H30: =MAX(0,1-(1/AVERAGEIFS(COP!$L$2:$L$500,COP!$C$2:$C$500,'Ambient Heat'!$B30,COP!$G$2:$G$500,'Ambient Heat'!H$4,COP!$D$2:$D$500,$E30))) -> 0 | I30: =MAX(0,1-(1/AVERAGEIFS(COP!$L$2:$L$500,COP!$C$2:$C$500,'Ambient Heat'!$B30,COP!$G$2:$G$500,'Ambient Heat'!I$4,COP!$D$2:$D$500,$E30))) -> 0 | J30: 5
B31: S-SH-PU_GAS_N6 | C31: FLO_SHAR | D31: SRVAHT2 | E31: SRVWH-PU | F31: =MAX(0,1-(1/AVERAGEIFS(COP!$L$2:$L$500,COP!$C$2:$C$500,'Ambient Heat'!$B31,COP!$G$2:$G$500,'Ambient Heat'!F$4,COP!$D$2:$D$500,$E31))) -> 0 | G31: =MAX(0,1-(1/AVERAGEIFS(COP!$L$2:$L$500,COP!$C$2:$C$500,'Ambient Heat'!$B31,COP!$G$2:$G$500,'Ambient Heat'!G$4,COP!$D$2:$D$500,$E31))) -> 0 | H31: =MAX(0,1-(1/AVERAGEIFS(COP!$L$2:$L$500,COP!$C$2:$C$500,'Ambient Heat'!$B31,COP!$G$2:$G$500,'Ambient Heat'!H$4,COP!$D$2:$D$500,$E31))) -> 0 | I31: =MAX(0,1-(1/AVERAGEIFS(COP!$L$2:$L$500,COP!$C$2:$C$500,'Ambient Heat'!$B31,COP!$G$2:$G$500,'Ambient Heat'!I$4,COP!$D$2:$D$500,$E31))) -> 0 | J31: 5
B32: \I: Commercial services HPs - WH
B33: S-SH-CS_ELC_N5 | C33: FLO_SHAR | D33: SRVAHT2 | E33: SRVWH-CS | F33: =MAX(0,1-(1/AVERAGEIFS(COP!$L$2:$L$500,COP!$C$2:$C$500,'Ambient Heat'!$B33,COP!$G$2:$G$500,'Ambient Heat'!F$4,COP!$D$2:$D$500,$E33))) -> 0.31972789 | G33: =MAX(0,1-(1/AVERAGEIFS(COP!$L$2:$L$500,COP!$C$2:$C$500,'Ambient Heat'!$B33,COP!$G$2:$G$500,'Ambient Heat'!G$4,COP!$D$2:$D$500,$E33))) -> 0.44842802 | H33: =MAX(0,1-(1/AVERAGEIFS(COP!$L$2:$L$500,COP!$C$2:$C$500,'Ambient Heat'!$B33,COP!$G$2:$G$500,'Ambient Heat'!H$4,COP!$D$2:$D$500,$E33))) -> 0.48979592 | I33: =MAX(0,1-(1/AVERAGEIFS(COP!$L$2:$L$500,COP!$C$2:$C$500,'Ambient Heat'!$B33,COP!$G$2:$G$500,'Ambient Heat'!I$4,COP!$D$2:$D$500,$E33))) -> 0.48979592 | J33: 5
B34: S-SH-CS_ELC_N6 | C34: FLO_SHAR | D34: SRVAHT2 | E34: SRVWH-CS | F34: =MAX(0,1-(1/AVERAGEIFS(COP!$L$2:$L$500,COP!$C$2:$C$500,'Ambient Heat'!$B34,COP!$G$2:$G$500,'Ambient Heat'!F$4,COP!$D$2:$D$500,$E34))) -> 0.65618016 | G34: =MAX(0,1-(1/AVERAGEIFS(COP!$L$2:$L$500,COP!$C$2:$C$500,'Ambient Heat'!$B34,COP!$G$2:$G$500,'Ambient Heat'!G$4,COP!$D$2:$D$500,$E34))) -> 0.67759616 | H34: =MAX(0,1-(1/AVERAGEIFS(COP!$L$2:$L$500,COP!$C$2:$C$500,'Ambient Heat'!$B34,COP!$G$2:$G$500,'Ambient Heat'!H$4,COP!$D$2:$D$500,$E34))) -> 0.69078541 | I34: =MAX(0,1-(1/AVERAGEIFS(COP!$L$2:$L$500,COP!$C$2:$C$500,'Ambient Heat'!$B34,COP!$G$2:$G$500,'Ambient Heat'!I$4,COP!$D$2:$D$500,$E34))) -> 0.69078541 | J34: 5
B35: S-SH-CS_GAS_N5 | C35: FLO_SHAR | D35: SRVAHT2 | E35: SRVWH-CS | F35: =MAX(0,1-(1/AVERAGEIFS(COP!$L$2:$L$500,COP!$C$2:$C$500,'Ambient Heat'!$B35,COP!$G$2:$G$500,'Ambient Heat'!F$4,COP!$D$2:$D$500,$E35))) -> 0 | G35: =MAX(0,1-(1/AVERAGEIFS(COP!$L$2:$L$500,COP!$C$2:$C$500,'Ambient Heat'!$B35,COP!$G$2:$G$500,'Ambient Heat'!G$4,COP!$D$2:$D$500,$E35))) -> 0 | H35: =MAX(0,1-(1/AVERAGEIFS(COP!$L$2:$L$500,COP!$C$2:$C$500,'Ambient Heat'!$B35,COP!$G$2:$G$500,'Ambient Heat'!H$4,COP!$D$2:$D$500,$E35))) -> 0 | I35: =MAX(0,1-(1/AVERAGEIFS(COP!$L$2:$L$500,COP!$C$2:$C$500,'Ambient Heat'!$B35,COP!$G$2:$G$500,'Ambient Heat'!I$4,COP!$D$2:$D$500,$E35))) -> 0 | J35: 5
B36: S-SH-CS_GAS_N6 | C36: FLO_SHAR | D36: SRVAHT2 | E36: SRVWH-CS | F36: =MAX(0,1-(1/AVERAGEIFS(COP!$L$2:$L$500,COP!$C$2:$C$500,'Ambient Heat'!$B36,COP!$G$2:$G$500,'Ambient Heat'!F$4,COP!$D$2:$D$500,$E36))) -> 0 | G36: =MAX(0,1-(1/AVERAGEIFS(COP!$L$2:$L$500,COP!$C$2:$C$500,'Ambient Heat'!$B36,COP!$G$2:$G$500,'Ambient Heat'!G$4,COP!$D$2:$D$500,$E36))) -> 0 | H36: =MAX(0,1-(1/AVERAGEIFS(COP!$L$2:$L$500,COP!$C$2:$C$500,'Ambient Heat'!$B36,COP!$G$2:$G$500,'Ambient Heat'!H$4,COP!$D$2:$D$500,$E36))) -> 0 | I36: =MAX(0,1-(1/AVERAGEIFS(COP!$L$2:$L$500,COP!$C$2:$C$500,'Ambient Heat'!$B36,COP!$G$2:$G$500,'Ambient Heat'!I$4,COP!$D$2:$D$500,$E36))) -> 0 | J36: 5

Sheet FillData
A2: ~TFM_Fill-R: w=COP; Hcol=Region
A3: Scenario | B3: LimType | C3: Attribute | D3: Year | E3: AllRegions | F3: Pset_PN
C4: CEFF | E4: 1 | F4: S-SH*ELC_N*, S-SH*GAS_N5, S-SH*GAS_N6, -*N1

Sheet COP
A1: scenario | B1: attribute | C1: process | D1: commodity | E1: lim_type | F1: time_slice | G1: year | H1: commodity_group | I1: currency | J1: stage | K1: sow | L1: IE | M1: National | N1: year2
A2: SRV_NewTechs | B2: CEFF | C2: S-SH-CS_ELC_N2 | D2: SRVSH-CS | E2: - | F2: ANNUAL | G2: 2018 | H2: - | I2: - | J2: - | K2: - | L2: 2.1 | M2: 2.1 | N2: -
A3: SRV_NewTechs | B3: CEFF | C3: S-SH-CS_ELC_N2 | D3: SRVSH-CS | E3: - | F3: ANNUAL | G3: 2020 | H3: - | I3: - | J3: - | K3: - | L3: 2.24 | M3: 2.24 | N3: -
A4: SRV_NewTechs | B4: CEFF | C4: S-SH-CS_ELC_N2 | D4: SRVSH-CS | E4: - | F4: ANNUAL | G4: 2030 | H4: - | I4: - | J4: - | K4: - | L4: 2.59 | M4: 2.59 | N4: -
A5: SRV_NewTechs | B5: CEFF | C5: S-SH-CS_ELC_N2 | D5: SRVSH-CS | E5: - | F5: ANNUAL | G5: 2040 | H5: - | I5: - | J5: - | K5: - | L5: 2.8 | M5: 2.8 | N5: -
A6: SRV_NewTechs | B6: CEFF | C6: S-SH-CS_ELC_N2 | D6: SRVSH-CS | E6: - | F6: ANNUAL | G6: 2050 | H6: - | I6: - | J6: - | K6: - | L6: 2.8 | M6: 2.8 | N6: -
A7: SRV_NewTechs | B7: CEFF | C7: S-SH-CS_ELC_N3 | D7: SRVSC-CS | E7: - | F7: ANNUAL | G7: 2018 | H7: - | I7: - | J7: - | K7: - | L7: 2.7466472 | M7: 2.7466472 | N7: -
A8: SRV_NewTechs | B8: CEFF | C8: S-SH-CS_ELC_N3 | D8: SRVSC-CS | E8: - | F8: ANNUAL | G8: 2020 | H8: - | I8: - | J8: - | K8: - | L8: 2.7466472 | M8: 2.7466472 | N8: -
A9: SRV_NewTechs | B9: CEFF | C9: S-SH-CS_ELC_N3 | D9: SRVSC-CS | E9: - | F9: ANNUAL | G9: 2030 | H9: - | I9: - | J9: - | K9: - | L9: 2.7466472 | M9: 2.7466472 | N9: -
A10: SRV_NewTechs | B10: CEFF | C10: S-SH-CS_ELC_N3 | D10: SRVSC-CS | E10: - | F10: ANNUAL | G10: 2040 | H10: - | I10: - | J10: - | K10: - | L10: 2.7466472 | M10: 2.7466472 | N10: -
A11: SRV_NewTechs | B11: CEFF | C11: S-SH-CS_ELC_N3 | D11: SRVSC-CS | E11: - | F11: ANNUAL | G11: 2050 | H11: - | I11: - | J11: - | K11: - | L11: 2.7466472 | M11: 2.7466472 | N11: -
A12: SRV_NewTechs | B12: CEFF | C12: S-SH-CS_ELC_N3 | D12: SRVSH-CS | E12: - | F12: ANNUAL | G12: 2018 | H12: - | I12: - | J12: - | K12: - | L12: 2.1 | M12: 2.1 | N12: -
A13: SRV_NewTechs | B13: CEFF | C13: S-SH-CS_ELC_N3 | D13: SRVSH-CS | E13: - | F13: ANNUAL | G13: 2020 | H13: - | I13: - | J13: - | K13: - | L13: 2.24 | M13: 2.24 | N13: -
... A171: SRV_NewTechs | B171: CEFF | C171: S-SH-PU_GAS_N6 | D171: SRVWH-PU | E171: - | F171: ANNUAL | G171: 2050 | H171: - | I171: - | J171: - | K171: - | L171: 0.69203656 | M171: 0.69203656 | N171: -
