Workbook

Sheet Cover
A16: TIMES-Ireland Model
A19: Document type: | B19: Scenario
A20: Sector(s): | B20: Supply sector (SUP)
A21: Purpose: | B21: Specify bioenergy potential
A23: Original developer(s): | B23: Alessandro Chiodi (UCC, a.chiodi@ucc.ie)
B24: James Glynn (UCC, james.glynn@ucc.ie)
A26: Current maintainer(s): | B26: Olexandr Balyk (UCC, olexandr.balyk@ucc.ie)
B27: Neha Jaggeshar (UCC, Neha.Jaggeshar@ucc.ie)
A29: Part of TIM version: | B29: 1
A30: Model repository: | B30: https://github.com/MaREI-EPMG/TIMES-Ireland-model
A31: Licence: | B31: CC BY-NC-SA 4.0 (unless specified otherwise)
B32: https://creativecommons.org/licenses/by-nc-sa/4.0/

Sheet TIM-LEAF BE baseline
B4: Potentials at low price
B5: ~TFM_INS-TS | AI5: ~TFM_INS-TS
B6: Pset_PN | C6: *Description | D6: Attribute | E6: *Output | F6: *Unit | G6: 2012 | H6: 2013 | I6: 2014 | J6: 2015 | K6: 2016 | L6: 2017 | M6: 2018 | N6: 2019 | O6: 2020 | P6: 2021 | Q6: 2022 | R6: 2023 | S6: 2024 | T6: 2025 | U6: 2026 | V6: 2027 | W6: 2028 | X6: 2029 | Y6: 2030 | Z6: 2031 | AA6: 2032 | AB6: 2033 | AC6: 2034 | AD6: 2035 | AE6: 2050 | AF6: 0 | AI6: Pset_PN | AJ6: *Description | AK6: Attribute | AL6: Curr | AM6: *Output | AN6: *Unit | AO6: 2012 | AP6: 2013 | AQ6: 2014 | AR6: 2015 | AS6: 2016 | AT6: 2017 | AU6: 2018 | AV6: 2019 | AW6: 2020 | AX6: 2021 | AY6: 2022 | AZ6: 2023 | BA6: 2024 | BB6: 2025 | BC6: 2026 | BD6: 2027 | BE6: 2028 | BF6: 2029 | BG6: 2030 | BH6: 2031 | BI6: 2032 | BJ6: 2033 | BK6: 2034 | BL6: 2035 | BM6: 0
B7: MINBIOMSW1_S1 | C7: Solid BMSW - Lo | D7: ACT_BND | E7: BIOMUN | F7: PJ | G7: 0 | H7: 0 | I7: 0 | J7: 3.1262909 | K7: 2.6049608 | L7: 2.6994647 | M7: 2.8452221 | N7: 2.9895776 | O7: 3.1322717 | P7: 3.2396892 | Q7: 3.3175766 | R7: 0.9936 | S7: 0.9936 | T7: 0.9936 | Y7: 1.3248 | AD7: 1.6956 | AE7: 1.9296 | AF7: 5 | AH7: * | AI7: MINBIOMSW1_S1 | AJ7: Solid BMSW - Lo | AK7: COST | AL7: MEUR2014 | AM7: BIOMUN | AN7: €14/GJ | AO7: -17.5 | AP7: -17.5 | AQ7: -17.5 | AR7: -17.5 | AS7: -17.5 | AT7: -17.5 | AU7: -17.5 | AV7: -17.5 | AW7: -17.5 | AX7: -17.5 | AY7: -17.5 | AZ7: -17.5 | BA7: -17.5 | BB7: -17.5 | BC7: -17.5 | BD7: -17.5 | BE7: -17.5 | BF7: -17.5 | BG7: -17.5 | BH7: -17.5 | BI7: -17.5 | BJ7: -17.5 | BK7: -17.5 | BL7: -17.5 | BM7: 5
B8: MINBIOTLW_S1 | C8: Tallow - Lo | D8: ACT_BND | E8: BIOWOO | F8: PJ | G8: 1.2166789 | H8: 1.2098959 | I8: 1.2031129 | J8: 1.1963299 | K8: 1.1956766 | L8: 1.1872518 | M8: 1.1939839 | N8: 1.199398 | O8: 1.2038833 | P8: 1.2075657 | Q8: 1.2114961 | R8: 1.2816 | S8: 1.2816 | T8: 1.2816 | Y8: 1.278 | AD8: 1.278 | AE8: 1.278 | AF8: 5 | AI8: MINBIOTLW_S1 | AJ8: Tallow - Lo | AK8: COST | AL8: MEUR2014 | AM8: BIOWOO | AN8: €14/GJ | AO8: 8.6111111 | AP8: 8.6111111 | AQ8: 8.6111111 | AR8: 8.6111111 | AS8: 8.6111111 | AT8: 8.6111111 | AU8: 8.6111111 | AV8: 8.6111111 | AW8: 8.6111111 | AX8: 8.6111111 | AY8: 8.6111111 | AZ8: 8.6111111 | BA8: 8.6111111 | BB8: 8.6111111 | BC8: 8.6111111 | BD8: 8.6111111 | BE8: 8.6111111 | BF8: 8.6111111 | BG8: 8.6111111 | BH8: 8.6111111 | BI8: 8.6111111 | BJ8: 8.6111111 | BK8: 8.6111111 | BL8: 8.6111111 | BM8: 5
B9: MINBIORVO_S1 | C9: RVO - Lo | D9: ACT_BND | E9: BIORPS | F9: PJ | G9: 0.1651369 | H9: 0.1657408 | I9: 0.16655123 | J9: 0.16754954 | K9: 0.16871342 | L9: 0.16996435 | M9: 0.17134549 | N9: 0.17272681 | O9: 0.17411101 | P9: 0.17550439 | Q9: 0.17682556 | R9: 0.1872 | S9: 0.1872 | T9: 0.1872 | Y9: 0.1944 | AD9: 0.198 | AE9: 0.216 | AF9: 5 | AI9: MINBIORVO_S1 | AJ9: RVO - Lo | AK9: COST | AL9: MEUR2014 | AM9: BIORPS | AN9: €14/GJ | AO9: 15.555556 | AP9: 15.555556 | AQ9: 15.555556 | AR9: 15.555556 | AS9: 15.555556 | AT9: 15.555556 | AU9: 15.555556 | AV9: 15.555556 | AW9: 15.555556 | AX9: 15.555556 | AY9: 15.555556 | AZ9: 15.555556 | BA9: 15.555556 | BB9: 15.555556 | BC9: 15.555556 | BD9: 15.555556 | BE9: 15.555556 | BF9: 15.555556 | BG9: 15.555556 | BH9: 15.555556 | BI9: 15.555556 | BJ9: 15.555556 | BK9: 15.555556 | BL9: 15.555556 | BM9: 5
B10: MINBIOWOO3_S1 | C10: Straw - Lo | D10: ACT_BND | E10: BIOWOO | F10: PJ | G10: 0.96587329 | H10: 0.60965915 | I10: 0.72384035 | J10: 0.69491738 | K10: 0.74952286 | L10: 0.92067764 | M10: 1.0008293 | N10: 1.0820166 | O10: 1.1594483 | P10: 1.2266257 | Q10: 1.2825322 | R10: 0 | S10: 0 | T10: 0 | Y10: 0.072 | AD10: 0.072 | AE10: 0.072 | AF10: 5 | AI10: MINBIOWOO3_S1 | AJ10: Straw - Lo | AK10: COST | AL10: MEUR2014 | AM10: BIOWOO | AN10: €14/GJ | AO10: 2.7777778 | AP10: 2.7777778 | AQ10: 2.7777778 | AR10: 2.7777778 | AS10: 2.7777778 | AT10: 2.7777778 | AU10: 2.7777778 | AV10: 2.7777778 | AW10: 2.7777778 | AX10: 2.7777778 | AY10: 2.7777778 | AZ10: 2.7777778 | BA10: 2.7777778 | BB10: 2.7777778 | BC10: 2.7777778 | BD10: 2.7777778 | BE10: 2.7777778 | BF10: 2.7777778 | BG10: 2.7777778 | BH10: 2.7777778 | BI10: 2.7777778 | BJ10: 2.7777778 | BK10: 2.7777778 | BL10: 2.7777778 | BM10: 5
B11: MINBIOMSW2_S1 | C11: BMSW - Lo | D11: ACT_BND | E11: BIOMUN | F11: PJ | G11: 0.20413994 | H11: 0.25525375 | I11: 0.26222224 | J11: 0.27412924 | K11: 0.29545303 | L11: 0.30611938 | M11: 0.3150569 | N11: 0.32396077 | O11: 0.33281576 | P11: 0.33973891 | Q11: 0.34503662 | R11: 4.5432 | S11: 4.5432 | T11: 4.5432 | AF11: 5 | AI11: MINBIOMSW2_S1 | AJ11: BMSW - Lo | AK11: COST | AL11: MEUR2014 | AM11: BIOMUN | AN11: €14/GJ | AO11: -13.055556 | AP11: -13.055556 | AQ11: -13.055556 | AR11: -13.055556 | AS11: -13.055556 | AT11: -13.055556 | AU11: -13.055556 | AV11: -13.055556 | AW11: -13.055556 | AX11: -13.055556 | AY11: -13.055556 | AZ11: -13.055556 | BA11: -13.055556 | BB11: -13.055556 | BC11: -13.055556 | BD11: -13.055556 | BE11: -13.055556 | BF11: -13.055556 | BG11: -13.055556 | BH11: -13.055556 | BI11: -13.055556 | BJ11: -13.055556 | BK11: -13.055556 | BL11: -13.055556 | BM11: 5
B12: MINBIOINDF_S1 | C12: Industrial Food - Lo | D12: ACT_BND | E12: BIOSLU | F12: PJ | G12: 0 | H12: 0 | I12: 0 | J12: 0.57087653 | K12: 0.57291491 | L12: 0.57327233 | M12: 0.57482637 | N12: 0.57674672 | O12: 0.57880001 | P12: 0.58064982 | Q12: 0.58232064 | R12: 0.2772 | S12: 0.2772 | T12: 0.2772 | Y12: 0.3492 | AD12: 0.3492 | AE12: 0.3492 | AF12: 5 | AI12: MINBIOINDF_S1 | AJ12: Industrial Food - Lo | AK12: COST | AL12: MEUR2014 | AM12: BIOSLU | AN12: €14/GJ | AO12: 0 | AP12: 0 | AQ12: 0 | AR12: 0 | AS12: 0 | AT12: 0 | AU12: 0 | AV12: 0 | AW12: 0 | AX12: 0 | AY12: 0 | AZ12: 0 | BA12: 0 | BB12: 0 | BC12: 0 | BD12: 0 | BE12: 0 | BF12: 0 | BG12: 0 | BH12: 0 | BI12: 0 | BJ12: 0 | BK12: 0 | BL12: 0 | BM12: 5
B18: Potentials at medium price
B19: ~TFM_INS-TS | AI19: ~TFM_INS-TS
B20: Pset_PN | C20: *Description | D20: Attribute | E20: *Output | F20: *Unit | G20: 2012 | H20: 2013 | I20: 2014 | J20: 2015 | K20: 2016 | L20: 2017 | M20: 2018 | N20: 2019 | O20: 2020 | P20: 2021 | Q20: 2022 | R20: 2023 | S20: 2024 | T20: 2025 | U20: 2026 | V20: 2027 | W20: 2028 | X20: 2029 | Y20: 2030 | Z20: 2031 | AA20: 2032 | AB20: 2033 | AC20: 2034 | AD20: 2035 | AE20: 2050 | AF20: 0 | AI20: Pset_PN | AJ20: *Description | AK20: Attribute | AL20: Curr | AM20: *Output | AN20: *Unit | AO20: 2012 | AP20: 2013 | AQ20: 2014 | AR20: 2015 | AS20: 2016 | AT20: 2017 | AU20: 2018 | AV20: 2019 | AW20: 2020 | AX20: 2021 | AY20: 2022 | AZ20: 2023 | BA20: 2024 | BB20: 2025 | BC20: 2026 | BD20: 2027 | BE20: 2028 | BF20: 2029 | BG20: 2030 | BH20: 2031 | BI20: 2032 | BJ20: 2033 | BK20: 2034 | BL20: 2035 | BM20: 0
B21: MINBIOMSW1_S2 | C21: Solid BMSW - Me | D21: ACT_BND | E21: BIOMUN | F21: PJ | G21: 2.0096725 | H21: 3.6110097 | I21: 3.3041336 | J21: 3.3041336 | K21: 3.3041336 | L21: 3.3041336 | M21: 3.3041336 | N21: 3.3041336 | O21: 3.3041336 | P21: 3.3041336 | Q21: 3.3041336 | R21: 3.3041336 | S21: 3.3041336 | T21: 0.2484 | Y21: 0.3312 | AD21: 0.4248 | AE21: 0.4824 | AF21: 5 | AH21: * | AI21: MINBIOMSW1_S2 | AJ21: Solid BMSW - Me | AK21: COST | AL21: MEUR2014 | AM21: BIOMUN | AN21: €14/GJ | AO21: -10 | AP21: -10 | AQ21: -10 | AR21: -10 | AS21: -10 | AT21: -10 | AU21: -10 | AV21: -10 | AW21: -10 | AX21: -10 | AY21: -10 | AZ21: -10 | BA21: -10 | BB21: -10 | BC21: -10 | BD21: -10 | BE21: -10 | BF21: -10 | BG21: -10 | BH21: -10 | BI21: -10 | BJ21: -10 | BK21: -10 | BL21: -10 | BM21: 5
B22: MINBIOTLW_S2 | C22: Tallow - Me | D22: ACT_BND | E22: BIOWOO | F22: PJ | G22: 0.60833944 | H22: 0.60494794 | I22: 0.60155645 | J22: 0.59816495 | K22: 0.59783829 | L22: 0.59362588 | M22: 0.59699193 | N22: 0.59969899 | O22: 0.60194164 | P22: 0.60378287 | Q22: 0.60574805 | R22: 0.6408 | S22: 0.6408 | T22: 0.6408 | Y22: 0.6372 | AD22: 0.6372 | AE22: 0.6372 | AF22: 5 | AI22: MINBIOTLW_S2 | AJ22: Tallow - Me | AK22: COST | AL22: MEUR2014 | AM22: BIOWOO | AN22: €14/GJ | AO22: 10.277778 | AP22: 10.277778 | AQ22: 10.277778 | AR22: 10.277778 | AS22: 10.277778 | AT22: 10.277778 | AU22: 10.277778 | AV22: 10.277778 | AW22: 10.277778 | AX22: 10.277778 | AY22: 10.277778 | AZ22: 10.277778 | BA22: 10.277778 | BB22: 10.277778 | BC22: 10.277778 | BD22: 10.277778 | BE22: 10.277778 | BF22: 10.277778 | BG22: 10.277778 | BH22: 10.277778 | BI22: 10.277778 | BJ22: 10.277778 | BK22: 10.277778 | BL22: 10.277778 | BM22: 5
B23: MINBIORVO_S2 | C23: RVO - Me | D23: ACT_BND | E23: BIORPS | F23: PJ | G23: 0.1651369 | H23: 0.1657408 | I23: 0.16655123 | J23: 0.16754954 | K23: 0.16871342 | L23: 0.16996435 | M23: 0.17134549 | N23: 0.17272681 | O23: 0.17411101 | P23: 0.17550439 | Q23: 0.17682556 | R23: 0.1872 | S23: 0.1872 | T23: 0.1872 | Y23: 0.1944 | AD23: 0.198 | AE23: 0.216 | AF23: 5 | AI23: MINBIORVO_S2 | AJ23: RVO - Me | AK23: COST | AL23: MEUR2014 | AM23: BIORPS | AN23: €14/GJ | AO23: 22.5 | AP23: 22.5 | AQ23: 22.5 | AR23: 22.5 | AS23: 22.5 | AT23: 22.5 | AU23: 22.5 | AV23: 22.5 | AW23: 22.5 | AX23: 22.5 | AY23: 22.5 | AZ23: 22.5 | BA23: 22.5 | BB23: 22.5 | BC23: 22.5 | BD23: 22.5 | BE23: 22.5 | BF23: 22.5 | BG23: 22.5 | BH23: 22.5 | BI23: 22.5 | BJ23: 22.5 | BK23: 22.5 | BL23: 22.5 | BM23: 5
B24: MINBIOWOO3_S2 | C24: Straw - Me | D24: ACT_BND | E24: BIOWOO | F24: PJ | G24: 1.7707677 | H24: 1.1177084 | I24: 1.3270406 | J24: 1.2740152 | K24: 1.3741252 | L24: 1.687909 | M24: 1.8348537 | N24: 1.9836971 | O24: 2.1256553 | P24: 2.2488138 | Q24: 2.351309 | R24: 0 | S24: 0 | T24: 0 | Y24: 0.1332 | AD24: 0.1332 | AE24: 0.1332 | AF24: 5 | AI24: MINBIOWOO3_S2 | AJ24: Straw - Me | AK24: COST | AL24: MEUR2014 | AM24: BIOWOO | AN24: €14/GJ | AO24: 4.1666667 | AP24: 4.1666667 | AQ24: 4.1666667 | AR24: 4.1666667 | AS24: 4.1666667 | AT24: 4.1666667 | AU24: 4.1666667 | AV24: 4.1666667 | AW24: 4.1666667 | AX24: 4.1666667 | AY24: 4.1666667 | AZ24: 4.1666667 | BA24: 4.1666667 | BB24: 4.1666667 | BC24: 4.1666667 | BD24: 4.1666667 | BE24: 4.1666667 | BF24: 4.1666667 | BG24: 4.1666667 | BH24: 4.1666667 | BI24: 4.1666667 | BJ24: 4.1666667 | BK24: 4.1666667 | BL24: 4.1666667 | BM24: 5
B25: MINBIOMSW2_S2 | C25: BMSW - Me | D25: ACT_BND | E25: BIOMUN | F25: PJ | G25: 0.10206997 | H25: 0.12762688 | I25: 0.13111112 | J25: 0.13706462 | K25: 0.14772652 | L25: 0.15305969 | M25: 8 | N25: 8 | O25: 8 | P25: 8 | Q25: 8 | R25: 8 | S25: 8 | T25: 8 | U25: 8 | V25: 8 | W25: 8 | X25: 8 | Y25: 8 | Z25: 8 | AA25: 8 | AB25: 8 | AC25: 8 | AD25: 8 | AE25: 8 | AF25: 5 | AI25: MINBIOMSW2_S2 | AJ25: BMSW - Me | AK25: COST | AL25: MEUR2014 | AM25: BIOMUN | AN25: €14/GJ | AO25: 0.01 | AP25: 0.01 | AQ25: 0.01 | AR25: 0.01 | AS25: 0.01 | AT25: 0.01 | AU25: 0.01 | AV25: 0.01 | AW25: 0.01 | AX25: 0.01 | AY25: 0.01 | AZ25: 0.01 | BA25: 0.01 | BB25: 0.01 | BC25: 0.01 | BD25: 0.01 | BE25: 0.01 | BF25: 0.01 | BG25: 0.01 | BH25: 0.01 | BI25: 0.01 | BJ25: 0.01 | BK25: 0.01 | BL25: 0.01 | BM25: 5
B26: MINBIOINDF_S2 | C26: Industrial Food - Me | D26: ACT_BND | E26: BIOSLU | F26: PJ | G26: 0 | H26: 0 | I26: 0 | J26: 0 | K26: 0 | L26: 0 | M26: 0 | N26: 0 | O26: 0 | P26: 0 | Q26: 0 | R26: 0 | S26: 0 | T26: 0 | U26: 0 | V26: 0 | W26: 0 | X26: 0 | Y26: 0 | Z26: 0 | AA26: 0 | AB26: 0 | AC26: 0 | AD26: 0 | AE26: 0 | AF26: 5 | AI26: MINBIOINDF_S2 | AJ26: Industrial Food - Me | AK26: COST | AL26: MEUR2014 | AM26: BIOSLU | AN26: €14/GJ | AO26: 0 | AP26: 0 | AQ26: 0 | AR26: 0 | AS26: 0 | AT26: 0 | AU26: 0 | AV26: 0 | AW26: 0 | AX26: 0 | AY26: 0 | AZ26: 0 | BA26: 0 | BB26: 0 | BC26: 0 | BD26: 0 | BE26: 0 | BF26: 0 | BG26: 0 | BH26: 0 | BI26: 0 | BJ26: 0 | BK26: 0 | BL26: 0 | BM26: 5
B32: Potentials at high price
B33: ~TFM_INS-TS | AI33: ~TFM_INS-TS
B34: Pset_PN | C34: *Description | D34: Attribute | E34: *Output | F34: *Unit | G34: 2012 | H34: 2013 | I34: 2014 | J34: 2015 | K34: 2016 | L34: 2017 | M34: 2018 | N34: 2019 | O34: 2020 | P34: 2021 | Q34: 2022 | R34: 2023 | S34: 2024 | T34: 2025 | U34: 2026 | V34: 2027 | W34: 2028 | X34: 2029 | Y34: 2030 | Z34: 2031 | AA34: 2032 | AB34: 2033 | AC34: 2034 | AD34: 2035 | AE34: 2050 | AF34: 0 | AI34: Pset_PN | AJ34: *Description | AK34: Attribute | AL34: Curr | AM34: *Output | AN34: *Unit | AO34: 2012 | AP34: 2013 | AQ34: 2014 | AR34: 2015 | AS34: 2016 | AT34: 2017 | AU34: 2018 | AV34: 2019 | AW34: 2020 | AX34: 2021 | AY34: 2022 | AZ34: 2023 | BA34: 2024 | BB34: 2025 | BC34: 2026 | BD34: 2027 | BE34: 2028 | BF34: 2029 | BG34: 2030 | BH34: 2031 | BI34: 2032 | BJ34: 2033 | BK34: 2034 | BL34: 2035 | BM34: 0
B35: MINBIOMSW1_S3 | C35: Solid BMSW - Hi | D35: ACT_BND | E35: BIOMUN | F35: PJ | G35: 0 | H35: 0 | I35: 0 | J35: 0 | K35: 0 | L35: 0 | M35: 0 | N35: 0 | O35: 0 | P35: 0 | Q35: 0 | R35: 0.2484 | S35: 0.2484 | T35: 0.2484 | Y35: 0.3312 | AD35: 0.4248 | AE35: 0.4824 | AF35: 5 | AH35: * | AI35: MINBIOMSW1_S3 | AJ35: Solid BMSW - Hi | AK35: COST | AL35: MEUR2014 | AM35: BIOMUN | AN35: €14/GJ | AO35: -2.5 | AP35: -2.5 | AQ35: -2.5 | AR35: -2.5 | AS35: -2.5 | AT35: -2.5 | AU35: -2.5 | AV35: -2.5 | AW35: -2.5 | AX35: -2.5 | AY35: -2.5 | AZ35: -2.5 | BA35: -2.5 | BB35: -2.5 | BC35: -2.5 | BD35: -2.5 | BE35: -2.5 | BF35: -2.5 | BG35: -2.5 | BH35: -2.5 | BI35: -2.5 | BJ35: -2.5 | BK35: -2.5 | BL35: -2.5 | BM35: 5
B36: MINBIOTLW_S3 | C36: Tallow - Hi | D36: ACT_BND | E36: BIOWOO | F36: PJ | G36: 1.1233366 | H36: 1.117074 | I36: 1.1108114 | J36: 1.1045487 | K36: 1.1039455 | L36: 1.0961671 | M36: 1.1023827 | N36: 1.1073814 | O36: 1.1115226 | P36: 1.1149226 | Q36: 1.1185514 | R36: 1.1808 | S36: 1.1808 | T36: 1.1808 | Y36: 1.1808 | AD36: 1.1808 | AE36: 1.1808 | AF36: 5 | AI36: MINBIOTLW_S3 | AJ36: Tallow - Hi | AK36: COST | AL36: MEUR2014 | AM36: BIOWOO | AN36: €14/GJ | AO36: 11.111111 | AP36: 11.111111 | AQ36: 11.111111 | AR36: 11.111111 | AS36: 11.111111 | AT36: 11.111111 | AU36: 11.111111 | AV36: 11.111111 | AW36: 11.111111 | AX36: 11.111111 | AY36: 11.111111 | AZ36: 11.111111 | BA36: 11.111111 | BB36: 11.111111 | BC36: 11.111111 | BD36: 11.111111 | BE36: 11.111111 | BF36: 11.111111 | BG36: 11.111111 | BH36: 11.111111 | BI36: 11.111111 | BJ36: 11.111111 | BK36: 11.111111 | BL36: 11.111111 | BM36: 5
B37: MINBIORVO_S3 | C37: RVO - Hi | D37: ACT_BND | E37: BIORPS | F37: PJ | G37: 0 | H37: 0 | I37: 0 | J37: 0 | K37: 0 | L37: 0 | M37: 0 | N37: 0 | O37: 0 | P37: 0 | Q37: 0 | R37: 0 | S37: 0 | T37: 0 | Y37: 0 | AD37: 0 | AE37: 0 | AF37: 5 | AI37: MINBIORVO_S3 | AJ37: RVO - Hi | AK37: COST | AL37: MEUR2014 | AM37: BIORPS | AN37: €14/GJ | AO37: 27.777778 | AP37: 27.777778 | AQ37: 27.777778 | AR37: 27.777778 | AS37: 27.777778 | AT37: 27.777778 | AU37: 27.777778 | AV37: 27.777778 | AW37: 27.777778 | AX37: 27.777778 | AY37: 27.777778 | AZ37: 27.777778 | BA37: 27.777778 | BB37: 27.777778 | BC37: 27.777778 | BD37: 27.777778 | BE37: 27.777778 | BF37: 27.777778 | BG37: 27.777778 | BH37: 27.777778 | BI37: 27.777778 | BJ37: 27.777778 | BK37: 27.777778 | BL37: 27.777778 | BM37: 5
B38: MINBIOWOO3_S3 | C38: Straw - Hi | D38: ACT_BND | E38: BIOWOO | F38: PJ | G38: 0.48293664 | H38: 0.30482957 | I38: 0.36192017 | J38: 0.34745869 | K38: 0.37476143 | L38: 0.46033882 | M38: 0.50041466 | N38: 0.5410083 | O38: 0.57972417 | P38: 0.61331286 | Q38: 0.64126609 | R38: 0 | S38: 0 | T38: 0 | Y38: 0.036 | AD38: 0.036 | AE38: 0.036 | AF38: 5 | AI38: MINBIOWOO3_S3 | AJ38: Straw - Hi | AK38: COST | AL38: MEUR2014 | AM38: BIOWOO | AN38: €14/GJ | AO38: 6.9444444 | AP38: 6.9444444 | AQ38: 6.9444444 | AR38: 6.9444444 | AS38: 6.9444444 | AT38: 6.9444444 | AU38: 6.9444444 | AV38: 6.9444444 | AW38: 6.9444444 | AX38: 6.9444444 | AY38: 6.9444444 | AZ38: 6.9444444 | BA38: 6.9444444 | BB38: 6.9444444 | BC38: 6.9444444 | BD38: 6.9444444 | BE38: 6.9444444 | BF38: 6.9444444 | BG38: 6.9444444 | BH38: 6.9444444 | BI38: 6.9444444 | BJ38: 6.9444444 | BK38: 6.9444444 | BL38: 6.9444444 | BM38: 5
B39: MINBIOMSW2_S3 | C39: BMSW - Hi | D39: ACT_BND | E39: BIOMUN | F39: PJ | G39: 0.10206997 | H39: 0.12762688 | I39: 0.13111112 | J39: 0.13706462 | K39: 0.14772652 | L39: 0.15305969 | M39: 0.15752845 | N39: 0.16198038 | O39: 0 | P39: 0 | Q39: 0 | R39: 0 | S39: 0 | T39: 0 | U39: 0 | V39: 0 | W39: 0 | X39: 0 | Y39: 0 | Z39: 0 | AA39: 0 | AB39: 0 | AC39: 0 | AD39: 0 | AE39: 0 | AF39: 5 | AI39: MINBIOMSW2_S3 | AJ39: BMSW - Hi | AK39: COST | AL39: MEUR2014 | AM39: BIOMUN | AN39: €14/GJ | AO39: 0 | AP39: 0 | AQ39: 0 | AR39: 0 | AS39: 0 | AT39: 0 | AU39: 0 | AV39: 0 | AW39: 0 | AX39: 0 | AY39: 0 | AZ39: 0 | BA39: 0 | BB39: 0 | BC39: 0 | BD39: 0 | BE39: 0 | BF39: 0 | BG39: 0 | BH39: 0 | BI39: 0 | BJ39: 0 | BK39: 0 | BL39: 0 | BM39: 5
B40: MINBIOINDF_S3 | C40: Industrial Food - Hi | D40: ACT_BND | E40: BIOSLU | F40: PJ | G40: 0 | H40: 0 | I40: 0 | J40: 0 | K40: 0 | L40: 0 | M40: 0 | N40: 0 | O40: 0 | P40: 0 | Q40: 0 | R40: 0 | S40: 0 | T40: 0 | U40: 0 | V40: 0 | W40: 0 | X40: 0 | Y40: 0 | Z40: 0 | AA40: 0 | AB40: 0 | AC40: 0 | AD40: 0 | AE40: 0 | AF40: 5 | AI40: MINBIOINDF_S3 | AJ40: Industrial Food - Hi | AK40: COST | AL40: MEUR2014 | AM40: BIOSLU | AN40: €14/GJ | AO40: 0 | AP40: 0 | AQ40: 0 | AR40: 0 | AS40: 0 | AT40: 0 | AU40: 0 | AV40: 0 | AW40: 0 | AX40: 0 | AY40: 0 | AZ40: 0 | BA40: 0 | BB40: 0 | BC40: 0 | BD40: 0 | BE40: 0 | BF40: 0 | BG40: 0 | BH40: 0 | BI40: 0 | BJ40: 0 | BK40: 0 | BL40: 0 | BM40: 5
C45: Using the costs for Low potential
B46: ~TFM_INS-TS
B47: Pset_PN | C47: *Description | D47: Attribute | E47: Curr | F47: *Output | G47: *Unit | H47: 2012 | I47: 2013 | J47: 2014 | K47: 2015 | L47: 2016 | M47: 2017 | N47: 2018 | O47: 2019 | P47: 2020 | Q47: 2021 | R47: 2022 | S47: 2023 | T47: 2024 | U47: 2025 | V47: 2026 | W47: 2027 | X47: 2028 | Y47: 2029 | Z47: 2030 | AA47: 2031 | AB47: 2032 | AC47: 2033 | AD47: 2034 | AE47: 2035 | AF47: 0
B48: ABIOFRSR1 | C48: Forest thinnings - Lo | D48: ACTCOST | E48: MEUR2014 | F48: BIOWOO | G48: €14/GJ | H48: 4.7222222 | I48: 4.7222222 | J48: 4.7222222 | K48: 4.7222222 | L48: 4.7222222 | M48: 4.7222222 | N48: 4.7222222 | O48: 4.7222222 | P48: 4.7222222 | Q48: 4.7222222 | R48: 4.7222222 | S48: 4.7222222 | T48: 4.7222222 | U48: 4.7222222 | V48: 4.7222222 | W48: 4.7222222 | X48: 4.7222222 | Y48: 4.7222222 | Z48: 4.7222222 | AA48: 4.7222222 | AB48: 4.7222222 | AC48: 4.7222222 | AD48: 4.7222222 | AE48: 4.7222222 | AF48: 5
B49: ABIOCRP41 | C49: Willow - Lo | D49: ACTCOST | E49: MEUR2014 | F49: BIOWOO | G49: €14/GJ | H49: 6.3888889 | I49: 6.3888889 | J49: 6.3888889 | K49: 6.3888889 | L49: 6.3888889 | M49: 6.3888889 | N49: 6.3888889 | O49: 6.3888889 | P49: 6.3888889 | Q49: 6.3888889 | R49: 6.3888889 | S49: 6.3888889 | T49: 6.3888889 | U49: 6.3888889 | V49: 6.3888889 | W49: 6.3888889 | X49: 6.3888889 | Y49: 6.3888889 | Z49: 6.3888889 | AA49: 6.3888889 | AB49: 6.3888889 | AC49: 6.3888889 | AD49: 6.3888889 | AE49: 6.3888889 | AF49: 5
B50: ABIOCRP31 | C50: Miscanthus - Lo | D50: ACTCOST | E50: MEUR2014 | F50: BIOWOO | G50: €14/GJ | H50: 4 | I50: 4 | J50: 4 | K50: 4 | L50: 4 | M50: 4 | N50: 4 | O50: 4 | P50: 4 | Q50: 4 | R50: 4 | S50: 4 | T50: 4 | U50: 4 | V50: 4 | W50: 4 | X50: 4 | Y50: 4 | Z50: 4 | AA50: 4 | AB50: 4 | AC50: 4 | AD50: 4 | AE50: 4 | AF50: 5
B51: ABIOCRP11 | C51: Wheat - Lo | D51: ACTCOST | E51: MEUR2014 | F51: BIOCRP1 | G51: €14/GJ | H51: 19.01806 | I51: 19.01806 | J51: 19.01806 | K51: 19.01806 | L51: 19.01806 | M51: 19.01806 | N51: 19.01806 | O51: 19.01806 | P51: 19.01806 | Q51: 19.01806 | R51: 19.01806 | S51: 19.01806 | T51: 19.01806 | U51: 19.01806 | V51: 19.01806 | W51: 19.01806 | X51: 19.01806 | Y51: 19.01806 | Z51: 19.01806 | AA51: 19.01806 | AB51: 19.01806 | AC51: 19.01806 | AD51: 19.01806 | AE51: 19.01806 | AF51: 5
B52: ABIOCRP21 | C52: OSR - Lo | D52: ACTCOST | E52: MEUR2014 | F52: BIORPS | G52: €14/GJ | H52: 21.561401 | I52: 21.561401 | J52: 21.561401 | K52: 21.561401 | L52: 21.561401 | M52: 21.561401 | N52: 21.561401 | O52: 21.561401 | P52: 21.561401 | Q52: 21.561401 | R52: 21.561401 | S52: 21.561401 | T52: 21.561401 | U52: 21.561401 | V52: 21.561401 | W52: 21.561401 | X52: 21.561401 | Y52: 21.561401 | Z52: 21.561401 | AA52: 21.561401 | AB52: 21.561401 | AC52: 21.561401 | AD52: 21.561401 | AE52: 21.561401 | AF52: 5
B53: ABIOGAS11 | C53: Crops Anaerobic - Lo | D53: ACTCOST | E53: MEUR2014 | F53: BIOGAS | G53: €14/GJ | H53: 14.694444 | I53: 14.694444 | J53: 14.694444 | K53: 14.694444 | L53: 14.694444 | M53: 14.694444 | N53: 14.694444 | O53: 14.694444 | P53: 14.694444 | Q53: 14.694444 | R53: 14.694444 | S53: 14.694444 | T53: 14.694444 | U53: 14.694444 | V53: 14.694444 | W53: 14.694444 | X53: 14.694444 | Y53: 14.694444 | Z53: 14.694444 | AA53: 14.694444 | AB53: 14.694444 | AC53: 14.694444 | AD53: 14.694444 | AE53: 14.694444 | AF53: 5
B54: BIOWPE_Domestic | C54: WPE from domestic wod residues | D54: ACTCOST | E54: MEUR2013 | F54: BIOWPE | H54: 4.4444444 | I54: 4.4444444 | J54: 4.4444444 | K54: 4.4444444 | L54: 4.4444444 | M54: 4.4444444 | N54: 4.4444444 | O54: 4.4444444 | P54: 4.4444444 | Q54: 4.4444444 | R54: 4.4444444 | S54: 4.4444444 | T54: 4.4444444 | U54: 4.4444444 | V54: 4.4444444 | W54: 4.4444444 | X54: 4.4444444 | Y54: 4.4444444 | Z54: 4.4444444 | AA54: 4.4444444 | AB54: 4.4444444 | AC54: 4.4444444 | AD54: 4.4444444 | AE54: 4.4444444 | AF54: 5
B55: MINBIOWOO1_S1 | C55: Sawmill residues - Lo | D55: ACTCOST | E55: MEUR2014 | F55: BIOWOO1 | G55: €14/GJ | H55: 4.4444444 | I55: 4.4444444 | J55: 4.4444444 | K55: 4.4444444 | L55: 4.4444444 | M55: 4.4444444 | N55: 4.4444444 | O55: 4.4444444 | P55: 4.4444444 | Q55: 4.4444444 | R55: 4.4444444 | S55: 4.4444444 | T55: 4.4444444 | U55: 4.4444444 | V55: 4.4444444 | W55: 4.4444444 | X55: 4.4444444 | Y55: 4.4444444 | Z55: 4.4444444 | AA55: 4.4444444 | AB55: 4.4444444 | AC55: 4.4444444 | AD55: 4.4444444 | AE55: 4.4444444 | AF55: 5
B56: MINBIOWOO2_S1 | C56: PCRW - Lo | D56: ACTCOST | E56: MEUR2014 | F56: BIOWOO2 | G56: €14/GJ | H56: -0.83333333 | I56: -0.83333333 | J56: -0.83333333 | K56: -0.83333333 | L56: -0.83333333 | M56: -0.83333333 | N56: -0.83333333 | O56: -0.83333333 | P56: -0.83333333 | Q56: -0.83333333 | R56: -0.83333333 | S56: -0.83333333 | T56: -0.83333333 | U56: -0.83333333 | V56: -0.83333333 | W56: -0.83333333 | X56: -0.83333333 | Y56: -0.83333333 | Z56: -0.83333333 | AA56: -0.83333333 | AB56: -0.83333333 | AC56: -0.83333333 | AD56: -0.83333333 | AE56: -0.83333333 | AF56: 5
B57: ADGSCAT101 | C57: Cattle waste to biogas | D57: ACTCOST | E57: MEUR2014 | F57: AGRBGS | G57: €14/GJ | H57: 4.5992817 | I57: 4.5992817 | J57: 4.5992817 | K57: 4.5992817 | L57: 4.5992817 | M57: 4.5992817 | N57: 4.5992817 | O57: 4.5992817 | P57: 4.5992817 | Q57: 4.5992817 | R57: 4.5992817 | S57: 5.2210719 | T57: 4.5992817 | U57: 4.5992817 | V57: 4.5992817 | W57: 4.5992817 | X57: 4.5992817 | Y57: 4.5992817 | Z57: 4.5992817 | AA57: 4.5992817 | AB57: 4.5992817 | AC57: 4.5992817 | AD57: 4.5992817 | AE57: 4.5992817 | AF57: 5
...

Sheet BioenergySupply-Baseline
A1: Resource at low price | AD1: Low Price
A2: Feedstock | B2: Data Set | C2: Total Available for Bioenergy use (toe) | AD2: Feestock price (€/toe)
C3: 2010 | D3: 2011 | E3: 2012 | F3: 2013 | G3: 2014 | H3: 2015 | I3: 2016 | J3: 2017 | K3: 2018 | L3: 2019 | M3: 2020 | N3: 2021 | O3: 2022 | P3: 2023 | Q3: 2024 | R3: 2025 | S3: 2026 | T3: 2027 | U3: 2028 | V3: 2029 | W3: 2030 | X3: 2031 | Y3: 2032 | Z3: 2033 | AA3: 2034 | AB3: 2035 | AD3: 2010 | AE3: 2011 | AF3: 2012 | AG3: 2013 | AH3: 2014 | AI3: 2015 | AJ3: 2016 | AK3: 2017 | AL3: 2018 | AM3: 2019 | AN3: 2020 | AO3: 2021 | AP3: 2022 | AQ3: 2023 | AR3: 2024 | AS3: 2025 | AT3: 2026 | AU3: 2027 | AV3: 2028 | AW3: 2029 | AX3: 2030 | AY3: 2031 | AZ3: 2032 | BA3: 2033 | BB3: 2034 | BC3: 2035 | BG3: Potentials at low price
BG4: TFM_INS-TS | CN4: TFM_INS-TS
BG5: Pset_PN | BH5: *Description | BI5: Attribute | BJ5: *Output | BK5: *Unit | BL5: 2012 | BM5: 2013 | BN5: 2014 | BO5: 2015 | BP5: 2016 | BQ5: 2017 | BR5: 2018 | BS5: 2019 | BT5: 2020 | BU5: 2021 | BV5: 2022 | BW5: 2023 | BX5: 2024 | BY5: 2025 | BZ5: 2026 | CA5: 2027 | CB5: 2028 | CC5: 2029 | CD5: 2030 | CE5: 2031 | CF5: 2032 | CG5: 2033 | CH5: 2034 | CI5: 2035 | CJ5: 2050 | CK5: 0 | CN5: Pset_PN | CO5: *Description | CP5: Attribute | CQ5: Curr | CR5: *Output | CS5: *Unit | CT5: 2012 | CU5: 2013 | CV5: 2014 | CW5: 2015 | CX5: 2016 | CY5: 2017 | CZ5: 2018 | DA5: 2019 | DB5: 2020 | DC5: 2021 | DD5: 2022 | DE5: 2023 | DF5: 2024 | DG5: 2025 | DH5: 2026 | DI5: 2027 | DJ5: 2028 | DK5: 2029 | DL5: 2030 | DM5: 2031 | DN5: 2032 | DO5: 2033 | DP5: 2034 | DQ5: 2035 | DR5: 0
A6: Forest thinnings - Lo | B6: Forest | C6: 44167.383 | D6: 58670.106 | E6: 47298.653 | F6: 63449.412 | G6: 54385.211 | H6: 60016.003 | I6: 65646.795 | J6: 46721.84 | K6: 34389.032 | L6: 67377.233 | M6: 78116.939 | N6: 72237.914 | O6: 115737.81 | P6: 195427.64 | Q6: 239777.85 | R6: 270702.44 | S6: 295777.41 | T6: 330983.63 | U6: 238045.64 | V6: 282127.24 | W6: 264469.8 | X6: 261701.52 | Y6: 294087.6 | Z6: 304765.03 | AA6: 326688.68 | AB6: 458240.33 | AD6: 144.4446 | AE6: 144.4446 | AF6: 144.4446 | AG6: 144.4446 | AH6: 144.4446 | AI6: 144.4446 | AJ6: 144.4446 | AK6: 144.4446 | AL6: 144.4446 | AM6: 144.4446 | AN6: 144.4446 | AO6: 144.4446 | AP6: 144.4446 | AQ6: 144.4446 | AR6: 144.4446 | AS6: 144.4446 | AT6: 144.4446 | AU6: 144.4446 | AV6: 144.4446 | AW6: 144.4446 | AX6: 144.4446 | AY6: 144.4446 | AZ6: 144.4446 | BA6: 144.4446 | BB6: 144.4446 | BC6: 144.4446 | BE6: 1 | BG6: ="ABIOFRSR"&BE6 -> ABIOFRSR1 | BH6: =A6 -> Forest thinnings - Lo | BI6: ACT_BND | BJ6: BIOWOO | BK6: PJ | BL6: =E6/1000*Conversions!$B$2 -> 1.9803 | BM6: =F6/1000*Conversions!$B$2 -> 2.6565 | BN6: =G6/1000*Conversions!$B$2 -> 2.277 | BO6: =H6/1000*Conversions!$B$2 -> 2.51275 | BP6: =I6/1000*Conversions!$B$2 -> 2.7485 | BQ6: =J6/1000*Conversions!$B$2 -> 1.95615 | BR6: =K6/1000*Conversions!$B$2 -> 1.4398 | BS6: =L6/1000*Conversions!$B$2 -> 2.82095 | ... BV6: =O6/1000*Conversions!$B$2 -> 4.8457104 | BW6: =BX6 -> 4.824 | BX6: =BY6 -> 4.824 | BY6: =SEAI!N12 -> 4.824 | CD6: =SEAI!O12 -> 5.5764 | CI6: =SEAI!P12 -> 5.4432 | CJ6: =SEAI!S12 -> 2.6028 | CK6: 5 | CN6: =BG6 -> ABIOFRSR1 | CO6: =BH6 -> Forest thinnings - Lo | CP6: ACTCOST | CQ6: MEUR2014 | CR6: =BJ6 -> BIOWOO | CS6: €14/GJ | CT6: =SEAI!$L$12 -> 4.7222222 | CU6: =SEAI!$L$12 -> 4.7222222 | CV6: =SEAI!$L$12 -> 4.7222222 | CW6: =SEAI!$L$12 -> 4.7222222 | CX6: =SEAI!$L$12 -> 4.7222222 | CY6: =SEAI!$L$12 -> 4.7222222 | CZ6: =SEAI!$L$12 -> 4.7222222 | DA6: =SEAI!$L$12 -> 4.7222222 | ... DQ6: =SEAI!$L$12 -> 4.7222222 | DR6: 5
A7: Sawmill residues - Lo | B7: Sawmill | C7: 66580.682 | D7: 82072.227 | E7: 89488.392 | F7: 86357.122 | G7: 85697.908 | H7: 100130.34 | I7: 108535.13 | J7: 116928.29 | K7: 125309.68 | L7: 133679.14 | M7: 142036.55 | N7: 145559.22 | O7: 149159.73 | P7: 152839.75 | Q7: 156600.97 | R7: 160445.13 | S7: 164373.99 | T7: 168389.36 | U7: 172493.08 | V7: 176687.04 | W7: 180973.15 | X7: 185353.37 | Y7: 189829.71 | Z7: 194404.21 | AA7: 199078.95 | AB7: 203856.07 | AD7: 104.67 | AE7: 104.67 | AF7: 104.67 | AG7: 104.67 | AH7: 104.67 | AI7: 104.67 | AJ7: 104.67 | AK7: 104.67 | AL7: 104.67 | AM7: 104.67 | AN7: 104.67 | AO7: 104.67 | AP7: 104.67 | AQ7: 104.67 | AR7: 104.67 | AS7: 104.67 | AT7: 104.67 | AU7: 104.67 | AV7: 104.67 | AW7: 104.67 | AX7: 104.67 | AY7: 104.67 | AZ7: 104.67 | BA7: 104.67 | BB7: 104.67 | BC7: 104.67 | BE7: _S1 | BG7: ="MINBIOWOO1"&BE7 -> MINBIOWOO1_S1 | BH7: =A7 -> Sawmill residues - Lo | BI7: ACT_BND | BJ7: BIOWOO | BK7: PJ | BL7: =E7/1000*Conversions!$B$2 -> 3.7467 | BM7: =F7/1000*Conversions!$B$2 -> 3.6156 | BN7: =G7/1000*Conversions!$B$2 -> 3.588 | BO7: =H7/1000*Conversions!$B$2 -> 4.192257 | BP7: =I7/1000*Conversions!$B$2 -> 4.5441489 | BQ7: =J7/1000*Conversions!$B$2 -> 4.8955538 | BR7: =K7/1000*Conversions!$B$2 -> 5.2464656 | BS7: =L7/1000*Conversions!$B$2 -> 5.5968784 | ... BV7: =O7/1000*Conversions!$B$2 -> 6.2450197 | BW7: =BX7 -> 7.1604 | BX7: =BY7 -> 7.1604 | BY7: =SEAI!N13 -> 7.1604 | CD7: =SEAI!O13 -> 8.8236 | CI7: =SEAI!P13 -> 10.8036 | CJ7: =SEAI!S13 -> 13.1328 | CK7: 5 | CN7: =BG7 -> MINBIOWOO1_S1 | CO7: =BH7 -> Sawmill residues - Lo | CP7: COST | CQ7: MEUR2014 | CR7: =BJ7 -> BIOWOO | CS7: €14/GJ | CT7: =SEAI!$L$13 -> 4.4444444 | CU7: =SEAI!$L$13 -> 4.4444444 | CV7: =SEAI!$L$13 -> 4.4444444 | CW7: =SEAI!$L$13 -> 4.4444444 | CX7: =SEAI!$L$13 -> 4.4444444 | CY7: =SEAI!$L$13 -> 4.4444444 | CZ7: =SEAI!$L$13 -> 4.4444444 | DA7: =SEAI!$L$13 -> 4.4444444 | ... DQ7: =SEAI!$L$13 -> 4.4444444 | DR7: 5
A8: PCRW - Lo | B8: PCRW | C8: 21623.409 | D8: 16561.749 | E8: 15618.088 | F8: 16672.133 | G8: 16793.55 | H8: 17226.659 | I8: 17664.978 | J8: 18192.976 | K8: 18707.269 | L8: 19218.704 | M8: 19726.394 | N8: 19448.219 | O8: 19053.539 | P8: 18644.468 | Q8: 18190.13 | R8: 17757.167 | S8: 17311.964 | T8: 16848.622 | U8: 16366.683 | V8: 15865.681 | W8: 11508.855 | X8: 11687.822 | Y8: 11869.571 | Z8: 12054.147 | AA8: 12241.592 | AB8: 12431.953 | AD8: 61.805143 | AE8: 61.805143 | AF8: 61.805143 | AG8: 61.805143 | AH8: 61.805143 | AI8: 61.805143 | AJ8: 61.805143 | AK8: 61.805143 | AL8: 61.805143 | AM8: 61.805143 | AN8: 61.805143 | AO8: 61.805143 | AP8: 61.805143 | AQ8: 61.805143 | AR8: 61.805143 | AS8: 61.805143 | AT8: 61.805143 | AU8: 61.805143 | AV8: 61.805143 | AW8: 61.805143 | AX8: 61.805143 | AY8: 61.805143 | AZ8: 61.805143 | BA8: 61.805143 | BB8: 61.805143 | BC8: 61.805143 | BE8: _S1 | BG8: ="MINBIOWOO2"&BE8 -> MINBIOWOO2_S1 | BH8: =A8 -> PCRW - Lo | BI8: ACT_BND | BJ8: BIOWOO | BK8: PJ | BL8: =E8/1000*Conversions!$B$2 -> 0.65389811 | BM8: =F8/1000*Conversions!$B$2 -> 0.69802888 | BN8: =G8/1000*Conversions!$B$2 -> 0.70311235 | BO8: =H8/1000*Conversions!$B$2 -> 0.72124575 | BP8: =I8/1000*Conversions!$B$2 -> 0.73959732 | BQ8: =J8/1000*Conversions!$B$2 -> 0.76170351 | BR8: =K8/1000*Conversions!$B$2 -> 0.78323593 | BS8: =L8/1000*Conversions!$B$2 -> 0.80464869 | ... BV8: =O8/1000*Conversions!$B$2 -> 0.79773356 | BW8: =BX8 -> 0.6912 | BX8: =BY8 -> 0.6912 | BY8: =SEAI!N21 -> 0.6912 | CD8: =SEAI!O21 -> 0.5868 | CI8: =SEAI!P21 -> 0.432 | CJ8: =SEAI!S21 -> 0.4932 | CK8: 5 | CN8: =BG8 -> MINBIOWOO2_S1 | CO8: =BH8 -> PCRW - Lo | CP8: COST | CQ8: MEUR2014 | CR8: =BJ8 -> BIOWOO | CS8: €14/GJ | CT8: =SEAI!$L$21 -> -0.83333333 | CU8: =SEAI!$L$21 -> -0.83333333 | CV8: =SEAI!$L$21 -> -0.83333333 | CW8: =SEAI!$L$21 -> -0.83333333 | CX8: =SEAI!$L$21 -> -0.83333333 | CY8: =SEAI!$L$21 -> -0.83333333 | CZ8: =SEAI!$L$21 -> -0.83333333 | DA8: =SEAI!$L$21 -> -0.83333333 | ... DQ8: =SEAI!$L$21 -> -0.83333333 | DR8: 5
A9: Solid BMSW - Lo | B9: SolidBMSW | C9: 0 | D9: 0 | E9: 0 | F9: 0 | G9: 0 | H9: 74670.176 | I9: 62218.419 | J9: 64475.608 | K9: 67956.963 | L9: 71404.835 | M9: 74813.025 | N9: 77378.647 | O9: 79238.957 | P9: 81135 | Q9: 82816.248 | R9: 84830.878 | S9: 86919.511 | T9: 89037.5 | U9: 91185.288 | V9: 93363.326 | W9: 95572.07 | X9: 97810.596 | Y9: 100079.3 | Z9: 102378.57 | AA9: 104708.82 | AB9: 107070.45 | AD9: -610 | AE9: -610 | AF9: -610 | AG9: -610 | AH9: -610 | AI9: -610 | AJ9: -610 | AK9: -610 | AL9: -610 | AM9: -610 | AN9: -610 | AO9: -610 | AP9: -610 | AQ9: -610 | AR9: -610 | AS9: -610 | AT9: -610 | AU9: -610 | AV9: -610 | AW9: -610 | AX9: -610 | AY9: -610 | AZ9: -610 | BA9: -610 | BB9: -610 | BC9: -610 | BE9: _S1 | BG9: ="MINBIOMSW1"&BE9 -> MINBIOMSW1_S1 | BH9: =A9 -> Solid BMSW - Lo | BI9: ACT_BND | BJ9: BIOMUN | BK9: PJ | BL9: =E9/1000*Conversions!$B$2 -> 0 | BM9: =F9/1000*Conversions!$B$2 -> 0 | BN9: =G9/1000*Conversions!$B$2 -> 0 | BO9: =H9/1000*Conversions!$B$2 -> 3.1262909 | BP9: =I9/1000*Conversions!$B$2 -> 2.6049608 | BQ9: =J9/1000*Conversions!$B$2 -> 2.6994647 | BR9: =K9/1000*Conversions!$B$2 -> 2.8452221 | BS9: =L9/1000*Conversions!$B$2 -> 2.9895776 | ... BV9: =O9/1000*Conversions!$B$2 -> 3.3175766 | BW9: =BX9 -> 0.9936 | BX9: =BY9 -> 0.9936 | BY9: =SEAI!N25+SEAI!N24+SEAI!N23 -> 0.9936 | CD9: =SEAI!O25+SEAI!O24+SEAI!O23 -> 1.3248 | CI9: =SEAI!P25+SEAI!P24+SEAI!P23 -> 1.6956 | CJ9: =SEAI!S25+SEAI!S24+SEAI!S23 -> 1.9296 | CK9: 5 | CN9: =BG9 -> MINBIOMSW1_S1 | CO9: =BH9 -> Solid BMSW - Lo | CP9: COST | CQ9: MEUR2014 | CR9: =BJ9 -> BIOMUN | CS9: €14/GJ | CT9: =SEAI!$L$25 -> -17.5 | CU9: =SEAI!$L$25 -> -17.5 | CV9: =SEAI!$L$25 -> -17.5 | CW9: =SEAI!$L$25 -> -17.5 | CX9: =SEAI!$L$25 -> -17.5 | CY9: =SEAI!$L$25 -> -17.5 | CZ9: =SEAI!$L$25 -> -17.5 | DA9: =SEAI!$L$25 -> -17.5 | ... DQ9: =SEAI!$L$25 -> -17.5 | DR9: 5
A10: Tallow - Lo | B10: Tallow | C10: 28180.575 | D10: 27975.062 | E10: 29059.876 | F10: 28897.867 | G10: 28735.858 | H10: 28573.849 | I10: 28558.244 | J10: 28357.021 | K10: 28517.815 | L10: 28647.129 | M10: 28754.258 | N10: 28842.212 | O10: 28936.087 | P10: 29007.062 | Q10: 29032.932 | R10: 29022.325 | S10: 28954.046 | T10: 28843.993 | U10: 28702.375 | V10: 28536.84 | W10: 28354.122 | X10: 28161.438 | Y10: 27962.206 | Z10: 27759.012 | AA10: 27555.5 | AB10: 27345.909 | AD10: 365.12791 | AE10: 365.12791 | AF10: 365.12791 | AG10: 365.12791 | AH10: 365.12791 | AI10: 365.12791 | AJ10: 365.12791 | AK10: 365.12791 | AL10: 365.12791 | AM10: 365.12791 | AN10: 365.12791 | AO10: 365.12791 | AP10: 365.12791 | AQ10: 365.12791 | AR10: 365.12791 | AS10: 365.12791 | AT10: 365.12791 | AU10: 365.12791 | AV10: 365.12791 | AW10: 365.12791 | AX10: 365.12791 | AY10: 365.12791 | AZ10: 365.12791 | BA10: 365.12791 | BB10: 365.12791 | BC10: 365.12791 | BE10: _S1 | BG10: ="MINBIOTLW"&BE10 -> MINBIOTLW_S1 | BH10: =A10 -> Tallow - Lo | BI10: ACT_BND | BJ10: BIOWOO | BK10: PJ | BL10: =E10/1000*Conversions!$B$2 -> 1.2166789 | BM10: =F10/1000*Conversions!$B$2 -> 1.2098959 | BN10: =G10/1000*Conversions!$B$2 -> 1.2031129 | BO10: =H10/1000*Conversions!$B$2 -> 1.1963299 | BP10: =I10/1000*Conversions!$B$2 -> 1.1956766 | BQ10: =J10/1000*Conversions!$B$2 -> 1.1872518 | BR10: =K10/1000*Conversions!$B$2 -> 1.1939839 | BS10: =L10/1000*Conversions!$B$2 -> 1.199398 | ... BV10: =O10/1000*Conversions!$B$2 -> 1.2114961 | BW10: =BX10 -> 1.2816 | BX10: =BY10 -> 1.2816 | BY10: =SEAI!N30 -> 1.2816 | CD10: =SEAI!O30 -> 1.278 | CI10: =SEAI!P30 -> 1.278 | CJ10: =SEAI!S30 -> 1.278 | CK10: 5 | CN10: =BG10 -> MINBIOTLW_S1 | CO10: =BH10 -> Tallow - Lo | CP10: COST | CQ10: MEUR2014 | CR10: =BJ10 -> BIOWOO | CS10: €14/GJ | CT10: =SEAI!$L$30 -> 8.6111111 | CU10: =SEAI!$L$30 -> 8.6111111 | CV10: =SEAI!$L$30 -> 8.6111111 | CW10: =SEAI!$L$30 -> 8.6111111 | CX10: =SEAI!$L$30 -> 8.6111111 | CY10: =SEAI!$L$30 -> 8.6111111 | CZ10: =SEAI!$L$30 -> 8.6111111 | DA10: =SEAI!$L$30 -> 8.6111111 | ... DQ10: =SEAI!$L$30 -> 8.6111111 | DR10: 5
A11: RVO - Lo | B11: RVO | C11: 3807.4402 | D11: 3933.6956 | E11: 3944.227 | F11: 3958.6509 | G11: 3978.0077 | H11: 4001.8521 | I11: 4029.6509 | J11: 4059.5288 | K11: 4092.5168 | L11: 4125.509 | M11: 4158.5701 | N11: 4191.8504 | O11: 4223.4058 | P11: 4253.4058 | Q11: 4281.9613 | R11: 4309.2476 | S11: 4335.4222 | T11: 4360.5804 | U11: 4385.4394 | V11: 4410.2674 | W11: 4435.2571 | X11: 4460.3938 | Y11: 4485.638 | Z11: 4511.0765 | AA11: 4536.8598 | AB11: 4563 | AD11: 648.954 | AE11: 648.954 | AF11: 648.954 | AG11: 648.954 | AH11: 648.954 | AI11: 648.954 | AJ11: 648.954 | AK11: 648.954 | AL11: 648.954 | AM11: 648.954 | AN11: 648.954 | AO11: 648.954 | AP11: 648.954 | AQ11: 648.954 | AR11: 648.954 | AS11: 648.954 | AT11: 648.954 | AU11: 648.954 | AV11: 648.954 | AW11: 648.954 | AX11: 648.954 | AY11: 648.954 | AZ11: 648.954 | BA11: 648.954 | BB11: 648.954 | BC11: 648.954 | BE11: _S1 | BG11: ="MINBIORVO"&BE11 -> MINBIORVO_S1 | BH11: =A11 -> RVO - Lo | BI11: ACT_BND | BJ11: BIORPS | BK11: PJ | BL11: =E11/1000*Conversions!$B$2 -> 0.1651369 | BM11: =F11/1000*Conversions!$B$2 -> 0.1657408 | BN11: =G11/1000*Conversions!$B$2 -> 0.16655123 | BO11: =H11/1000*Conversions!$B$2 -> 0.16754954 | BP11: =I11/1000*Conversions!$B$2 -> 0.16871342 | BQ11: =J11/1000*Conversions!$B$2 -> 0.16996435 | BR11: =K11/1000*Conversions!$B$2 -> 0.17134549 | BS11: =L11/1000*Conversions!$B$2 -> 0.17272681 | ... BV11: =O11/1000*Conversions!$B$2 -> 0.17682556 | BW11: =BX11 -> 0.1872 | BX11: =BY11 -> 0.1872 | BY11: =SEAI!N27 -> 0.1872 | CD11: =SEAI!O27 -> 0.1944 | CI11: =SEAI!P27 -> 0.198 | CJ11: =SEAI!S27 -> 0.216 | CK11: 5 | CN11: =BG11 -> MINBIORVO_S1 | CO11: =BH11 -> RVO - Lo | CP11: COST | CQ11: MEUR2014 | CR11: =BJ11 -> BIORPS | CS11: €14/GJ | CT11: =SEAI!$L$26 -> 15.555556 | CU11: =SEAI!$L$26 -> 15.555556 | CV11: =SEAI!$L$26 -> 15.555556 | CW11: =SEAI!$L$26 -> 15.555556 | CX11: =SEAI!$L$26 -> 15.555556 | CY11: =SEAI!$L$26 -> 15.555556 | CZ11: =SEAI!$L$26 -> 15.555556 | DA11: =SEAI!$L$26 -> 15.555556 | ... DQ11: =SEAI!$L$26 -> 15.555556 | DR11: 5
A12: Straw - Lo | B12: Straw | C12: 10842.319 | D12: 18162.111 | E12: 23069.487 | F12: 14561.459 | G12: 17288.63 | H12: 16597.817 | I12: 17902.046 | J12: 21990.008 | K12: 23904.397 | L12: 25843.522 | M12: 27692.948 | N12: 29297.452 | O12: 30632.755 | P12: 31834.905 | Q12: 33105.149 | R12: 33724.835 | S12: 33082.003 | T12: 33917.295 | U12: 34854.172 | V12: 35869.801 | W12: 36944.226 | X12: 38056.562 | Y12: 39191.841 | Z12: 40330.036 | AA12: 41459.758 | AB12: 42613.71 | AD12: 118.26267 | AE12: 118.26267 | AF12: 118.26267 | AG12: 118.26267 | AH12: 118.26267 | AI12: 118.26267 | AJ12: 118.26267 | AK12: 118.26267 | AL12: 118.26267 | AM12: 118.26267 | AN12: 118.26267 | AO12: 118.26267 | AP12: 118.26267 | AQ12: 118.26267 | AR12: 118.26267 | AS12: 118.26267 | AT12: 118.26267 | AU12: 118.26267 | AV12: 118.26267 | AW12: 118.26267 | AX12: 118.26267 | AY12: 118.26267 | AZ12: 118.26267 | BA12: 118.26267 | BB12: 118.26267 | BC12: 118.26267 | BE12: _S1 | BG12: ="MINBIOWOO3"&BE12 -> MINBIOWOO3_S1 | BH12: =A12 -> Straw - Lo | BI12: ACT_BND | BJ12: BIOWOO | BK12: PJ | BL12: =E12/1000*Conversions!$B$2 -> 0.96587329 | BM12: =F12/1000*Conversions!$B$2 -> 0.60965915 | BN12: =G12/1000*Conversions!$B$2 -> 0.72384035 | BO12: =H12/1000*Conversions!$B$2 -> 0.69491738 | BP12: =I12/1000*Conversions!$B$2 -> 0.74952286 | BQ12: =J12/1000*Conversions!$B$2 -> 0.92067764 | BR12: =K12/1000*Conversions!$B$2 -> 1.0008293 | BS12: =L12/1000*Conversions!$B$2 -> 1.0820166 | ... BV12: =O12/1000*Conversions!$B$2 -> 1.2825322 | BW12: =BX12 -> 0 | BX12: =BY12 -> 0 | BY12: =SEAI!N16 -> 0 | CD12: =SEAI!O16 -> 0.072 | CI12: =SEAI!P16 -> 0.072 | CJ12: =SEAI!S16 -> 0.072 | CK12: 5 | CN12: =BG12 -> MINBIOWOO3_S1 | CO12: =BH12 -> Straw - Lo | CP12: COST | CQ12: MEUR2014 | CR12: =BJ12 -> BIOWOO | CS12: €14/GJ | CT12: =SEAI!$L$16 -> 2.7777778 | CU12: =SEAI!$L$16 -> 2.7777778 | CV12: =SEAI!$L$16 -> 2.7777778 | CW12: =SEAI!$L$16 -> 2.7777778 | CX12: =SEAI!$L$16 -> 2.7777778 | CY12: =SEAI!$L$16 -> 2.7777778 | CZ12: =SEAI!$L$16 -> 2.7777778 | DA12: =SEAI!$L$16 -> 2.7777778 | ... DQ12: =SEAI!$L$16 -> 2.7777778 | DR12: 5
A13: Cattle waste - Lo | B13: Cattle | C13: 810.6545 | D13: 830.90023 | E13: 853.49227 | F13: 872.70638 | G13: 891.92048 | H13: 911.13459 | I13: 939.63001 | J13: 948.58764 | K13: 965.37848 | L13: 987.90983 | M13: 1012.7292 | N13: 1035.2913 | O13: 1055.292 | P13: 945.22758 | Q13: 1088.324 | R13: 1101.6427 | S13: 1112.9368 | T13: 1122.1473 | U13: 1129.5181 | V13: 1135.3689 | W13: 1139.9266 | X13: 1143.3366 | Y13: 1145.4953 | Z13: 1146.642 | AA13: 1147.1695 | AB13: 1147.0261 | AD13: 0 | AE13: 0 | AF13: 0 | AG13: 0 | AH13: 0 | AI13: 0 | AJ13: 0 | AK13: 0 | AL13: 0 | AM13: 0 | AN13: 0 | AO13: 0 | AP13: 0 | AQ13: 0 | AR13: 0 | AS13: 0 | AT13: 0 | AU13: 0 | AV13: 0 | AW13: 0 | AX13: 0 | AY13: 0 | AZ13: 0 | BA13: 0 | BB13: 0 | BC13: 0 | BE13: _S1 | BG13: ="MINBIOCATW"&BE13 -> MINBIOCATW_S1 | BH13: =A13 -> Cattle waste - Lo | BI13: ACT_BND | BJ13: BIOSLU | BK13: PJ | BL13: =E13/1000*Conversions!$B$2 -> 0.035734014 | BM13: =F13/1000*Conversions!$B$2 -> 0.036538471 | BN13: =G13/1000*Conversions!$B$2 -> 0.037342927 | BO13: =H13/1000*Conversions!$B$2 -> 0.038147383 | BP13: =I13/1000*Conversions!$B$2 -> 0.039340429 | BQ13: =J13/1000*Conversions!$B$2 -> 0.039715467 | BR13: =K13/1000*Conversions!$B$2 -> 0.040418466 | BS13: =L13/1000*Conversions!$B$2 -> 0.041361809 | BT13: 0 | BU13: 0 | BV13: 0 | BW13: 0 | BX13: 0 | BY13: 0 | BZ13: 0 | CA13: 0 | CB13: 0 | CC13: 0 | CD13: 0 | CE13: 0 | CF13: 0 | CG13: 0 | CH13: 0 | CI13: 0 | CJ13: 0 | CK13: 5 | CN13: =BG13 -> MINBIOCATW_S1 | CO13: =BH13 -> Cattle waste - Lo | CP13: COST | CQ13: MEUR2014 | CR13: =BJ13 -> BIOSLU | CS13: €14/GJ | CT13: =IF(AF13<0,0.01,AF13/Conversions!$B$3) -> 0 | CU13: =IF(AG13<0,0.01,AG13/Conversions!$B$3) -> 0 | CV13: =IF(AH13<0,0.01,AH13/Conversions!$B$3) -> 0 | CW13: =IF(AI13<0,0.01,AI13/Conversions!$B$3) -> 0 | CX13: =IF(AJ13<0,0.01,AJ13/Conversions!$B$3) -> 0 | CY13: =IF(AK13<0,0.01,AK13/Conversions!$B$3) -> 0 | CZ13: =IF(AL13<0,0.01,AL13/Conversions!$B$3) -> 0 | DA13: =IF(AM13<0,0.01,AM13/Conversions!$B$3) -> 0 | ... DQ13: =IF(BC13<0,0.01,BC13/Conversions!$B$3) -> 0 | DR13: 5
A14: Pig waste - Lo | B14: Pig | C14: 23799.232 | D14: 24461.636 | E14: 24161.977 | F14: 23960.004 | G14: 23758.031 | H14: 23556.057 | I14: 23587.896 | J14: 23766.656 | K14: 23904.758 | L14: 23998.276 | M14: 24060.884 | N14: 24099.154 | O14: 24117.393 | P14: 24121.288 | Q14: 24117.717 | R14: 24111.082 | S14: 24102.731 | T14: 24093.283 | U14: 24082.668 | V14: 24070.806 | W14: 24059.124 | X14: 24060.316 | Y14: 24070.305 | Z14: 24075.871 | AA14: 24075.151 | AB14: 24069.188 | AD14: 0 | AE14: 0 | AF14: 0 | AG14: 0 | AH14: 0 | AI14: 0 | AJ14: 0 | AK14: 0 | AL14: 0 | AM14: 0 | AN14: 0 | AO14: 0 | AP14: 0 | AQ14: 0 | AR14: 0 | AS14: 0 | AT14: 0 | AU14: 0 | AV14: 0 | AW14: 0 | AX14: 0 | AY14: 0 | AZ14: 0 | BA14: 0 | BB14: 0 | BC14: 0 | BE14: _S1 | BG14: ="MINBIOPIGW"&BE14 -> MINBIOPIGW_S1 | BH14: =A14 -> Pig waste - Lo | BI14: ACT_BND | BJ14: BIOSLU | BK14: PJ | BL14: =E14/1000*Conversions!$B$2 -> 1.0116137 | BM14: =F14/1000*Conversions!$B$2 -> 1.0031574 | BN14: =G14/1000*Conversions!$B$2 -> 0.99470123 | BO14: =H14/1000*Conversions!$B$2 -> 0.98624501 | BP14: =I14/1000*Conversions!$B$2 -> 0.98757803 | BQ14: =J14/1000*Conversions!$B$2 -> 0.99506235 | BR14: =K14/1000*Conversions!$B$2 -> 1.0008444 | BS14: =L14/1000*Conversions!$B$2 -> 1.0047598 | ... BV14: =O14/1000*Conversions!$B$2 -> 1.009747 | BW14: =BX14 -> 1.8216 | BX14: =BY14 -> 1.8216 | BY14: =SEAI!N17 -> 1.8216 | CD14: =SEAI!O17 -> 1.8756 | CI14: =SEAI!P17 -> 1.8756 | CJ14: =SEAI!S17 -> 1.8756 | CK14: 5 | CN14: =BG14 -> MINBIOPIGW_S1 | CO14: =BH14 -> Pig waste - Lo | CP14: COST | CQ14: MEUR2014 | CR14: =BJ14 -> BIOSLU | CS14: €14/GJ | CT14: =SEAI!$L$17 -> 0 | CU14: =SEAI!$L$17 -> 0 | CV14: =SEAI!$L$17 -> 0 | CW14: =SEAI!$L$17 -> 0 | CX14: =SEAI!$L$17 -> 0 | CY14: =SEAI!$L$17 -> 0 | CZ14: =SEAI!$L$17 -> 0 | DA14: =SEAI!$L$17 -> 0 | ... DQ14: =SEAI!$L$17 -> 0 | DR14: 5
A15: BMSW - Lo | B15: BMSW | C15: 3097.2496 | D15: 4323.3142 | E15: 4875.7988 | F15: 6096.6311 | G15: 6263.0705 | H15: 6547.4643 | I15: 7056.7744 | J15: 7311.5358 | K15: 7525.0048 | L15: 7737.67 | M15: 7949.1679 | N15: 8114.5244 | O15: 8241.0581 | P15: 8370.1612 | Q15: 8487.7062 | R15: 8624.619 | S15: 8766.3294 | T15: 8910.3279 | U15: 9056.6504 | V15: 9205.3334 | W15: 9356.4139 | X15: 9509.9672 | Y15: 9666.0336 | Z15: 9824.6541 | AA15: 9985.8705 | AB15: 10149.725 | AD15: -1274.2435 | AE15: -1274.2435 | AF15: -1274.2435 | AG15: -1274.2435 | AH15: -1274.2435 | AI15: -1274.2435 | AJ15: -1274.2435 | AK15: -1274.2435 | AL15: -1274.2435 | AM15: -1274.2435 | AN15: -1274.2435 | AO15: -1274.2435 | AP15: -1274.2435 | AQ15: -1274.2435 | AR15: -1274.2435 | AS15: -1274.2435 | AT15: -1274.2435 | AU15: -1274.2435 | AV15: -1274.2435 | AW15: -1274.2435 | AX15: -1274.2435 | AY15: -1274.2435 | AZ15: -1274.2435 | BA15: -1274.2435 | BB15: -1274.2435 | BC15: -1274.2435 | BE15: _S1 | BG15: ="MINBIOMSW2"&BE15 -> MINBIOMSW2_S1 | BH15: =A15 -> BMSW - Lo | BI15: ACT_BND | BJ15: BIOMUN | BK15: PJ | BL15: =E15/1000*Conversions!$B$2 -> 0.20413994 | BM15: =F15/1000*Conversions!$B$2 -> 0.25525375 | BN15: =G15/1000*Conversions!$B$2 -> 0.26222224 | BO15: =H15/1000*Conversions!$B$2 -> 0.27412924 | BP15: =I15/1000*Conversions!$B$2 -> 0.29545303 | BQ15: =J15/1000*Conversions!$B$2 -> 0.30611938 | BR15: =K15/1000*Conversions!$B$2 -> 0.3150569 | BS15: =L15/1000*Conversions!$B$2 -> 0.32396077 | ... BV15: =O15/1000*Conversions!$B$2 -> 0.34503662 | BW15: =BX15 -> 4.5432 | BX15: =BY15 -> 4.5432 | BY15: =SEAI!N18 -> 4.5432 | CK15: 5 | CN15: =BG15 -> MINBIOMSW2_S1 | CO15: =BH15 -> BMSW - Lo | CP15: COST | CQ15: MEUR2014 | CR15: =BJ15 -> BIOMUN | CS15: €14/GJ | CT15: =SEAI!$L$18 -> -13.055556 | CU15: =SEAI!$L$18 -> -13.055556 | CV15: =SEAI!$L$18 -> -13.055556 | CW15: =SEAI!$L$18 -> -13.055556 | CX15: =SEAI!$L$18 -> -13.055556 | CY15: =SEAI!$L$18 -> -13.055556 | CZ15: =SEAI!$L$18 -> -13.055556 | DA15: =SEAI!$L$18 -> -13.055556 | ... DQ15: =SEAI!$L$18 -> -13.055556 | DR15: 5
A16: Willow - Lo | B16: Willow | C16: 0 | D16: 0 | E16: 0 | F16: 0 | G16: 839.54333 | H16: 1429.4927 | I16: 1903.812 | J16: 2217.7256 | K16: 2732.6455 | L16: 3260.0299 | M16: 3785.3572 | N16: 4322.7859 | O16: 4897.1243 | P16: 5510.5355 | Q16: 6165.3067 | R16: 6863.8561 | S16: 7608.7403 | T16: 8402.6623 | U16: 9248.4794 | V16: 10149.212 | W16: 11108.053 | X16: 12128.376 | Y16: 13213.75 | Z16: 14367.944 | AA16: 15594.942 | AB16: 15760.845 | AD16: 167.472 | AE16: 167.472 | AF16: 167.472 | AG16: 167.472 | AH16: 167.472 | AI16: 167.472 | AJ16: 167.472 | AK16: 167.472 | AL16: 167.472 | AM16: 167.472 | AN16: 167.472 | AO16: 167.472 | AP16: 167.472 | AQ16: 167.472 | AR16: 167.472 | AS16: 167.472 | AT16: 167.472 | AU16: 167.472 | AV16: 167.472 | AW16: 167.472 | AX16: 167.472 | AY16: 167.472 | AZ16: 167.472 | BA16: 167.472 | BB16: 167.472 | BC16: 167.472 | BE16: 1 | BG16: ="ABIOCRP4"&BE16 -> ABIOCRP41 | BH16: =A16 -> Willow - Lo | BI16: ACT_BND | BJ16: BIOWOO | BK16: PJ | BL16: =E16/1000*Conversions!$B$2 -> 0 | BM16: =F16/1000*Conversions!$B$2 -> 0 | BN16: =G16/1000*Conversions!$B$2 -> 0.03515 | BO16: =H16/1000*Conversions!$B$2 -> 0.05985 | BP16: =I16/1000*Conversions!$B$2 -> 0.0797088 | BQ16: =J16/1000*Conversions!$B$2 -> 0.092851733 | BR16: =K16/1000*Conversions!$B$2 -> 0.1144104 | BS16: =L16/1000*Conversions!$B$2 -> 0.13649093 | ... BV16: =O16/1000*Conversions!$B$2 -> 0.2050328 | BW16: =BX16 -> 0.882 | BX16: =BY16 -> 0.882 | BY16: =SEAI!N64 -> 0.882 | CD16: =SEAI!O64 -> 3.9204 | CI16: =SEAI!P64 -> 6.0552 | CJ16: =SEAI!S64 -> 6.0552 | CK16: 5 | CN16: =BG16 -> ABIOCRP41 | CO16: =BH16 -> Willow - Lo | CP16: ACTCOST | CQ16: MEUR2014 | CR16: =BJ16 -> BIOWOO | CS16: €14/GJ | CT16: =SEAI!$L$64 -> 6.3888889 | CU16: =SEAI!$L$64 -> 6.3888889 | CV16: =SEAI!$L$64 -> 6.3888889 | CW16: =SEAI!$L$64 -> 6.3888889 | CX16: =SEAI!$L$64 -> 6.3888889 | CY16: =SEAI!$L$64 -> 6.3888889 | CZ16: =SEAI!$L$64 -> 6.3888889 | DA16: =SEAI!$L$64 -> 6.3888889 | ... DQ16: =SEAI!$L$64 -> 6.3888889 | DR16: 5
A17: Miscanthus - Lo | B17: Miscanthus | C17: 0 | D17: 0 | E17: 0 | F17: 0 | G17: 721.55345 | H17: 1075.5231 | I17: 1384.1725 | J17: 1458.2943 | K17: 1477.2332 | L17: 1496.1721 | M17: 1757.1415 | N17: 2269.2175 | O17: 2818.2032 | P17: 3406.2617 | Q17: 4035.6802 | R17: 4708.8769 | S17: 5428.4085 | T17: 6196.9778 | U17: 7017.4421 | V17: 7892.822 | W17: 8826.3101 | X17: 9821.2812 | Y17: 10881.302 | Z17: 12010.143 | AA17: 13211.788 | AB17: 13352.339 | AD17: 167.472 | AE17: 167.472 | AF17: 167.472 | AG17: 167.472 | AH17: 167.472 | AI17: 167.472 | AJ17: 167.472 | AK17: 167.472 | AL17: 167.472 | AM17: 167.472 | AN17: 167.472 | AO17: 167.472 | AP17: 167.472 | AQ17: 167.472 | AR17: 167.472 | AS17: 167.472 | AT17: 167.472 | AU17: 167.472 | AV17: 167.472 | AW17: 167.472 | AX17: 167.472 | AY17: 167.472 | AZ17: 167.472 | BA17: 167.472 | BB17: 167.472 | BC17: 167.472 | BE17: 1 | BG17: ="ABIOCRP3"&BE17 -> ABIOCRP31 | BH17: =A17 -> Miscanthus - Lo | BI17: ACT_BND | BJ17: BIOWOO | BK17: PJ | BL17: =E17/1000*Conversions!$B$2 -> 0 | BM17: =F17/1000*Conversions!$B$2 -> 0 | BN17: =G17/1000*Conversions!$B$2 -> 0.03021 | BO17: =H17/1000*Conversions!$B$2 -> 0.04503 | BP17: =I17/1000*Conversions!$B$2 -> 0.057952533 | BQ17: =J17/1000*Conversions!$B$2 -> 0.061055867 | BR17: =K17/1000*Conversions!$B$2 -> 0.0618488 | BS17: =L17/1000*Conversions!$B$2 -> 0.062641733 | BT17: 0 | BU17: 0 | BV17: 0 | BW17: 0 | BX17: 0 | BY17: 0 | BZ17: 0 | CA17: 0 | CB17: 0 | CC17: 0 | CD17: 0 | CE17: 0 | CF17: 0 | CG17: 0 | CH17: 0 | CI17: 0 | CJ17: 0 | CK17: 5 | CN17: =BG17 -> ABIOCRP31 | CO17: =BH17 -> Miscanthus - Lo | CP17: ACTCOST | CQ17: MEUR2014 | CR17: =BJ17 -> BIOWOO | CS17: €14/GJ | CT17: =IF(AF17<0,0.01,AF17/Conversions!$B$3) -> 4 | CU17: =IF(AG17<0,0.01,AG17/Conversions!$B$3) -> 4 | CV17: =IF(AH17<0,0.01,AH17/Conversions!$B$3) -> 4 | CW17: =IF(AI17<0,0.01,AI17/Conversions!$B$3) -> 4 | CX17: =IF(AJ17<0,0.01,AJ17/Conversions!$B$3) -> 4 | CY17: =IF(AK17<0,0.01,AK17/Conversions!$B$3) -> 4 | CZ17: =IF(AL17<0,0.01,AL17/Conversions!$B$3) -> 4 | DA17: =IF(AM17<0,0.01,AM17/Conversions!$B$3) -> 4 | ... DQ17: =IF(BC17<0,0.01,BC17/Conversions!$B$3) -> 4 | DR17: 5
A18: Wheat - Lo | B18: Wheat | C18: 0 | D18: 0 | E18: 0 | F18: 0 | G18: 0 | H18: 0 | I18: 0 | J18: 0 | K18: 0 | L18: 0 | M18: 0 | N18: 0 | O18: 0 | P18: 0 | Q18: 0 | R18: 0 | S18: 0 | T18: 0 | U18: 0 | V18: 0 | W18: 0 | X18: 0 | Y18: 0 | Z18: 0 | AA18: 0 | AB18: 0 | AD18: 796.24812 | AE18: 796.24812 | AF18: 796.24812 | AG18: 796.24812 | AH18: 796.24812 | AI18: 796.24812 | AJ18: 796.24812 | AK18: 796.24812 | AL18: 796.24812 | AM18: 796.24812 | AN18: 796.24812 | AO18: 796.24812 | AP18: 796.24812 | AQ18: 796.24812 | AR18: 796.24812 | AS18: 796.24812 | AT18: 796.24812 | AU18: 796.24812 | AV18: 796.24812 | AW18: 796.24812 | AX18: 796.24812 | AY18: 796.24812 | AZ18: 796.24812 | BA18: 796.24812 | BB18: 796.24812 | BC18: 796.24812 | BE18: 1 | BG18: ="ABIOCRP1"&BE18 -> ABIOCRP11 | BH18: =A18 -> Wheat - Lo | BI18: ACT_BND | BJ18: BIOCRP1 | BK18: PJ | BL18: =E18/1000*Conversions!$B$2 -> 0 | BM18: =F18/1000*Conversions!$B$2 -> 0 | BN18: =G18/1000*Conversions!$B$2 -> 0 | BO18: =H18/1000*Conversions!$B$2 -> 0 | BP18: =I18/1000*Conversions!$B$2 -> 0 | BQ18: =J18/1000*Conversions!$B$2 -> 0 | BR18: =K18/1000*Conversions!$B$2 -> 0 | BS18: =L18/1000*Conversions!$B$2 -> 0 | BT18: 0 | BU18: 0 | BV18: 0 | BW18: 0 | BX18: 0 | BY18: 0 | BZ18: 0 | CA18: 0 | CB18: 0 | CC18: 0 | CD18: 0 | CE18: 0 | CF18: 0 | CG18: 0 | CH18: 0 | CI18: 0 | CJ18: 0 | CK18: 5 | CN18: =BG18 -> ABIOCRP11 | CO18: =BH18 -> Wheat - Lo | CP18: ACTCOST | CQ18: MEUR2014 | CR18: =BJ18 -> BIOCRP1 | CS18: €14/GJ | CT18: =IF(AF18<0,0.01,AF18/Conversions!$B$3) -> 19.01806 | CU18: =IF(AG18<0,0.01,AG18/Conversions!$B$3) -> 19.01806 | CV18: =IF(AH18<0,0.01,AH18/Conversions!$B$3) -> 19.01806 | CW18: =IF(AI18<0,0.01,AI18/Conversions!$B$3) -> 19.01806 | CX18: =IF(AJ18<0,0.01,AJ18/Conversions!$B$3) -> 19.01806 | CY18: =IF(AK18<0,0.01,AK18/Conversions!$B$3) -> 19.01806 | CZ18: =IF(AL18<0,0.01,AL18/Conversions!$B$3) -> 19.01806 | DA18: =IF(AM18<0,0.01,AM18/Conversions!$B$3) -> 19.01806 | ... DQ18: =IF(BC18<0,0.01,BC18/Conversions!$B$3) -> 19.01806 | DR18: 5
A19: OSR - Lo | B19: OSR | C19: 0 | D19: 0 | E19: 0 | F19: 0 | G19: 0 | H19: 0 | I19: 0 | J19: 0 | K19: 0 | L19: 0 | M19: 0 | N19: 0 | O19: 0 | P19: 0 | Q19: 0 | R19: 0 | S19: 0 | T19: 0 | U19: 0 | V19: 0 | W19: 0 | X19: 0 | Y19: 0 | Z19: 0 | AA19: 0 | AB19: 0 | AD19: 902.73276 | AE19: 902.73276 | AF19: 902.73276 | AG19: 902.73276 | AH19: 902.73276 | AI19: 902.73276 | AJ19: 902.73276 | AK19: 902.73276 | AL19: 902.73276 | AM19: 902.73276 | AN19: 902.73276 | AO19: 902.73276 | AP19: 902.73276 | AQ19: 902.73276 | AR19: 902.73276 | AS19: 902.73276 | AT19: 902.73276 | AU19: 902.73276 | AV19: 902.73276 | AW19: 902.73276 | AX19: 902.73276 | AY19: 902.73276 | AZ19: 902.73276 | BA19: 902.73276 | BB19: 902.73276 | BC19: 902.73276 | BE19: 1 | BG19: ="ABIOCRP2"&BE19 -> ABIOCRP21 | BH19: =A19 -> OSR - Lo | BI19: ACT_BND | BJ19: BIORPS | BK19: PJ | BL19: =E19/1000*Conversions!$B$2 -> 0 | BM19: =F19/1000*Conversions!$B$2 -> 0 | BN19: =G19/1000*Conversions!$B$2 -> 0 | BO19: =H19/1000*Conversions!$B$2 -> 0 | BP19: =I19/1000*Conversions!$B$2 -> 0 | BQ19: =J19/1000*Conversions!$B$2 -> 0 | BR19: =K19/1000*Conversions!$B$2 -> 0 | BS19: =L19/1000*Conversions!$B$2 -> 0 | BT19: 0 | BU19: 0 | BV19: 0 | BW19: 0 | BX19: 0 | BY19: 0 | BZ19: 0 | CA19: 0 | CB19: 0 | CC19: 0 | CD19: 0 | CE19: 0 | CF19: 0 | CG19: 0 | CH19: 0 | CI19: 0 | CJ19: 0 | CK19: 5 | CN19: =BG19 -> ABIOCRP21 | CO19: =BH19 -> OSR - Lo | CP19: ACTCOST | CQ19: MEUR2014 | CR19: =BJ19 -> BIORPS | CS19: €14/GJ | CT19: =IF(AF19<0,0.01,AF19/Conversions!$B$3) -> 21.561401 | CU19: =IF(AG19<0,0.01,AG19/Conversions!$B$3) -> 21.561401 | CV19: =IF(AH19<0,0.01,AH19/Conversions!$B$3) -> 21.561401 | CW19: =IF(AI19<0,0.01,AI19/Conversions!$B$3) -> 21.561401 | CX19: =IF(AJ19<0,0.01,AJ19/Conversions!$B$3) -> 21.561401 | CY19: =IF(AK19<0,0.01,AK19/Conversions!$B$3) -> 21.561401 | CZ19: =IF(AL19<0,0.01,AL19/Conversions!$B$3) -> 21.561401 | DA19: =IF(AM19<0,0.01,AM19/Conversions!$B$3) -> 21.561401 | ... DQ19: =IF(BC19<0,0.01,BC19/Conversions!$B$3) -> 21.561401 | DR19: 5
A20: Crops Anaerobic - Lo | B20: Anaerobic | C20: 0 | D20: 0 | E20: 0 | F20: 0 | G20: 0 | H20: 0 | I20: 27433.453 | J20: 28191.483 | K20: 28949.513 | L20: 29707.542 | M20: 30465.572 | N20: 31223.602 | O20: 31981.631 | P20: =AVERAGE(O20,Q20) -> 32739.661 | Q20: 33497.691 | R20: 34255.72 | S20: 35013.75 | T20: 35771.779 | U20: 36529.809 | V20: 37287.839 | W20: 38045.868 | X20: 38803.898 | Y20: 39561.928 | Z20: 40319.957 | AA20: 41077.987 | AB20: 41836.017 | AD20: 196.27917 | AE20: 196.27917 | AF20: 196.27917 | AG20: 196.27917 | AH20: 196.27917 | AI20: 196.27917 | AJ20: 196.27917 | AK20: 196.27917 | AL20: 196.27917 | AM20: 196.27917 | AN20: 196.27917 | AO20: 196.27917 | AP20: 196.27917 | AQ20: 196.27917 | AR20: 196.27917 | AS20: 196.27917 | AT20: 196.27917 | AU20: 196.27917 | AV20: 196.27917 | AW20: 196.27917 | AX20: 196.27917 | AY20: 196.27917 | AZ20: 196.27917 | BA20: 196.27917 | BB20: 196.27917 | BC20: 196.27917 | BE20: 1 | BG20: ="ABIOGAS1"&BE20 -> ABIOGAS11 | BH20: =A20 -> Crops Anaerobic - Lo | BI20: ACT_BND | BJ20: BIOGAS | BK20: PJ | BL20: =E20/1000*Conversions!$B$2 -> 0 | BM20: =F20/1000*Conversions!$B$2 -> 0 | BN20: =G20/1000*Conversions!$B$2 -> 0 | BO20: =H20/1000*Conversions!$B$2 -> 0 | BP20: =I20/1000*Conversions!$B$2 -> 1.1485838 | BQ20: =J20/1000*Conversions!$B$2 -> 1.180321 | BR20: =K20/1000*Conversions!$B$2 -> 1.2120582 | BS20: =L20/1000*Conversions!$B$2 -> 1.2437954 | ... BV20: =O20/1000*Conversions!$B$2 -> 1.3390069 | BW20: =BX20 -> 4.4388 | BX20: =BY20 -> 4.4388 | BY20: =SEAI!N48 -> 4.4388 | CD20: =SEAI!O48 -> 11.8332 | CI20: =SEAI!P48 -> 11.8332 | CJ20: =SEAI!S48 -> 11.8332 | CK20: 5 | CN20: =BG20 -> ABIOGAS11 | CO20: =BH20 -> Crops Anaerobic - Lo | CP20: ACTCOST | CQ20: MEUR2014 | CR20: =BJ20 -> BIOGAS | CS20: €14/GJ | CT20: =SEAI!$L$48 -> 14.694444 | CU20: =SEAI!$L$48 -> 14.694444 | CV20: =SEAI!$L$48 -> 14.694444 | CW20: =SEAI!$L$48 -> 14.694444 | CX20: =SEAI!$L$48 -> 14.694444 | CY20: =SEAI!$L$48 -> 14.694444 | CZ20: =SEAI!$L$48 -> 14.694444 | DA20: =SEAI!$L$48 -> 14.694444 | ... DQ20: =SEAI!$L$48 -> 14.694444 | DR20: 5
A21: Industrial Food - Lo | B21: IndFood | C21: 0 | D21: 0 | E21: 0 | F21: 0 | G21: 0 | H21: 13635.152 | I21: 13683.837 | J21: 13692.374 | K21: 13729.492 | L21: 13775.359 | M21: 13824.401 | N21: 13868.583 | O21: 13908.489 | P21: 13943.453 | Q21: 13972.354 | R21: 13996.313 | S21: 14014.004 | T21: 14026.093 | U21: 14033.5 | V21: 14037.148 | W21: 14037.755 | X21: 14035.926 | Y21: 14031.633 | Z21: 14025.377 | AA21: 14018.01 | AB21: 14009.21 | AD21: 0 | AE21: 0 | AF21: 0 | AG21: 0 | AH21: 0 | AI21: 0 | AJ21: 0 | AK21: 0 | AL21: 0 | AM21: 0 | AN21: 0 | AO21: 0 | AP21: 0 | AQ21: 0 | AR21: 0 | AS21: 0 | AT21: 0 | AU21: 0 | AV21: 0 | AW21: 0 | AX21: 0 | AY21: 0 | AZ21: 0 | BA21: 0 | BB21: 0 | BC21: 0 | BE21: _S1 | BG21: ="MINBIOINDF"&BE21 -> MINBIOINDF_S1 | BH21: =A21 -> Industrial Food - Lo | BI21: ACT_BND | BJ21: BIOSLU | BK21: PJ | BL21: =E21/1000*Conversions!$B$2 -> 0 | BM21: =F21/1000*Conversions!$B$2 -> 0 | BN21: =G21/1000*Conversions!$B$2 -> 0 | BO21: =H21/1000*Conversions!$B$2 -> 0.57087653 | BP21: =I21/1000*Conversions!$B$2 -> 0.57291491 | BQ21: =J21/1000*Conversions!$B$2 -> 0.57327233 | BR21: =K21/1000*Conversions!$B$2 -> 0.57482637 | BS21: =L21/1000*Conversions!$B$2 -> 0.57674672 | ... BV21: =O21/1000*Conversions!$B$2 -> 0.58232064 | BW21: =BX21 -> 0.2772 | BX21: =BY21 -> 0.2772 | BY21: =SEAI!N22 -> 0.2772 | CD21: =SEAI!O22 -> 0.3492 | CI21: =SEAI!P22 -> 0.3492 | CJ21: =SEAI!S22 -> 0.3492 | CK21: 5 | CN21: =BG21 -> MINBIOINDF_S1 | CO21: =BH21 -> Industrial Food - Lo | CP21: COST | CQ21: MEUR2014 | CR21: =BJ21 -> BIOSLU | CS21: €14/GJ | CT21: =SEAI!$L$22 -> 0 | CU21: =SEAI!$L$22 -> 0 | CV21: =SEAI!$L$22 -> 0 | CW21: =SEAI!$L$22 -> 0 | CX21: =SEAI!$L$22 -> 0 | CY21: =SEAI!$L$22 -> 0 | CZ21: =SEAI!$L$22 -> 0 | DA21: =SEAI!$L$22 -> 0 | ... DQ21: =SEAI!$L$22 -> 0 | DR21: 5
A23: Resource at medium price | AD23: Medium Price
A24: Feedstock | B24: Sheet Name | C24: Total Available for Bioenergy use (toe) | AD24: Feestock price (€/toe)
C25: 2010 | D25: 2011 | E25: 2012 | F25: 2013 | G25: 2014 | H25: 2015 | I25: 2016 | J25: 2017 | K25: 2018 | L25: 2019 | M25: 2020 | N25: 2021 | O25: 2022 | P25: 2023 | Q25: 2024 | R25: 2025 | S25: 2026 | T25: 2027 | U25: 2028 | V25: 2029 | W25: 2030 | X25: 2031 | Y25: 2032 | Z25: 2033 | AA25: 2034 | AB25: 2035 | AD25: 2010 | AE25: 2011 | AF25: 2012 | AG25: 2013 | AH25: 2014 | AI25: 2015 | AJ25: 2016 | AK25: 2017 | AL25: 2018 | AM25: 2019 | AN25: 2020 | AO25: 2021 | AP25: 2022 | AQ25: 2023 | AR25: 2024 | AS25: 2025 | AT25: 2026 | AU25: 2027 | AV25: 2028 | AW25: 2029 | AX25: 2030 | AY25: 2031 | AZ25: 2032 | BA25: 2033 | BB25: 2034 | BC25: 2035 | BG25: Potentials at medium price
BG26: TFM_INS-TS | CN26: TFM_INS-TS
BG27: Pset_PN | BH27: *Description | BI27: Attribute | BJ27: *Output | BK27: *Unit | BL27: 2012 | BM27: 2013 | BN27: 2014 | BO27: 2015 | BP27: 2016 | BQ27: 2017 | BR27: 2018 | BS27: 2019 | BT27: 2020 | BU27: 2021 | BV27: 2022 | BW27: 2023 | BX27: 2024 | BY27: 2025 | BZ27: 2026 | CA27: 2027 | CB27: 2028 | CC27: 2029 | CD27: 2030 | CE27: 2031 | CF27: 2032 | CG27: 2033 | CH27: 2034 | CI27: 2035 | CJ27: 2050 | CK27: 0 | CN27: Pset_PN | CO27: *Description | CP27: Attribute | CQ27: Curr | CR27: *Output | CS27: *Unit | CT27: 2012 | CU27: 2013 | CV27: 2014 | CW27: 2015 | CX27: 2016 | CY27: 2017 | CZ27: 2018 | DA27: 2019 | DB27: 2020 | DC27: 2021 | DD27: 2022 | DE27: 2023 | DF27: 2024 | DG27: 2025 | DH27: 2026 | DI27: 2027 | DJ27: 2028 | DK27: 2029 | DL27: 2030 | DM27: 2031 | DN27: 2032 | DO27: 2033 | DP27: 2034 | DQ27: 2035 | DR27: 0
